Workbook

Sheet Compras
A1: Total: | B1: =C2+C8+C13+C18+C23+C28+C32+C34+C38+C50 -> 0 | E1: Deck | F1: =A2 -> Marcelo | G1: =B3 -> Victor | H1: =B4 -> Hamster | I1: =B5 -> Marcelo | J1: =B6 -> Liga | L1: Deck | M1: Entra | N1: Sai | O1: Fonte
A2: Marcelo | B2: Total Lojas: | C2: =SUM(C3:C6) -> 0 | F2: Jhoira | L2: Arabella | M2: Take Up The Shield | O2: Leilão 3
A3: =COUNTA(F2:F215) -> 4 | B3: Victor | C3: =SUM(G:G) -> 0 | F3: JhoiraB | L3: Hivelord | M3: Avenge | O3: Leilão 3
B4: Hamster | C4: =SUM(H:H) -> 0 | F4: 4cRash | L4: Inalla | M4: Gilded Lotus | N4: Mana Echoes | O4: Leilão 3
B5: Marcelo | C5: =SUM(I:I) -> 0 | F5: Baylen | L5: Oona | M5: The Great Mound | N5: Island | O5: Leilão 3
B6: Liga | C6: =SUM(J:J) -> 0 | L6: Sisay | M6: Freyalise, Llanowar's Fury | N6: Life Insurance | O6: Elfos
L7: Thrakiri | M7: Plaza of Heroes | N7: Kessig Wolf Run | O7: Leilão 3
L8: Oona | M8: Arc Reactor | N8: Spell Stuter | O8: Rei
L9: Oona | M9: Shuri, Wakandan Inventor | N9: Liliana of the Dark Realms | O9: Rei
L10: Toph | M10: Coin of Mastery | N10: Harrow | O10: Rei
L11: Toph | M11: The Ooze | N11: Costume Closet | O11: Rei
L12: Spara | M12: Kellan, the Kid | N12: Omnivorous Flytrap | O12: Rei
L13: Arabella | M13: Battle Screech | O13: Rei
L14: Sisay | M14: The Peregrine Dynamo | N14: Urza Assembles the Titans | O14: Rei
L15: Arabella | M15: Genasi Enforcers | O15: Rei
L16: Arabella | M16: Wyrm's Crossing Patrol | O16: Rei
L17: Arabella | M17: Clowning Around | O17: Rei
L18: Arabella | M18: Blacksmith's Skill | O18: Rei
L19: Baylen | M19: Artifact Mutation | N19: Chatterstorm | O19: Rei
L20: Arabella | M20: Goblin Smuggler | O20: Rei
L21: Arabella | M21: Goblin Instigator | O21: Rei
L22: Alela | M22: Damping Sphere | N22: Dispeller's Capsule | O22: Rei
L23: Arabella | M23: Pathmaker Initiate | O23: Rei
L24: Yorion | M24: Ephara, God of the Polis | N24: Ellyn Harbreeze, Busybody | O24: Rei
L25: Pests | M25: Nuisance Engine | N25: Tablet of the Guilds | O25: Rei
L26: Arabella | M26: Goblin Tunneler | O26: Rei
L27: Arabella | M27: Gold Myr | O27: Rei

Sheet Missing
A1: Nome da Origem | B1: Carta Ideal | C1: Em Uso | D1: Deck | F1: Alterações | H1: Cores | M1: =COUNTA(F3:F5000) & " Decks" -> 37 Decks
A2: Narset.xlsx | B2: Abandoned Air Temple | C2: =IF(COUNTIF(Substitutas!$B:$B, B2) > 0, "✅ Tenho", "❌ Faltando") -> ❌ Faltando | D2: =_xlfn.XLOOKUP(B2, Substitutas!$B:$B, Substitutas!$A:$A, "-") -> - | F2: Total | G2: =SUM(G3:G62) -> 410 | H2: =COUNTIF(H3:H5000,"Sim") -> 23 | I2: =COUNTIF(I3:I5000,"Sim") -> 27 | J2: =COUNTIF(J3:J5000,"Sim") -> 27 | K2: =COUNTIF(K3:K5000,"Sim") -> 27 | L2: =COUNTIF(L3:L5000,"Sim") -> 23 | M2: Wincon | N2: Sub Plan | O2: Descrição | P2: Prioridade
A3: Spara.xlsx | B3: Abandoned Air Temple | C3: =IF(COUNTIF(Substitutas!$B:$B, B3) > 0, "✅ Tenho", "❌ Faltando") -> ❌ Faltando | D3: =_xlfn.XLOOKUP(B3, Substitutas!$B:$B, Substitutas!$A:$A, "-") -> - | G3: =COUNTIF(A:A,F3&".xlsx") -> 0 | H3: Não | I3: Não | J3: Não | K3: Não | L3: Não | P3: =IF(G3<6,"1",IF(G3<11,"2",IF(G3<16,"3",IF(G3<31,"4","5")))) -> 1
A4: Kadena.xlsx | B4: Abhorrent Oculus | C4: =IF(COUNTIF(Substitutas!$B:$B, B4) > 0, "✅ Tenho", "❌ Faltando") -> ❌ Faltando | D4: =_xlfn.XLOOKUP(B4, Substitutas!$B:$B, Substitutas!$A:$A, "-") -> - | G4: =COUNTIF(A:A,F4&".xlsx") -> 0 | H4: Sim | I4: Não | J4: Não | K4: Não | L4: Não | P4: =IF(G4<6,"1",IF(G4<11,"2",IF(G4<16,"3",IF(G4<31,"4","5")))) -> 1
A5: Arabella.xlsx | B5: Abraded Bluffs | C5: =IF(COUNTIF(Substitutas!$B:$B, B5) > 0, "✅ Tenho", "❌ Faltando") -> ❌ Faltando | D5: =_xlfn.XLOOKUP(B5, Substitutas!$B:$B, Substitutas!$A:$A, "-") -> - | F5: Muzzio | G5: =COUNTIF(A:A,F5&".xlsx") -> 4 | H5: Não | I5: Sim | J5: Não | K5: Não | L5: Não | M5: Combo | N5: - | O5: Engrenagens para Combar | P5: =IF(G5<6,"1",IF(G5<11,"2",IF(G5<16,"3",IF(G5<31,"4","5")))) -> 1
A6: Pé.xlsx | B6: Abrupt Decay | C6: =IF(COUNTIF(Substitutas!$B:$B, B6) > 0, "✅ Tenho", "❌ Faltando") -> ❌ Faltando | D6: =_xlfn.XLOOKUP(B6, Substitutas!$B:$B, Substitutas!$A:$A, "-") -> - | G6: =COUNTIF(A:A,F6&".xlsx") -> 0 | H6: Não | I6: Não | J6: Sim | K6: Não | L6: Não | P6: =IF(G6<6,"1",IF(G6<11,"2",IF(G6<16,"3",IF(G6<31,"4","5")))) -> 1
A7: Elfos.xlsx | B7: Abundant Countryside | C7: =IF(COUNTIF(Substitutas!$B:$B, B7) > 0, "✅ Tenho", "❌ Faltando") -> ❌ Faltando | D7: =_xlfn.XLOOKUP(B7, Substitutas!$B:$B, Substitutas!$A:$A, "-") -> - | G7: =COUNTIF(A:A,F7&".xlsx") -> 0 | H7: Não | I7: Não | J7: Não | K7: Sim | L7: Não | P7: =IF(G7<6,"1",IF(G7<11,"2",IF(G7<16,"3",IF(G7<31,"4","5")))) -> 1
A8: Fractius.xlsx | B8: Abundant Countryside | C8: =IF(COUNTIF(Substitutas!$B:$B, B8) > 0, "✅ Tenho", "❌ Faltando") -> ❌ Faltando | D8: =_xlfn.XLOOKUP(B8, Substitutas!$B:$B, Substitutas!$A:$A, "-") -> - | G8: =COUNTIF(A:A,F8&".xlsx") -> 0 | H8: Não | I8: Não | J8: Não | K8: Não | L8: Sim | P8: =IF(G8<6,"1",IF(G8<11,"2",IF(G8<16,"3",IF(G8<31,"4","5")))) -> 1
A9: Rani.xlsx | B9: Access Tunnel | C9: =IF(COUNTIF(Substitutas!$B:$B, B9) > 0, "✅ Tenho", "❌ Faltando") -> ❌ Faltando | D9: =_xlfn.XLOOKUP(B9, Substitutas!$B:$B, Substitutas!$A:$A, "-") -> - | F9: Yorion | G9: =COUNTIF(A:A,F9&".xlsx") -> 11 | H9: Sim | I9: Sim | J9: Não | K9: Não | L9: Não | P9: =IF(G9<6,"1",IF(G9<11,"2",IF(G9<16,"3",IF(G9<31,"4","5")))) -> 3
A10: Narset.xlsx | B10: Adarkar Wastes | C10: =IF(COUNTIF(Substitutas!$B:$B, B10) > 0, "✅ Tenho", "❌ Faltando") -> ❌ Faltando | D10: =_xlfn.XLOOKUP(B10, Substitutas!$B:$B, Substitutas!$A:$A, "-") -> - | F10: Arabella | G10: =COUNTIF(A:A,F10&".xlsx") -> 75 | H10: Sim | I10: Não | J10: Sim | K10: Não | L10: Não | M10: Combate | N10: Ping | O10: PauperEDH Aggro | P10: =IF(G10<6,"1",IF(G10<11,"2",IF(G10<16,"3",IF(G10<31,"4","5")))) -> 5
A11: Jhoira.xlsx | B11: Agna Qel'a | C11: =IF(COUNTIF(Substitutas!$B:$B, B11) > 0, "✅ Tenho", "❌ Faltando") -> ❌ Faltando | D11: =_xlfn.XLOOKUP(B11, Substitutas!$B:$B, Substitutas!$A:$A, "-") -> - | F11: Akiri | G11: =COUNTIF(A:A,F11&".xlsx") -> 12 | H11: Sim | I11: Não | J11: Sim | K11: Não | L11: Não | M11: Combate | N11: Voltron | O11: Equipamentos | P11: =IF(G11<6,"1",IF(G11<11,"2",IF(G11<16,"3",IF(G11<31,"4","5")))) -> 3
A12: JhoiraBichao.xlsx | B12: Agna Qel'a | C12: =IF(COUNTIF(Substitutas!$B:$B, B12) > 0, "✅ Tenho", "❌ Faltando") -> ❌ Faltando | D12: =_xlfn.XLOOKUP(B12, Substitutas!$B:$B, Substitutas!$A:$A, "-") -> - | F12: Carlos | G12: =COUNTIF(A:A,F12&".xlsx") -> 5 | H12: Sim | I12: Não | J12: Não | K12: Sim | L12: Não | M12: Voltron | N12: Dano Direto | O12: Ganhar Vida e Reanimate | P12: =IF(G12<6,"1",IF(G12<11,"2",IF(G12<16,"3",IF(G12<31,"4","5")))) -> 1
A13: Rielle.xlsx | B13: Agna Qel'a | C13: =IF(COUNTIF(Substitutas!$B:$B, B13) > 0, "✅ Tenho", "❌ Faltando") -> ❌ Faltando | D13: =_xlfn.XLOOKUP(B13, Substitutas!$B:$B, Substitutas!$A:$A, "-") -> - | G13: =COUNTIF(A:A,F13&".xlsx") -> 0 | H13: Sim | I13: Não | J13: Não | K13: Não | L13: Sim | P13: =IF(G13<6,"1",IF(G13<11,"2",IF(G13<16,"3",IF(G13<31,"4","5")))) -> 1
A14: Littles.xlsx | B14: Ainok Strike Leader | C14: =IF(COUNTIF(Substitutas!$B:$B, B14) > 0, "✅ Tenho", "❌ Faltando") -> ❌ Faltando | D14: =_xlfn.XLOOKUP(B14, Substitutas!$B:$B, Substitutas!$A:$A, "-") -> - | F14: JhoiraBichao | G14: =COUNTIF(A:A,F14&".xlsx") -> 9 | H14: Não | I14: Sim | J14: Sim | K14: Não | L14: Não | M14: Combo | N14: Combate | O14: Big Mana | P14: =IF(G14<6,"1",IF(G14<11,"2",IF(G14<16,"3",IF(G14<31,"4","5")))) -> 2
A15: Arcades.xlsx | B15: Alchemist's Refuge | C15: =IF(COUNTIF(Substitutas!$B:$B, B15) > 0, "✅ Tenho", "❌ Faltando") -> ❌ Faltando | D15: =_xlfn.XLOOKUP(B15, Substitutas!$B:$B, Substitutas!$A:$A, "-") -> - | F15: Jhoira | G15: =COUNTIF(A:A,F15&".xlsx") -> 5 | H15: Não | I15: Sim | J15: Sim | K15: Não | L15: Não | M15: Combo | N15: Combate | O15: Destruição em Massa | P15: =IF(G15<6,"1",IF(G15<11,"2",IF(G15<16,"3",IF(G15<31,"4","5")))) -> 1
A16: Spara.xlsx | B16: Alchemist's Refuge | C16: =IF(COUNTIF(Substitutas!$B:$B, B16) > 0, "✅ Tenho", "❌ Faltando") -> ❌ Faltando | D16: =_xlfn.XLOOKUP(B16, Substitutas!$B:$B, Substitutas!$A:$A, "-") -> - | F16: Rielle | G16: =COUNTIF(A:A,F16&".xlsx") -> 9 | H16: Não | I16: Sim | J16: Sim | K16: Não | L16: Não | M16: Voltron | N16: Dano Direto | O16: Controle Voltron x1 | P16: =IF(G16<6,"1",IF(G16<11,"2",IF(G16<16,"3",IF(G16<31,"4","5")))) -> 2
A17: Arabella.xlsx | B17: Alpine Meadow | C17: =IF(COUNTIF(Substitutas!$B:$B, B17) > 0, "✅ Tenho", "❌ Faltando") -> ❌ Faltando | D17: =_xlfn.XLOOKUP(B17, Substitutas!$B:$B, Substitutas!$A:$A, "-") -> - | F17: Yuriko | G17: =COUNTIF(A:A,F17&".xlsx") -> 9 | H17: Não | I17: Sim | J17: Não | K17: Sim | L17: Não | M17: Ping | N17: - | O17: Turnos Extras | P17: =IF(G17<6,"1",IF(G17<11,"2",IF(G17<16,"3",IF(G17<31,"4","5")))) -> 2
A18: VialIshai.xlsx | B18: Amphibian Downpour | C18: =IF(COUNTIF(Substitutas!$B:$B, B18) > 0, "✅ Tenho", "❌ Faltando") -> ❌ Faltando | D18: =_xlfn.XLOOKUP(B18, Substitutas!$B:$B, Substitutas!$A:$A, "-") -> - | F18: Oona | G18: =COUNTIF(A:A,F18&".xlsx") -> 3 | H18: Não | I18: Sim | J18: Não | K18: Sim | L18: Não | M18: Mill | N18: Combate | O18: Mill e Tokens | P18: =IF(G18<6,"1",IF(G18<11,"2",IF(G18<16,"3",IF(G18<31,"4","5")))) -> 1
A19: Spara.xlsx | B19: An Offer You Can't Refuse | C19: =IF(COUNTIF(Substitutas!$B:$B, B19) > 0, "✅ Tenho", "❌ Faltando") -> ❌ Faltando | D19: =_xlfn.XLOOKUP(B19, Substitutas!$B:$B, Substitutas!$A:$A, "-") -> - | F19: Kumena | G19: =COUNTIF(A:A,F19&".xlsx") -> 0 | H19: Não | I19: Sim | J19: Não | K19: Não | L19: Sim | M19: Combate | N19: Voltron | O19: Tribal de Tritões | P19: =IF(G19<6,"1",IF(G19<11,"2",IF(G19<16,"3",IF(G19<31,"4","5")))) -> 1
A20: Yorion.xlsx | B20: An Offer You Can't Refuse | C20: =IF(COUNTIF(Substitutas!$B:$B, B20) > 0, "✅ Tenho", "❌ Faltando") -> ❌ Faltando | D20: =_xlfn.XLOOKUP(B20, Substitutas!$B:$B, Substitutas!$A:$A, "-") -> - | G20: =COUNTIF(A:A,F20&".xlsx") -> 0 | H20: Não | I20: Não | J20: Sim | K20: Sim | L20: Não | P20: =IF(G20<6,"1",IF(G20<11,"2",IF(G20<16,"3",IF(G20<31,"4","5")))) -> 1
A21: Littles.xlsx | B21: Anguished Unmaking | C21: =IF(COUNTIF(Substitutas!$B:$B, B21) > 0, "✅ Tenho", "❌ Faltando") -> ❌ Faltando | D21: =_xlfn.XLOOKUP(B21, Substitutas!$B:$B, Substitutas!$A:$A, "-") -> - | G21: =COUNTIF(A:A,F21&".xlsx") -> 0 | H21: Não | I21: Não | J21: Sim | K21: Não | L21: Sim | P21: =IF(G21<6,"1",IF(G21<11,"2",IF(G21<16,"3",IF(G21<31,"4","5")))) -> 1
A22: Necrobloom.xlsx | B22: Anguished Unmaking | C22: =IF(COUNTIF(Substitutas!$B:$B, B22) > 0, "✅ Tenho", "❌ Faltando") -> ❌ Faltando | D22: =_xlfn.XLOOKUP(B22, Substitutas!$B:$B, Substitutas!$A:$A, "-") -> - | F22: Pé | G22: =COUNTIF(A:A,F22&".xlsx") -> 29 | H22: Não | I22: Não | J22: Não | K22: Sim | L22: Sim | M22: Ping | N22: Combate | O22: Aristocrata | P22: =IF(G22<6,"1",IF(G22<11,"2",IF(G22<16,"3",IF(G22<31,"4","5")))) -> 4
A23: Inalla.xlsx | B23: Apprentice Necromancer | C23: =IF(COUNTIF(Substitutas!$B:$B, B23) > 0, "✅ Tenho", "❌ Faltando") -> ❌ Faltando | D23: =_xlfn.XLOOKUP(B23, Substitutas!$B:$B, Substitutas!$A:$A, "-") -> - | F23: Pests | G23: =COUNTIF(A:A,F23&".xlsx") -> 19 | H23: Não | I23: Não | J23: Não | K23: Sim | L23: Sim | M23: Combate | N23: Voltron | O23: Tribal de Pestes | P23: =IF(G23<6,"1",IF(G23<11,"2",IF(G23<16,"3",IF(G23<31,"4","5")))) -> 4
A24: Pests.xlsx | B24: Arasta of the Endless Web | C24: =IF(COUNTIF(Substitutas!$B:$B, B24) > 0, "✅ Tenho", "❌ Faltando") -> ❌ Faltando | D24: =_xlfn.XLOOKUP(B24, Substitutas!$B:$B, Substitutas!$A:$A, "-") -> - | F24: Narset | G24: =COUNTIF(A:A,F24&".xlsx") -> 15 | H24: Sim | I24: Sim | J24: Sim | K24: Não | L24: Não | M24: Mill | N24: Combate | O24: Mill e Tokens | P24: =IF(G24<6,"1",IF(G24<11,"2",IF(G24<16,"3",IF(G24<31,"4","5")))) -> 3
A25: Muzzio.xlsx | B25: Arc Reactor | C25: =IF(COUNTIF(Substitutas!$B:$B, B25) > 0, "✅ Tenho", "❌ Faltando") -> ❌ Faltando | D25: =_xlfn.XLOOKUP(B25, Substitutas!$B:$B, Substitutas!$A:$A, "-") -> - | F25: Zedruu | G25: =COUNTIF(A:A,F25&".xlsx") -> 1 | H25: Sim | I25: Sim | J25: Sim | K25: Não | L25: Não | M25: Dano Direto | N25: Combo | O25: Caos | P25: =IF(G25<6,"1",IF(G25<11,"2",IF(G25<16,"3",IF(G25<31,"4","5")))) -> 1
A26: Oona.xlsx | B26: Arc Reactor | C26: =IF(COUNTIF(Substitutas!$B:$B, B26) > 0, "✅ Tenho", "❌ Faltando") -> ❌ Faltando | D26: =_xlfn.XLOOKUP(B26, Substitutas!$B:$B, Substitutas!$A:$A, "-") -> - | F26: Alela | G26: =COUNTIF(A:A,F26&".xlsx") -> 6 | H26: Sim | I26: Sim | J26: Não | K26: Sim | L26: Não | M26: Combate | N26: Voltron | O26: Stax e Tokens | P26: =IF(G26<6,"1",IF(G26<11,"2",IF(G26<16,"3",IF(G26<31,"4","5")))) -> 2
A27: Spara.xlsx | B27: Arcane Denial | C27: =IF(COUNTIF(Substitutas!$B:$B, B27) > 0, "✅ Tenho", "❌ Faltando") -> ❌ Faltando | D27: =_xlfn.XLOOKUP(B27, Substitutas!$B:$B, Substitutas!$A:$A, "-") -> - | F27: Arcades | G27: =COUNTIF(A:A,F27&".xlsx") -> 1 | H27: Sim | I27: Sim | J27: Não | K27: Não | L27: Sim | M27: Combate | N27: Voltron | O27: Bater sem Apanhar | P27: =IF(G27<6,"1",IF(G27<11,"2",IF(G27<16,"3",IF(G27<31,"4","5")))) -> 1
A28: Pé.xlsx | B28: Arcane Signet | C28: =IF(COUNTIF(Substitutas!$B:$B, B28) > 0, "✅ Tenho", "❌ Faltando") -> ❌ Faltando | D28: =_xlfn.XLOOKUP(B28, Substitutas!$B:$B, Substitutas!$A:$A, "-") -> - | F28: Littles | G28: =COUNTIF(A:A,F28&".xlsx") -> 23 | H28: Sim | I28: Não | J28: Sim | K28: Sim | L28: Não | M28: Combate | N28: Ping | O28: Aggro Small Creatures | P28: =IF(G28<6,"1",IF(G28<11,"2",IF(G28<16,"3",IF(G28<31,"4","5")))) -> 4
A29: VialIshai.xlsx | B29: Arid Mesa | C29: =IF(COUNTIF(Substitutas!$B:$B, B29) > 0, "✅ Tenho", "❌ Faltando") -> ❌ Faltando | D29: =_xlfn.XLOOKUP(B29, Substitutas!$B:$B, Substitutas!$A:$A, "-") -> - | F29: Zuko | G29: =COUNTIF(A:A,F29&".xlsx") -> 19 | H29: Sim | I29: Não | J29: Sim | K29: Sim | L29: Não | M29: Combate | N29: Voltron | O29: Sunforge Exile | P29: =IF(G29<6,"1",IF(G29<11,"2",IF(G29<16,"3",IF(G29<31,"4","5")))) -> 4
A30: Baylen.xlsx | B30: Artifact Mutation | C30: =IF(COUNTIF(Substitutas!$B:$B, B30) > 0, "✅ Tenho", "❌ Faltando") -> ❌ Faltando | D30: =_xlfn.XLOOKUP(B30, Substitutas!$B:$B, Substitutas!$A:$A, "-") -> - | F30: Baylen | G30: =COUNTIF(A:A,F30&".xlsx") -> 15 | H30: Sim | I30: Não | J30: Sim | K30: Não | L30: Sim | M30: Voltron | N30: Combate | O30: Muitos Tokens | P30: =IF(G30<6,"1",IF(G30<11,"2",IF(G30<16,"3",IF(G30<31,"4","5")))) -> 3
A31: Spara.xlsx | B31: Arwen, Weaver of Hope | C31: =IF(COUNTIF(Substitutas!$B:$B, B31) > 0, "✅ Tenho", "❌ Faltando") -> ❌ Faltando | D31: =_xlfn.XLOOKUP(B31, Substitutas!$B:$B, Substitutas!$A:$A, "-") -> - | F31: Toph | G31: =COUNTIF(A:A,F31&".xlsx") -> 10 | H31: Sim | I31: Não | J31: Sim | K31: Não | L31: Sim | M31: Combate | N31: - | O31: Marcador e Modular | P31: =IF(G31<6,"1",IF(G31<11,"2",IF(G31<16,"3",IF(G31<31,"4","5")))) -> 2
A32: Hivelord.xlsx | B32: Asceticism | C32: =IF(COUNTIF(Substitutas!$B:$B, B32) > 0, "✅ Tenho", "❌ Faltando") -> ❌ Faltando | D32: =_xlfn.XLOOKUP(B32, Substitutas!$B:$B, Substitutas!$A:$A, "-") -> - | G32: =COUNTIF(A:A,F32&".xlsx") -> 0 | H32: Sim | I32: Não | J32: Não | K32: Sim | L32: Sim | P32: =IF(G32<6,"1",IF(G32<11,"2",IF(G32<16,"3",IF(G32<31,"4","5")))) -> 1
A33: Baylen.xlsx | B33: Aura Mutation | C33: =IF(COUNTIF(Substitutas!$B:$B, B33) > 0, "✅ Tenho", "❌ Faltando") -> ❌ Faltando | D33: =_xlfn.XLOOKUP(B33, Substitutas!$B:$B, Substitutas!$A:$A, "-") -> - | F33: OWA | G33: =COUNTIF(A:A,F33&".xlsx") -> 5 | H33: Sim | I33: Não | J33: Não | K33: Sim | L33: Sim | M33: Combate | N33: Dano Direto | O33: Tokens e Reanimate | P33: =IF(G33<6,"1",IF(G33<11,"2",IF(G33<16,"3",IF(G33<31,"4","5")))) -> 1
A34: Carlos.xlsx | B34: Authority of the Consuls | C34: =IF(COUNTIF(Substitutas!$B:$B, B34) > 0, "✅ Tenho", "❌ Faltando") -> ❌ Faltando | D34: =_xlfn.XLOOKUP(B34, Substitutas!$B:$B, Substitutas!$A:$A, "-") -> - | F34: Piratas | G34: =COUNTIF(A:A,F34&".xlsx") -> 2 | H34: Não | I34: Sim | J34: Sim | K34: Sim | L34: Não | M34: Combate | N34: Combo | O34: Tesouros e Roubos | P34: =IF(G34<6,"1",IF(G34<11,"2",IF(G34<16,"3",IF(G34<31,"4","5")))) -> 1
A35: Yorion.xlsx | B35: Avatar's Wrath | C35: =IF(COUNTIF(Substitutas!$B:$B, B35) > 0, "✅ Tenho", "❌ Faltando") -> ❌ Faltando | D35: =_xlfn.XLOOKUP(B35, Substitutas!$B:$B, Substitutas!$A:$A, "-") -> - | F35: Rani | G35: =COUNTIF(A:A,F35&".xlsx") -> 4 | H35: Não | I35: Sim | J35: Sim | K35: Sim | L35: Não | M35: Combate | N35: Voltron | O35: Atiçar e Investigar | P35: =IF(G35<6,"1",IF(G35<11,"2",IF(G35<16,"3",IF(G35<31,"4","5")))) -> 1
A36: Zuko.xlsx | B36: Avatar's Wrath | C36: =IF(COUNTIF(Substitutas!$B:$B, B36) > 0, "✅ Tenho", "❌ Faltando") -> ❌ Faltando | D36: =_xlfn.XLOOKUP(B36, Substitutas!$B:$B, Substitutas!$A:$A, "-") -> - | F36: Inalla | G36: =COUNTIF(A:A,F36&".xlsx") -> 13 | H36: Não | I36: Sim | J36: Sim | K36: Sim | L36: Não | M36: Combo | N36: Dano Direto | O36: Magos e Combos | P36: =IF(G36<6,"1",IF(G36<11,"2",IF(G36<16,"3",IF(G36<31,"4","5")))) -> 3
A37: Zuko.xlsx | B37: Axgard Armory | C37: =IF(COUNTIF(Substitutas!$B:$B, B37) > 0, "✅ Tenho", "❌ Faltando") -> ❌ Faltando | D37: =_xlfn.XLOOKUP(B37, Substitutas!$B:$B, Substitutas!$A:$A, "-") -> - | G37: =COUNTIF(A:A,F37&".xlsx") -> 0 | H37: Não | I37: Sim | J37: Sim | K37: Não | L37: Sim | P37: =IF(G37<6,"1",IF(G37<11,"2",IF(G37<16,"3",IF(G37<31,"4","5")))) -> 1
A38: Hivelord.xlsx | B38: Azorius Signet | C38: =IF(COUNTIF(Substitutas!$B:$B, B38) > 0, "✅ Tenho", "❌ Faltando") -> ❌ Faltando | D38: =_xlfn.XLOOKUP(B38, Substitutas!$B:$B, Substitutas!$A:$A, "-") -> - | F38: Kadena | G38: =COUNTIF(A:A,F38&".xlsx") -> 8 | H38: Não | I38: Sim | J38: Não | K38: Sim | L38: Sim | M38: Combate | N38: - | O38: Morph Control | P38: =IF(G38<6,"1",IF(G38<11,"2",IF(G38<16,"3",IF(G38<31,"4","5")))) -> 2
A39: Rani.xlsx | B39: Baeloth Barrityl, Entertainer | C39: =IF(COUNTIF(Substitutas!$B:$B, B39) > 0, "✅ Tenho", "❌ Faltando") -> ❌ Faltando | D39: =_xlfn.XLOOKUP(B39, Substitutas!$B:$B, Substitutas!$A:$A, "-") -> - | F39: Zimone | G39: =COUNTIF(A:A,F39&".xlsx") -> 7 | H39: Não | I39: Sim | J39: Não | K39: Sim | L39: Sim | M39: Combate | N39: Dano Direto | O39: Terrenos e Valor | P39: =IF(G39<6,"1",IF(G39<11,"2",IF(G39<16,"3",IF(G39<31,"4","5")))) -> 2
A40: Pé.xlsx | B40: Bala Ged Recovery | C40: =IF(COUNTIF(Substitutas!$B:$B, B40) > 0, "✅ Tenho", "❌ Faltando") -> ❌ Faltando | D40: =_xlfn.XLOOKUP(B40, Substitutas!$B:$B, Substitutas!$A:$A, "-") -> - | F40: Elfos | G40: =COUNTIF(A:A,F40&".xlsx") -> 8 | H40: Não | I40: Sim | J40: Não | K40: Sim | L40: Sim | M40: Combo | N40: Combate | O40: Muita Mana | P40: =IF(G40<6,"1",IF(G40<11,"2",IF(G40<16,"3",IF(G40<31,"4","5")))) -> 2
...

Sheet Prices
A1: Nome da Origem | B1: Carta Ideal | C1: API.prices.usd | D1: Faixa
A2: Arabella.xlsx | B2: Pathmaker Initiate | C2: 0.03 | D2: Baratera
A3: Arabella.xlsx | B3: Plains | C3: 0.11 | D3: Baratera
A4: Arabella.xlsx | B4: Decommission | C4: 0.11 | D4: Baratera
A5: Arabella.xlsx | B5: Boros Guildgate | C5: 0.12 | D5: Baratera
A6: Arabella.xlsx | B6: Goblin Smuggler | C6: 0.12 | D6: Baratera
A7: Arabella.xlsx | B7: Cursebreak | C7: 0.12 | D7: Baratera
A8: Arabella.xlsx | B8: Thraben Inspector | C8: 0.14 | D8: Baratera
A9: Arabella.xlsx | B9: Dimension X | C9: 0.17 | D9: Baratera
A10: Arabella.xlsx | B10: Clowning Around | C10: 0.17 | D10: Baratera
A11: Arabella.xlsx | B11: Mountain | C11: 0.18 | D11: Baratera
A12: Arabella.xlsx | B12: Molten Gatekeeper | C12: 0.18 | D12: Baratera
A13: Arabella.xlsx | B13: Pursue the Past | C13: 0.19 | D13: Baratera
... A355: Toph.xlsx | B355: The Great Henge | C355: 63.98 | D355: Facada
A356: 4cRash.xlsx | B356: Blasphemous Act | D356: Não Encontrada
A357: Alela.xlsx | B357: Monologue Tax | D357: Não Encontrada
A358: Arabella.xlsx | B358: Impact Tremors | D358: Não Encontrada
A359: Baylen.xlsx | B359: The Shire | D359: Não Encontrada
A360: Carlos.xlsx | B360: Black Market Connections | D360: Não Encontrada
A361: Elfos.xlsx | B361: Watery Grave | D361: Não Encontrada
A362: Fractius.xlsx | B362: Steam Vents | D362: Não Encontrada
A363: Fractius.xlsx | B363: Overgrown Tomb | D363: Não Encontrada
A364: Fractius.xlsx | B364: Fetch n WG WU | D364: Não Encontrada
A365: Fractius.xlsx | B365: Sliver Gravemother | D365: Não Encontrada
A366: Jhoira.xlsx | B366: Valfenda | D366: Não Encontrada
A367: JhoiraBichao.xlsx | B367: Rivendell | D367: Não Encontrada
... A377: Zuko.xlsx | B377: Prosper, Tome-Bound | D377: Não Encontrada

Sheet Substitutas
A1: Nome da Origem | B1: Carta Atual
A2: Jhoira.xlsx | B2: ?
A3: Yorion.xlsx | B3: Abdel Adrian, Gorion's Ward
A4: Spara.xlsx | B4: Abzan Falconeer
A5: JhoiraBichao.xlsx | B5: Aeon Chronicler
A6: Inalla.xlsx | B6: Aether Adept
A7: Narset.xlsx | B7: Antecipar
A8: Kadena.xlsx | B8: Aphetto Exterminator
A9: Zuko.xlsx | B9: Aranã, Heart of the Spider
A10: Toph.xlsx | B10: Arcbound Slith
A11: Toph.xlsx | B11: Ark of Hunger
A12: Alela.xlsx | B12: Artificer of Curiosity
... A309: 4cRash.xlsx | B309: Zhur-Taa Druid

Sheet Decks
A1: Nome da Origem | B1: Carta Atual
A2: Carlos.xlsx | B2: Abigale, Eloquent First-Year
A3: Yuriko.xlsx | B3: Abjure
A4: Necrobloom.xlsx | B4: Abrupt Decay
A5: Ool.xlsx | B5: Abrupt Decay
A6: Zimone.xlsx | B6: Abrupt Decay
A7: Breya.xlsx | B7: Abstruse Appropriation
A8: Jhoira.xlsx | B8: Academy Loremaster
A9: JhoiraBichao.xlsx | B9: Academy Loremaster
A10: Baylen.xlsx | B10: Academy Manufactor
A11: OwA.xlsx | B11: Academy Manufactor
A12: Piratas.xlsx | B12: Academy Manufactor
... A2801: Littles.xlsx | B2801: Zurgo, Thunder's Decree

Sheet Watch
A1: Carta | B1: Identidade | G1: Tipo | H1: Categoria | I1: Classe
A2: Weathered Runestone | B2: Não | C2: Não | D2: Não | E2: Não | F2: Não | G2: Artefato | H2: Stax | I2: Cemitério
A3: Shivan Harvest | B3: Não | C3: Não | D3: Sim | E3: Não | F3: Não | G3: Encantamento | H3: Remoção | I3: Terreno
A4: Scouting Trek | B4: Não | C4: Não | D4: Não | E4: Não | F4: Sim | G4: Feitiço | H4: Combo | I4: Tutor
A5: Overabundance | B5: Não | C5: Não | D5: Sim | E5: Não | F5: Não | G5: Encantamento | H5: Ramp | I5: Punição
A6: Spreading Plague | B6: Não | C6: Não | D6: Não | E6: Sim | F6: Não | G6: Encantamento | H6: Stax | I6: Criaturas
A7: Explosão da Alma | B7: Não | C7: Não | D7: Sim | E7: Não | F7: Não | G7: Instantânea | H7: Wincon | I7: Dano
A8: Interdict | B8: Não | C8: Sim | D8: Não | E8: Não | F8: Não | G8: Instantânea | H8: Anule | I8: Habilidade
A9: Mogg Infestation | B9: Não | C9: Não | D9: Sim | E9: Não | F9: Não | G9: Feitiço | H9: Remoção | I9: Criaturas
A10: Life // Death | B10: Não | C10: Não | D10: Não | E10: Não | F10: Sim | G10: Feitiço | H10: Combo | I10: Terreno
A11: Debt of Loyalt | B11: Sim | C11: Não | D11: Não | E11: Não | F11: Não | G11: Instantânea | H11: Remoção | I11: Roubo
A12: Yavimaya Hollow | B12: Não | C12: Não | D12: Não | E12: Não | F12: Sim | G12: Terreno | H12: Proteção | I12: Criaturas
A13: Dreams of the Dead | B13: Não | C13: Sim | D13: Não | E13: Não | F13: Não | G13: Encantamento | H13: Combo | I13: Cemitério
... A25: The Infamous Cruelclaw | B25: Não | C25: Não | D25: Sim | E25: Sim | F25: Não | G25: Criatura | H25: Commander | I25: Voltron

Sheet Tokens
A1: Nome | B1: Tipo | C1: Cor | D1: Cor 2 | E1: Poder | F1: Resistência | G1: Keyword | H1: Keyword | I1: Texto | J1: Possuídos | K1: Necessários | L1: 4c Rash | M1: Akiri | N1: Alela | O1: Arcades | P1: Baylen | Q1: Breya | R1: Carlos | S1: Elfos | T1: Fractius | U1: Gitrog | V1: Inalla | W1: Jhoira | X1: JhoiraB | Y1: Kresh | Z1: Kumena | AA1: Little | AB1: Modular | AC1: Muzzio | AD1: Narset | AE1: Ool | AF1: Oona | AG1: OWA | AH1: Piratas | AI1: Rani | AJ1: Rielle | AK1: Sisay | AL1: Tayam | AM1: Thrakiri | AN1: VialIshai | AO1: Yorion | AP1: Yuriko | AQ1: Zedruu | AR1: Zimone | AS1: Zuko
A2: Alien Warrior | B2: Creature | C2: Red | D2: - | E2: 2 | F2: 2 | G2: - | H2: - | I2: - | K2: =COUNTIF(L2:BD2,">0") -> 0
A3: Ally | B3: Creature | C3: Colorless | D3: - | E3: 1 | F3: 1 | G3: - | H3: - | I3: - | K3: =COUNTIF(L3:BD3,">0") -> 0
A4: Angel | B4: Creature | C4: White | D4: - | E4: 4 | F4: 4 | G4: Fly | H4: - | I4: - | K4: =COUNTIF(L4:BD4,">0") -> 0
A5: Ape | B5: Creature | C5: Green | D5: - | E5: 3 | F5: 3 | G5: - | H5: - | I5: - | K5: =COUNTIF(L5:BD5,">0") -> 0
A6: Assassin | B6: Creature | C6: Black | D6: - | E6: 1 | F6: 1 | G6: - | H6: - | I6: HK | K6: =COUNTIF(L6:BD6,">0") -> 0
A7: Bat | B7: Creature | C7: Black | D7: - | E7: 1 | F7: 1 | G7: Fly | H7: - | I7: - | K7: =COUNTIF(L7:BD7,">0") -> 0
A8: Bear | B8: Creature | C8: Green | D8: - | E8: 2 | F8: 2 | G8: - | H8: - | I8: - | K8: =COUNTIF(L8:BD8,">0") -> 0
A9: Bear | B9: Creature | C9: Green | D9: - | E9: 4 | F9: 4 | G9: - | H9: - | I9: - | K9: =COUNTIF(L9:BD9,">0") -> 0
A10: Beast | B10: Creature | C10: Green | D10: - | E10: 3 | F10: 3 | G10: - | H10: - | I10: - | K10: =COUNTIF(L10:BD10,">0") -> 0
A11: Bird | B11: Creature | C11: Blue | D11: - | E11: 2 | F11: 2 | G11: Fly | H11: - | I11: - | K11: =COUNTIF(L11:BD11,">0") -> 0
A12: Bird | B12: Creature | C12: White | D12: - | E12: 1 | F12: 1 | G12: Fly | H12: - | I12: - | K12: =COUNTIF(L12:BD12,">0") -> 0
A13: Cat | B13: Creature | C13: Green | D13: - | E13: 2 | F13: 2 | G13: - | H13: - | I13: - | K13: =COUNTIF(L13:BD13,">0") -> 0
A14: Chandra, Awakened Inferno | B14: Emblem | C14: - | D14: - | E14: - | F14: - | G14: - | H14: - | I14: - | K14: =COUNTIF(L14:BD14,">0") -> 0
A15: Citizen | B15: Creature | C15: Green | D15: White | E15: 1 | F15: 1 | G15: - | H15: - | I15: - | K15: =COUNTIF(L15:BD15,">0") -> 0
A16: Clone | B16: Creature | C16: Colorless | D16: - | E16: X | F16: X | G16: - | H16: - | I16: - | K16: =COUNTIF(L16:BD16,">0") -> 1 | AO16: 2
A17: Clue | B17: Artifact | C17: Colorless | D17: - | E17: - | F17: - | G17: - | H17: - | I17: - | K17: =COUNTIF(L17:BD17,">0") -> 0
A18: Construct | B18: Creature | C18: Colorless | D18: - | E18: 0 | F18: 0 | G18: - | H18: - | I18: +1/+1 por Artefato | K18: =COUNTIF(L18:BD18,">0") -> 0
A19: Construct | B19: Creature | C19: Colorless | D19: - | E19: 1 | F19: 1 | G19: - | H19: - | I19: - | K19: =COUNTIF(L19:BD19,">0") -> 0
A20: Construct | B20: Creature | C20: Colorless | D20: - | E20: 1 | F20: 1 | G20: Defender | H20: - | I20: - | K20: =COUNTIF(L20:BD20,">0") -> 0
A21: Construct | B21: Creature | C21: Colorless | D21: - | E21: 4 | F21: 4 | G21: - | H21: - | I21: - | K21: =COUNTIF(L21:BD21,">0") -> 0
A22: Construct | B22: Creature | C22: Colorless | D22: - | E22: 2 | F22: 2 | G22: - | H22: - | I22: - | K22: =COUNTIF(L22:BD22,">0") -> 0
A23: Coruscation Mage | B23: Creature | C23: Red | D23: - | E23: 1 | F23: 1 | G23: - | H23: - | I23: - | K23: =COUNTIF(L23:BD23,">0") -> 1 | L23: 1
A24: Crab | B24: Creature | C24: Blue | D24: - | E24: 0 | F24: 3 | G24: - | H24: - | I24: - | K24: =COUNTIF(L24:BD24,">0") -> 0
A25: Darkstar Augur | B25: Creature | C25: Black | D25: - | E25: 1 | F25: 1 | G25: Fly | H25: - | I25: - | K25: =COUNTIF(L25:BD25,">0") -> 0
A26: Demon | B26: Creature | C26: Black | D26: - | E26: 3 | F26: 3 | G26: - | H26: - | I26: - | K26: =COUNTIF(L26:BD26,">0") -> 0
A27: Demon Vampire | B27: Creature | C27: White | D27: Black | E27: 4 | F27: 3 | G27: Fly | H27: - | I27: - | K27: =COUNTIF(L27:BD27,">0") -> 0
A28: Dragon | B28: Creature | C28: Red | D28: - | E28: 4 | F28: 4 | G28: Fly | H28: - | I28: - | K28: =COUNTIF(L28:BD28,">0") -> 0
A29: Dragon | B29: Creature | C29: Red | D29: - | E29: 4 | F29: 4 | G29: Fly | H29: Firebending 4 | I29: - | K29: =COUNTIF(L29:BD29,">0") -> 0
A30: Dragon Scorpion | B30: Creature | C30: Red | D30: - | E30: 4 | F30: 4 | G30: Fly | H30: Haste | I30: - | K30: =COUNTIF(L30:BD30,">0") -> 0
A31: Drake | B31: Creature | C31: Blue | D31: - | E31: 2 | F31: 2 | G31: Fly | H31: - | I31: - | K31: =COUNTIF(L31:BD31,">0") -> 0
A32: Dungeon of the Mad Mage | B32: Emblem | C32: - | D32: - | E32: - | F32: - | G32: - | H32: - | I32: - | K32: =COUNTIF(L32:BD32,">0") -> 0
A33: Dwarf | B33: Creature | C33: Red | D33: - | E33: 1 | F33: 1 | G33: - | H33: - | I33: - | K33: =COUNTIF(L33:BD33,">0") -> 0
A34: Eldrazi Spawn | B34: Creature | C34: Colorless | D34: - | E34: 0 | F34: 1 | G34: - | H34: - | I34: sac: I | K34: =COUNTIF(L34:BD34,">0") -> 0
A35: Elemental | B35: Creature | C35: White | D35: Green | E35: 8 | F35: 8 | G35: Vigilance | H35: - | I35: - | K35: =COUNTIF(L35:BD35,">0") -> 0
A36: Elemental | B36: Creature | C36: Red | D36: - | E36: 1 | F36: 1 | G36: - | H36: - | I36: Dano LTB | K36: =COUNTIF(L36:BD36,">0") -> 0
A37: Elemental | B37: Creature | C37: Red | D37: - | E37: 2 | F37: 1 | G37: Haste | H37: Trample | I37: - | K37: =COUNTIF(L37:BD37,">0") -> 0
A38: Elephant | B38: Creature | C38: Green | D38: - | E38: 3 | F38: 3 | G38: - | H38: - | I38: - | K38: =COUNTIF(L38:BD38,">0") -> 0
A39: Elf | B39: Creature | C39: Green | D39: - | E39: 1 | F39: 1 | G39: - | H39: - | K39: =COUNTIF(L39:BD39,">0") -> 0
A40: Elf Druid | B40: Creature | C40: Green | D40: - | E40: 1 | F40: 1 | G40: - | H40: - | I40: t: G | K40: =COUNTIF(L40:BD40,">0") -> 0
...

Sheet Lands
A1: Edição | B1: Planície | C1: Ilha | D1: Montanha | E1: Pântano | F1: Floresta | H1: Edição | I1: Oath 1 | J1: Oath 2 | K1: Love Your LGS | L1: FF | M1: MH3 Snow | O1: Warhammer 1 | P1: Warhammer 2 | Q1: Fallout 1 | R1: Fallout 2
A2: Aetherdrift | B2: 272 | C2: 273 | D2: 275 | E2: 274 | F2: 276 | H2: Wastes | I2: s | J2: s | K2: 1 | L2: 309 | M2: 309
A3: Aetherdrift Drivers | B3: 507 | C3: 508 | D3: 510 | E3: 509 | F3: 511
A4: Aetherdrift Rotes | B4: 512 | C4: 513 | D4: 515 | E4: 514 | F4: 516
A5: Amonkhet | B5: s | C5: s | D5: s | E5: s | F5: s
A6: Assassin's Creed 1 | B6: s | C6: s | D6: s | E6: s | F6: s
A7: Assassin's Creed 2 | B7: s | C7: s | D7: s | E7: s | F7: s
A8: Avatar - Appa Lands | B8: s | C8: s | D8: s | E8: s | F8: s
A9: Avatar - Momo Lands | B9: 292 | C9: s | D9: 295 | E9: s | F9: s
A10: Battle for Zendikar 1 | B10: s | C10: s | D10: s | E10: s | F10: s
A11: Battle for Zendikar 2 | B11: s | C11: s | D11: s | E11: s | F11: s
A12: Battle for Zendikar 3 | B12: s | C12: s | D12: s | E12: s | F12: s
A13: Battle for Zendikar 4 | B13: s | C13: s | D13: s | E13: s | F13: s
A14: Battle for Zendikar 5 | B14: s | C14: s | D14: s | E14: s | F14: 274
A15: Bloomburrow Fall | B15: 264 | C15: 268 | D15: 276 | E15: 273 | F15: 280
A16: Bloomburrow Spring | B16: 263 | C16: 267 | D16: 275 | E16: 272 | F16: 279
A17: Bloomburrow Summer | B17: 262 | C17: 266 | D17: 274 | E17: 271 | F17: 278
A18: Bloomburrow Winter | B18: 265 | C18: 269 | D18: 277 | E18: 274 | F18: 281
A19: Cappena 1 | B19: 272 | C19: 274 | D19: 278 | E19: s | F19: 280
A20: Cappena 2 | B20: 273 | C20: 275 | D20: 279 | E20: 277 | F20: 281
A21: Dominaria United | B21: s | C21: 278 | D21: s | E21: s | F21: s
A22: Double Masters VIP 1 | B22: 373 | C22: 375 | D22: 379 | E22: 377 | F22: 381
A23: Double Masters VIP 2 | B23: 374 | C23: 376 | D23: 380 | E23: 378 | F23: 382
A24: Dragonstorm Eyes | B24: 287 | C24: 288 | D24: 290 | E24: 289 | F24: 291
A25: Dragonstorm Shades | B25: 272 | C25: 273 | D25: 275 | E25: 274 | F25: 276
A26: Duskmourn | B26: 272 | C26: 273 | D26: 275 | E26: 274 | F26: 276
A27: Edges of Eternities Celestial | B27: 262 | C27: 263 | D27: 265 | E27: 264 | F27: s
A28: Fallout 1 | B28: s | C28: 319 | D28: s | E28: s | F28: s
A29: Fallout 2 | B29: s | C29: 320 | D29: s | E29: s | F29: s
A30: Final Fantasy 1 | B30: s | C30: s | D30: 303 | E30: s | F30: 306
A31: Final Fantasy 2 | B31: 295 | C31: 298 | D31: s | E31: s | F31: 307
A32: Final Fantasy 3 | B32: 296 | C32: 299 | D32: 305 | E32: 302 | F32: 308
A33: Foundations 1 | B33: 282 | C33: 284 | D33: 288 | E33: 286 | F33: 290
A34: Foundations 2 | B34: 283 | C34: 285 | D34: 289 | E34: 287 | F34: 291
A35: Hora da Devastação | B35: 185 | C35: 186 | D35: 188 | E35: s | F35: 189
A36: Innistrad Crimson 1 | B36: 268 | C36: 270 | D36: s | E36: 272 | F36: 276
A37: Innistrad Crimson 2 | B37: 269 | C37: 271 | D37: 275 | E37: 273 | F37: 277
A38: Innistrad Midnight 1 | B38: s | C38: s | D38: s | E38: s | F38: s
A39: Innistrad Midnight 2 | B39: s | C39: 271 | D39: s | E39: 273 | F39: s
A40: Jurassic World Collection | B40: 21 | C40: 22 | D40: 24 | E40: 23 | F40: 25
...
