Workbook

Sheet COMPRAS
A1: Total: | B1: =C2+C7+C12+C17+C22+C27+C32+C37+C42+C55 -> 0 | E1: =A2 -> Compras | F1: =B3 -> MTG Cards Games | G1: =B4 -> Legacy | H1: =B5 -> Mana Vai | J1: Deck/Função | K1: =A7 -> Interessantes | L1: =B8 -> Liga | M1: =B9 -> Legacy | N1: =B10 -> Overrun | P1: =A12 -> 0 | Q1: =B13 -> 0 | R1: =B14 -> 0 | S1: =B15 -> 0 | U1: =A17 -> 0 | V1: =B18 -> 0 | W1: =B19 -> 0 | X1: =B20 -> 0
A2: Compras | B2: Total Lojas: | C2: =SUM(C3:C5) -> 0
A3: =COUNTA(E2:E175) -> 0 | B3: MTG Cards Games | C3: =SUM(F:F) -> 0
B4: Legacy | C4: =SUM(G:G) -> 0
B5: Mana Vai | C5: =SUM(H:H) -> 0
A7: Interessantes | B7: Total Lojas: | C7: =SUM(C9:C10) -> 0
A8: =COUNTA(K2:K193) -> 0 | B8: Liga | C8: =SUM(L:L) -> 0
B9: Legacy | C9: =SUM(M:M) -> 0
B10: Overrun | C10: =SUM(N:N) -> 0

Sheet RESUMO
A1: Fractius | E1: Vida | I1: Fadas | M1: Knights | Q1: Modular | U1: Allies
A3: Total | B3: {=_xlfn._xlws.SORT(C3:C86,1,-1,0)} -> #NAME? | C3: =IF(Fractius!D3="Não",Fractius!C3, " ") | E3: Total | F3: {=_xlfn._xlws.SORT(G3:G86,1,-1,0)} -> #NAME? | G3: =IF(Life!D3="Não",Life!C3, " ") | I3: Total | J3: {=_xlfn._xlws.SORT(K3:K86,1,-1,0)} -> #REF! | K3: =IF(#REF!="Não",#REF!, " ") -> #REF! | M3: Total | N3: {=_xlfn._xlws.SORT(O3:O86,1,-1,0)} -> #REF! | O3: =IF(#REF!="Não",#REF!, " ") -> #REF! | Q3: Total | R3: {=_xlfn._xlws.SORT(S3:S86,1,-1,0)} -> #REF! | S3: =IF(#REF!="Não",#REF!, " ") -> #REF! | U3: Total | V3: {=_xlfn._xlws.SORT(W3:W86,1,-1,0)} -> Swamp | W3: =IF(WBGAllies!D3="Não",WBGAllies!C3, " ")
A4: =Fractius!G3 -> 15 | B4: #NAME? | C4: =IF(Fractius!D4="Não",Fractius!C4, " ") | E4: =Life!G3 -> 13 | F4: #NAME? | G4: =IF(Life!D4="Não",Life!C4, " ") | I4: =#REF! -> #REF! | J4: #REF! | K4: =IF(#REF!="Não",#REF!, " ") -> #REF! | M4: =#REF! -> #REF! | N4: #REF! | O4: =IF(#REF!="Não",#REF!, " ") -> #REF! | Q4: =#REF! -> #REF! | R4: #REF! | S4: =IF(#REF!="Não",#REF!, " ") -> #REF! | U4: =WBGAllies!G3 -> 36 | V4: Swamp | W4: =IF(WBGAllies!D4="Não",WBGAllies!C4, " ")
B5: #NAME? | C5: =IF(Fractius!D5="Não",Fractius!C5, " ") | F5: #NAME? | G5: =IF(Life!D5="Não",Life!C5, " ") | J5: #REF! | K5: =IF(#REF!="Não",#REF!, " ") -> #REF! | N5: #REF! | O5: =IF(#REF!="Não",#REF!, " ") -> #REF! | R5: #REF! | S5: =IF(#REF!="Não",#REF!, " ") -> #REF! | V5: Oran-Rief Survivalist | W5: =IF(WBGAllies!D5="Não",WBGAllies!C5, " ")
B6: #NAME? | C6: =IF(Fractius!D6="Não",Fractius!C6, " ") | F6: #NAME? | G6: =IF(Life!D6="Não",Life!C6, " ") | J6: #REF! | K6: =IF(#REF!="Não",#REF!, " ") -> #REF! | N6: #REF! | O6: =IF(#REF!="Não",#REF!, " ") -> #REF! | R6: #REF! | S6: =IF(#REF!="Não",#REF!, " ") -> #REF! | V6: Oran-Rief Survivalist | W6: =IF(WBGAllies!D6="Não",WBGAllies!C6, " ") -> Blossoming Sands
B7: #NAME? | C7: =IF(Fractius!D7="Não",Fractius!C7, " ") | F7: #NAME? | G7: =IF(Life!D7="Não",Life!C7, " ") -> Bojuka Bog | J7: #REF! | K7: =IF(#REF!="Não",#REF!, " ") -> #REF! | N7: #REF! | O7: =IF(#REF!="Não",#REF!, " ") -> #REF! | R7: #REF! | S7: =IF(#REF!="Não",#REF!, " ") -> #REF! | V7: Oran-Rief Survivalist | W7: =IF(WBGAllies!D7="Não",WBGAllies!C7, " ") -> Blossoming Sands
B8: #NAME? | C8: =IF(Fractius!D8="Não",Fractius!C8, " ") | F8: #NAME? | G8: =IF(Life!D8="Não",Life!C8, " ") -> Bojuka Bog | J8: #REF! | K8: =IF(#REF!="Não",#REF!, " ") -> #REF! | N8: #REF! | O8: =IF(#REF!="Não",#REF!, " ") -> #REF! | R8: #REF! | S8: =IF(#REF!="Não",#REF!, " ") -> #REF! | V8: Oran-Rief Survivalist | W8: =IF(WBGAllies!D8="Não",WBGAllies!C8, " ") -> Blossoming Sands
B9: #NAME? | C9: =IF(Fractius!D9="Não",Fractius!C9, " ") | F9: #NAME? | G9: =IF(Life!D9="Não",Life!C9, " ") | J9: #REF! | K9: =IF(#REF!="Não",#REF!, " ") -> #REF! | N9: #REF! | O9: =IF(#REF!="Não",#REF!, " ") -> #REF! | R9: #REF! | S9: =IF(#REF!="Não",#REF!, " ") -> #REF! | V9: Masked Vandal | W9: =IF(WBGAllies!D9="Não",WBGAllies!C9, " ") -> Blossoming Sands
B10: #NAME? | C10: =IF(Fractius!D10="Não",Fractius!C10, " ") | F10: #NAME? | G10: =IF(Life!D10="Não",Life!C10, " ") | J10: #REF! | K10: =IF(#REF!="Não",#REF!, " ") -> #REF! | N10: #REF! | O10: =IF(#REF!="Não",#REF!, " ") -> #REF! | R10: #REF! | S10: =IF(#REF!="Não",#REF!, " ") -> #REF! | V10: Masked Vandal | W10: =IF(WBGAllies!D10="Não",WBGAllies!C10, " ") -> Jungle Hollow
B11: #NAME? | C11: =IF(Fractius!D11="Não",Fractius!C11, " ") | F11: #NAME? | G11: =IF(Life!D11="Não",Life!C11, " ") | J11: #REF! | K11: =IF(#REF!="Não",#REF!, " ") -> #REF! | N11: #REF! | O11: =IF(#REF!="Não",#REF!, " ") -> #REF! | R11: #REF! | S11: =IF(#REF!="Não",#REF!, " ") -> #REF! | V11: Masked Vandal | W11: =IF(WBGAllies!D11="Não",WBGAllies!C11, " ") -> Jungle Hollow
B12: #NAME? | C12: =IF(Fractius!D12="Não",Fractius!C12, " ") | F12: #NAME? | G12: =IF(Life!D12="Não",Life!C12, " ") | J12: #REF! | K12: =IF(#REF!="Não",#REF!, " ") -> #REF! | N12: #REF! | O12: =IF(#REF!="Não",#REF!, " ") -> #REF! | R12: #REF! | S12: =IF(#REF!="Não",#REF!, " ") -> #REF! | V12: Masked Vandal | W12: =IF(WBGAllies!D12="Não",WBGAllies!C12, " ") -> Jungle Hollow
B13: #NAME? | C13: =IF(Fractius!D13="Não",Fractius!C13, " ") | F13: #NAME? | G13: =IF(Life!D13="Não",Life!C13, " ") | J13: #REF! | K13: =IF(#REF!="Não",#REF!, " ") -> #REF! | N13: #REF! | O13: =IF(#REF!="Não",#REF!, " ") -> #REF! | R13: #REF! | S13: =IF(#REF!="Não",#REF!, " ") -> #REF! | V13: Jungle Hollow | W13: =IF(WBGAllies!D13="Não",WBGAllies!C13, " ") -> Evolving Wilds
B14: #NAME? | C14: =IF(Fractius!D14="Não",Fractius!C14, " ") | F14: #NAME? | G14: =IF(Life!D14="Não",Life!C14, " ") | J14: #REF! | K14: =IF(#REF!="Não",#REF!, " ") -> #REF! | N14: #REF! | O14: =IF(#REF!="Não",#REF!, " ") -> #REF! | R14: #REF! | S14: =IF(#REF!="Não",#REF!, " ") -> #REF! | V14: Jungle Hollow | W14: =IF(WBGAllies!D14="Não",WBGAllies!C14, " ")
B15: #NAME? | C15: =IF(Fractius!D15="Não",Fractius!C15, " ") | F15: #NAME? | G15: =IF(Life!D15="Não",Life!C15, " ") | J15: #REF! | K15: =IF(#REF!="Não",#REF!, " ") -> #REF! | N15: #REF! | O15: =IF(#REF!="Não",#REF!, " ") -> #REF! | R15: #REF! | S15: =IF(#REF!="Não",#REF!, " ") -> #REF! | V15: Jungle Hollow | W15: =IF(WBGAllies!D15="Não",WBGAllies!C15, " ") -> Swamp
B16: #NAME? | C16: =IF(Fractius!D16="Não",Fractius!C16, " ") | F16: #NAME? | G16: =IF(Life!D16="Não",Life!C16, " ") | J16: #REF! | K16: =IF(#REF!="Não",#REF!, " ") -> #REF! | N16: #REF! | O16: =IF(#REF!="Não",#REF!, " ") -> #REF! | R16: #REF! | S16: =IF(#REF!="Não",#REF!, " ") -> #REF! | V16: Graypelt Hunter | W16: =IF(WBGAllies!D16="Não",WBGAllies!C16, " ") -> Swamp
... B38: #NAME? | C38: =IF(Fractius!D38="Não",Fractius!C38, " ") | F38: #NAME? | G38: =IF(Life!D38="Não",Life!C38, " ") -> Novice Inspector | J38: #REF! | K38: =IF(#REF!="Não",#REF!, " ") -> #REF! | N38: #REF! | O38: =IF(#REF!="Não",#REF!, " ") -> #REF! | R38: #REF! | S38: =IF(#REF!="Não",#REF!, " ") -> #REF! | V38: Blessed Hippogriff // Tyr's Blessing | W38: =IF(WBGAllies!D38="Não",WBGAllies!C38, " ")
B39: #NAME? | C39: =IF(Fractius!D39="Não",Fractius!C39, " ") | F39: #NAME? | G39: =IF(Life!D39="Não",Life!C39, " ") | J39: #REF! | K39: =IF(#REF!="Não",#REF!, " ") -> #REF! | N39: #REF! | O39: =IF(#REF!="Não",#REF!, " ") -> #REF! | R39: #REF! | S39: =IF(#REF!="Não",#REF!, " ") -> #REF! | W39: =IF(WBGAllies!D39="Não",WBGAllies!C39, " ") -> Masked Vandal
B40: #NAME? | C40: =IF(Fractius!D40="Não",Fractius!C40, " ") | F40: #NAME? | G40: =IF(Life!D40="Não",Life!C40, " ") | J40: #REF! | K40: =IF(#REF!="Não",#REF!, " ") -> #REF! | N40: #REF! | O40: =IF(#REF!="Não",#REF!, " ") -> #REF! | R40: #REF! | S40: =IF(#REF!="Não",#REF!, " ") -> #REF! | W40: =IF(WBGAllies!D40="Não",WBGAllies!C40, " ") -> Masked Vandal
B41: #NAME? | C41: =IF(Fractius!D41="Não",Fractius!C41, " ") | F41: #NAME? | G41: =IF(Life!D41="Não",Life!C41, " ") | J41: #REF! | K41: =IF(#REF!="Não",#REF!, " ") -> #REF! | N41: #REF! | O41: =IF(#REF!="Não",#REF!, " ") -> #REF! | R41: #REF! | S41: =IF(#REF!="Não",#REF!, " ") -> #REF! | W41: =IF(WBGAllies!D41="Não",WBGAllies!C41, " ") -> Masked Vandal
B42: #NAME? | C42: =IF(Fractius!D42="Não",Fractius!C42, " ") | F42: #NAME? | G42: =IF(Life!D42="Não",Life!C42, " ") | J42: #REF! | K42: =IF(#REF!="Não",#REF!, " ") -> #REF! | N42: #REF! | O42: =IF(#REF!="Não",#REF!, " ") -> #REF! | R42: #REF! | S42: =IF(#REF!="Não",#REF!, " ") -> #REF! | W42: =IF(WBGAllies!D42="Não",WBGAllies!C42, " ") -> Masked Vandal
B43: #NAME? | C43: =IF(Fractius!D43="Não",Fractius!C43, " ") | F43: #NAME? | G43: =IF(Life!D43="Não",Life!C43, " ") | J43: #REF! | K43: =IF(#REF!="Não",#REF!, " ") -> #REF! | N43: #REF! | O43: =IF(#REF!="Não",#REF!, " ") -> #REF! | R43: #REF! | S43: =IF(#REF!="Não",#REF!, " ") -> #REF! | W43: =IF(WBGAllies!D43="Não",WBGAllies!C43, " ") -> Oran-Rief Survivalist
B44: #NAME? | C44: =IF(Fractius!D44="Não",Fractius!C44, " ") | F44: #NAME? | G44: =IF(Life!D44="Não",Life!C44, " ") | J44: #REF! | K44: =IF(#REF!="Não",#REF!, " ") -> #REF! | N44: #REF! | O44: =IF(#REF!="Não",#REF!, " ") -> #REF! | R44: #REF! | S44: =IF(#REF!="Não",#REF!, " ") -> #REF! | W44: =IF(WBGAllies!D44="Não",WBGAllies!C44, " ") -> Oran-Rief Survivalist
B45: #NAME? | C45: =IF(Fractius!D45="Não",Fractius!C45, " ") | F45: #NAME? | G45: =IF(Life!D45="Não",Life!C45, " ") | J45: #REF! | K45: =IF(#REF!="Não",#REF!, " ") -> #REF! | N45: #REF! | O45: =IF(#REF!="Não",#REF!, " ") -> #REF! | R45: #REF! | S45: =IF(#REF!="Não",#REF!, " ") -> #REF! | W45: =IF(WBGAllies!D45="Não",WBGAllies!C45, " ") -> Oran-Rief Survivalist
B46: #NAME? | C46: =IF(Fractius!D46="Não",Fractius!C46, " ") | F46: #NAME? | G46: =IF(Life!D46="Não",Life!C46, " ") | J46: #REF! | K46: =IF(#REF!="Não",#REF!, " ") -> #REF! | N46: #REF! | O46: =IF(#REF!="Não",#REF!, " ") -> #REF! | R46: #REF! | S46: =IF(#REF!="Não",#REF!, " ") -> #REF! | W46: =IF(WBGAllies!D46="Não",WBGAllies!C46, " ") -> Oran-Rief Survivalist
B47: #NAME? | C47: =IF(Fractius!D47="Não",Fractius!C47, " ") | F47: #NAME? | G47: =IF(Life!D47="Não",Life!C47, " ") | J47: #REF! | K47: =IF(#REF!="Não",#REF!, " ") -> #REF! | N47: #REF! | O47: =IF(#REF!="Não",#REF!, " ") -> #REF! | R47: #REF! | S47: =IF(#REF!="Não",#REF!, " ") -> #REF! | W47: =IF(WBGAllies!D47="Não",WBGAllies!C47, " ") -> Graypelt Hunter
B48: #NAME? | C48: =IF(Fractius!D48="Não",Fractius!C48, " ") | F48: #NAME? | G48: =IF(Life!D48="Não",Life!C48, " ") | J48: #REF! | K48: =IF(#REF!="Não",#REF!, " ") -> #REF! | N48: #REF! | O48: =IF(#REF!="Não",#REF!, " ") -> #REF! | R48: #REF! | S48: =IF(#REF!="Não",#REF!, " ") -> #REF! | W48: =IF(WBGAllies!D48="Não",WBGAllies!C48, " ") -> Graypelt Hunter
B49: #NAME? | C49: =IF(Fractius!D49="Não",Fractius!C49, " ") | F49: #NAME? | G49: =IF(Life!D49="Não",Life!C49, " ") | J49: #REF! | K49: =IF(#REF!="Não",#REF!, " ") -> #REF! | N49: #REF! | O49: =IF(#REF!="Não",#REF!, " ") -> #REF! | R49: #REF! | S49: =IF(#REF!="Não",#REF!, " ") -> #REF! | W49: =IF(WBGAllies!D49="Não",WBGAllies!C49, " ") -> Graypelt Hunter
B50: #NAME? | C50: =IF(Fractius!D50="Não",Fractius!C50, " ") | F50: #NAME? | G50: =IF(Life!D50="Não",Life!C50, " ") | J50: #REF! | K50: =IF(#REF!="Não",#REF!, " ") -> #REF! | N50: #REF! | O50: =IF(#REF!="Não",#REF!, " ") -> #REF! | R50: #REF! | S50: =IF(#REF!="Não",#REF!, " ") -> #REF! | W50: =IF(WBGAllies!D50="Não",WBGAllies!C50, " ") -> Graypelt Hunter
... B86: #NAME? | C86: =IF(Fractius!D86="Não",Fractius!C86, " ") | F86: #NAME? | G86: =IF(Life!D86="Não",Life!C86, " ") | J86: #REF! | K86: =IF(#REF!="Não",#REF!, " ") -> #REF! | N86: #REF! | O86: =IF(#REF!="Não",#REF!, " ") -> #REF! | R86: #REF! | S86: =IF(#REF!="Não",#REF!, " ") -> #REF! | W86: =IF(WBGAllies!D86="Não",WBGAllies!C86, " ")
O87: =IF(#REF!="Não",#REF!, " ") -> #REF!
O88: =IF(#REF!="Não",#REF!, " ") -> #REF!

Sheet RESUMO (2)
A1: Temur Control | E1: Jeskay Control | I1: Esper Modular
A3: Total | B3: {=_xlfn._xlws.SORT(C3:C86,1,-1,0)} -> #REF! | C3: =IF(#REF!="Não",#REF!, " ") -> #REF! | E3: Total | F3: {=_xlfn._xlws.SORT(G3:G86,1,-1,0)} -> #NAME? | G3: =IF(Flicker!D3="Não",Flicker!C3, " ") | I3: Total | J3: {=_xlfn._xlws.SORT(K3:K86,1,-1,0)} -> #REF! | K3: =IF(Modular!D3="Não",Modular!C3, " ")
A4: =#REF! -> #REF! | B4: #REF! | C4: =IF(#REF!="Não",#REF!, " ") -> #REF! | E4: =Flicker!G3 -> 8 | F4: #NAME? | G4: =IF(Flicker!D4="Não",Flicker!C4, " ") | I4: =Modular!G3 -> 1 | J4: #REF! | K4: =IF(Modular!D4="Não",Modular!C4, " ")
B5: #REF! | C5: =IF(#REF!="Não",#REF!, " ") -> #REF! | F5: #NAME? | G5: =IF(Flicker!D5="Não",Flicker!C5, " ") | J5: #REF! | K5: =IF(Modular!D5="Não",Modular!C5, " ")
B6: #REF! | C6: =IF(#REF!="Não",#REF!, " ") -> #REF! | F6: #NAME? | G6: =IF(Flicker!D6="Não",Flicker!C6, " ") | J6: #REF! | K6: =IF(Modular!D6="Não",Modular!C6, " ")
B7: #REF! | C7: =IF(#REF!="Não",#REF!, " ") -> #REF! | F7: #NAME? | G7: =IF(Flicker!D7="Não",Flicker!C7, " ") | J7: #REF! | K7: =IF(Modular!D7="Não",Modular!C7, " ")
B8: #REF! | C8: =IF(#REF!="Não",#REF!, " ") -> #REF! | F8: #NAME? | G8: =IF(Flicker!D8="Não",Flicker!C8, " ") | J8: #REF! | K8: =IF(Modular!D8="Não",Modular!C8, " ")
B9: #REF! | C9: =IF(#REF!="Não",#REF!, " ") -> #REF! | F9: #NAME? | G9: =IF(Flicker!D9="Não",Flicker!C9, " ") | J9: #REF! | K9: =IF(Modular!D9="Não",Modular!C9, " ")
B10: #REF! | C10: =IF(#REF!="Não",#REF!, " ") -> #REF! | F10: #NAME? | G10: =IF(Flicker!D10="Não",Flicker!C10, " ") | J10: #REF! | K10: =IF(Modular!D10="Não",Modular!C10, " ")
B11: #REF! | C11: =IF(#REF!="Não",#REF!, " ") -> #REF! | F11: #NAME? | G11: =IF(Flicker!D11="Não",Flicker!C11, " ") | J11: #REF! | K11: =IF(Modular!D11="Não",Modular!C11, " ")
B12: #REF! | C12: =IF(#REF!="Não",#REF!, " ") -> #REF! | F12: #NAME? | G12: =IF(Flicker!D12="Não",Flicker!C12, " ") | J12: Ancient Den | K12: =IF(Modular!D12="Não",Modular!C12, " ")
B13: #REF! | C13: =IF(#REF!="Não",#REF!, " ") -> #REF! | F13: #NAME? | G13: =IF(Flicker!D13="Não",Flicker!C13, " ") | K13: =IF(Modular!D13="Não",Modular!C13, " ")
B14: #REF! | C14: =IF(#REF!="Não",#REF!, " ") -> #REF! | F14: #NAME? | G14: =IF(Flicker!D14="Não",Flicker!C14, " ") | K14: =IF(Modular!D14="Não",Modular!C14, " ")
B15: #REF! | C15: =IF(#REF!="Não",#REF!, " ") -> #REF! | F15: #NAME? | G15: =IF(Flicker!D15="Não",Flicker!C15, " ") | K15: =IF(Modular!D15="Não",Modular!C15, " ")
B16: #REF! | C16: =IF(#REF!="Não",#REF!, " ") -> #REF! | F16: #NAME? | G16: =IF(Flicker!D16="Não",Flicker!C16, " ") | K16: =IF(Modular!D16="Não",Modular!C16, " ")
B17: #REF! | C17: =IF(#REF!="Não",#REF!, " ") -> #REF! | F17: #NAME? | G17: =IF(Flicker!D17="Não",Flicker!C17, " ") | K17: =IF(Modular!D17="Não",Modular!C17, " ")
B18: #REF! | C18: =IF(#REF!="Não",#REF!, " ") -> #REF! | F18: #NAME? | G18: =IF(Flicker!D18="Não",Flicker!C18, " ") | K18: =IF(Modular!D18="Não",Modular!C18, " ")
B19: #REF! | C19: =IF(#REF!="Não",#REF!, " ") -> #REF! | F19: #NAME? | G19: =IF(Flicker!D19="Não",Flicker!C19, " ") | K19: =IF(Modular!D19="Não",Modular!C19, " ")
B20: #REF! | C20: =IF(#REF!="Não",#REF!, " ") -> #REF! | F20: #NAME? | G20: =IF(Flicker!D20="Não",Flicker!C20, " ") | K20: =IF(Modular!D20="Não",Modular!C20, " ")
B21: #REF! | C21: =IF(#REF!="Não",#REF!, " ") -> #REF! | F21: #NAME? | G21: =IF(Flicker!D21="Não",Flicker!C21, " ") | K21: =IF(Modular!D21="Não",Modular!C21, " ") -> Ancient Den
B22: #REF! | C22: =IF(#REF!="Não",#REF!, " ") -> #REF! | F22: #NAME? | G22: =IF(Flicker!D22="Não",Flicker!C22, " ") | K22: =IF(Modular!D22="Não",Modular!C22, " ")
B23: #REF! | C23: =IF(#REF!="Não",#REF!, " ") -> #REF! | F23: #NAME? | G23: =IF(Flicker!D23="Não",Flicker!C23, " ") | K23: =IF(Modular!D23="Não",Modular!C23, " ")
B24: #REF! | C24: =IF(#REF!="Não",#REF!, " ") -> #REF! | F24: #NAME? | G24: =IF(Flicker!D24="Não",Flicker!C24, " ") | K24: =IF(Modular!D24="Não",Modular!C24, " ")
... B31: #REF! | C31: =IF(#REF!="Não",#REF!, " ") -> #REF! | F31: #NAME? | G31: =IF(Flicker!D31="Não",Flicker!C31, " ") | K31: =IF(Modular!D31="Não",Modular!C31, " ")
B32: #REF! | C32: =IF(#REF!="Não",#REF!, " ") -> #REF! | F32: #NAME? | G32: =IF(Flicker!D49="Não",Flicker!C49, " ") | K32: =IF(Modular!D32="Não",Modular!C32, " ")
B33: #REF! | C33: =IF(#REF!="Não",#REF!, " ") -> #REF! | F33: #NAME? | G33: =IF(Flicker!D50="Não",Flicker!C50, " ") -> Lórien Revealed | K33: =IF(Modular!D33="Não",Modular!C33, " ")
B34: #REF! | C34: =IF(#REF!="Não",#REF!, " ") -> #REF! | F34: #NAME? | G34: =IF(Flicker!D32="Não",Flicker!C32, " ") | K34: =IF(Modular!D34="Não",Modular!C34, " ")
B35: #REF! | C35: =IF(#REF!="Não",#REF!, " ") -> #REF! | F35: #NAME? | G35: =IF(Flicker!D33="Não",Flicker!C33, " ") | K35: =IF(Modular!D35="Não",Modular!C35, " ")
B36: #REF! | C36: =IF(#REF!="Não",#REF!, " ") -> #REF! | F36: #NAME? | G36: =IF(Flicker!D34="Não",Flicker!C34, " ") | K36: =IF(Modular!D36="Não",Modular!C36, " ")
B37: #REF! | C37: =IF(#REF!="Não",#REF!, " ") -> #REF! | F37: #NAME? | G37: =IF(Flicker!D35="Não",Flicker!C35, " ") | K37: =IF(Modular!D37="Não",Modular!C37, " ")
B38: #REF! | C38: =IF(#REF!="Não",#REF!, " ") -> #REF! | F38: #NAME? | G38: =IF(Flicker!D36="Não",Flicker!C36, " ") | K38: =IF(Modular!D38="Não",Modular!C38, " ")
B39: #REF! | C39: =IF(#REF!="Não",#REF!, " ") -> #REF! | F39: #NAME? | G39: =IF(Flicker!D37="Não",Flicker!C37, " ") -> Ponder | K39: =IF(Modular!D39="Não",Modular!C39, " ")
B40: #REF! | C40: =IF(#REF!="Não",#REF!, " ") -> #REF! | F40: #NAME? | G40: =IF(Flicker!D38="Não",Flicker!C38, " ") -> Ponder | K40: =IF(Modular!D40="Não",Modular!C40, " ")
B41: #REF! | C41: =IF(#REF!="Não",#REF!, " ") -> #REF! | F41: #NAME? | G41: =IF(Flicker!D39="Não",Flicker!C39, " ") -> Ponder | K41: =IF(Modular!D41="Não",Modular!C41, " ")
B42: #REF! | C42: =IF(#REF!="Não",#REF!, " ") -> #REF! | F42: #NAME? | G42: =IF(Flicker!D40="Não",Flicker!C40, " ") -> Ponder | K42: =IF(Modular!D42="Não",Modular!C42, " ")
B43: #REF! | C43: =IF(#REF!="Não",#REF!, " ") -> #REF! | F43: #NAME? | G43: =IF(Flicker!D41="Não",Flicker!C41, " ") | K43: =IF(Modular!D43="Não",Modular!C43, " ")
B44: #REF! | C44: =IF(#REF!="Não",#REF!, " ") -> #REF! | F44: #NAME? | G44: =IF(Flicker!D42="Não",Flicker!C42, " ") | K44: =IF(Modular!D44="Não",Modular!C44, " ")
B45: #REF! | C45: =IF(#REF!="Não",#REF!, " ") -> #REF! | F45: #NAME? | G45: =IF(Flicker!D43="Não",Flicker!C43, " ") | K45: =IF(Modular!D45="Não",Modular!C45, " ")
... B50: #REF! | C50: =IF(#REF!="Não",#REF!, " ") -> #REF! | F50: #NAME? | G50: =IF(Flicker!D48="Não",Flicker!C48, " ") | K50: =IF(Modular!D50="Não",Modular!C50, " ")
B51: #REF! | C51: =IF(#REF!="Não",#REF!, " ") -> #REF! | F51: #NAME? | G51: =IF(Flicker!D51="Não",Flicker!C51, " ") | K51: =IF(Modular!D51="Não",Modular!C51, " ")
...

Sheet Fractius
A1: Selesnya Fractius - Pauper
A2: Função | B2: Carta Atual | C2: Carta Ideal | D2: Carta Final
A3: Terreno | B3: Blossoming Sands | C3: Blossoming Sands | D3: =IF(B3=C3, "Sim", "Não") -> Sim | F3: Mudanças Faltando | G3: =COUNTIF(D3:D105,"Não") -> 15
A4: Terreno | B4: Blossoming Sands | C4: Blossoming Sands | D4: =IF(B4=C4, "Sim", "Não") -> Sim | F4: Total de Cartas | G4: =SUM(G7:G25) -> 75
A5: Terreno | B5: Blossoming Sands | C5: Blossoming Sands | D5: =IF(B5=C5, "Sim", "Não") -> Sim
A6: Terreno | B6: Blossoming Sands | C6: Blossoming Sands | D6: =IF(B6=C6, "Sim", "Não") -> Sim | F6: Funções
A7: Terreno | B7: Tranquil Thicket | C7: Tranquil Thicket | D7: =IF(B7=C7, "Sim", "Não") -> Sim | F7: Terreno | G7: =COUNTIF(A:A,F7) -> 21
A8: Terreno | B8: Tranquil Thicket | C8: Tranquil Thicket | D8: =IF(B8=C8, "Sim", "Não") -> Sim | F8: Combate | G8: =COUNTIF(A:A,F8) -> 20
A9: Terreno | B9: Tranquil Thicket | C9: Tranquil Thicket | D9: =IF(B9=C9, "Sim", "Não") -> Sim | F9: Draw | G9: =COUNTIF(A:A,F9) -> 8
A10: Terreno | B10: Secluded Steppe | C10: Secluded Steppe | D10: =IF(B10=C10, "Sim", "Não") -> Sim | F10: Trick | G10: =COUNTIF(A:A,F10) -> 9
A11: Terreno | B11: Forest | C11: Forest | D11: =IF(B11=C11, "Sim", "Não") -> Sim | F11: Controle | G11: =COUNTIF(A:A,F11) -> 2
A12: Terreno | B12: Forest | C12: Forest | D12: =IF(B12=C12, "Sim", "Não") -> Sim | F12: Sideboard | G12: =COUNTIF(A:A,F12) -> 15
A13: Terreno | B13: Forest | C13: Forest | D13: =IF(B13=C13, "Sim", "Não") -> Sim
A14: Terreno | B14: Forest | C14: Forest | D14: =IF(B14=C14, "Sim", "Não") -> Sim
A15: Terreno | B15: Forest | C15: Forest | D15: =IF(B15=C15, "Sim", "Não") -> Sim
A16: Terreno | B16: Forest | C16: Forest | D16: =IF(B16=C16, "Sim", "Não") -> Sim
A17: Terreno | B17: Plains | C17: Plains | D17: =IF(B17=C17, "Sim", "Não") -> Sim
A18: Terreno | B18: Plains | C18: Plains | D18: =IF(B18=C18, "Sim", "Não") -> Sim
A19: Terreno | B19: Plains | C19: Plains | D19: =IF(B19=C19, "Sim", "Não") -> Sim
A20: Terreno | B20: Plains | C20: Plains | D20: =IF(B20=C20, "Sim", "Não") -> Sim
A21: Terreno | B21: Plains | C21: Plains | D21: =IF(B21=C21, "Sim", "Não") -> Sim
A22: Terreno | B22: Tranquil Expanse | C22: Tranquil Expanse | D22: =IF(B22=C22, "Sim", "Não") -> Sim
A23: Terreno | B23: Tranquil Expanse | C23: Tranquil Expanse | D23: =IF(B23=C23, "Sim", "Não") -> Sim
A24: Combate | B24: Predatory Sliver | C24: Predatory Sliver | D24: =IF(B24=C24, "Sim", "Não") -> Sim
... A62: Controle | B62: Journey to Nowhere | C62: Journey to Nowhere | D62: =IF(B62=C62, "Sim", "Não") -> Sim
A63: Sideboard | C63: Journey to Nowhere | D63: =IF(B63=C63, "Sim", "Não") -> Não
A64: Sideboard | C64: Journey to Nowhere | D64: =IF(B64=C64, "Sim", "Não") -> Não
A65: Sideboard | C65: Young Wolf | D65: =IF(B65=C65, "Sim", "Não") -> Não
A66: Sideboard | C66: Young Wolf | D66: =IF(B66=C66, "Sim", "Não") -> Não
A67: Sideboard | B67: Standard Bearer | C67: Standard Bearer | D67: =IF(B67=C67, "Sim", "Não") -> Sim
A68: Sideboard | C68: Standard Bearer | D68: =IF(B68=C68, "Sim", "Não") -> Não
A69: Sideboard | C69: Standard Bearer | D69: =IF(B69=C69, "Sim", "Não") -> Não
A70: Sideboard | C70: Gut Shot | D70: =IF(B70=C70, "Sim", "Não") -> Não
A71: Sideboard | C71: Gut Shot | D71: =IF(B71=C71, "Sim", "Não") -> Não
A72: Sideboard | C72: Gut Shot | D72: =IF(B72=C72, "Sim", "Não") -> Não
A73: Sideboard | C73: Scattershot Archer | D73: =IF(B73=C73, "Sim", "Não") -> Não
A74: Sideboard | C74: Scattershot Archer | D74: =IF(B74=C74, "Sim", "Não") -> Não
A75: Sideboard | C75: Relic of Progenitus | D75: =IF(B75=C75, "Sim", "Não") -> Não
A76: Sideboard | C76: Relic of Progenitus | D76: =IF(B76=C76, "Sim", "Não") -> Não
A77: Sideboard | C77: Relic of Progenitus | D77: =IF(B77=C77, "Sim", "Não") -> Não

Sheet Life
A1: Vida e Morte - Pauper
A2: Função | B2: Carta Atual | C2: Carta Ideal | D2: Carta Final
A3: Terreno | B3: Scoured Barrens | C3: Scoured Barrens | D3: =IF(B3=C3, "Sim", "Não") -> Sim | F3: Mudanças Faltando | G3: =COUNTIF(D3:D105,"Não") -> 13
A4: Terreno | B4: Scoured Barrens | C4: Scoured Barrens | D4: =IF(B4=C4, "Sim", "Não") -> Sim | F4: Total de Cartas | G4: =SUM(G7:G25) -> 73
A5: Terreno | B5: Scoured Barrens | C5: Scoured Barrens | D5: =IF(B5=C5, "Sim", "Não") -> Sim
A6: Terreno | B6: Scoured Barrens | C6: Scoured Barrens | D6: =IF(B6=C6, "Sim", "Não") -> Sim | F6: Funções
A7: Terreno | B7: Plains | C7: Bojuka Bog | D7: =IF(B7=C7, "Sim", "Não") -> Não | F7: Terreno | G7: =COUNTIF(A:A,F7) -> 20
A8: Terreno | B8: Swamp | C8: Bojuka Bog | D8: =IF(B8=C8, "Sim", "Não") -> Não | F8: Vida | G8: =COUNTIF(A:A,F8) -> 12
A9: Terreno | B9: Secluded Steppe | C9: Secluded Steppe | D9: =IF(B9=C9, "Sim", "Não") -> Sim | F9: Blink | G9: =COUNTIF(A:A,F9) -> 10
A10: Terreno | B10: Secluded Steppe | C10: Secluded Steppe | D10: =IF(B10=C10, "Sim", "Não") -> Sim | F10: Draw | G10: =COUNTIF(A:A,F10) -> 12
A11: Terreno | B11: Secluded Steppe | C11: Secluded Steppe | D11: =IF(B11=C11, "Sim", "Não") -> Sim | F11: Win | G11: =COUNTIF(A:A,F11) -> 4
A12: Terreno | B12: Barren Moor | C12: Barren Moor | D12: =IF(B12=C12, "Sim", "Não") -> Sim | F12: Controle | G12: =COUNTIF(A:A,F12) -> 0
A13: Terreno | B13: Barren Moor | C13: Barren Moor | D13: =IF(B13=C13, "Sim", "Não") -> Sim | F13: Sideboard | G13: =COUNTIF(A:A,F13) -> 15
A14: Terreno | B14: Kabira Crossroads | C14: Kabira Crossroads | D14: =IF(B14=C14, "Sim", "Não") -> Sim
A15: Terreno | B15: Kabira Crossroads | C15: Kabira Crossroads | D15: =IF(B15=C15, "Sim", "Não") -> Sim
A16: Terreno | B16: Plains | C16: Plains | D16: =IF(B16=C16, "Sim", "Não") -> Sim
A17: Terreno | B17: Plains | C17: Plains | D17: =IF(B17=C17, "Sim", "Não") -> Sim
A18: Terreno | B18: Plains | C18: Plains | D18: =IF(B18=C18, "Sim", "Não") -> Sim
A19: Terreno | B19: Swamp | C19: Swamp | D19: =IF(B19=C19, "Sim", "Não") -> Sim
A20: Terreno | B20: Swamp | C20: Swamp | D20: =IF(B20=C20, "Sim", "Não") -> Sim
A21: Terreno | B21: Swamp | C21: Swamp | D21: =IF(B21=C21, "Sim", "Não") -> Sim
A22: Terreno | B22: Swamp | C22: Swamp | D22: =IF(B22=C22, "Sim", "Não") -> Sim
A23: Vida | B23: Soul Warden | C23: Soul Warden | D23: =IF(B23=C23, "Sim", "Não") -> Sim
A24: Vida | B24: Soul Warden | C24: Soul Warden | D24: =IF(B24=C24, "Sim", "Não") -> Sim
A25: Vida | B25: Soul Warden | C25: Soul Warden | D25: =IF(B25=C25, "Sim", "Não") -> Sim
... A50: Blink | B50: Kor Skyfisher | C50: Kor Skyfisher | D50: =IF(B50=C50, "Sim", "Não") -> Sim
A51: Blink | C51: Ephemerate | D51: =IF(B51=C51, "Sim", "Não") -> Não
A52: Blink | C52: Ephemerate | D52: =IF(B52=C52, "Sim", "Não") -> Não
A53: Blink | C53: Ephemerate | D53: =IF(B53=C53, "Sim", "Não") -> Não
A54: Blink | C54: Ephemerate | D54: =IF(B54=C54, "Sim", "Não") -> Não
A55: Blink | B55: Whitemane Lion | C55: Whitemane Lion | D55: =IF(B55=C55, "Sim", "Não") -> Sim
A56: Blink | B56: Whitemane Lion | C56: Whitemane Lion | D56: =IF(B56=C56, "Sim", "Não") -> Sim
A57: Win | B57: Whitemane Lion | C57: Marauding-Blight Priest | D57: =IF(B57=C57, "Sim", "Não") -> Não
A58: Win | B58: Marauding-Blight Priest | C58: Marauding-Blight Priest | D58: =IF(B58=C58, "Sim", "Não") -> Sim
A59: Win | B59: Marauding-Blight Priest | C59: Marauding-Blight Priest | D59: =IF(B59=C59, "Sim", "Não") -> Sim
A60: Win | B60: Marauding-Blight Priest | C60: Marauding-Blight Priest | D60: =IF(B60=C60, "Sim", "Não") -> Sim
A61: Remoção | B61: Cast Down | C61: Cast Down | D61: =IF(B61=C61, "Sim", "Não") -> Sim
A62: Remoção | B62: Cast Down | C62: Cast Down | D62: =IF(B62=C62, "Sim", "Não") -> Sim
A63: Sideboard | B63: Lâmina da Coleta | C63: Thraben Charm | D63: =IF(B63=C63, "Sim", "Não") -> Não
A64: Sideboard | B64: Lâmina da Coleta | C64: Thraben Charm | D64: =IF(B64=C64, "Sim", "Não") -> Não
...

Sheet Flicker
A1: WUR Flicker
A2: Função | B2: Carta Atual | C2: Carta Ideal | D2: Carta Final
A3: Terreno | B3: Silverbluff Bridge | C3: Silverbluff Bridge | D3: =IF(B3=C3, "Sim", "Não") -> Sim | F3: Mudanças Faltando | G3: =COUNTIF(D3:D105,"Não") -> 8
A4: Terreno | B4: Silverbluff Bridge | C4: Silverbluff Bridge | D4: =IF(B4=C4, "Sim", "Não") -> Sim | F4: Total de Cartas | G4: =SUM(G7:G25) -> 75
A5: Terreno | B5: Silverbluff Bridge | C5: Silverbluff Bridge | D5: =IF(B5=C5, "Sim", "Não") -> Sim
A6: Terreno | B6: Silverbluff Bridge | C6: Silverbluff Bridge | D6: =IF(B6=C6, "Sim", "Não") -> Sim | F6: Funções
A7: Terreno | B7: Rustvale Bridge | C7: Rustvale Bridge | D7: =IF(B7=C7, "Sim", "Não") -> Sim | F7: Terreno | G7: =COUNTIF(A:A,F7) -> 19
A8: Terreno | B8: Rustvale Bridge | C8: Rustvale Bridge | D8: =IF(B8=C8, "Sim", "Não") -> Sim | F8: ETB | G8: =COUNTIF(A:A,F8) -> 11
A9: Terreno | B9: Rustvale Bridge | C9: Rustvale Bridge | D9: =IF(B9=C9, "Sim", "Não") -> Sim | F9: Blink | G9: =COUNTIF(A:A,F9) -> 4
A10: Terreno | B10: Rustvale Bridge | C10: Rustvale Bridge | D10: =IF(B10=C10, "Sim", "Não") -> Sim | F10: Draw | G10: =COUNTIF(A:A,F10) -> 18
A11: Terreno | B11: Razortide Bridge | C11: Razortide Bridge | D11: =IF(B11=C11, "Sim", "Não") -> Sim | F11: Controle | G11: =COUNTIF(A:A,F11) -> 8
A12: Terreno | B12: Razortide Bridge | C12: Razortide Bridge | D12: =IF(B12=C12, "Sim", "Não") -> Sim | F12: Sideboard | G12: =COUNTIF(A:A,F12) -> 15
A13: Terreno | B13: Island | C13: Island | D13: =IF(B13=C13, "Sim", "Não") -> Sim
A14: Terreno | B14: Island | C14: Island | D14: =IF(B14=C14, "Sim", "Não") -> Sim
A15: Terreno | B15: Island | C15: Island | D15: =IF(B15=C15, "Sim", "Não") -> Sim
A16: Terreno | B16: Island | C16: Island | D16: =IF(B16=C16, "Sim", "Não") -> Sim
A17: Terreno | B17: Island | C17: Island | D17: =IF(B17=C17, "Sim", "Não") -> Sim
A18: Terreno | B18: Island | C18: Island | D18: =IF(B18=C18, "Sim", "Não") -> Sim
A19: Terreno | B19: Island | C19: Island | D19: =IF(B19=C19, "Sim", "Não") -> Sim
A20: Terreno | B20: Mountain | C20: Mountain | D20: =IF(B20=C20, "Sim", "Não") -> Sim
A21: Terreno | B21: Plains | C21: Plains | D21: =IF(B21=C21, "Sim", "Não") -> Sim
A22: ETB | B22: Stonehorn Dignitary | C22: Stonehorn Dignitary | D22: =IF(B22=C22, "Sim", "Não") -> Sim
A23: ETB | B23: Stonehorn Dignitary | C23: Stonehorn Dignitary | D23: =IF(B23=C23, "Sim", "Não") -> Sim
A24: ETB | B24: Dawnbringer Cleric | C24: Dawnbringer Cleric | D24: =IF(B24=C24, "Sim", "Não") -> Sim
... A77: Sideboard | B77: Late to Dinner | C77: Late to Dinner | D77: =IF(B77=C77, "Sim", "Não") -> Sim

Sheet Modular
A1: WUR Flicker
A2: Função | B2: Carta Atual | C2: Carta Ideal | D2: Carta Final
A3: Terreno | B3: Razortide Bridge | C3: Razortide Bridge | D3: =IF(B3=C3, "Sim", "Não") -> Sim | F3: Mudanças Faltando | G3: =COUNTIF(D3:D105,"Não") -> 1
A4: Terreno | B4: Razortide Bridge | C4: Razortide Bridge | D4: =IF(B4=C4, "Sim", "Não") -> Sim | F4: Total de Cartas | G4: =SUM(G7:G25) -> 75
A5: Terreno | B5: Razortide Bridge | C5: Razortide Bridge | D5: =IF(B5=C5, "Sim", "Não") -> Sim
A6: Terreno | B6: Razortide Bridge | C6: Razortide Bridge | D6: =IF(B6=C6, "Sim", "Não") -> Sim | F6: Funções
A7: Terreno | B7: Goldmire Bridge | C7: Goldmire Bridge | D7: =IF(B7=C7, "Sim", "Não") -> Sim | F7: Terreno | G7: =COUNTIF(A:A,F7) -> 20
A8: Terreno | B8: Goldmire Bridge | C8: Goldmire Bridge | D8: =IF(B8=C8, "Sim", "Não") -> Sim | F8: Modular | G8: =COUNTIF(A:A,F8) -> 20
A9: Terreno | B9: Goldmire Bridge | C9: Goldmire Bridge | D9: =IF(B9=C9, "Sim", "Não") -> Sim | F9: Sacrifício | G9: =COUNTIF(A:A,F9) -> 6
A10: Terreno | B10: Goldmire Bridge | C10: Goldmire Bridge | D10: =IF(B10=C10, "Sim", "Não") -> Sim | F10: Draw | G10: =COUNTIF(A:A,F10) -> 10
A11: Terreno | B11: Mistvault Bridge | C11: Mistvault Bridge | D11: =IF(B11=C11, "Sim", "Não") -> Sim | F11: Controle | G11: =COUNTIF(A:A,F11) -> 2
A12: Terreno | B12: Mistvault Bridge | C12: Mistvault Bridge | D12: =IF(B12=C12, "Sim", "Não") -> Sim | F12: Pump | G12: =COUNTIF(A:A,F12) -> 2
A13: Terreno | B13: Mistvault Bridge | C13: Mistvault Bridge | D13: =IF(B13=C13, "Sim", "Não") -> Sim | F13: Sideboard | G13: =COUNTIF(A:A,F13) -> 15
A14: Terreno | B14: Mistvault Bridge | C14: Mistvault Bridge | D14: =IF(B14=C14, "Sim", "Não") -> Sim
A15: Terreno | B15: Seat of the Synod | C15: Seat of the Synod | D15: =IF(B15=C15, "Sim", "Não") -> Sim
A16: Terreno | B16: Seat of the Synod | C16: Seat of the Synod | D16: =IF(B16=C16, "Sim", "Não") -> Sim
A17: Terreno | B17: Seat of the Synod | C17: Seat of the Synod | D17: =IF(B17=C17, "Sim", "Não") -> Sim
A18: Terreno | B18: Island | C18: Island | D18: =IF(B18=C18, "Sim", "Não") -> Sim
A19: Terreno | B19: Vault of Whispers | C19: Vault of Whispers | D19: =IF(B19=C19, "Sim", "Não") -> Sim
A20: Terreno | B20: Swamp | C20: Swamp | D20: =IF(B20=C20, "Sim", "Não") -> Sim
A21: Terreno | C21: Ancient Den | D21: =IF(B21=C21, "Sim", "Não") -> Não
A22: Terreno | B22: Plains | C22: Plains | D22: =IF(B22=C22, "Sim", "Não") -> Sim
A23: Modular | B23: Arcbound Mouser | C23: Arcbound Mouser | D23: =IF(B23=C23, "Sim", "Não") -> Sim
A24: Modular | B24: Arcbound Mouser | C24: Arcbound Mouser | D24: =IF(B24=C24, "Sim", "Não") -> Sim
A25: Modular | B25: Arcbound Mouser | C25: Arcbound Mouser | D25: =IF(B25=C25, "Sim", "Não") -> Sim
A26: Modular | B26: Arcbound Mouser | C26: Arcbound Mouser | D26: =IF(B26=C26, "Sim", "Não") -> Sim
A27: Modular | B27: Arcbound Worker | C27: Arcbound Worker | D27: =IF(B27=C27, "Sim", "Não") -> Sim
A28: Modular | B28: Arcbound Worker | C28: Arcbound Worker | D28: =IF(B28=C28, "Sim", "Não") -> Sim
A29: Modular | B29: Arcbound Worker | C29: Arcbound Worker | D29: =IF(B29=C29, "Sim", "Não") -> Sim
A30: Modular | B30: Arcbound Worker | C30: Arcbound Worker | D30: =IF(B30=C30, "Sim", "Não") -> Sim
A31: Modular | B31: Arcbound Stinger | C31: Arcbound Stinger | D31: =IF(B31=C31, "Sim", "Não") -> Sim
A32: Modular | B32: Arcbound Stinger | C32: Arcbound Stinger | D32: =IF(B32=C32, "Sim", "Não") -> Sim
A33: Modular | B33: Arcbound Stinger | C33: Arcbound Stinger | D33: =IF(B33=C33, "Sim", "Não") -> Sim
A34: Modular | B34: Arcbound Stinger | C34: Arcbound Stinger | D34: =IF(B34=C34, "Sim", "Não") -> Sim
A35: Modular | B35: Iron Apprentice | C35: Iron Apprentice | D35: =IF(B35=C35, "Sim", "Não") -> Sim | F35: Gengibruto
A36: Modular | B36: Iron Apprentice | C36: Iron Apprentice | D36: =IF(B36=C36, "Sim", "Não") -> Sim | F36: Airlift Captain
A37: Modular | B37: Iron Apprentice | C37: Iron Apprentice | D37: =IF(B37=C37, "Sim", "Não") -> Sim | F37: Vault Skirge
A38: Modular | B38: Iron Apprentice | C38: Iron Apprentice | D38: =IF(B38=C38, "Sim", "Não") -> Sim | F38: Arcbound Prototype
A39: Modular | B39: Kenku Artificer | C39: Kenku Artificer | D39: =IF(B39=C39, "Sim", "Não") -> Sim | F39: Dockworker Drone
A40: Modular | B40: Kenku Artificer | C40: Kenku Artificer | D40: =IF(B40=C40, "Sim", "Não") -> Sim
...

Sheet WBGAllies
A1: Orzhov Aliados - Pauper
A2: Função | B2: Carta Atual | C2: Carta Ideal | D2: Carta Final
A3: Terreno | B3: Scoured Barrens | C3: Scoured Barrens | D3: =IF(B3=C3, "Sim", "Não") -> Sim | F3: Mudanças Faltando | G3: =COUNTIF(D3:D105,"Não") -> 36
A4: Terreno | B4: Scoured Barrens | C4: Scoured Barrens | D4: =IF(B4=C4, "Sim", "Não") -> Sim | F4: Total de Cartas | G4: =SUM(G7:G25) -> 75
A5: Terreno | B5: Scoured Barrens | C5: Scoured Barrens | D5: =IF(B5=C5, "Sim", "Não") -> Sim
A6: Terreno | B6: Scoured Barrens | C6: Blossoming Sands | D6: =IF(B6=C6, "Sim", "Não") -> Não | F6: Funções
A7: Terreno | B7: Swamp | C7: Blossoming Sands | D7: =IF(B7=C7, "Sim", "Não") -> Não | F7: Terreno | G7: =COUNTIF(A:A,F7) -> 20
A8: Terreno | B8: Swamp | C8: Blossoming Sands | D8: =IF(B8=C8, "Sim", "Não") -> Não | F8: Aliado | G8: =COUNTIF(A:A,F8) -> 24
A9: Terreno | B9: Swamp | C9: Blossoming Sands | D9: =IF(B9=C9, "Sim", "Não") -> Não | F9: Win | G9: =COUNTIF(A:A,F9) -> 4
A10: Terreno | B10: Swamp | C10: Jungle Hollow | D10: =IF(B10=C10, "Sim", "Não") -> Não | F10: Draw | G10: =COUNTIF(A:A,F10) -> 8
A11: Terreno | B11: Swamp | C11: Jungle Hollow | D11: =IF(B11=C11, "Sim", "Não") -> Não | F11: Blink | G11: =COUNTIF(A:A,F11) -> 4
A12: Terreno | B12: Swamp | C12: Jungle Hollow | D12: =IF(B12=C12, "Sim", "Não") -> Não | F12: Sideboard | G12: =COUNTIF(A:A,F12) -> 15
A13: Terreno | B13: Swamp | C13: Evolving Wilds | D13: =IF(B13=C13, "Sim", "Não") -> Não
A14: Terreno | B14: Swamp | C14: Swamp | D14: =IF(B14=C14, "Sim", "Não") -> Sim
A15: Terreno | B15: Plains | C15: Swamp | D15: =IF(B15=C15, "Sim", "Não") -> Não
A16: Terreno | B16: Plains | C16: Swamp | D16: =IF(B16=C16, "Sim", "Não") -> Não
A17: Terreno | B17: Plains | C17: Forest | D17: =IF(B17=C17, "Sim", "Não") -> Não
A18: Terreno | B18: Plains | C18: Forest | D18: =IF(B18=C18, "Sim", "Não") -> Não
A19: Terreno | B19: Plains | C19: Forest | D19: =IF(B19=C19, "Sim", "Não") -> Não
A20: Terreno | B20: Plains | C20: Plains | D20: =IF(B20=C20, "Sim", "Não") -> Sim
A21: Terreno | B21: Plains | C21: Plains | D21: =IF(B21=C21, "Sim", "Não") -> Sim
A22: Terreno | B22: Plains | C22: Plains | D22: =IF(B22=C22, "Sim", "Não") -> Sim
A23: Aliado | B23: Bojuka Brigand | C23: Bojuka Brigand | D23: =IF(B23=C23, "Sim", "Não") -> Sim
A24: Aliado | B24: Bojuka Brigand | C24: Bojuka Brigand | D24: =IF(B24=C24, "Sim", "Não") -> Sim
... A66: Sideboard | B66: Beckon Apparition | C66: Beckon Apparition | D66: =IF(B66=C66, "Sim", "Não") -> Sim
A67: Sideboard | C67: Diabolic Edict | D67: =IF(B67=C67, "Sim", "Não") -> Não
A68: Sideboard | C68: Diabolic Edict | D68: =IF(B68=C68, "Sim", "Não") -> Não
A69: Sideboard | C69: Diabolic Edict | D69: =IF(B69=C69, "Sim", "Não") -> Não
A70: Sideboard | C70: Diabolic Edict | D70: =IF(B70=C70, "Sim", "Não") -> Não
A71: Sideboard | C71: Blessed Hippogriff // Tyr's Blessing | D71: =IF(B71=C71, "Sim", "Não") -> Não
A72: Sideboard | C72: Blessed Hippogriff // Tyr's Blessing | D72: =IF(B72=C72, "Sim", "Não") -> Não
A73: Sideboard | C73: Blessed Hippogriff // Tyr's Blessing | D73: =IF(B73=C73, "Sim", "Não") -> Não
A74: Sideboard | C74: Doom Blade | D74: =IF(B74=C74, "Sim", "Não") -> Não
A75: Sideboard | C75: Doom Blade | D75: =IF(B75=C75, "Sim", "Não") -> Não
A76: Sideboard | C76: Doom Blade | D76: =IF(B76=C76, "Sim", "Não") -> Não
A77: Sideboard | C77: Doom Blade | D77: =IF(B77=C77, "Sim", "Não") -> Não

Sheet WURAffinity
A1: WUR Affinity
A2: Função | B2: Carta Atual | C2: Carta Ideal | D2: Carta Final
A3: Terreno | B3: Rustvale Bridge | C3: Rustvale Bridge | D3: =IF(B3=C3, "Sim", "Não") -> Sim | F3: Mudanças Faltando | G3: =COUNTIF(D3:D105,"Não") -> 37
A4: Terreno | B4: Rustvale Bridge | C4: Rustvale Bridge | D4: =IF(B4=C4, "Sim", "Não") -> Sim | F4: Total de Cartas | G4: =SUM(G7:G25) -> 75
A5: Terreno | B5: Rustvale Bridge | C5: Rustvale Bridge | D5: =IF(B5=C5, "Sim", "Não") -> Sim
A6: Terreno | B6: Rustvale Bridge | C6: Rustvale Bridge | D6: =IF(B6=C6, "Sim", "Não") -> Sim | F6: Funções
A7: Terreno | B7: Razortide Bridge | C7: Razortide Bridge | D7: =IF(B7=C7, "Sim", "Não") -> Sim | E7: 3.9 | F7: Terreno | G7: =COUNTIF(A:A,F7) -> 16
A8: Terreno | B8: Razortide Bridge | C8: Razortide Bridge | D8: =IF(B8=C8, "Sim", "Não") -> Sim | E8: 3.9 | F8: Affinity | G8: =COUNTIF(A:A,F8) -> 16
A9: Terreno | B9: Silverbluff Bridge | C9: Silverbluff Bridge | D9: =IF(B9=C9, "Sim", "Não") -> Sim | E9: 4.9 | F9: Draw | G9: =COUNTIF(A:A,F9) -> 12
A10: Terreno | C10: Seat of the Synod | D10: =IF(B10=C10, "Sim", "Não") -> Não | F10: Suporte | G10: =COUNTIF(A:A,F10) -> 16
A11: Terreno | C11: Seat of the Synod | D11: =IF(B11=C11, "Sim", "Não") -> Não | F11: Sideboard | G11: =COUNTIF(A:A,F11) -> 15
A12: Terreno | C12: Great Furnace | D12: =IF(B12=C12, "Sim", "Não") -> Não
A13: Terreno | C13: Great Furnace | D13: =IF(B13=C13, "Sim", "Não") -> Não
A14: Terreno | C14: Great Furnace | D14: =IF(B14=C14, "Sim", "Não") -> Não
A15: Terreno | C15: Ancient Den | D15: =IF(B15=C15, "Sim", "Não") -> Não
A16: Terreno | C16: Ancient Den | D16: =IF(B16=C16, "Sim", "Não") -> Não
A17: Terreno | C17: Ancient Den | D17: =IF(B17=C17, "Sim", "Não") -> Não
A18: Terreno | C18: Ancient Den | D18: =IF(B18=C18, "Sim", "Não") -> Não
A19: Affinity | B19: Ornithopter | C19: Ornithopter | D19: =IF(B19=C19, "Sim", "Não") -> Sim
A20: Affinity | B20: Ornithopter | C20: Ornithopter | D20: =IF(B20=C20, "Sim", "Não") -> Sim
A21: Affinity | B21: Ornithopter | C21: Ornithopter | D21: =IF(B21=C21, "Sim", "Não") -> Sim
A22: Affinity | B22: Ornithopter | C22: Ornithopter | D22: =IF(B22=C22, "Sim", "Não") -> Sim
A23: Affinity | B23: Gengibrute | C23: Gengibrute | D23: =IF(B23=C23, "Sim", "Não") -> Sim
A24: Affinity | B24: Gengibrute | C24: Gengibrute | D24: =IF(B24=C24, "Sim", "Não") -> Sim
A25: Affinity | B25: Gengibrute | C25: Gengibrute | D25: =IF(B25=C25, "Sim", "Não") -> Sim
A26: Affinity | B26: Gengibrute | C26: Gengibrute | D26: =IF(B26=C26, "Sim", "Não") -> Sim
A27: Affinity | B27: Frogmite | C27: Frogmite | D27: =IF(B27=C27, "Sim", "Não") -> Sim
A28: Affinity | B28: Frogmite | C28: Frogmite | D28: =IF(B28=C28, "Sim", "Não") -> Sim
A29: Affinity | C29: Frogmite | D29: =IF(B29=C29, "Sim", "Não") -> Não
A30: Affinity | C30: Frogmite | D30: =IF(B30=C30, "Sim", "Não") -> Não
A31: Affinity | B31: Myr Enforcer | C31: Myr Enforcer | D31: =IF(B31=C31, "Sim", "Não") -> Sim
A32: Affinity | B32: Myr Enforcer | C32: Myr Enforcer | D32: =IF(B32=C32, "Sim", "Não") -> Sim
A33: Affinity | C33: Myr Enforcer | D33: =IF(B33=C33, "Sim", "Não") -> Não
A34: Affinity | C34: Myr Enforcer | D34: =IF(B34=C34, "Sim", "Não") -> Não
A35: Draw | B35: Thraben Inspector | C35: Thraben Inspector | D35: =IF(B35=C35, "Sim", "Não") -> Sim
A36: Draw | B36: Thraben Inspector | C36: Thraben Inspector | D36: =IF(B36=C36, "Sim", "Não") -> Sim
A37: Draw | B37: Thraben Inspector | C37: Thraben Inspector | D37: =IF(B37=C37, "Sim", "Não") -> Sim
A38: Draw | B38: Thraben Inspector | C38: Thraben Inspector | D38: =IF(B38=C38, "Sim", "Não") -> Sim
A39: Draw | B39: Thoughtcast | C39: Thoughtcast | D39: =IF(B39=C39, "Sim", "Não") -> Sim
A40: Draw | B40: Thoughtcast | C40: Thoughtcast | D40: =IF(B40=C40, "Sim", "Não") -> Sim
...
