Workbook

Sheet COMPRAS
A1: Total: | B1: =C2+C7+C12+C17+C22+C27+C32+C37+C42+C55 -> 0 | E1: =A2 -> Compras | F1: =B3 -> MTG Cards Games | G1: =B4 -> Legacy | H1: =B5 -> Mana Vai | J1: Deck/Função | K1: =A7 -> Interessantes | L1: =B8 -> Liga | M1: =B9 -> Legacy | N1: =B10 -> Overrun | P1: =A12 -> 0 | Q1: =B13 -> 0 | R1: =B14 -> 0 | S1: =B15 -> 0 | U1: =A17 -> 0 | V1: =B18 -> 0 | W1: =B19 -> 0 | X1: =B20 -> 0
A2: Compras | B2: Total Lojas: | C2: =SUM(C3:C5) -> 0 | E2: 4 Thorn of the Black Rose
A3: =COUNTA(E2:E175) -> 36 | B3: MTG Cards Games | C3: =SUM(F:F) -> 0 | E3: 3 Tithing Blade
B4: Legacy | C4: =SUM(G:G) -> 0 | E4: 4 Brainstorm
B5: Mana Vai | C5: =SUM(H:H) -> 0 | E5: 4 Portão da Mansão
E6: 4 Esmiuça-Tumba
A7: Interessantes | B7: Total Lojas: | C7: =SUM(C9:C10) -> 0 | E7: 4 Opt
A8: =COUNTA(K2:K193) -> 0 | B8: Liga | C8: =SUM(L:L) -> 0 | E8: 4 Existência Torturada
B9: Legacy | C9: =SUM(M:M) -> 0 | E9: 2 Portão do Dragão Negro
B10: Overrun | C10: =SUM(N:N) -> 0 | E10: 2 Porteiros de Saruli
E11: 4 Opt
E12: 3 Brainstorm
E13: 2 Roer até os Ossos
E14: 4 Tormod's Crypt
E15: 2 Smash to Dust
E16: 4 Spirited Companion
E17: 2 Ancient Den
E18: 1 Kenku Artificer
E19: 2 Experimental Augury
E20: 2 Thoughtcast
E21: 2 Saqueador Saco-de-Carne
E22: 1 All That Glitters
... E37: 3 Vândalo Mascarado

Sheet RESUMO
A1: Fractius | E1: Vida | I1: Fadas | M1: Knights | Q1: Modular | U1: Allies
A3: Total | B3: {=_xlfn._xlws.SORT(C3:C86,1,-1,0)} -> Young Wolf | C3: =IF(WGFractius!D3="Não",WGFractius!C3, " ") | E3: Total | F3: {=_xlfn._xlws.SORT(G3:G86,1,-1,0)} -> Unmake | G3: =IF(Vida!D3="Não",Vida!C3, " ") | I3: Total | J3: {=_xlfn._xlws.SORT(K3:K86,1,-1,0)} -> Vapor Snag | K3: =IF(Fadas!D3="Não",Fadas!C3, " ") | M3: Total | N3: {=_xlfn._xlws.SORT(O3:O86,1,-1,0)} -> Thorn of the Black Rose | O3: =IF(WBRKnights!D3="Não",WBRKnights!C3, " ") | Q3: Total | R3: {=_xlfn._xlws.SORT(S3:S86,1,-1,0)} -> Thoughtcast | S3: =IF(Modular!D3="Não",Modular!C3, " ") | U3: Total | V3: {=_xlfn._xlws.SORT(W3:W86,1,-1,0)} -> Swamp | W3: =IF(WBGAllies!D3="Não",WBGAllies!C3, " ")
A4: =WGFractius!G3 -> 17 | B4: Young Wolf | C4: =IF(WGFractius!D4="Não",WGFractius!C4, " ") | E4: =Vida!G3 -> 10 | F4: Thraben Inspector | G4: =IF(Vida!D4="Não",Vida!C4, " ") | I4: =Fadas!G3 -> 41 | J4: Vapor Snag | K4: =IF(Fadas!D4="Não",Fadas!C4, " ") | M4: =WBRKnights!G3 -> 14 | N4: Thorn of the Black Rose | O4: =IF(WBRKnights!D4="Não",WBRKnights!C4, " ") | Q4: =Modular!G3 -> 33 | R4: Thoughtcast | S4: =IF(Modular!D4="Não",Modular!C4, " ") | U4: =WBGAllies!G3 -> 36 | V4: Swamp | W4: =IF(WBGAllies!D4="Não",WBGAllies!C4, " ")
B5: Standard Bearer | C5: =IF(WGFractius!D5="Não",WGFractius!C5, " ") | F5: Ephemerate | G5: =IF(Vida!D5="Não",Vida!C5, " ") | J5: Vapor Snag | K5: =IF(Fadas!D5="Não",Fadas!C5, " ") | N5: Thorn of the Black Rose | O5: =IF(WBRKnights!D5="Não",WBRKnights!C5, " ") | R5: Thoughtcast | S5: =IF(Modular!D5="Não",Modular!C5, " ") | V5: Oran-Rief Survivalist | W5: =IF(WBGAllies!D5="Não",WBGAllies!C5, " ")
B6: Standard Bearer | C6: =IF(WGFractius!D6="Não",WGFractius!C6, " ") | F6: Ephemerate | G6: =IF(Vida!D6="Não",Vida!C6, " ") | J6: Vapor Snag | K6: =IF(Fadas!D6="Não",Fadas!C6, " ") | N6: Terminate | O6: =IF(WBRKnights!D6="Não",WBRKnights!C6, " ") | R6: Thoughtcast | S6: =IF(Modular!D6="Não",Modular!C6, " ") | V6: Oran-Rief Survivalist | W6: =IF(WBGAllies!D6="Não",WBGAllies!C6, " ") -> Blossoming Sands
B7: Standard Bearer | C7: =IF(WGFractius!D7="Não",WGFractius!C7, " ") | F7: Ephemerate | G7: =IF(Vida!D7="Não",Vida!C7, " ") -> Bojuka Bog | J7: Spellstutter Sprite | K7: =IF(Fadas!D7="Não",Fadas!C7, " ") | N7: Terminate | O7: =IF(WBRKnights!D7="Não",WBRKnights!C7, " ") -> Bojuka Bog | R7: Silverbluff Bridge | S7: =IF(Modular!D7="Não",Modular!C7, " ") | V7: Oran-Rief Survivalist | W7: =IF(WBGAllies!D7="Não",WBGAllies!C7, " ") -> Blossoming Sands
B8: Scattershot Archer | C8: =IF(WGFractius!D8="Não",WGFractius!C8, " ") | F8: Ephemerate | G8: =IF(Vida!D8="Não",Vida!C8, " ") -> Bojuka Bog | J8: Spellstutter Sprite | K8: =IF(Fadas!D8="Não",Fadas!C8, " ") | N8: Shining Armor | O8: =IF(WBRKnights!D8="Não",WBRKnights!C8, " ") -> Bojuka Bog | R8: Silverbluff Bridge | S8: =IF(Modular!D8="Não",Modular!C8, " ") | V8: Oran-Rief Survivalist | W8: =IF(WBGAllies!D8="Não",WBGAllies!C8, " ") -> Blossoming Sands
B9: Scattershot Archer | C9: =IF(WGFractius!D9="Não",WGFractius!C9, " ") | F9: Doom Blade | G9: =IF(Vida!D9="Não",Vida!C9, " ") | J9: Spellstutter Sprite | K9: =IF(Fadas!D9="Não",Fadas!C9, " ") | N9: Shining Armor | O9: =IF(WBRKnights!D9="Não",WBRKnights!C9, " ") | R9: Silverbluff Bridge | S9: =IF(Modular!D9="Não",Modular!C9, " ") | V9: Masked Vandal | W9: =IF(WBGAllies!D9="Não",WBGAllies!C9, " ") -> Blossoming Sands
B10: Relic of Progenitus | C10: =IF(WGFractius!D10="Não",WGFractius!C10, " ") | F10: Doom Blade | G10: =IF(Vida!D10="Não",Vida!C10, " ") | J10: Snaremaster Sprite | K10: =IF(Fadas!D10="Não",Fadas!C10, " ") | N10: Shining Armor | O10: =IF(WBRKnights!D10="Não",WBRKnights!C10, " ") | R10: Silverbluff Bridge | S10: =IF(Modular!D10="Não",Modular!C10, " ") | V10: Masked Vandal | W10: =IF(WBGAllies!D10="Não",WBGAllies!C10, " ") -> Jungle Hollow
B11: Relic of Progenitus | C11: =IF(WGFractius!D11="Não",WGFractius!C11, " ") | F11: Bojuka Bog | G11: =IF(Vida!D11="Não",Vida!C11, " ") | J11: Snaremaster Sprite | K11: =IF(Fadas!D11="Não",Fadas!C11, " ") | N11: Gallant Cavalry | O11: =IF(WBRKnights!D11="Não",WBRKnights!C11, " ") | R11: Scrapyard Salvo | S11: =IF(Modular!D11="Não",Modular!C11, " ") -> Silverbluff Bridge | V11: Masked Vandal | W11: =IF(WBGAllies!D11="Não",WBGAllies!C11, " ") -> Jungle Hollow
B12: Relic of Progenitus | C12: =IF(WGFractius!D12="Não",WGFractius!C12, " ") | F12: Bojuka Bog | G12: =IF(Vida!D12="Não",Vida!C12, " ") | J12: Snaremaster Sprite | K12: =IF(Fadas!D12="Não",Fadas!C12, " ") | N12: Diabolic Edict | O12: =IF(WBRKnights!D12="Não",WBRKnights!C12, " ") | R12: Scrapyard Salvo | S12: =IF(Modular!D12="Não",Modular!C12, " ") -> Silverbluff Bridge | V12: Masked Vandal | W12: =IF(WBGAllies!D12="Não",WBGAllies!C12, " ") -> Jungle Hollow
B13: Mutagenic Growth | C13: =IF(WGFractius!D13="Não",WGFractius!C13, " ") | G13: =IF(Vida!D13="Não",Vida!C13, " ") | J13: Snaremaster Sprite | K13: =IF(Fadas!D13="Não",Fadas!C13, " ") | N13: Diabolic Edict | O13: =IF(WBRKnights!D13="Não",WBRKnights!C13, " ") | R13: Relic of Progenitus | S13: =IF(Modular!D13="Não",Modular!C13, " ") -> Silverbluff Bridge | V13: Jungle Hollow | W13: =IF(WBGAllies!D13="Não",WBGAllies!C13, " ") -> Evolving Wilds
B14: Mutagenic Growth | C14: =IF(WGFractius!D14="Não",WGFractius!C14, " ") | G14: =IF(Vida!D14="Não",Vida!C14, " ") | J14: Psychic Barrier | K14: =IF(Fadas!D14="Não",Fadas!C14, " ") | N14: Diabolic Edict | O14: =IF(WBRKnights!D14="Não",WBRKnights!C14, " ") | R14: Relic of Progenitus | S14: =IF(Modular!D14="Não",Modular!C14, " ") -> Silverbluff Bridge | V14: Jungle Hollow | W14: =IF(WBGAllies!D14="Não",WBGAllies!C14, " ")
B15: Journey to Nowhere | C15: =IF(WGFractius!D15="Não",WGFractius!C15, " ") | G15: =IF(Vida!D15="Não",Vida!C15, " ") | J15: Psychic Barrier | K15: =IF(Fadas!D15="Não",Fadas!C15, " ") | N15: Bojuka Bog | O15: =IF(WBRKnights!D15="Não",WBRKnights!C15, " ") | R15: Recommission | S15: =IF(Modular!D15="Não",Modular!C15, " ") | V15: Jungle Hollow | W15: =IF(WBGAllies!D15="Não",WBGAllies!C15, " ") -> Swamp
B16: Journey to Nowhere | C16: =IF(WGFractius!D16="Não",WGFractius!C16, " ") | G16: =IF(Vida!D16="Não",Vida!C16, " ") | J16: Psychic Barrier | K16: =IF(Fadas!D16="Não",Fadas!C16, " ") | N16: Bojuka Bog | O16: =IF(WBRKnights!D16="Não",WBRKnights!C16, " ") | R16: Recommission | S16: =IF(Modular!D16="Não",Modular!C16, " ") | V16: Graypelt Hunter | W16: =IF(WBGAllies!D16="Não",WBGAllies!C16, " ") -> Swamp
B17: Gut Shot | C17: =IF(WGFractius!D17="Não",WGFractius!C17, " ") | G17: =IF(Vida!D17="Não",Vida!C17, " ") | J17: Olhos Noturnos | K17: =IF(Fadas!D17="Não",Fadas!C17, " ") | O17: =IF(WBRKnights!D17="Não",WBRKnights!C17, " ") | R17: Recommission | S17: =IF(Modular!D17="Não",Modular!C17, " ") | V17: Graypelt Hunter | W17: =IF(WBGAllies!D17="Não",WBGAllies!C17, " ") -> Forest
B18: Gut Shot | C18: =IF(WGFractius!D18="Não",WGFractius!C18, " ") | G18: =IF(Vida!D18="Não",Vida!C18, " ") | J18: Olhos Noturnos | K18: =IF(Fadas!D18="Não",Fadas!C18, " ") | O18: =IF(WBRKnights!D18="Não",WBRKnights!C18, " ") | R18: Metallic Rebuke | S18: =IF(Modular!D18="Não",Modular!C18, " ") | V18: Graypelt Hunter | W18: =IF(WBGAllies!D18="Não",WBGAllies!C18, " ") -> Forest
B19: Gut Shot | C19: =IF(WGFractius!D19="Não",WGFractius!C19, " ") | G19: =IF(Vida!D19="Não",Vida!C19, " ") | J19: Olhos Noturnos | K19: =IF(Fadas!D19="Não",Fadas!C19, " ") | O19: =IF(WBRKnights!D19="Não",WBRKnights!C19, " ") | R19: Metallic Rebuke | S19: =IF(Modular!D19="Não",Modular!C19, " ") | V19: Graypelt Hunter | W19: =IF(WBGAllies!D19="Não",WBGAllies!C19, " ") -> Forest
C20: =IF(WGFractius!D20="Não",WGFractius!C20, " ") | G20: =IF(Vida!D20="Não",Vida!C20, " ") | J20: Olhos Noturnos | K20: =IF(Fadas!D20="Não",Fadas!C20, " ") | O20: =IF(WBRKnights!D20="Não",WBRKnights!C20, " ") | R20: Metallic Rebuke | S20: =IF(Modular!D20="Não",Modular!C20, " ") | V20: Forest | W20: =IF(WBGAllies!D20="Não",WBGAllies!C20, " ")
C21: =IF(WGFractius!D21="Não",WGFractius!C21, " ") | G21: =IF(Vida!D21="Não",Vida!C21, " ") | J21: Ninja das Horas Tardias | K21: =IF(Fadas!D21="Não",Fadas!C21, " ") | O21: =IF(WBRKnights!D21="Não",WBRKnights!C21, " ") | R21: Metallic Rebuke | S21: =IF(Modular!D21="Não",Modular!C21, " ") | V21: Forest | W21: =IF(WBGAllies!D21="Não",WBGAllies!C21, " ")
C22: =IF(WGFractius!D22="Não",WGFractius!C22, " ") | G22: =IF(Vida!D22="Não",Vida!C22, " ") | J22: Ninja das Horas Tardias | K22: =IF(Fadas!D22="Não",Fadas!C22, " ") | O22: =IF(WBRKnights!D22="Não",WBRKnights!C22, " ") | R22: Makeshift Munitions | S22: =IF(Modular!D22="Não",Modular!C22, " ") | V22: Forest | W22: =IF(WBGAllies!D22="Não",WBGAllies!C22, " ")
C23: =IF(WGFractius!D23="Não",WGFractius!C23, " ") | G23: =IF(Vida!D23="Não",Vida!C23, " ") | J23: Ninja das Horas Tardias | K23: =IF(Fadas!D23="Não",Fadas!C23, " ") | O23: =IF(WBRKnights!D23="Não",WBRKnights!C23, " ") | R23: Makeshift Munitions | S23: =IF(Modular!D23="Não",Modular!C23, " ") | V23: Evolving Wilds | W23: =IF(WBGAllies!D23="Não",WBGAllies!C23, " ")
C24: =IF(WGFractius!D24="Não",WGFractius!C24, " ") | G24: =IF(Vida!D24="Não",Vida!C24, " ") | J24: Ninja das Horas Tardias | K24: =IF(Fadas!D24="Não",Fadas!C24, " ") | O24: =IF(WBRKnights!D24="Não",WBRKnights!C24, " ") | R24: Kenku Artificer | S24: =IF(Modular!D24="Não",Modular!C24, " ") | V24: Doom Blade | W24: =IF(WBGAllies!D24="Não",WBGAllies!C24, " ")
C25: =IF(WGFractius!D25="Não",WGFractius!C25, " ") | G25: =IF(Vida!D25="Não",Vida!C25, " ") | J25: Negação Altiva | K25: =IF(Fadas!D25="Não",Fadas!C25, " ") | O25: =IF(WBRKnights!D25="Não",WBRKnights!C25, " ") | R25: Kenku Artificer | S25: =IF(Modular!D25="Não",Modular!C25, " ") | V25: Doom Blade | W25: =IF(WBGAllies!D25="Não",WBGAllies!C25, " ")
C26: =IF(WGFractius!D26="Não",WGFractius!C26, " ") | G26: =IF(Vida!D26="Não",Vida!C26, " ") | J26: Negação Altiva | K26: =IF(Fadas!D26="Não",Fadas!C26, " ") | O26: =IF(WBRKnights!D26="Não",WBRKnights!C26, " ") | R26: Kenku Artificer | S26: =IF(Modular!D26="Não",Modular!C26, " ") | V26: Doom Blade | W26: =IF(WBGAllies!D26="Não",WBGAllies!C26, " ")
C27: =IF(WGFractius!D27="Não",WGFractius!C27, " ") | G27: =IF(Vida!D27="Não",Vida!C27, " ") | J27: Negação Altiva | K27: =IF(Fadas!D27="Não",Fadas!C27, " ") | O27: =IF(WBRKnights!D27="Não",WBRKnights!C27, " ") | R27: Kenku Artificer | S27: =IF(Modular!D27="Não",Modular!C27, " ") | V27: Doom Blade | W27: =IF(WBGAllies!D27="Não",WBGAllies!C27, " ")
C28: =IF(WGFractius!D28="Não",WGFractius!C28, " ") | G28: =IF(Vida!D28="Não",Vida!C28, " ") | J28: Negação Altiva | K28: =IF(Fadas!D28="Não",Fadas!C28, " ") | O28: =IF(WBRKnights!D28="Não",WBRKnights!C28, " ") | R28: Galvanic Blast | S28: =IF(Modular!D28="Não",Modular!C28, " ") | V28: Diabolic Edict | W28: =IF(WBGAllies!D28="Não",WBGAllies!C28, " ")
C29: =IF(WGFractius!D29="Não",WGFractius!C29, " ") | G29: =IF(Vida!D29="Não",Vida!C29, " ") | J29: Mulldrifter | K29: =IF(Fadas!D29="Não",Fadas!C29, " ") -> Snaremaster Sprite | O29: =IF(WBRKnights!D29="Não",WBRKnights!C29, " ") | R29: Galvanic Blast | S29: =IF(Modular!D29="Não",Modular!C29, " ") | V29: Diabolic Edict | W29: =IF(WBGAllies!D29="Não",WBGAllies!C29, " ")
C30: =IF(WGFractius!D30="Não",WGFractius!C30, " ") | G30: =IF(Vida!D30="Não",Vida!C30, " ") | J30: Mulldrifter | K30: =IF(Fadas!D30="Não",Fadas!C30, " ") -> Snaremaster Sprite | O30: =IF(WBRKnights!D30="Não",WBRKnights!C30, " ") | R30: Galvanic Blast | S30: =IF(Modular!D30="Não",Modular!C30, " ") | V30: Diabolic Edict | W30: =IF(WBGAllies!D30="Não",WBGAllies!C30, " ")
C31: =IF(WGFractius!D31="Não",WGFractius!C31, " ") | G31: =IF(Vida!D31="Não",Vida!C31, " ") | J31: Mulldrifter | K31: =IF(Fadas!D31="Não",Fadas!C31, " ") -> Snaremaster Sprite | O31: =IF(WBRKnights!D31="Não",WBRKnights!C31, " ") | R31: Galvanic Blast | S31: =IF(Modular!D31="Não",Modular!C31, " ") | V31: Diabolic Edict | W31: =IF(WBGAllies!D31="Não",WBGAllies!C31, " ")
... C35: =IF(WGFractius!D35="Não",WGFractius!C35, " ") | G35: =IF(Vida!D35="Não",Vida!C35, " ") | J35: Eterno Aviano | K35: =IF(Fadas!D35="Não",Fadas!C35, " ") -> Mulldrifter | O35: =IF(WBRKnights!D35="Não",WBRKnights!C35, " ") | R35: Apostle's Blessing | S35: =IF(Modular!D35="Não",Modular!C35, " ") | V35: Blossoming Sands | W35: =IF(WBGAllies!D35="Não",WBGAllies!C35, " ")
C36: =IF(WGFractius!D36="Não",WGFractius!C36, " ") | G36: =IF(Vida!D36="Não",Vida!C36, " ") | J36: Estalo | K36: =IF(Fadas!D36="Não",Fadas!C36, " ") -> Mulldrifter | O36: =IF(WBRKnights!D36="Não",WBRKnights!C36, " ") | S36: =IF(Modular!D36="Não",Modular!C36, " ") | V36: Blessed Hippogriff // Tyr's Blessing | W36: =IF(WBGAllies!D36="Não",WBGAllies!C36, " ")
C37: =IF(WGFractius!D37="Não",WGFractius!C37, " ") | G37: =IF(Vida!D37="Não",Vida!C37, " ") | J37: Estalo | K37: =IF(Fadas!D37="Não",Fadas!C37, " ") | O37: =IF(WBRKnights!D37="Não",WBRKnights!C37, " ") | S37: =IF(Modular!D37="Não",Modular!C37, " ") | V37: Blessed Hippogriff // Tyr's Blessing | W37: =IF(WBGAllies!D37="Não",WBGAllies!C37, " ")
C38: =IF(WGFractius!D38="Não",WGFractius!C38, " ") | G38: =IF(Vida!D38="Não",Vida!C38, " ") | J38: Estalo | K38: =IF(Fadas!D38="Não",Fadas!C38, " ") | O38: =IF(WBRKnights!D38="Não",WBRKnights!C38, " ") | S38: =IF(Modular!D38="Não",Modular!C38, " ") | V38: Blessed Hippogriff // Tyr's Blessing | W38: =IF(WBGAllies!D38="Não",WBGAllies!C38, " ")
C39: =IF(WGFractius!D39="Não",WGFractius!C39, " ") | G39: =IF(Vida!D39="Não",Vida!C39, " ") | J39: Estalo | K39: =IF(Fadas!D39="Não",Fadas!C39, " ") | O39: =IF(WBRKnights!D39="Não",WBRKnights!C39, " ") | S39: =IF(Modular!D39="Não",Modular!C39, " ") -> Kenku Artificer | W39: =IF(WBGAllies!D39="Não",WBGAllies!C39, " ") -> Masked Vandal
C40: =IF(WGFractius!D40="Não",WGFractius!C40, " ") | G40: =IF(Vida!D40="Não",Vida!C40, " ") | J40: Counterspell | K40: =IF(Fadas!D40="Não",Fadas!C40, " ") -> Eterno Aviano | O40: =IF(WBRKnights!D40="Não",WBRKnights!C40, " ") | S40: =IF(Modular!D40="Não",Modular!C40, " ") -> Kenku Artificer | W40: =IF(WBGAllies!D40="Não",WBGAllies!C40, " ") -> Masked Vandal
C41: =IF(WGFractius!D41="Não",WGFractius!C41, " ") | G41: =IF(Vida!D41="Não",Vida!C41, " ") | J41: Counterspell | K41: =IF(Fadas!D41="Não",Fadas!C41, " ") -> Ninja das Horas Tardias | O41: =IF(WBRKnights!D41="Não",WBRKnights!C41, " ") | S41: =IF(Modular!D41="Não",Modular!C41, " ") -> Kenku Artificer | W41: =IF(WBGAllies!D41="Não",WBGAllies!C41, " ") -> Masked Vandal
C42: =IF(WGFractius!D42="Não",WGFractius!C42, " ") | G42: =IF(Vida!D42="Não",Vida!C42, " ") | J42: Counterspell | K42: =IF(Fadas!D42="Não",Fadas!C42, " ") -> Ninja das Horas Tardias | O42: =IF(WBRKnights!D42="Não",WBRKnights!C42, " ") | S42: =IF(Modular!D42="Não",Modular!C42, " ") -> Kenku Artificer | W42: =IF(WBGAllies!D42="Não",WBGAllies!C42, " ") -> Masked Vandal
C43: =IF(WGFractius!D43="Não",WGFractius!C43, " ") | G43: =IF(Vida!D43="Não",Vida!C43, " ") | J43: Counterspell | K43: =IF(Fadas!D43="Não",Fadas!C43, " ") -> Ninja das Horas Tardias | O43: =IF(WBRKnights!D43="Não",WBRKnights!C43, " ") -> Gallant Cavalry | S43: =IF(Modular!D43="Não",Modular!C43, " ") | W43: =IF(WBGAllies!D43="Não",WBGAllies!C43, " ") -> Oran-Rief Survivalist
C44: =IF(WGFractius!D44="Não",WGFractius!C44, " ") | G44: =IF(Vida!D44="Não",Vida!C44, " ") | K44: =IF(Fadas!D44="Não",Fadas!C44, " ") -> Ninja das Horas Tardias | O44: =IF(WBRKnights!D44="Não",WBRKnights!C44, " ") | S44: =IF(Modular!D44="Não",Modular!C44, " ") | W44: =IF(WBGAllies!D44="Não",WBGAllies!C44, " ") -> Oran-Rief Survivalist
...

Sheet RESUMO (2)
A1: Temur Control | E1: Jeskay Control | I1: Esper Modular
A3: Total | B3: {=_xlfn._xlws.SORT(C3:C86,1,-1,0)} -> Wilt | C3: =IF(TemurC!D3="Não",TemurC!C3, " ") -> Simic Growth Chamber | E3: Total | F3: {=_xlfn._xlws.SORT(G3:G86,1,-1,0)} -> Ponder | G3: =IF(WURFlicker!D3="Não",WURFlicker!C3, " ") | I3: Total | J3: {=_xlfn._xlws.SORT(K3:K86,1,-1,0)} -> Ancient Den | K3: =IF(WUBModular!D3="Não",WUBModular!C3, " ")
A4: =TemurC!G3 -> 75 | B4: Wilt | C4: =IF(TemurC!D4="Não",TemurC!C4, " ") -> Simic Growth Chamber | E4: =WURFlicker!G3 -> 10 | F4: Ponder | G4: =IF(WURFlicker!D4="Não",WURFlicker!C4, " ") | I4: =WUBModular!G3 -> 1 | K4: =IF(WUBModular!D4="Não",WUBModular!C4, " ")
B5: Wilt | C5: =IF(TemurC!D5="Não",TemurC!C5, " ") -> Izzet Boilerworks | F5: Ponder | G5: =IF(WURFlicker!D5="Não",WURFlicker!C5, " ") | K5: =IF(WUBModular!D5="Não",WUBModular!C5, " ")
B6: Wilt | C6: =IF(TemurC!D6="Não",TemurC!C6, " ") -> Izzet Boilerworks | F6: Ponder | G6: =IF(WURFlicker!D6="Não",WURFlicker!C6, " ") | K6: =IF(WUBModular!D6="Não",WUBModular!C6, " ")
B7: Vapor Snag | C7: =IF(TemurC!D7="Não",TemurC!C7, " ") -> Gruul Turf | F7: Lórien Revealed | G7: =IF(WURFlicker!D7="Não",WURFlicker!C7, " ") | K7: =IF(WUBModular!D7="Não",WUBModular!C7, " ")
B8: Vapor Snag | C8: =IF(TemurC!D8="Não",TemurC!C8, " ") -> Gruul Turf | F8: Lórien Revealed | G8: =IF(WURFlicker!D8="Não",WURFlicker!C8, " ") | K8: =IF(WUBModular!D8="Não",WUBModular!C8, " ")
B9: Vapor Snag | C9: =IF(TemurC!D9="Não",TemurC!C9, " ") -> Swiftwater Cliffs | F9: Destroy Evil | G9: =IF(WURFlicker!D9="Não",WURFlicker!C9, " ") | K9: =IF(WUBModular!D9="Não",WUBModular!C9, " ")
B10: Vapor Snag | C10: =IF(TemurC!D10="Não",TemurC!C10, " ") -> Swiftwater Cliffs | F10: Destroy Evil | G10: =IF(WURFlicker!D10="Não",WURFlicker!C10, " ") | K10: =IF(WUBModular!D10="Não",WUBModular!C10, " ")
B11: Thornwood Falls | C11: =IF(TemurC!D11="Não",TemurC!C11, " ") -> Rugged Highlands | F11: Destroy Evil | G11: =IF(WURFlicker!D11="Não",WURFlicker!C11, " ") | K11: =IF(WUBModular!D11="Não",WUBModular!C11, " ")
B12: Thornwood Falls | C12: =IF(TemurC!D12="Não",TemurC!C12, " ") -> Rugged Highlands | F12: Cast into the Fire | G12: =IF(WURFlicker!D12="Não",WURFlicker!C12, " ") | K12: =IF(WUBModular!D12="Não",WUBModular!C12, " ")
B13: Terror Tolariano | C13: =IF(TemurC!D13="Não",TemurC!C13, " ") -> Thornwood Falls | G13: =IF(WURFlicker!D13="Não",WURFlicker!C13, " ") | K13: =IF(WUBModular!D13="Não",WUBModular!C13, " ")
B14: Terror Tolariano | C14: =IF(TemurC!D14="Não",TemurC!C14, " ") -> Thornwood Falls | G14: =IF(WURFlicker!D14="Não",WURFlicker!C14, " ") | K14: =IF(WUBModular!D14="Não",WUBModular!C14, " ")
B15: Terror Tolariano | C15: =IF(TemurC!D15="Não",TemurC!C15, " ") -> Evolving Wilds | G15: =IF(WURFlicker!D15="Não",WURFlicker!C15, " ") | K15: =IF(WUBModular!D15="Não",WUBModular!C15, " ")
B16: Terror Tolariano | C16: =IF(TemurC!D16="Não",TemurC!C16, " ") -> Evolving Wilds | G16: =IF(WURFlicker!D16="Não",WURFlicker!C16, " ") | K16: =IF(WUBModular!D16="Não",WUBModular!C16, " ")
B17: Swiftwater Cliffs | C17: =IF(TemurC!D17="Não",TemurC!C17, " ") -> Island | G17: =IF(WURFlicker!D17="Não",WURFlicker!C17, " ") | K17: =IF(WUBModular!D17="Não",WUBModular!C17, " ")
B18: Swiftwater Cliffs | C18: =IF(TemurC!D18="Não",TemurC!C18, " ") -> Island | G18: =IF(WURFlicker!D18="Não",WURFlicker!C18, " ") | K18: =IF(WUBModular!D18="Não",WUBModular!C18, " ")
B19: Sprout Swarm | C19: =IF(TemurC!D19="Não",TemurC!C19, " ") -> Island | G19: =IF(WURFlicker!D19="Não",WURFlicker!C19, " ") | K19: =IF(WUBModular!D19="Não",WUBModular!C19, " ")
B20: Sprout Swarm | C20: =IF(TemurC!D20="Não",TemurC!C20, " ") -> Mountain | G20: =IF(WURFlicker!D20="Não",WURFlicker!C20, " ") | K20: =IF(WUBModular!D20="Não",WUBModular!C20, " ")
B21: Spell Pierce | C21: =IF(TemurC!D21="Não",TemurC!C21, " ") -> Mountain | G21: =IF(WURFlicker!D21="Não",WURFlicker!C21, " ") | K21: =IF(WUBModular!D21="Não",WUBModular!C21, " ") -> Ancient Den
B22: Spell Pierce | C22: =IF(TemurC!D22="Não",TemurC!C22, " ") -> Mountain | G22: =IF(WURFlicker!D22="Não",WURFlicker!C22, " ") | K22: =IF(WUBModular!D22="Não",WUBModular!C22, " ")
B23: Spell Pierce | C23: =IF(TemurC!D23="Não",TemurC!C23, " ") -> Forest | G23: =IF(WURFlicker!D23="Não",WURFlicker!C23, " ") | K23: =IF(WUBModular!D23="Não",WUBModular!C23, " ")
B24: Spell Pierce | C24: =IF(TemurC!D24="Não",TemurC!C24, " ") -> Forest | G24: =IF(WURFlicker!D24="Não",WURFlicker!C24, " ") | K24: =IF(WUBModular!D24="Não",WUBModular!C24, " ")
... B31: Relic of Progenitus | C31: =IF(TemurC!D31="Não",TemurC!C31, " ") -> Sprout Swarm | G31: =IF(WURFlicker!D31="Não",WURFlicker!C31, " ") | K31: =IF(WUBModular!D31="Não",WUBModular!C31, " ")
B32: Pulse of Murasa | C32: =IF(TemurC!D32="Não",TemurC!C32, " ") -> Coiling Oracle | G32: =IF(WURFlicker!D49="Não",WURFlicker!C49, " ") -> Lórien Revealed | K32: =IF(WUBModular!D32="Não",WUBModular!C32, " ")
B33: Pulse of Murasa | C33: =IF(TemurC!D33="Não",TemurC!C33, " ") -> Coiling Oracle | G33: =IF(WURFlicker!D50="Não",WURFlicker!C50, " ") -> Lórien Revealed | K33: =IF(WUBModular!D33="Não",WUBModular!C33, " ")
B34: Pulse of Murasa | C34: =IF(TemurC!D34="Não",TemurC!C34, " ") -> Behold the Multiverse | G34: =IF(WURFlicker!D32="Não",WURFlicker!C32, " ") | K34: =IF(WUBModular!D34="Não",WUBModular!C34, " ")
B35: Pulse of Murasa | C35: =IF(TemurC!D35="Não",TemurC!C35, " ") -> Behold the Multiverse | G35: =IF(WURFlicker!D33="Não",WURFlicker!C33, " ") | K35: =IF(WUBModular!D35="Não",WUBModular!C35, " ")
B36: Mountain | C36: =IF(TemurC!D36="Não",TemurC!C36, " ") -> Behold the Multiverse | G36: =IF(WURFlicker!D34="Não",WURFlicker!C34, " ") | K36: =IF(WUBModular!D36="Não",WUBModular!C36, " ")
B37: Mountain | C37: =IF(TemurC!D37="Não",TemurC!C37, " ") -> Growth Spiral | G37: =IF(WURFlicker!D35="Não",WURFlicker!C35, " ") | K37: =IF(WUBModular!D37="Não",WUBModular!C37, " ")
B38: Mountain | C38: =IF(TemurC!D38="Não",TemurC!C38, " ") -> Growth Spiral | G38: =IF(WURFlicker!D36="Não",WURFlicker!C36, " ") | K38: =IF(WUBModular!D38="Não",WUBModular!C38, " ")
B39: Lightning Bolt | C39: =IF(TemurC!D39="Não",TemurC!C39, " ") -> Growth Spiral | G39: =IF(WURFlicker!D37="Não",WURFlicker!C37, " ") -> Ponder | K39: =IF(WUBModular!D39="Não",WUBModular!C39, " ")
B40: Lightning Bolt | C40: =IF(TemurC!D40="Não",TemurC!C40, " ") -> Growth Spiral | G40: =IF(WURFlicker!D38="Não",WURFlicker!C38, " ") -> Ponder | K40: =IF(WUBModular!D40="Não",WUBModular!C40, " ")
B41: Lightning Bolt | C41: =IF(TemurC!D41="Não",TemurC!C41, " ") -> Eureka Moment | G41: =IF(WURFlicker!D39="Não",WURFlicker!C39, " ") -> Ponder | K41: =IF(WUBModular!D41="Não",WUBModular!C41, " ")
B42: Lightning Bolt | C42: =IF(TemurC!D42="Não",TemurC!C42, " ") -> Eureka Moment | G42: =IF(WURFlicker!D40="Não",WURFlicker!C40, " ") -> Ponder | K42: =IF(WUBModular!D42="Não",WUBModular!C42, " ")
B43: Izzet Boilerworks | C43: =IF(TemurC!D43="Não",TemurC!C43, " ") -> Eureka Moment | G43: =IF(WURFlicker!D41="Não",WURFlicker!C41, " ") | K43: =IF(WUBModular!D43="Não",WUBModular!C43, " ")
B44: Izzet Boilerworks | C44: =IF(TemurC!D44="Não",TemurC!C44, " ") -> Eureka Moment | G44: =IF(WURFlicker!D42="Não",WURFlicker!C42, " ") | K44: =IF(WUBModular!D44="Não",WUBModular!C44, " ")
B45: Island | C45: =IF(TemurC!D45="Não",TemurC!C45, " ") -> Counterspell | G45: =IF(WURFlicker!D43="Não",WURFlicker!C43, " ") | K45: =IF(WUBModular!D45="Não",WUBModular!C45, " ")
... B50: Growth Spiral | C50: =IF(TemurC!D50="Não",TemurC!C50, " ") -> Spell Pierce | G50: =IF(WURFlicker!D48="Não",WURFlicker!C48, " ") | K50: =IF(WUBModular!D50="Não",WUBModular!C50, " ")
B51: Growth Spiral | C51: =IF(TemurC!D51="Não",TemurC!C51, " ") -> Lightning Bolt | G51: =IF(WURFlicker!D51="Não",WURFlicker!C51, " ") | K51: =IF(WUBModular!D51="Não",WUBModular!C51, " ")
...

Sheet WGFractius
A1: Selesnya Fractius - Pauper
A2: Função | B2: Carta Atual | C2: Carta Ideal | D2: Carta Final
A3: Terreno | B3: Blossoming Sands | C3: Blossoming Sands | D3: =IF(B3=C3, "Sim", "Não") -> Sim | F3: Mudanças Faltando | G3: =COUNTIF(D3:D105,"Não") -> 17
A4: Terreno | B4: Blossoming Sands | C4: Blossoming Sands | D4: =IF(B4=C4, "Sim", "Não") -> Sim | F4: Total de Cartas | G4: =SUM(G7:G25) -> 75
A5: Terreno | B5: Blossoming Sands | C5: Blossoming Sands | D5: =IF(B5=C5, "Sim", "Não") -> Sim
A6: Terreno | B6: Blossoming Sands | C6: Blossoming Sands | D6: =IF(B6=C6, "Sim", "Não") -> Sim | F6: Funções
A7: Terreno | B7: Tranquil Thicket | C7: Tranquil Thicket | D7: =IF(B7=C7, "Sim", "Não") -> Sim | F7: Terreno | G7: =COUNTIF(A:A,F7) -> 21
A8: Terreno | B8: Tranquil Thicket | C8: Tranquil Thicket | D8: =IF(B8=C8, "Sim", "Não") -> Sim | F8: Combate | G8: =COUNTIF(A:A,F8) -> 20
A9: Terreno | B9: Tranquil Thicket | C9: Tranquil Thicket | D9: =IF(B9=C9, "Sim", "Não") -> Sim | F9: Draw | G9: =COUNTIF(A:A,F9) -> 8
A10: Terreno | B10: Secluded Steppe | C10: Secluded Steppe | D10: =IF(B10=C10, "Sim", "Não") -> Sim | F10: Trick | G10: =COUNTIF(A:A,F10) -> 9
A11: Terreno | B11: Forest | C11: Forest | D11: =IF(B11=C11, "Sim", "Não") -> Sim | F11: Controle | G11: =COUNTIF(A:A,F11) -> 2
A12: Terreno | B12: Forest | C12: Forest | D12: =IF(B12=C12, "Sim", "Não") -> Sim | F12: Sideboard | G12: =COUNTIF(A:A,F12) -> 15
A13: Terreno | B13: Forest | C13: Forest | D13: =IF(B13=C13, "Sim", "Não") -> Sim
A14: Terreno | B14: Forest | C14: Forest | D14: =IF(B14=C14, "Sim", "Não") -> Sim
A15: Terreno | B15: Forest | C15: Forest | D15: =IF(B15=C15, "Sim", "Não") -> Sim
A16: Terreno | B16: Forest | C16: Forest | D16: =IF(B16=C16, "Sim", "Não") -> Sim
A17: Terreno | B17: Plains | C17: Plains | D17: =IF(B17=C17, "Sim", "Não") -> Sim
A18: Terreno | B18: Plains | C18: Plains | D18: =IF(B18=C18, "Sim", "Não") -> Sim
A19: Terreno | B19: Plains | C19: Plains | D19: =IF(B19=C19, "Sim", "Não") -> Sim
A20: Terreno | B20: Plains | C20: Plains | D20: =IF(B20=C20, "Sim", "Não") -> Sim
A21: Terreno | B21: Plains | C21: Plains | D21: =IF(B21=C21, "Sim", "Não") -> Sim
A22: Terreno | B22: Tranquil Expanse | C22: Tranquil Expanse | D22: =IF(B22=C22, "Sim", "Não") -> Sim
A23: Terreno | B23: Tranquil Expanse | C23: Tranquil Expanse | D23: =IF(B23=C23, "Sim", "Não") -> Sim
A24: Combate | B24: Predatory Sliver | C24: Predatory Sliver | D24: =IF(B24=C24, "Sim", "Não") -> Sim
... A62: Controle | B62: Journey to Nowhere | C62: Journey to Nowhere | D62: =IF(B62=C62, "Sim", "Não") -> Sim
A63: Sideboard | C63: Journey to Nowhere | D63: =IF(B63=C63, "Sim", "Não") -> Não
A64: Sideboard | C64: Journey to Nowhere | D64: =IF(B64=C64, "Sim", "Não") -> Não
A65: Sideboard | C65: Young Wolf | D65: =IF(B65=C65, "Sim", "Não") -> Não
A66: Sideboard | C66: Young Wolf | D66: =IF(B66=C66, "Sim", "Não") -> Não
A67: Sideboard | C67: Standard Bearer | D67: =IF(B67=C67, "Sim", "Não") -> Não
A68: Sideboard | C68: Standard Bearer | D68: =IF(B68=C68, "Sim", "Não") -> Não
A69: Sideboard | C69: Standard Bearer | D69: =IF(B69=C69, "Sim", "Não") -> Não
A70: Sideboard | C70: Gut Shot | D70: =IF(B70=C70, "Sim", "Não") -> Não
A71: Sideboard | C71: Gut Shot | D71: =IF(B71=C71, "Sim", "Não") -> Não
A72: Sideboard | C72: Gut Shot | D72: =IF(B72=C72, "Sim", "Não") -> Não
A73: Sideboard | C73: Scattershot Archer | D73: =IF(B73=C73, "Sim", "Não") -> Não
A74: Sideboard | C74: Scattershot Archer | D74: =IF(B74=C74, "Sim", "Não") -> Não
... A77: Sideboard | C77: Relic of Progenitus | D77: =IF(B77=C77, "Sim", "Não") -> Não
D78: =IF(B78=C78, "Sim", "Não") -> Sim
D79: =IF(B79=C79, "Sim", "Não") -> Sim
...

Sheet Vida
A1: Vida e Morte - Pauper
A2: Função | B2: Carta Atual | C2: Carta Ideal | D2: Carta Final
A3: Terreno | B3: Scoured Barrens | C3: Scoured Barrens | D3: =IF(B3=C3, "Sim", "Não") -> Sim | F3: Mudanças Faltando | G3: =COUNTIF(D3:D105,"Não") -> 10
A4: Terreno | B4: Scoured Barrens | C4: Scoured Barrens | D4: =IF(B4=C4, "Sim", "Não") -> Sim | F4: Total de Cartas | G4: =SUM(G7:G25) -> 75
A5: Terreno | B5: Scoured Barrens | C5: Scoured Barrens | D5: =IF(B5=C5, "Sim", "Não") -> Sim
A6: Terreno | B6: Scoured Barrens | C6: Scoured Barrens | D6: =IF(B6=C6, "Sim", "Não") -> Sim | F6: Funções
A7: Terreno | B7: Plains | C7: Bojuka Bog | D7: =IF(B7=C7, "Sim", "Não") -> Não | F7: Terreno | G7: =COUNTIF(A:A,F7) -> 20
A8: Terreno | B8: Swamp | C8: Bojuka Bog | D8: =IF(B8=C8, "Sim", "Não") -> Não | F8: Vida | G8: =COUNTIF(A:A,F8) -> 12
A9: Terreno | B9: Secluded Steppe | C9: Secluded Steppe | D9: =IF(B9=C9, "Sim", "Não") -> Sim | F9: Blink | G9: =COUNTIF(A:A,F9) -> 11
A10: Terreno | B10: Secluded Steppe | C10: Secluded Steppe | D10: =IF(B10=C10, "Sim", "Não") -> Sim | F10: Draw | G10: =COUNTIF(A:A,F10) -> 12
A11: Terreno | B11: Secluded Steppe | C11: Secluded Steppe | D11: =IF(B11=C11, "Sim", "Não") -> Sim | F11: Win | G11: =COUNTIF(A:A,F11) -> 5
A12: Terreno | B12: Barren Moor | C12: Barren Moor | D12: =IF(B12=C12, "Sim", "Não") -> Sim | F12: Controle | G12: =COUNTIF(A:A,F12) -> 0
A13: Terreno | B13: Barren Moor | C13: Barren Moor | D13: =IF(B13=C13, "Sim", "Não") -> Sim | F13: Sideboard | G13: =COUNTIF(A:A,F13) -> 15
A14: Terreno | B14: Kabira Crossroads | C14: Kabira Crossroads | D14: =IF(B14=C14, "Sim", "Não") -> Sim
A15: Terreno | B15: Kabira Crossroads | C15: Kabira Crossroads | D15: =IF(B15=C15, "Sim", "Não") -> Sim
A16: Terreno | B16: Plains | C16: Plains | D16: =IF(B16=C16, "Sim", "Não") -> Sim
A17: Terreno | B17: Plains | C17: Plains | D17: =IF(B17=C17, "Sim", "Não") -> Sim
A18: Terreno | B18: Plains | C18: Plains | D18: =IF(B18=C18, "Sim", "Não") -> Sim
A19: Terreno | B19: Swamp | C19: Swamp | D19: =IF(B19=C19, "Sim", "Não") -> Sim
A20: Terreno | B20: Swamp | C20: Swamp | D20: =IF(B20=C20, "Sim", "Não") -> Sim
A21: Terreno | B21: Swamp | C21: Swamp | D21: =IF(B21=C21, "Sim", "Não") -> Sim
A22: Terreno | B22: Swamp | C22: Swamp | D22: =IF(B22=C22, "Sim", "Não") -> Sim
A23: Vida | B23: Soul Warden | C23: Soul Warden | D23: =IF(B23=C23, "Sim", "Não") -> Sim
A24: Vida | B24: Soul Warden | C24: Soul Warden | D24: =IF(B24=C24, "Sim", "Não") -> Sim
A25: Vida | B25: Soul Warden | C25: Soul Warden | D25: =IF(B25=C25, "Sim", "Não") -> Sim
... A46: Blink | B46: Kor Skyfisher | C46: Kor Skyfisher | D46: =IF(B46=C46, "Sim", "Não") -> Sim
A47: Blink | C47: Ephemerate | D47: =IF(B47=C47, "Sim", "Não") -> Não
A48: Blink | C48: Ephemerate | D48: =IF(B48=C48, "Sim", "Não") -> Não
A49: Blink | C49: Ephemerate | D49: =IF(B49=C49, "Sim", "Não") -> Não
A50: Blink | C50: Ephemerate | D50: =IF(B50=C50, "Sim", "Não") -> Não
A51: Blink | B51: Whitemane Lion | C51: Whitemane Lion | D51: =IF(B51=C51, "Sim", "Não") -> Sim
A52: Blink | B52: Whitemane Lion | C52: Whitemane Lion | D52: =IF(B52=C52, "Sim", "Não") -> Sim
A53: Blink | B53: Whitemane Lion | C53: Whitemane Lion | D53: =IF(B53=C53, "Sim", "Não") -> Sim
A54: Win | B54: Marauding-Blight Priest | C54: Marauding-Blight Priest | D54: =IF(B54=C54, "Sim", "Não") -> Sim
A55: Win | B55: Marauding-Blight Priest | C55: Marauding-Blight Priest | D55: =IF(B55=C55, "Sim", "Não") -> Sim
A56: Win | B56: Marauding-Blight Priest | C56: Marauding-Blight Priest | D56: =IF(B56=C56, "Sim", "Não") -> Sim
A57: Win | B57: Epicure of Blood | C57: Epicure of Blood | D57: =IF(B57=C57, "Sim", "Não") -> Sim
A58: Win | B58: Epicure of Blood | C58: Epicure of Blood | D58: =IF(B58=C58, "Sim", "Não") -> Sim
A59: Draw | B59: Thraben Inspector | C59: Thraben Inspector | D59: =IF(B59=C59, "Sim", "Não") -> Sim
A60: Draw | B60: Thraben Inspector | C60: Thraben Inspector | D60: =IF(B60=C60, "Sim", "Não") -> Sim
...

Sheet Fadas
A1: Fadas e Machados - Pauper
A2: Função | B2: Carta Atual | C2: Carta Ideal | D2: Carta Final
A3: Terreno | B3: Lonely Sandbar | C3: Lonely Sandbar | D3: =IF(B3=C3, "Sim", "Não") -> Sim | F3: Mudanças Faltando | G3: =COUNTIF(D3:D105,"Não") -> 41
A4: Terreno | B4: Lonely Sandbar | C4: Lonely Sandbar | D4: =IF(B4=C4, "Sim", "Não") -> Sim | F4: Total de Cartas | G4: =SUM(G7:G25) -> 75
A5: Terreno | B5: Lonely Sandbar | C5: Lonely Sandbar | D5: =IF(B5=C5, "Sim", "Não") -> Sim
A6: Terreno | B6: Lonely Sandbar | C6: Lonely Sandbar | D6: =IF(B6=C6, "Sim", "Não") -> Sim | F6: Funções
A7: Terreno | B7: Island | C7: Island | D7: =IF(B7=C7, "Sim", "Não") -> Sim | F7: Terreno | G7: =COUNTIF(A:A,F7) -> 18
A8: Terreno | B8: Island | C8: Island | D8: =IF(B8=C8, "Sim", "Não") -> Sim | F8: Flyer | G8: =COUNTIF(A:A,F8) -> 28
A9: Terreno | B9: Island | C9: Island | D9: =IF(B9=C9, "Sim", "Não") -> Sim | F9: Axe | G9: =COUNTIF(A:A,F9) -> 14
A10: Terreno | B10: Island | C10: Island | D10: =IF(B10=C10, "Sim", "Não") -> Sim | F10: Sideboard | G10: =COUNTIF(A:A,F10) -> 15
A11: Terreno | B11: Island | C11: Island | D11: =IF(B11=C11, "Sim", "Não") -> Sim
A12: Terreno | B12: Island | C12: Island | D12: =IF(B12=C12, "Sim", "Não") -> Sim
A13: Terreno | B13: Island | C13: Island | D13: =IF(B13=C13, "Sim", "Não") -> Sim
A14: Terreno | B14: Island | C14: Island | D14: =IF(B14=C14, "Sim", "Não") -> Sim
A15: Terreno | B15: Island | C15: Island | D15: =IF(B15=C15, "Sim", "Não") -> Sim
A16: Terreno | B16: Island | C16: Island | D16: =IF(B16=C16, "Sim", "Não") -> Sim
A17: Terreno | B17: Island | C17: Island | D17: =IF(B17=C17, "Sim", "Não") -> Sim
A18: Terreno | B18: Island | C18: Island | D18: =IF(B18=C18, "Sim", "Não") -> Sim
A19: Terreno | B19: Island | C19: Island | D19: =IF(B19=C19, "Sim", "Não") -> Sim
A20: Terreno | B20: Island | C20: Island | D20: =IF(B20=C20, "Sim", "Não") -> Sim
A21: Flyer | B21: Faerie Seer | C21: Faerie Seer | D21: =IF(B21=C21, "Sim", "Não") -> Sim
A22: Flyer | B22: Faerie Seer | C22: Faerie Seer | D22: =IF(B22=C22, "Sim", "Não") -> Sim
... A32: Flyer | B32: Surveilling Sprite | C32: Snaremaster Sprite | D32: =IF(B32=C32, "Sim", "Não") -> Não
A33: Flyer | C33: Mulldrifter | D33: =IF(B33=C33, "Sim", "Não") -> Não
A34: Flyer | C34: Mulldrifter | D34: =IF(B34=C34, "Sim", "Não") -> Não
A35: Flyer | C35: Mulldrifter | D35: =IF(B35=C35, "Sim", "Não") -> Não
A36: Flyer | C36: Mulldrifter | D36: =IF(B36=C36, "Sim", "Não") -> Não
A37: Flyer | B37: Eterno Aviano | C37: Eterno Aviano | D37: =IF(B37=C37, "Sim", "Não") -> Sim
A38: Flyer | B38: Eterno Aviano | C38: Eterno Aviano | D38: =IF(B38=C38, "Sim", "Não") -> Sim
A39: Flyer | B39: Eterno Aviano | C39: Eterno Aviano | D39: =IF(B39=C39, "Sim", "Não") -> Sim
A40: Flyer | B40: Aviation Pioneer | C40: Eterno Aviano | D40: =IF(B40=C40, "Sim", "Não") -> Não
A41: Flyer | B41: Stormbound Geist | C41: Ninja das Horas Tardias | D41: =IF(B41=C41, "Sim", "Não") -> Não
A42: Flyer | B42: Stormbound Geist | C42: Ninja das Horas Tardias | D42: =IF(B42=C42, "Sim", "Não") -> Não
A43: Flyer | B43: Stormbound Geist | C43: Ninja das Horas Tardias | D43: =IF(B43=C43, "Sim", "Não") -> Não
A44: Flyer | B44: Stormbound Geist | C44: Ninja das Horas Tardias | D44: =IF(B44=C44, "Sim", "Não") -> Não
A45: Flyer | B45: Spellstutter Sprite | C45: Spellstutter Sprite | D45: =IF(B45=C45, "Sim", "Não") -> Sim
A46: Flyer | B46: Aviation Pioneer | C46: Spellstutter Sprite | D46: =IF(B46=C46, "Sim", "Não") -> Não
A47: Flyer | B47: Aviation Pioneer | C47: Spellstutter Sprite | D47: =IF(B47=C47, "Sim", "Não") -> Não
A48: Flyer | B48: Aviation Pioneer | C48: Spellstutter Sprite | D48: =IF(B48=C48, "Sim", "Não") -> Não
... A62: Axe | B62: Island | C62: Manto das Marés | D62: =IF(B62=C62, "Sim", "Não") -> Não
...

Sheet WBRKnights
A1: Mardu Knights - Pauper
A2: Função | B2: Carta Atual | C2: Carta Ideal | D2: Carta Final
A3: Terreno | B3: Scoured Barrens | C3: Scoured Barrens | D3: =IF(B3=C3, "Sim", "Não") -> Sim | F3: Mudanças Faltando | G3: =COUNTIF(D3:D105,"Não") -> 14
A4: Terreno | B4: Scoured Barrens | C4: Scoured Barrens | D4: =IF(B4=C4, "Sim", "Não") -> Sim | F4: Total de Cartas | G4: =SUM(G7:G25) -> 75
A5: Terreno | B5: Scoured Barrens | C5: Scoured Barrens | D5: =IF(B5=C5, "Sim", "Não") -> Sim
A6: Terreno | B6: Scoured Barrens | C6: Scoured Barrens | D6: =IF(B6=C6, "Sim", "Não") -> Sim | F6: Funções
A7: Terreno | B7: Swamp | C7: Bojuka Bog | D7: =IF(B7=C7, "Sim", "Não") -> Não | F7: Terreno | G7: =COUNTIF(A:A,F7) -> 20
A8: Terreno | B8: Swamp | C8: Bojuka Bog | D8: =IF(B8=C8, "Sim", "Não") -> Não | F8: Knight | G8: =COUNTIF(A:A,F8) -> 26
A9: Terreno | B9: Wind-Scarred Crag | C9: Wind-Scarred Crag | D9: =IF(B9=C9, "Sim", "Não") -> Sim | F9: Draw | G9: =COUNTIF(A:A,F9) -> 6
A10: Terreno | B10: Wind-Scarred Crag | C10: Wind-Scarred Crag | D10: =IF(B10=C10, "Sim", "Não") -> Sim | F10: Pump | G10: =COUNTIF(A:A,F10) -> 4
A11: Terreno | B11: Wind-Scarred Crag | C11: Wind-Scarred Crag | D11: =IF(B11=C11, "Sim", "Não") -> Sim | F11: Remoção | G11: =COUNTIF(A:A,F11) -> 4
A12: Terreno | B12: Wind-Scarred Crag | C12: Wind-Scarred Crag | D12: =IF(B12=C12, "Sim", "Não") -> Sim | F12: Sideboard | G12: =COUNTIF(A:A,F12) -> 15
A13: Terreno | B13: Bloodfell Caves | C13: Bloodfell Caves | D13: =IF(B13=C13, "Sim", "Não") -> Sim
A14: Terreno | B14: Bloodfell Caves | C14: Bloodfell Caves | D14: =IF(B14=C14, "Sim", "Não") -> Sim
A15: Terreno | B15: Bloodfell Caves | C15: Bloodfell Caves | D15: =IF(B15=C15, "Sim", "Não") -> Sim
A16: Terreno | B16: Bloodfell Caves | C16: Bloodfell Caves | D16: =IF(B16=C16, "Sim", "Não") -> Sim
A17: Terreno | B17: Plains | C17: Plains | D17: =IF(B17=C17, "Sim", "Não") -> Sim
A18: Terreno | B18: Plains | C18: Plains | D18: =IF(B18=C18, "Sim", "Não") -> Sim
A19: Terreno | B19: Plains | C19: Plains | D19: =IF(B19=C19, "Sim", "Não") -> Sim
A20: Terreno | B20: Swamp | C20: Swamp | D20: =IF(B20=C20, "Sim", "Não") -> Sim
A21: Terreno | B21: Swamp | C21: Swamp | D21: =IF(B21=C21, "Sim", "Não") -> Sim
A22: Terreno | B22: Mountain | C22: Mountain | D22: =IF(B22=C22, "Sim", "Não") -> Sim
A23: Knight | B23: Smitten Swordmaster | C23: Smitten Swordmaster | D23: =IF(B23=C23, "Sim", "Não") -> Sim
A24: Knight | B24: Smitten Swordmaster | C24: Smitten Swordmaster | D24: =IF(B24=C24, "Sim", "Não") -> Sim
... A76: Sideboard | B76: Shining Armor | C76: Shining Armor | D76: =IF(B76=C76, "Sim", "Não") -> Sim
A77: Sideboard | C77: Shining Armor | D77: =IF(B77=C77, "Sim", "Não") -> Não

Sheet Modular
A1: Jeskai Modular - Pauper
A2: Função | B2: Carta Atual | C2: Carta Ideal | D2: Carta Final
A3: Terreno | B3: Razortide Bridge | C3: Razortide Bridge | D3: =IF(B3=C3, "Sim", "Não") -> Sim | F3: Mudanças Faltando | G3: =COUNTIF(D3:D105,"Não") -> 33
A4: Terreno | B4: Razortide Bridge | C4: Razortide Bridge | D4: =IF(B4=C4, "Sim", "Não") -> Sim | F4: Total de Cartas | G4: =SUM(G7:G25) -> 75
A5: Terreno | B5: Razortide Bridge | C5: Razortide Bridge | D5: =IF(B5=C5, "Sim", "Não") -> Sim
A6: Terreno | B6: Razortide Bridge | C6: Razortide Bridge | D6: =IF(B6=C6, "Sim", "Não") -> Sim | F6: Funções
A7: Terreno | B7: Rustvale Bridge | C7: Rustvale Bridge | D7: =IF(B7=C7, "Sim", "Não") -> Sim | F7: Terreno | G7: =COUNTIF(A:A,F7) -> 20
A8: Terreno | B8: Rustvale Bridge | C8: Rustvale Bridge | D8: =IF(B8=C8, "Sim", "Não") -> Sim | F8: Modular | G8: =COUNTIF(A:A,F8) -> 20
A9: Terreno | B9: Rustvale Bridge | C9: Rustvale Bridge | D9: =IF(B9=C9, "Sim", "Não") -> Sim | F9: Draw | G9: =COUNTIF(A:A,F9) -> 12
A10: Terreno | B10: Rustvale Bridge | C10: Rustvale Bridge | D10: =IF(B10=C10, "Sim", "Não") -> Sim | F10: Control | G10: =COUNTIF(A:A,F10) -> 8
A11: Terreno | C11: Silverbluff Bridge | D11: =IF(B11=C11, "Sim", "Não") -> Não | F11: Sideboard | G11: =COUNTIF(A:A,F11) -> 15
A12: Terreno | C12: Silverbluff Bridge | D12: =IF(B12=C12, "Sim", "Não") -> Não
A13: Terreno | C13: Silverbluff Bridge | D13: =IF(B13=C13, "Sim", "Não") -> Não
A14: Terreno | C14: Silverbluff Bridge | D14: =IF(B14=C14, "Sim", "Não") -> Não
A15: Terreno | B15: Mountain | C15: Mountain | D15: =IF(B15=C15, "Sim", "Não") -> Sim
A16: Terreno | B16: Mountain | C16: Mountain | D16: =IF(B16=C16, "Sim", "Não") -> Sim
A17: Terreno | B17: Island | C17: Island | D17: =IF(B17=C17, "Sim", "Não") -> Sim
A18: Terreno | B18: Island | C18: Island | D18: =IF(B18=C18, "Sim", "Não") -> Sim
A19: Terreno | B19: Island | C19: Island | D19: =IF(B19=C19, "Sim", "Não") -> Sim
A20: Terreno | B20: Plains | C20: Plains | D20: =IF(B20=C20, "Sim", "Não") -> Sim
A21: Terreno | B21: Plains | C21: Plains | D21: =IF(B21=C21, "Sim", "Não") -> Sim
A22: Terreno | B22: Plains | C22: Plains | D22: =IF(B22=C22, "Sim", "Não") -> Sim
A23: Modular | B23: Arcbound Mouser | C23: Arcbound Mouser | D23: =IF(B23=C23, "Sim", "Não") -> Sim
A24: Modular | B24: Arcbound Mouser | C24: Arcbound Mouser | D24: =IF(B24=C24, "Sim", "Não") -> Sim
A25: Modular | B25: Arcbound Mouser | C25: Arcbound Mouser | D25: =IF(B25=C25, "Sim", "Não") -> Sim
A26: Modular | B26: Arcbound Mouser | C26: Arcbound Mouser | D26: =IF(B26=C26, "Sim", "Não") -> Sim
... A50: Draw | B50: Contentious Plan | C50: Contentious Plan | D50: =IF(B50=C50, "Sim", "Não") -> Sim
A51: Draw | C51: Thoughtcast | D51: =IF(B51=C51, "Sim", "Não") -> Não
A52: Draw | C52: Thoughtcast | D52: =IF(B52=C52, "Sim", "Não") -> Não
A53: Draw | C53: Thoughtcast | D53: =IF(B53=C53, "Sim", "Não") -> Não
A54: Draw | C54: Thoughtcast | D54: =IF(B54=C54, "Sim", "Não") -> Não
A55: Control | B55: Apostle's Blessing | C55: Apostle's Blessing | D55: =IF(B55=C55, "Sim", "Não") -> Sim
A56: Control | B56: Apostle's Blessing | C56: Apostle's Blessing | D56: =IF(B56=C56, "Sim", "Não") -> Sim
A57: Control | C57: Apostle's Blessing | D57: =IF(B57=C57, "Sim", "Não") -> Não
A58: Control | C58: Apostle's Blessing | D58: =IF(B58=C58, "Sim", "Não") -> Não
A59: Control | C59: Metallic Rebuke | D59: =IF(B59=C59, "Sim", "Não") -> Não
A60: Control | C60: Metallic Rebuke | D60: =IF(B60=C60, "Sim", "Não") -> Não
A61: Control | C61: Metallic Rebuke | D61: =IF(B61=C61, "Sim", "Não") -> Não
A62: Control | C62: Metallic Rebuke | D62: =IF(B62=C62, "Sim", "Não") -> Não
A63: Sideboard | C63: Makeshift Munitions | D63: =IF(B63=C63, "Sim", "Não") -> Não | F63: Penregon Strongbull
...

Sheet WBGAllies
A1: Orzhov Aliados - Pauper
A2: Função | B2: Carta Atual | C2: Carta Ideal | D2: Carta Final
A3: Terreno | B3: Scoured Barrens | C3: Scoured Barrens | D3: =IF(B3=C3, "Sim", "Não") -> Sim | F3: Mudanças Faltando | G3: =COUNTIF(D3:D105,"Não") -> 36
A4: Terreno | B4: Scoured Barrens | C4: Scoured Barrens | D4: =IF(B4=C4, "Sim", "Não") -> Sim | F4: Total de Cartas | G4: =SUM(G7:G25) -> 75
A5: Terreno | B5: Scoured Barrens | C5: Scoured Barrens | D5: =IF(B5=C5, "Sim", "Não") -> Sim
A6: Terreno | B6: Scoured Barrens | C6: Blossoming Sands | D6: =IF(B6=C6, "Sim", "Não") -> Não | F6: Funções
A7: Terreno | B7: Swamp | C7: Blossoming Sands | D7: =IF(B7=C7, "Sim", "Não") -> Não | F7: Terreno | G7: =COUNTIF(A:A,F7) -> 20
A8: Terreno | B8: Swamp | C8: Blossoming Sands | D8: =IF(B8=C8, "Sim", "Não") -> Não | F8: Aliado | G8: =COUNTIF(A:A,F8) -> 24
A9: Terreno | B9: Swamp | C9: Blossoming Sands | D9: =IF(B9=C9, "Sim", "Não") -> Não | F9: Win | G9: =COUNTIF(A:A,F9) -> 4
A10: Terreno | B10: Swamp | C10: Jungle Hollow | D10: =IF(B10=C10, "Sim", "Não") -> Não | F10: Draw | G10: =COUNTIF(A:A,F10) -> 8
A11: Terreno | B11: Swamp | C11: Jungle Hollow | D11: =IF(B11=C11, "Sim", "Não") -> Não | F11: Blink | G11: =COUNTIF(A:A,F11) -> 4
A12: Terreno | B12: Swamp | C12: Jungle Hollow | D12: =IF(B12=C12, "Sim", "Não") -> Não | F12: Sideboard | G12: =COUNTIF(A:A,F12) -> 15
A13: Terreno | B13: Swamp | C13: Evolving Wilds | D13: =IF(B13=C13, "Sim", "Não") -> Não
A14: Terreno | B14: Swamp | C14: Swamp | D14: =IF(B14=C14, "Sim", "Não") -> Sim
A15: Terreno | B15: Plains | C15: Swamp | D15: =IF(B15=C15, "Sim", "Não") -> Não
A16: Terreno | B16: Plains | C16: Swamp | D16: =IF(B16=C16, "Sim", "Não") -> Não
A17: Terreno | B17: Plains | C17: Forest | D17: =IF(B17=C17, "Sim", "Não") -> Não
A18: Terreno | B18: Plains | C18: Forest | D18: =IF(B18=C18, "Sim", "Não") -> Não
A19: Terreno | B19: Plains | C19: Forest | D19: =IF(B19=C19, "Sim", "Não") -> Não
A20: Terreno | B20: Plains | C20: Plains | D20: =IF(B20=C20, "Sim", "Não") -> Sim
A21: Terreno | B21: Plains | C21: Plains | D21: =IF(B21=C21, "Sim", "Não") -> Sim
A22: Terreno | B22: Plains | C22: Plains | D22: =IF(B22=C22, "Sim", "Não") -> Sim
A23: Aliado | B23: Bojuka Brigand | C23: Bojuka Brigand | D23: =IF(B23=C23, "Sim", "Não") -> Sim
A24: Aliado | B24: Bojuka Brigand | C24: Bojuka Brigand | D24: =IF(B24=C24, "Sim", "Não") -> Sim
... A66: Sideboard | B66: Beckon Apparition | C66: Beckon Apparition | D66: =IF(B66=C66, "Sim", "Não") -> Sim
A67: Sideboard | C67: Diabolic Edict | D67: =IF(B67=C67, "Sim", "Não") -> Não
A68: Sideboard | C68: Diabolic Edict | D68: =IF(B68=C68, "Sim", "Não") -> Não
A69: Sideboard | C69: Diabolic Edict | D69: =IF(B69=C69, "Sim", "Não") -> Não
A70: Sideboard | C70: Diabolic Edict | D70: =IF(B70=C70, "Sim", "Não") -> Não
A71: Sideboard | C71: Blessed Hippogriff // Tyr's Blessing | D71: =IF(B71=C71, "Sim", "Não") -> Não
A72: Sideboard | C72: Blessed Hippogriff // Tyr's Blessing | D72: =IF(B72=C72, "Sim", "Não") -> Não
A73: Sideboard | C73: Blessed Hippogriff // Tyr's Blessing | D73: =IF(B73=C73, "Sim", "Não") -> Não
A74: Sideboard | C74: Doom Blade | D74: =IF(B74=C74, "Sim", "Não") -> Não
A75: Sideboard | C75: Doom Blade | D75: =IF(B75=C75, "Sim", "Não") -> Não
A76: Sideboard | C76: Doom Blade | D76: =IF(B76=C76, "Sim", "Não") -> Não
A77: Sideboard | C77: Doom Blade | D77: =IF(B77=C77, "Sim", "Não") -> Não

Sheet TemurC
A1: Temur Control - Modern
A2: Função | B2: Carta Atual | C2: Carta Ideal | D2: Carta Final
A3: Terreno | C3: Simic Growth Chamber | D3: =IF(B3=C3, "Sim", "Não") -> Não | F3: Mudanças Faltando | G3: =COUNTIF(D3:D105,"Não") -> 75
A4: Terreno | C4: Simic Growth Chamber | D4: =IF(B4=C4, "Sim", "Não") -> Não | F4: Total de Cartas | G4: =SUM(G7:G23) -> 75
A5: Terreno | C5: Izzet Boilerworks | D5: =IF(B5=C5, "Sim", "Não") -> Não
A6: Terreno | C6: Izzet Boilerworks | D6: =IF(B6=C6, "Sim", "Não") -> Não | F6: Funções
A7: Terreno | C7: Gruul Turf | D7: =IF(B7=C7, "Sim", "Não") -> Não | F7: Terreno | G7: =COUNTIF(A:A,F7) -> 23
A8: Terreno | C8: Gruul Turf | D8: =IF(B8=C8, "Sim", "Não") -> Não | F8: Draw | G8: =COUNTIF(A:A,F8) -> 11
A9: Terreno | C9: Swiftwater Cliffs | D9: =IF(B9=C9, "Sim", "Não") -> Não | F9: Finisher | G9: =COUNTIF(A:A,F9) -> 0
A10: Terreno | C10: Swiftwater Cliffs | D10: =IF(B10=C10, "Sim", "Não") -> Não | F10: Anule | G10: =COUNTIF(A:A,F10) -> 6
A11: Terreno | C11: Rugged Highlands | D11: =IF(B11=C11, "Sim", "Não") -> Não | F11: Remoção | G11: =COUNTIF(A:A,F11) -> 12
A12: Terreno | C12: Rugged Highlands | D12: =IF(B12=C12, "Sim", "Não") -> Não | F12: Field | G12: =COUNTIF(A:A,F12) -> 8
A13: Terreno | C13: Thornwood Falls | D13: =IF(B13=C13, "Sim", "Não") -> Não | F13: Sideboard | G13: =COUNTIF(A:A,F13) -> 15
A14: Terreno | C14: Thornwood Falls | D14: =IF(B14=C14, "Sim", "Não") -> Não
A15: Terreno | C15: Evolving Wilds | D15: =IF(B15=C15, "Sim", "Não") -> Não
A16: Terreno | C16: Evolving Wilds | D16: =IF(B16=C16, "Sim", "Não") -> Não
A17: Terreno | C17: Island | D17: =IF(B17=C17, "Sim", "Não") -> Não
A18: Terreno | C18: Island | D18: =IF(B18=C18, "Sim", "Não") -> Não
A19: Terreno | C19: Island | D19: =IF(B19=C19, "Sim", "Não") -> Não
A20: Terreno | C20: Mountain | D20: =IF(B20=C20, "Sim", "Não") -> Não
A21: Terreno | C21: Mountain | D21: =IF(B21=C21, "Sim", "Não") -> Não
A22: Terreno | C22: Mountain | D22: =IF(B22=C22, "Sim", "Não") -> Não
A23: Terreno | C23: Forest | D23: =IF(B23=C23, "Sim", "Não") -> Não
A24: Terreno | C24: Forest | D24: =IF(B24=C24, "Sim", "Não") -> Não
A25: Terreno | C25: Forest | D25: =IF(B25=C25, "Sim", "Não") -> Não
... A77: Sideboard | C77: Relic of Progenitus | D77: =IF(B77=C77, "Sim", "Não") -> Não

Sheet WURFlicker
A1: WUR Flicker
A2: Função | B2: Carta Atual | C2: Carta Ideal | D2: Carta Final
A3: Terreno | B3: Silverbluff Bridge | C3: Silverbluff Bridge | D3: =IF(B3=C3, "Sim", "Não") -> Sim | F3: Mudanças Faltando | G3: =COUNTIF(D3:D105,"Não") -> 10
A4: Terreno | B4: Silverbluff Bridge | C4: Silverbluff Bridge | D4: =IF(B4=C4, "Sim", "Não") -> Sim | F4: Total de Cartas | G4: =SUM(G7:G25) -> 75
A5: Terreno | B5: Silverbluff Bridge | C5: Silverbluff Bridge | D5: =IF(B5=C5, "Sim", "Não") -> Sim
A6: Terreno | B6: Silverbluff Bridge | C6: Silverbluff Bridge | D6: =IF(B6=C6, "Sim", "Não") -> Sim | F6: Funções
A7: Terreno | B7: Rustvale Bridge | C7: Rustvale Bridge | D7: =IF(B7=C7, "Sim", "Não") -> Sim | F7: Terreno | G7: =COUNTIF(A:A,F7) -> 19
A8: Terreno | B8: Rustvale Bridge | C8: Rustvale Bridge | D8: =IF(B8=C8, "Sim", "Não") -> Sim | F8: ETB | G8: =COUNTIF(A:A,F8) -> 11
A9: Terreno | B9: Rustvale Bridge | C9: Rustvale Bridge | D9: =IF(B9=C9, "Sim", "Não") -> Sim | F9: Blink | G9: =COUNTIF(A:A,F9) -> 4
A10: Terreno | B10: Rustvale Bridge | C10: Rustvale Bridge | D10: =IF(B10=C10, "Sim", "Não") -> Sim | F10: Draw | G10: =COUNTIF(A:A,F10) -> 18
A11: Terreno | B11: Razortide Bridge | C11: Razortide Bridge | D11: =IF(B11=C11, "Sim", "Não") -> Sim | F11: Controle | G11: =COUNTIF(A:A,F11) -> 8
A12: Terreno | B12: Razortide Bridge | C12: Razortide Bridge | D12: =IF(B12=C12, "Sim", "Não") -> Sim | F12: Sideboard | G12: =COUNTIF(A:A,F12) -> 15
A13: Terreno | B13: Island | C13: Island | D13: =IF(B13=C13, "Sim", "Não") -> Sim
A14: Terreno | B14: Island | C14: Island | D14: =IF(B14=C14, "Sim", "Não") -> Sim
A15: Terreno | B15: Island | C15: Island | D15: =IF(B15=C15, "Sim", "Não") -> Sim
A16: Terreno | B16: Island | C16: Island | D16: =IF(B16=C16, "Sim", "Não") -> Sim
A17: Terreno | B17: Island | C17: Island | D17: =IF(B17=C17, "Sim", "Não") -> Sim
A18: Terreno | B18: Island | C18: Island | D18: =IF(B18=C18, "Sim", "Não") -> Sim
A19: Terreno | B19: Island | C19: Island | D19: =IF(B19=C19, "Sim", "Não") -> Sim
A20: Terreno | B20: Mountain | C20: Mountain | D20: =IF(B20=C20, "Sim", "Não") -> Sim
A21: Terreno | B21: Plains | C21: Plains | D21: =IF(B21=C21, "Sim", "Não") -> Sim
A22: ETB | B22: Stonehorn Dignitary | C22: Stonehorn Dignitary | D22: =IF(B22=C22, "Sim", "Não") -> Sim
A23: ETB | B23: Stonehorn Dignitary | C23: Stonehorn Dignitary | D23: =IF(B23=C23, "Sim", "Não") -> Sim
A24: ETB | B24: Dawnbringer Cleric | C24: Dawnbringer Cleric | D24: =IF(B24=C24, "Sim", "Não") -> Sim
... A48: Draw | B48: Cleasing Fire | C48: Cleasing Fire | D48: =IF(B48=C48, "Sim", "Não") -> Sim
A49: Draw | C49: Lórien Revealed | D49: =IF(B49=C49, "Sim", "Não") -> Não
A50: Draw | C50: Lórien Revealed | D50: =IF(B50=C50, "Sim", "Não") -> Não
A51: Blink | B51: Ephemerate | C51: Ephemerate | D51: =IF(B51=C51, "Sim", "Não") -> Sim
A52: Blink | B52: Ephemerate | C52: Ephemerate | D52: =IF(B52=C52, "Sim", "Não") -> Sim
A53: Blink | B53: Ephemerate | C53: Ephemerate | D53: =IF(B53=C53, "Sim", "Não") -> Sim
A54: Blink | B54: Ephemerate | C54: Ephemerate | D54: =IF(B54=C54, "Sim", "Não") -> Sim
A55: Controle | B55: Counterspell | C55: Counterspell | D55: =IF(B55=C55, "Sim", "Não") -> Sim
A56: Controle | B56: Counterspell | C56: Counterspell | D56: =IF(B56=C56, "Sim", "Não") -> Sim
A57: Controle | B57: Counterspell | C57: Counterspell | D57: =IF(B57=C57, "Sim", "Não") -> Sim
A58: Controle | B58: Counterspell | C58: Counterspell | D58: =IF(B58=C58, "Sim", "Não") -> Sim
A59: Controle | B59: Lightning Bolt | C59: Lightning Bolt | D59: =IF(B59=C59, "Sim", "Não") -> Sim
A60: Controle | B60: Lightning Bolt | C60: Lightning Bolt | D60: =IF(B60=C60, "Sim", "Não") -> Sim
A61: Controle | B61: Lightning Bolt | C61: Lightning Bolt | D61: =IF(B61=C61, "Sim", "Não") -> Sim
A62: Controle | B62: Lightning Bolt | C62: Lightning Bolt | D62: =IF(B62=C62, "Sim", "Não") -> Sim
... A66: Sideboard | B66: Cast into the Fire | C66: Cast into the Fire | D66: =IF(B66=C66, "Sim", "Não") -> Sim
...

Sheet WUBModular
A1: WUR Flicker
A2: Função | B2: Carta Atual | C2: Carta Ideal | D2: Carta Final
A3: Terreno | B3: Razortide Bridge | C3: Razortide Bridge | D3: =IF(B3=C3, "Sim", "Não") -> Sim | F3: Mudanças Faltando | G3: =COUNTIF(D3:D105,"Não") -> 1
A4: Terreno | B4: Razortide Bridge | C4: Razortide Bridge | D4: =IF(B4=C4, "Sim", "Não") -> Sim | F4: Total de Cartas | G4: =SUM(G7:G25) -> 75
A5: Terreno | B5: Razortide Bridge | C5: Razortide Bridge | D5: =IF(B5=C5, "Sim", "Não") -> Sim
A6: Terreno | B6: Razortide Bridge | C6: Razortide Bridge | D6: =IF(B6=C6, "Sim", "Não") -> Sim | F6: Funções
A7: Terreno | B7: Goldmire Bridge | C7: Goldmire Bridge | D7: =IF(B7=C7, "Sim", "Não") -> Sim | F7: Terreno | G7: =COUNTIF(A:A,F7) -> 20
A8: Terreno | B8: Goldmire Bridge | C8: Goldmire Bridge | D8: =IF(B8=C8, "Sim", "Não") -> Sim | F8: Modular | G8: =COUNTIF(A:A,F8) -> 20
A9: Terreno | B9: Goldmire Bridge | C9: Goldmire Bridge | D9: =IF(B9=C9, "Sim", "Não") -> Sim | F9: Sacrifício | G9: =COUNTIF(A:A,F9) -> 6
A10: Terreno | B10: Goldmire Bridge | C10: Goldmire Bridge | D10: =IF(B10=C10, "Sim", "Não") -> Sim | F10: Draw | G10: =COUNTIF(A:A,F10) -> 10
A11: Terreno | B11: Mistvault Bridge | C11: Mistvault Bridge | D11: =IF(B11=C11, "Sim", "Não") -> Sim | F11: Controle | G11: =COUNTIF(A:A,F11) -> 2
A12: Terreno | B12: Mistvault Bridge | C12: Mistvault Bridge | D12: =IF(B12=C12, "Sim", "Não") -> Sim | F12: Pump | G12: =COUNTIF(A:A,F12) -> 2
A13: Terreno | B13: Mistvault Bridge | C13: Mistvault Bridge | D13: =IF(B13=C13, "Sim", "Não") -> Sim | F13: Sideboard | G13: =COUNTIF(A:A,F13) -> 15
A14: Terreno | B14: Mistvault Bridge | C14: Mistvault Bridge | D14: =IF(B14=C14, "Sim", "Não") -> Sim
A15: Terreno | B15: Seat of the Synod | C15: Seat of the Synod | D15: =IF(B15=C15, "Sim", "Não") -> Sim
A16: Terreno | B16: Seat of the Synod | C16: Seat of the Synod | D16: =IF(B16=C16, "Sim", "Não") -> Sim
A17: Terreno | B17: Seat of the Synod | C17: Seat of the Synod | D17: =IF(B17=C17, "Sim", "Não") -> Sim
A18: Terreno | B18: Island | C18: Island | D18: =IF(B18=C18, "Sim", "Não") -> Sim
A19: Terreno | B19: Vault of Whispers | C19: Vault of Whispers | D19: =IF(B19=C19, "Sim", "Não") -> Sim
A20: Terreno | B20: Swamp | C20: Swamp | D20: =IF(B20=C20, "Sim", "Não") -> Sim
A21: Terreno | C21: Ancient Den | D21: =IF(B21=C21, "Sim", "Não") -> Não
A22: Terreno | B22: Plains | C22: Plains | D22: =IF(B22=C22, "Sim", "Não") -> Sim
A23: Modular | B23: Arcbound Mouser | C23: Arcbound Mouser | D23: =IF(B23=C23, "Sim", "Não") -> Sim
A24: Modular | B24: Arcbound Mouser | C24: Arcbound Mouser | D24: =IF(B24=C24, "Sim", "Não") -> Sim
A25: Modular | B25: Arcbound Mouser | C25: Arcbound Mouser | D25: =IF(B25=C25, "Sim", "Não") -> Sim
A26: Modular | B26: Arcbound Mouser | C26: Arcbound Mouser | D26: =IF(B26=C26, "Sim", "Não") -> Sim
A27: Modular | B27: Arcbound Worker | C27: Arcbound Worker | D27: =IF(B27=C27, "Sim", "Não") -> Sim
A28: Modular | B28: Arcbound Worker | C28: Arcbound Worker | D28: =IF(B28=C28, "Sim", "Não") -> Sim
A29: Modular | B29: Arcbound Worker | C29: Arcbound Worker | D29: =IF(B29=C29, "Sim", "Não") -> Sim
A30: Modular | B30: Arcbound Worker | C30: Arcbound Worker | D30: =IF(B30=C30, "Sim", "Não") -> Sim
A31: Modular | B31: Arcbound Stinger | C31: Arcbound Stinger | D31: =IF(B31=C31, "Sim", "Não") -> Sim
A32: Modular | B32: Arcbound Stinger | C32: Arcbound Stinger | D32: =IF(B32=C32, "Sim", "Não") -> Sim
A33: Modular | B33: Arcbound Stinger | C33: Arcbound Stinger | D33: =IF(B33=C33, "Sim", "Não") -> Sim
A34: Modular | B34: Arcbound Stinger | C34: Arcbound Stinger | D34: =IF(B34=C34, "Sim", "Não") -> Sim
A35: Modular | B35: Iron Apprentice | C35: Iron Apprentice | D35: =IF(B35=C35, "Sim", "Não") -> Sim | F35: Gengibruto
A36: Modular | B36: Iron Apprentice | C36: Iron Apprentice | D36: =IF(B36=C36, "Sim", "Não") -> Sim | F36: Airlift Captain
A37: Modular | B37: Iron Apprentice | C37: Iron Apprentice | D37: =IF(B37=C37, "Sim", "Não") -> Sim | F37: Vault Skirge
A38: Modular | B38: Iron Apprentice | C38: Iron Apprentice | D38: =IF(B38=C38, "Sim", "Não") -> Sim | F38: Arcbound Prototype
A39: Modular | B39: Kenku Artificer | C39: Kenku Artificer | D39: =IF(B39=C39, "Sim", "Não") -> Sim
A40: Modular | B40: Kenku Artificer | C40: Kenku Artificer | D40: =IF(B40=C40, "Sim", "Não") -> Sim
...

Sheet UBFaeries
A1: UB Faeries
A2: Função | B2: Carta Atual | C2: Carta Ideal | D2: Carta Final
A3: Terreno | C3: Contaminated Aquifer | D3: =IF(B3=C3, "Sim", "Não") -> Não | F3: Mudanças Faltando | G3: =COUNTIF(D3:D105,"Não") -> 29
A4: Terreno | C4: Contaminated Aquifer | D4: =IF(B4=C4, "Sim", "Não") -> Não | F4: Total de Cartas | G4: =SUM(G7:G25) -> 33
A5: Terreno | C5: Contaminated Aquifer | D5: =IF(B5=C5, "Sim", "Não") -> Não
A6: Terreno | C6: Contaminated Aquifer | D6: =IF(B6=C6, "Sim", "Não") -> Não | F6: Funções
A7: Terreno | C7: Maestros Theater | D7: =IF(B7=C7, "Sim", "Não") -> Não | F7: Terreno | G7: =COUNTIF(A:A,F7) -> 18
A8: Terreno | C8: Bojuka Bog | D8: =IF(B8=C8, "Sim", "Não") -> Não | F8: ETB | G8: =COUNTIF(A:A,F8) -> 0
A9: Terreno | B9: Swamp | C9: Swamp | D9: =IF(B9=C9, "Sim", "Não") -> Sim | F9: Blink | G9: =COUNTIF(A:A,F9) -> 0
A10: Terreno | B10: Swamp | C10: Swamp | D10: =IF(B10=C10, "Sim", "Não") -> Sim | F10: Draw | G10: =COUNTIF(A:A,F10) -> 0
A11: Terreno | B11: Swamp | C11: Swamp | D11: =IF(B11=C11, "Sim", "Não") -> Sim | F11: Controle | G11: =COUNTIF(A:A,F11) -> 0
A12: Terreno | B12: Island | C12: Island | D12: =IF(B12=C12, "Sim", "Não") -> Sim | F12: Sideboard | G12: =COUNTIF(A:A,F12) -> 15
A13: Terreno | B13: Island | C13: Island | D13: =IF(B13=C13, "Sim", "Não") -> Sim
A14: Terreno | B14: Island | C14: Island | D14: =IF(B14=C14, "Sim", "Não") -> Sim
A15: Terreno | B15: Island | C15: Island | D15: =IF(B15=C15, "Sim", "Não") -> Sim
A16: Terreno | B16: Island | C16: Island | D16: =IF(B16=C16, "Sim", "Não") -> Sim
A17: Terreno | B17: Island | C17: Island | D17: =IF(B17=C17, "Sim", "Não") -> Sim
A18: Terreno | B18: Island | C18: Island | D18: =IF(B18=C18, "Sim", "Não") -> Sim
A19: Terreno | B19: Island | C19: Island | D19: =IF(B19=C19, "Sim", "Não") -> Sim
A20: Terreno | B20: Island | C20: Island | D20: =IF(B20=C20, "Sim", "Não") -> Sim
A21: Criaturas | C21: Murmuring Mystic | D21: =IF(B21=C21, "Sim", "Não") -> Não
A22: Criaturas | B22: Faerie Seer | C22: Faerie Seer | D22: =IF(B22=C22, "Sim", "Não") -> Sim | E22: 2.9
A23: Criaturas | B23: Faerie Seer | C23: Faerie Seer | D23: =IF(B23=C23, "Sim", "Não") -> Sim | E23: 2.9
A24: Criaturas | B24: Faerie Seer | C24: Faerie Seer | D24: =IF(B24=C24, "Sim", "Não") -> Sim | E24: 2.9
A25: Criaturas | B25: Faerie Seer | C25: Faerie Seer | D25: =IF(B25=C25, "Sim", "Não") -> Sim | E25: 2.9
A26: Criaturas | C26: Spellstutter Sprite | D26: =IF(B26=C26, "Sim", "Não") -> Não
A27: Criaturas | C27: Spellstutter Sprite | D27: =IF(B27=C27, "Sim", "Não") -> Não
A28: Criaturas | C28: Spellstutter Sprite | D28: =IF(B28=C28, "Sim", "Não") -> Não
A29: Criaturas | C29: Spellstutter Sprite | D29: =IF(B29=C29, "Sim", "Não") -> Não
A30: Criaturas | B30: Augur of Bolas | C30: Augur of Bolas | D30: =IF(B30=C30, "Sim", "Não") -> Sim | E30: 1.25
A31: Criaturas | B31: Augur of Bolas | C31: Augur of Bolas | D31: =IF(B31=C31, "Sim", "Não") -> Sim | E31: 1.25
A32: Criaturas | B32: Augur of Bolas | C32: Augur of Bolas | D32: =IF(B32=C32, "Sim", "Não") -> Sim | E32: 1.25
A33: Criaturas | B33: Augur of Bolas | C33: Augur of Bolas | D33: =IF(B33=C33, "Sim", "Não") -> Sim | E33: 1.25
A34: Criaturas | C34: Ninja of the Deep Hours | D34: =IF(B34=C34, "Sim", "Não") -> Não
A35: Criaturas | C35: Ninja of the Deep Hours | D35: =IF(B35=C35, "Sim", "Não") -> Não
