Workbook

Sheet COMPRAS
A1: Total: | B1: =C2+C8+C13+C18+C23+C28+C32+C34+C38+C50 -> 0 | E1: Deck | F1: =A2 -> Marcelo | G1: =B3 -> Overrun | H1: =B4 -> Base | I1: =B5 -> 0 | J1: =B6 -> Liga | L1: Deck | M1: Entra | N1: Sai | O1: Fonte
A2: Marcelo | B2: Total Lojas: | C2: =SUM(C3:C6) -> 0 | F2: Defesa Engenhosa | L2: Coleção | M2: Command Tower
A3: =COUNTA(F2:F216) -> 12 | B3: Overrun | C3: =SUM(G:G) -> 0 | F3: Horizon Explorer | L3: Baylen | M3: Canopy Vista | N3: Montanha
B4: Base | C4: =SUM(H:H) -> 0 | F4: Aguaceiro Anfíbio | L4: Baylen | M4: Cinder Glade | N4: Planície
C5: =SUM(I:I) -> 0 | F5: Dever Além da Morte | L5: Baylen | M5: Mossfire Valley | N5: Vatidão Morfoterrena
B6: Liga | C6: =SUM(J:J) -> 0 | F6: Comando Incendiário | L6: Gitrog | M6: Broodheart Engine | N6: Nyx Weaver
F7: Reyhan, Última dos Abzan | L7: Gitrog | M7: Hedge Shredder | N7: Cemetery Tampering
F8: Druida Devotado | L8: Inalla | M8: Dour-Port Mage | N8: Riverwise Augur
F9: Hidra Devoradora de Mana | L9: Modular | M9: Arcbound Crusher
F10: Pátio Reservado | L10: Modular | M10: Arcbound Javelineer
F11: Os Jardins Micossintéticos | L11: Modular | M11: Arcbound Mouser
F12: Pain for All | L12: Modular | M12: Arcbound Ravager
F13: Ressonador Estriônico | L13: Modular | M13: Arcbound Reclaimer
L14: Modular | M14: Arcbound Shikari
L15: Modular | M15: Arcbound Slith
L16: Modular | M16: Arcbound Stinger
L17: Modular | M17: Arcbound Tracker
L18: Modular | M18: Arcbound Whelp
L19: Modular | M19: Boros Signet
L20: Modular | M20: Command Tower
L21: Modular | M21: Darksteel Citadel
L22: Modular | M22: Hamza, Guardian of Arashin
L23: Modular | M23: Hangarback Walker
L24: Modular | M24: Long-Range Sensor
L25: Modular | M25: Marketback Walker
... L36: Modular | M36: Trading Post
L37: Muzzio | M37: Academy Ruins | N37: Ilha
L38: Narset | M38: Spark Double | N38: Mask of the Schemer
L39: Piratas | M39: Bident of Thassa
L40: Piratas | M40: Coastline Marauders
L41: Piratas | M41: Deadeye Tracker
L42: Piratas | M42: Forerunner of the Coalition
L43: Piratas | M43: Malcoln, Alluring Scoundrel
L44: Piratas | M44: Reckless Fireweaver
L45: Piratas | M45: Seething Landscape
L46: Piratas | M46: Siren Stormtamer
L47: Piratas | M47: Spyglass Siren
L48: Piratas | M48: Warkite Marauder
L49: Piratas | M49: Xorn
L50: Rani | M50: Powerbalance | N50: Afogar no Lago
...

Sheet STATS
A1: Dia | B1: Player 1 | C1: Deck 1 | D1: Player 2 | E1: Deck 2 | F1: Player 3 | G1: Deck 3 | H1: Player 4 | I1: Deck 4 | J1: Vitória | M1: Deck | N1: Partidas | O1: Winrate | Q1: Player | R1: Partidas | S1: Winrate
A2: 45587 | B2: Marcelo | C2: Elfos | D2: Vivian | E2: Zimone | F2: Renato | G2: Raffine | H2: Dexter | I2: Kaalia | J2: Marcelo | K2: Elfos | M2: Akiri | N2: =COUNTIF(C:C,M2)+COUNTIF(E:E,M2)+COUNTIF(G:G,M2)+COUNTIF(I:I,M2) -> 2 | O2: =IF(N2>=10,(COUNTIF(K:K,M2)/N2),"Insuficiente") -> Insuficiente | Q2: Marcelo | R2: =COUNTIF(B:B,Q2)+COUNTIF(D:D,Q2)+COUNTIF(F:F,Q2)+COUNTIF(H:H,Q2) -> 11 | S2: =IF(R2>=10, (COUNTIF(J:J,Q2)/R2), "Insuficiente") -> 0.36363636
A3: 45594 | B3: Marcelo | C3: Breya | D3: Vivian | E3: Zimone | F3: Renato | G3: Raffine | H3: Dexter | I3: Tovolar | J3: Vivian | K3: Zimone | M3: Arcades | N3: =COUNTIF(C:C,M3)+COUNTIF(E:E,M3)+COUNTIF(G:G,M3)+COUNTIF(I:I,M3) -> 1 | O3: =IF(N3>=10,(COUNTIF(K:K,M3)/N3),"Insuficiente") -> Insuficiente | Q3: Vivian | R3: =COUNTIF(B:B,Q3)+COUNTIF(D:D,Q3)+COUNTIF(F:F,Q3)+COUNTIF(H:H,Q3) -> 11 | S3: =IF(R3>=10, (COUNTIF(J:J,Q3)/R3), "Insuficiente") -> 0.27272727
A4: 45594 | B4: Marcelo | C4: Trakiri | D4: Vivian | E4: Zimone | F4: Renato | G4: Raffine | H4: Hamster | I4: Muzzio | J4: Marcelo | K4: Trakiri | M4: Baylen | N4: =COUNTIF(C:C,M4)+COUNTIF(E:E,M4)+COUNTIF(G:G,M4)+COUNTIF(I:I,M4) -> 1 | O4: =IF(N4>=10,(COUNTIF(K:K,M4)/N4),"Insuficiente") -> Insuficiente | Q4: Renato | R4: =COUNTIF(B:B,Q4)+COUNTIF(D:D,Q4)+COUNTIF(F:F,Q4)+COUNTIF(H:H,Q4) -> 6 | S4: =IF(R4>=10, (COUNTIF(J:J,Q4)/R4), "Insuficiente") -> Insuficiente
A5: 45594 | B5: Marcelo | C5: Akiri | D5: Vivian | E5: Zimone | F5: Renato | G5: Baylen | H5: Hamster | I5: Kumena | J5: Marcelo | K5: Akiri | M5: Breya | N5: =COUNTIF(C:C,M5)+COUNTIF(E:E,M5)+COUNTIF(G:G,M5)+COUNTIF(I:I,M5) -> 1 | O5: =IF(N5>=10,(COUNTIF(K:K,M5)/N5),"Insuficiente") -> Insuficiente | Q5: Dexter | R5: =COUNTIF(B:B,Q5)+COUNTIF(D:D,Q5)+COUNTIF(F:F,Q5)+COUNTIF(H:H,Q5) -> 5 | S5: =IF(R5>=10, (COUNTIF(J:J,Q5)/R5), "Insuficiente") -> Insuficiente
A6: 45597 | B6: Marcelo | C6: Inalla | D6: Vivian | E6: Zimone | F6: Renato | G6: Raffine | H6: João | I6: Winota | J6: João | K6: Winota | M6: Elfos | N6: =COUNTIF(C:C,M6)+COUNTIF(E:E,M6)+COUNTIF(G:G,M6)+COUNTIF(I:I,M6) -> 1 | O6: =IF(N6>=10,(COUNTIF(K:K,M6)/N6),"Insuficiente") -> Insuficiente | Q6: Hamster | R6: =COUNTIF(B:B,Q6)+COUNTIF(D:D,Q6)+COUNTIF(F:F,Q6)+COUNTIF(H:H,Q6) -> 2 | S6: =IF(R6>=10, (COUNTIF(J:J,Q6)/R6), "Insuficiente") -> Insuficiente
A7: 45597 | B7: Marcelo | C7: Yuriko | D7: Vivian | E7: Zimone | F7: Renato | G7: Raffine | H7: João | I7: Winota | J7: Vivian | K7: Zimone | M7: FF Counters | N7: =COUNTIF(C:C,M7)+COUNTIF(E:E,M7)+COUNTIF(G:G,M7)+COUNTIF(I:I,M7) -> 2 | O7: =IF(N7>=10,(COUNTIF(K:K,M7)/N7),"Insuficiente") -> Insuficiente | Q7: Talita | R7: =COUNTIF(B:B,Q7)+COUNTIF(D:D,Q7)+COUNTIF(F:F,Q7)+COUNTIF(H:H,Q7) -> 3 | S7: =IF(R7>=10, (COUNTIF(J:J,Q7)/R7), "Insuficiente") -> Insuficiente
A8: 45599 | B8: Marcelo | C8: Narset | D8: Vivian | E8: Arcades | F8: Dexter | G8: Who Villains | H8: Talita | I8: Who Time | J8: Vivian | K8: Arcades | M8: Hashaton | N8: =COUNTIF(C:C,M8)+COUNTIF(E:E,M8)+COUNTIF(G:G,M8)+COUNTIF(I:I,M8) -> 1 | O8: =IF(N8>=10,(COUNTIF(K:K,M8)/N8),"Insuficiente") -> Insuficiente | Q8: João | R8: =COUNTIF(B:B,Q8)+COUNTIF(D:D,Q8)+COUNTIF(F:F,Q8)+COUNTIF(H:H,Q8) -> 4 | S8: =IF(R8>=10, (COUNTIF(J:J,Q8)/R8), "Insuficiente") -> Insuficiente
A9: 45599 | B9: Marcelo | C9: Thantis | D9: Vivian | E9: Akiri | F9: Dexter | G9: Who Villains | H9: Talita | I9: Ladinos | J9: Talita | K9: Ladinos | M9: Inalla | N9: =COUNTIF(C:C,M9)+COUNTIF(E:E,M9)+COUNTIF(G:G,M9)+COUNTIF(I:I,M9) -> 1 | O9: =IF(N9>=10,(COUNTIF(K:K,M9)/N9),"Insuficiente") -> Insuficiente | Q9: Philips | R9: =COUNTIF(B:B,Q9)+COUNTIF(D:D,Q9)+COUNTIF(F:F,Q9)+COUNTIF(H:H,Q9) -> 2 | S9: =IF(R9>=10, (COUNTIF(J:J,Q9)/R9), "Insuficiente") -> Insuficiente
A10: 45835 | B10: Marcelo | C10: Zedruu | D10: Vivian | E10: Jhoira | F10: Dexter | G10: Who Villains | H10: Talita | I10: Who Time | J10: Dexter | K10: Who Villains | M10: Jhoira | N10: =COUNTIF(C:C,M10)+COUNTIF(E:E,M10)+COUNTIF(G:G,M10)+COUNTIF(I:I,M10) -> 1 | O10: =IF(N10>=10,(COUNTIF(K:K,M10)/N10),"Insuficiente") -> Insuficiente
A11: 45864 | B11: Marcelo | C11: Muzzio | D11: Vivian | E11: Zimone | F11: Philips | G11: Hashaton | H11: João | I11: FF Counters | J11: Marcelo | K11: Muzzio | M11: Kaalia | N11: =COUNTIF(C:C,M11)+COUNTIF(E:E,M11)+COUNTIF(G:G,M11)+COUNTIF(I:I,M11) -> 2 | O11: =IF(N11>=10,(COUNTIF(K:K,M11)/N11),"Insuficiente") -> Insuficiente
A12: 45864 | B12: Marcelo | C12: Sisay | D12: Vivian | E12: Zimone | F12: Philips | G12: Kaalia | H12: João | I12: FF Counters | J12: Philips | K12: Kaalia | M12: Kumena | N12: =COUNTIF(C:C,M12)+COUNTIF(E:E,M12)+COUNTIF(G:G,M12)+COUNTIF(I:I,M12) -> 1 | O12: =IF(N12>=10,(COUNTIF(K:K,M12)/N12),"Insuficiente") -> Insuficiente
M13: Ladinos | N13: =COUNTIF(C:C,M13)+COUNTIF(E:E,M13)+COUNTIF(G:G,M13)+COUNTIF(I:I,M13) -> 1 | O13: =IF(N13>=10,(COUNTIF(K:K,M13)/N13),"Insuficiente") -> Insuficiente
M14: Muzzio | N14: =COUNTIF(C:C,M14)+COUNTIF(E:E,M14)+COUNTIF(G:G,M14)+COUNTIF(I:I,M14) -> 2 | O14: =IF(N14>=10,(COUNTIF(K:K,M14)/N14),"Insuficiente") -> Insuficiente
M15: Narset | N15: =COUNTIF(C:C,M15)+COUNTIF(E:E,M15)+COUNTIF(G:G,M15)+COUNTIF(I:I,M15) -> 1 | O15: =IF(N15>=10,(COUNTIF(K:K,M15)/N15),"Insuficiente") -> Insuficiente
M16: Raffine | N16: =COUNTIF(C:C,M16)+COUNTIF(E:E,M16)+COUNTIF(G:G,M16)+COUNTIF(I:I,M16) -> 5 | O16: =IF(N16>=10,(COUNTIF(K:K,M16)/N16),"Insuficiente") -> Insuficiente
M17: Sisay | N17: =COUNTIF(C:C,M17)+COUNTIF(E:E,M17)+COUNTIF(G:G,M17)+COUNTIF(I:I,M17) -> 1 | O17: =IF(N17>=10,(COUNTIF(K:K,M17)/N17),"Insuficiente") -> Insuficiente
M18: Thantis | N18: =COUNTIF(C:C,M18)+COUNTIF(E:E,M18)+COUNTIF(G:G,M18)+COUNTIF(I:I,M18) -> 1 | O18: =IF(N18>=10,(COUNTIF(K:K,M18)/N18),"Insuficiente") -> Insuficiente
M19: Tovolar | N19: =COUNTIF(C:C,M19)+COUNTIF(E:E,M19)+COUNTIF(G:G,M19)+COUNTIF(I:I,M19) -> 1 | O19: =IF(N19>=10,(COUNTIF(K:K,M19)/N19),"Insuficiente") -> Insuficiente
M20: Trakiri | N20: =COUNTIF(C:C,M20)+COUNTIF(E:E,M20)+COUNTIF(G:G,M20)+COUNTIF(I:I,M20) -> 1 | O20: =IF(N20>=10,(COUNTIF(K:K,M20)/N20),"Insuficiente") -> Insuficiente
M21: Who Time | N21: =COUNTIF(C:C,M21)+COUNTIF(E:E,M21)+COUNTIF(G:G,M21)+COUNTIF(I:I,M21) -> 2 | O21: =IF(N21>=10,(COUNTIF(K:K,M21)/N21),"Insuficiente") -> Insuficiente
M22: Who Villains | N22: =COUNTIF(C:C,M22)+COUNTIF(E:E,M22)+COUNTIF(G:G,M22)+COUNTIF(I:I,M22) -> 3 | O22: =IF(N22>=10,(COUNTIF(K:K,M22)/N22),"Insuficiente") -> Insuficiente
M23: Winota | N23: =COUNTIF(C:C,M23)+COUNTIF(E:E,M23)+COUNTIF(G:G,M23)+COUNTIF(I:I,M23) -> 2 | O23: =IF(N23>=10,(COUNTIF(K:K,M23)/N23),"Insuficiente") -> Insuficiente
M24: Yuriko | N24: =COUNTIF(C:C,M24)+COUNTIF(E:E,M24)+COUNTIF(G:G,M24)+COUNTIF(I:I,M24) -> 1 | O24: =IF(N24>=10,(COUNTIF(K:K,M24)/N24),"Insuficiente") -> Insuficiente
... M26: Zimone | N26: =COUNTIF(C:C,M26)+COUNTIF(E:E,M26)+COUNTIF(G:G,M26)+COUNTIF(I:I,M26) -> 8 | O26: =IF(N26>=10,(COUNTIF(K:K,M26)/N26),"Insuficiente") -> Insuficiente

Sheet WATCH
A1: Carta | B1: Identidade | G1: Tipo | H1: Categoria | I1: Classe
A2: Weathered Runestone | B2: Não | C2: Não | D2: Não | E2: Não | F2: Não | G2: Artefato | H2: Stax | I2: Cemitério
A3: Shivan Harvest | B3: Não | C3: Não | D3: Sim | E3: Não | F3: Não | G3: Encantamento | H3: Remoção | I3: Terreno
A4: Scouting Trek | B4: Não | C4: Não | D4: Não | E4: Não | F4: Sim | G4: Feitiço | H4: Combo | I4: Tutor
A5: Overabundance | B5: Não | C5: Não | D5: Sim | E5: Não | F5: Não | G5: Encantamento | H5: Ramp | I5: Punição
A6: Spreading Plague | B6: Não | C6: Não | D6: Não | E6: Sim | F6: Não | G6: Encantamento | H6: Stax | I6: Criaturas
A7: Explosão da Alma | B7: Não | C7: Não | D7: Sim | E7: Não | F7: Não | G7: Instantânea | H7: Wincon | I7: Dano
A8: Obsidian Fireheat | B8: Não | C8: Não | D8: Sim | E8: Não | F8: Não | G8: Criatura | H8: Wincon | I8: Punição
A9: Interdict | B9: Não | C9: Sim | D9: Não | E9: Não | F9: Não | G9: Instantânea | H9: Anule | I9: Habilidade
A10: Mogg Infestation | B10: Não | C10: Não | D10: Sim | E10: Não | F10: Não | G10: Feitiço | H10: Remoção | I10: Criaturas
A11: Life // Death | B11: Não | C11: Não | D11: Não | E11: Não | F11: Sim | G11: Feitiço | H11: Combo | I11: Terreno
A12: Debt of Loyalt | B12: Sim | C12: Não | D12: Não | E12: Não | F12: Não | G12: Instantânea | H12: Remoção | I12: Roubo
A13: Yavimaya Hollow | B13: Não | C13: Não | D13: Não | E13: Não | F13: Sim | G13: Terreno | H13: Proteção | I13: Criaturas
... A23: Preferência de Cineréia | B23: Não | C23: Não | D23: Sim | E23: Não | F23: Não | G23: Encantamento | H23: Stax | I23: Criaturas

Sheet RESUMO
A1: Prioridade | B1: Faltam | C1: Deck 1 | D1: Deck 2 | E1: Deck 3 | F1: Deck 4 | G1: Carta | J1: Alterações | K1: Cores | P1: =COUNTA(I3:I5000) & " Decks" -> 30 Decks | U1: Piratas | V1: Baylen | W1: Narset | X1: Tayam | Y1: Carlos | Z1: Rani | AA1: Kumena | AB1: Zimone | AC1: JhoiraB | AD1: Gritrog | AE1: Muzzio | AF1: VialIshai | AG1: Yuriko | AH1: Inalla | AI1: Akiri | AJ1: Sisay | AK1: Thrakiri | AL1: Elfos | AM1: Jhoira | AN1: Fractius | AO1: Rielle | AP1: Oona | AQ1: Kresh | AR1: Breya | AS1: OWA | AT1: Alela | AU1: Arcades | AV1: Zedruu | AW1: Exaltado | AX1: Modular | AY1: Holder 1 | AZ1: Holder 2
A2: =IFERROR(INDEX($S$3:$S$200, MATCH($C2, $I$3:$I$200, 0)), "") -> 3 | B2: =COUNTIF(U:AX,G2) -> 1 | C2: =IFERROR( INDEX($U$1:$AX$1, MATCH(TRUE, CHOOSE({1;2;3;4;5;6;7;8;9;10;11;12;13;14;15;16;17;18;19;20;21;22;23;24;25;26;27;28;29;30;31;32}, COUNTIFS($U$2:$U$200,$G2)>0, COUNTIFS($V$2:$V$200,$G2)>0, COUNTIFS($W$2:$W$200,$G2)>0, COUNTIFS($X$2:$X$200,$G2)>0, COUNTIFS($Y$2:$Y$200,$G2)>0, COUNTIFS($Z$2:$Z$200,$G2)>0, COUNTIFS($AA$2:$AA$200,$G2)>0, COUNTIFS($AB$2:$AB$200,$G2)>0, COUNTIFS($AC$2:$AC$200,$G2)>0, COUNTIFS($AD$2:$AD$200,$G2)>0, COUNTIFS($AE$2:$AE$200,$G2)>0, COUNTIFS($AF$2:$AF$200,$G2)>0, COUNTIFS($AG$2:$AG$200,$G2)>0, COUNTIFS($AH$2:$AH$200,$G2)>0, COUNTIFS($AI$2:$AI$200,$G2)>0, COUNTIFS($AJ$2:$AJ$200,$G2)>0, COUNTIFS($AK$2:$AK$200,$G2)>0, COUNTIFS($AL$2:$AL$200,$G2)>0, COUNTIFS($AM$2:$AM$200,$G2)>0, COUNTIFS($AN$2:$AN$200,$G2)>0, COUNTIFS($AO$2:$AO$200,$G2)>0, COUNTIFS($AP$2:$AP$200,$G2)>0, COUNTIFS($AQ$2:$AQ$200,$G2)>0, COUNTIFS($AR$2:$AR$200,$G2)>0, COUNTIFS($AS$2:$AS$200,$G2)>0, COUNTIFS($AT$2:$AT$200,$G2)>0, COUNTIFS($AU$2:$AU$200,$G2)>0, COUNTIFS($AV$2:$AV$200,$G2)>0, COUNTIFS($AW$2:$AW$200,$G2)>0, COUNTIFS($AX$2:$AX$200,$G2)>0 ), 0) ), "") -> Muzzio | D2: {=IFERROR( INDEX( _xlfn._xlws.FILTER($U$1:$AX$1, TRANSPOSE( CHOOSE({1;2;3;4;5;6;7;8;9;10;11;12;13;14;15;16;17;18;19;20;21;22;23;24;25;26;27;28;29;30}, COUNTIFS($U$2:$U$200,$G2)>0, COUNTIFS($V$2:$V$200,$G2)>0, COUNTIFS($W$2:$W$200,$G2)>0, COUNTIFS($X$2:$X$200,$G2)>0, COUNTIFS($Y$2:$Y$200,$G2)>0, COUNTIFS($Z$2:$Z$200,$G2)>0, COUNTIFS($AA$2:$AA$200,$G2)>0, COUNTIFS($AB$2:$AB$200,$G2)>0, COUNTIFS($AC$2:$AC$200,$G2)>0, COUNTIFS($AD$2:$AD$200,$G2)>0, COUNTIFS($AE$2:$AE$200,$G2)>0, COUNTIFS($AF$2:$AF$200,$G2)>0, COUNTIFS($AG$2:$AG$200,$G2)>0, COUNTIFS($AH$2:$AH$200,$G2)>0, COUNTIFS($AI$2:$AI$200,$G2)>0, COUNTIFS($AJ$2:$AJ$200,$G2)>0, COUNTIFS($AK$2:$AK$200,$G2)>0, COUNTIFS($AL$2:$AL$200,$G2)>0, COUNTIFS($AM$2:$AM$200,$G2)>0, COUNTIFS($AN$2:$AN$200,$G2)>0, COUNTIFS($AO$2:$AO$200,$G2)>0, COUNTIFS($AP$2:$AP$200,$G2)>0, COUNTIFS($AQ$2:$AQ$200,$G2)>0, COUNTIFS($AR$2:$AR$200,$G2)>0, COUNTIFS($AS$2:$AS$200,$G2)>0, COUNTIFS($AT$2:$AT$200,$G2)>0, COUNTIFS($AU$2:$AU$200,$G2)>0, COUNTIFS($AV$2:$AV$200,$G2)>0, COUNTIFS($AW$2:$AW$200,$G2)>0, COUNTIFS($AX$2:$AX$200,$G2)>0 )), ), 2 ), "")} | E2: {=IFERROR( INDEX( _xlfn._xlws.FILTER($U$1:$AX$1, TRANSPOSE( CHOOSE({1;2;3;4;5;6;7;8;9;10;11;12;13;14;15;16;17;18;19;20;21;22;23;24;25;26;27;28;29;30}, COUNTIFS($U$2:$U$200,$G2)>0, COUNTIFS($V$2:$V$200,$G2)>0, COUNTIFS($W$2:$W$200,$G2)>0, COUNTIFS($X$2:$X$200,$G2)>0, COUNTIFS($Y$2:$Y$200,$G2)>0, COUNTIFS($Z$2:$Z$200,$G2)>0, COUNTIFS($AA$2:$AA$200,$G2)>0, COUNTIFS($AB$2:$AB$200,$G2)>0, COUNTIFS($AC$2:$AC$200,$G2)>0, COUNTIFS($AD$2:$AD$200,$G2)>0, COUNTIFS($AE$2:$AE$200,$G2)>0, COUNTIFS($AF$2:$AF$200,$G2)>0, COUNTIFS($AG$2:$AG$200,$G2)>0, COUNTIFS($AH$2:$AH$200,$G2)>0, COUNTIFS($AI$2:$AI$200,$G2)>0, COUNTIFS($AJ$2:$AJ$200,$G2)>0, COUNTIFS($AK$2:$AK$200,$G2)>0, COUNTIFS($AL$2:$AL$200,$G2)>0, COUNTIFS($AM$2:$AM$200,$G2)>0, COUNTIFS($AN$2:$AN$200,$G2)>0, COUNTIFS($AO$2:$AO$200,$G2)>0, COUNTIFS($AP$2:$AP$200,$G2)>0, COUNTIFS($AQ$2:$AQ$200,$G2)>0, COUNTIFS($AR$2:$AR$200,$G2)>0, COUNTIFS($AS$2:$AS$200,$G2)>0, COUNTIFS($AT$2:$AT$200,$G2)>0, COUNTIFS($AU$2:$AU$200,$G2)>0, COUNTIFS($AV$2:$AV$200,$G2)>0, COUNTIFS($AW$2:$AW$200,$G2)>0, COUNTIFS($AX$2:$AX$200,$G2)>0 )), ), 3 ), "")} | F2: {=IFERROR( INDEX( _xlfn._xlws.FILTER($U$1:$AX$1, TRANSPOSE( CHOOSE({1;2;3;4;5;6;7;8;9;10;11;12;13;14;15;16;17;18;19;20;21;22;23;24;25;26;27;28;29;30}, COUNTIFS($U$2:$U$200,$G2)>0, COUNTIFS($V$2:$V$200,$G2)>0, COUNTIFS($W$2:$W$200,$G2)>0, COUNTIFS($X$2:$X$200,$G2)>0, COUNTIFS($Y$2:$Y$200,$G2)>0, COUNTIFS($Z$2:$Z$200,$G2)>0, COUNTIFS($AA$2:$AA$200,$G2)>0, COUNTIFS($AB$2:$AB$200,$G2)>0, COUNTIFS($AC$2:$AC$200,$G2)>0, COUNTIFS($AD$2:$AD$200,$G2)>0, COUNTIFS($AE$2:$AE$200,$G2)>0, COUNTIFS($AF$2:$AF$200,$G2)>0, COUNTIFS($AG$2:$AG$200,$G2)>0, COUNTIFS($AH$2:$AH$200,$G2)>0, COUNTIFS($AI$2:$AI$200,$G2)>0, COUNTIFS($AJ$2:$AJ$200,$G2)>0, COUNTIFS($AK$2:$AK$200,$G2)>0, COUNTIFS($AL$2:$AL$200,$G2)>0, COUNTIFS($AM$2:$AM$200,$G2)>0, COUNTIFS($AN$2:$AN$200,$G2)>0, COUNTIFS($AO$2:$AO$200,$G2)>0, COUNTIFS($AP$2:$AP$200,$G2)>0, COUNTIFS($AQ$2:$AQ$200,$G2)>0, COUNTIFS($AR$2:$AR$200,$G2)>0, COUNTIFS($AS$2:$AS$200,$G2)>0, COUNTIFS($AT$2:$AT$200,$G2)>0, COUNTIFS($AU$2:$AU$200,$G2)>0, COUNTIFS($AV$2:$AV$200,$G2)>0, COUNTIFS($AW$2:$AW$200,$G2)>0, COUNTIFS($AX$2:$AX$200,$G2)>0 )), ), 4 ), "")} | G2: {=IF(COUNTA(_xlfn.ANCHORARRAY($CJ$2))=0,"",_xlfn._xlws.SORT(_xlfn.UNIQUE(_xlfn.ANCHORARRAY($CJ$2)),1,1))} -> A Joia do Enigma | I2: Total | J2: =SUM(J3:J30) -> 327 | K2: =COUNTIF(K3:K5000,"Sim") -> 16 | L2: =COUNTIF(L3:L5000,"Sim") -> 22 | M2: =COUNTIF(M3:M5000,"Sim") -> 17 | N2: =COUNTIF(N3:N5000,"Sim") -> 17 | O2: =COUNTIF(O3:O5000,"Sim") -> 14 | P2: Wincon | Q2: Sub Plan | R2: Descrição | S2: Prioridade | U2: {=IF(COUNTA(_xlfn._xlws.FILTER(Piratas!C3:C200,(Piratas!B3:B200<>Piratas!C3:C200)*(Piratas!C3:C200<>"")))=0,"",_xlfn._xlws.SORT(_xlfn._xlws.FILTER(Piratas!C3:C200,(Piratas!B3:B200<>Piratas!C3:C200)*(Piratas!C3:C200<>"")),1,1))} -> Back in Town | V2: {=IF(COUNTA(_xlfn._xlws.FILTER(Baylen!C3:C200,(Baylen!B3:B200<>Baylen!C3:C200)*(Baylen!C3:C200<>"")))=0,"",_xlfn._xlws.SORT(_xlfn._xlws.FILTER(Baylen!C3:C200,(Baylen!B3:B200<>Baylen!C3:C200)*(Baylen!C3:C200<>"")),1,1))} -> Artifact Mutation | W2: {=IF(COUNTA(_xlfn._xlws.FILTER(Narset!C3:C200,(Narset!B3:B200<>Narset!C3:C200)*(Narset!C3:C200<>"")))=0,"",_xlfn._xlws.SORT(_xlfn._xlws.FILTER(Narset!C3:C200,(Narset!B3:B200<>Narset!C3:C200)*(Narset!C3:C200<>"")),1,1))} -> Adarkar Wastes | X2: {=IF(COUNTA(_xlfn._xlws.FILTER(Tayam!C3:C200,(Tayam!B3:B200<>Tayam!C3:C200)*(Tayam!C3:C200<>"")))=0,"",_xlfn._xlws.SORT(_xlfn._xlws.FILTER(Tayam!C3:C200,(Tayam!B3:B200<>Tayam!C3:C200)*(Tayam!C3:C200<>"")),1,1))} -> Ardbert, Warrior of Darkness | Y2: {=IF(COUNTA(_xlfn._xlws.FILTER(Carlos!C3:C200,(Carlos!B3:B200<>Carlos!C3:C200)*(Carlos!C3:C200<>"")))=0,"",_xlfn._xlws.SORT(_xlfn._xlws.FILTER(Carlos!C3:C200,(Carlos!B3:B200<>Carlos!C3:C200)*(Carlos!C3:C200<>"")),1,1))} -> Ascensão do Avernus | Z2: {=IF(COUNTA(_xlfn._xlws.FILTER(Rani!C3:C200,(Rani!B3:B200<>Rani!C3:C200)*(Rani!C3:C200<>"")))=0,"",_xlfn._xlws.SORT(_xlfn._xlws.FILTER(Rani!C3:C200,(Rani!B3:B200<>Rani!C3:C200)*(Rani!C3:C200<>"")),1,1))} -> Access Tunnel | AA2: {=IF(COUNTA(_xlfn._xlws.FILTER(Kumena!C3:C200,(Kumena!B3:B200<>Kumena!C3:C200)*(Kumena!C3:C200<>"")))=0,"",_xlfn._xlws.SORT(_xlfn._xlws.FILTER(Kumena!C3:C200,(Kumena!B3:B200<>Kumena!C3:C200)*(Kumena!C3:C200<>"")),1,1))} -> Beast Within | AB2: {=IF(COUNTA(_xlfn._xlws.FILTER(Zimone!C3:C200,(Zimone!B3:B200<>Zimone!C3:C200)*(Zimone!C3:C200<>"")))=0,"",_xlfn._xlws.SORT(_xlfn._xlws.FILTER(Zimone!C3:C200,(Zimone!B3:B200<>Zimone!C3:C200)*(Zimone!C3:C200<>"")),1,1))} -> Ancient Greenwarden | AC2: {=IF(COUNTA(_xlfn._xlws.FILTER(JhoiraB!C3:C200,(JhoiraB!B3:B200<>JhoiraB!C3:C200)*(JhoiraB!C3:C200<>"")))=0,"",_xlfn._xlws.SORT(_xlfn._xlws.FILTER(JhoiraB!C3:C200,(JhoiraB!B3:B200<>JhoiraB!C3:C200)*(JhoiraB!C3:C200<>"")),1,1))} -> Emrakul, um Novo Mundo | AD2: {=IF(COUNTA(_xlfn._xlws.FILTER(Gitrog!C3:C200,(Gitrog!B3:B200<>Gitrog!C3:C200)*(Gitrog!C3:C200<>"")))=0,"",_xlfn._xlws.SORT(_xlfn._xlws.FILTER(Gitrog!C3:C200,(Gitrog!B3:B200<>Gitrog!C3:C200)*(Gitrog!C3:C200<>"")),1,1))} -> Ancient Tomb | AE2: {=IF(COUNTA(_xlfn._xlws.FILTER(Muzzio!C3:C200,(Muzzio!B3:B200<>Muzzio!C3:C200)*(Muzzio!C3:C200<>"")))=0,"",_xlfn._xlws.SORT(_xlfn._xlws.FILTER(Muzzio!C3:C200,(Muzzio!B3:B200<>Muzzio!C3:C200)*(Muzzio!C3:C200<>"")),1,1))} -> A Joia do Enigma | AF2: {=IF(COUNTA(_xlfn._xlws.FILTER(VialIshai!C3:C200,(VialIshai!B3:B200<>VialIshai!C3:C200)*(VialIshai!C3:C200<>"")))=0,"",_xlfn._xlws.SORT(_xlfn._xlws.FILTER(VialIshai!C3:C200,(VialIshai!B3:B200<>VialIshai!C3:C200)*(VialIshai!C3:C200<>"")),1,1))} -> Amphibian Downpour | AG2: {=IF(COUNTA(_xlfn._xlws.FILTER(Yuriko!C3:C200,(Yuriko!B3:B200<>Yuriko!C3:C200)*(Yuriko!C3:C200<>"")))=0,"",_xlfn._xlws.SORT(_xlfn._xlws.FILTER(Yuriko!C3:C200,(Yuriko!B3:B200<>Yuriko!C3:C200)*(Yuriko!C3:C200<>"")),1,1))} -> Creeping Tar Pit | AH2: {=IF(COUNTA(_xlfn._xlws.FILTER(Inalla!C3:C200,(Inalla!B3:B200<>Inalla!C3:C200)*(Inalla!C3:C200<>"")))=0,"",_xlfn._xlws.SORT(_xlfn._xlws.FILTER(Inalla!C3:C200,(Inalla!B3:B200<>Inalla!C3:C200)*(Inalla!C3:C200<>"")),1,1))} -> Arcane Lighthouse | AI2: {=IF(COUNTA(_xlfn._xlws.FILTER(Akiri!C3:C200,(Akiri!B3:B200<>Akiri!C3:C200)*(Akiri!C3:C200<>"")))=0,"",_xlfn._xlws.SORT(_xlfn._xlws.FILTER(Akiri!C3:C200,(Akiri!B3:B200<>Akiri!C3:C200)*(Akiri!C3:C200<>"")),1,1))} -> Cid, Freeflier Pilot | AJ2: {=IF(COUNTA(_xlfn._xlws.FILTER(Sisay!C3:C200,(Sisay!B3:B200<>Sisay!C3:C200)*(Sisay!C3:C200<>"")))=0,"",_xlfn._xlws.SORT(_xlfn._xlws.FILTER(Sisay!C3:C200,(Sisay!B3:B200<>Sisay!C3:C200)*(Sisay!C3:C200<>"")),1,1))} -> Commodore Guff | AK2: {=IF(COUNTA(_xlfn._xlws.FILTER(Thrakiri!C3:C200,(Thrakiri!B3:B200<>Thrakiri!C3:C200)*(Thrakiri!C3:C200<>"")))=0,"",_xlfn._xlws.SORT(_xlfn._xlws.FILTER(Thrakiri!C3:C200,(Thrakiri!B3:B200<>Thrakiri!C3:C200)*(Thrakiri!C3:C200<>"")),1,1))} -> Matoya, Archon Elder | AL2: {=IF(COUNTA(_xlfn._xlws.FILTER(Elfos!C3:C200,(Elfos!B3:B200<>Elfos!C3:C200)*(Elfos!C3:C200<>"")))=0,"",_xlfn._xlws.SORT(_xlfn._xlws.FILTER(Elfos!C3:C200,(Elfos!B3:B200<>Elfos!C3:C200)*(Elfos!C3:C200<>"")),1,1))} -> Alchemist's Refuge | AM2: {=IF(COUNTA(_xlfn._xlws.FILTER(Jhoira!C3:C200,(Jhoira!B3:B200<>Jhoira!C3:C200)*(Jhoira!C3:C200<>"")))=0,"",_xlfn._xlws.SORT(_xlfn._xlws.FILTER(Jhoira!C3:C200,(Jhoira!B3:B200<>Jhoira!C3:C200)*(Jhoira!C3:C200<>"")),1,1))} -> Emrakul, um Novo Mundo | AN2: {=IF(COUNTA(_xlfn._xlws.FILTER(Fractius!C3:C200,(Fractius!B3:B200<>Fractius!C3:C200)*(Fractius!C3:C200<>"")))=0,"",_xlfn._xlws.SORT(_xlfn._xlws.FILTER(Fractius!C3:C200,(Fractius!B3:B200<>Fractius!C3:C200)*(Fractius!C3:C200<>"")),1,1))} -> Caverna das Almas | AO2: {=IF(COUNTA(_xlfn._xlws.FILTER(Rielle!C3:C200,(Rielle!B3:B200<>Rielle!C3:C200)*(Rielle!C3:C200<>"")))=0,"",_xlfn._xlws.SORT(_xlfn._xlws.FILTER(Rielle!C3:C200,(Rielle!B3:B200<>Rielle!C3:C200)*(Rielle!C3:C200<>"")),1,1))} -> Afundar em Estupor | AP2: {=IF(COUNTA(_xlfn._xlws.FILTER(Oona!C3:C200,(Oona!B3:B200<>Oona!C3:C200)*(Oona!C3:C200<>"")))=0,"",_xlfn._xlws.SORT(_xlfn._xlws.FILTER(Oona!C3:C200,(Oona!B3:B200<>Oona!C3:C200)*(Oona!C3:C200<>"")),1,1))} -> Invasion of Segovia | AQ2: {=IF(COUNTA(_xlfn._xlws.FILTER(Kresh!C3:C200,(Kresh!B3:B200<>Kresh!C3:C200)*(Kresh!C3:C200<>"")))=0,"",_xlfn._xlws.SORT(_xlfn._xlws.FILTER(Kresh!C3:C200,(Kresh!B3:B200<>Kresh!C3:C200)*(Kresh!C3:C200<>"")),1,1))} -> Bugenhagen, Wise Elder | AR2: {=IF(COUNTA(_xlfn._xlws.FILTER(Breya!C3:C200,(Breya!B3:B200<>Breya!C3:C200)*(Breya!C3:C200<>"")))=0,"",_xlfn._xlws.SORT(_xlfn._xlws.FILTER(Breya!C3:C200,(Breya!B3:B200<>Breya!C3:C200)*(Breya!C3:C200<>"")),1,1))} -> Adagia, Windswept Bastion | AS2: {=IF(COUNTA(_xlfn._xlws.FILTER(OWA!C3:C200,(OWA!B3:B200<>OWA!C3:C200)*(OWA!C3:C200<>"")))=0,"",_xlfn._xlws.SORT(_xlfn._xlws.FILTER(OWA!C3:C200,(OWA!B3:B200<>OWA!C3:C200)*(OWA!C3:C200<>"")),1,1))} -> Dollmaker's Shop // Porcelain Gallery | AT2: {=IF(COUNTA(_xlfn._xlws.FILTER(Alela!C3:C200,(Alela!B3:B200<>Alela!C3:C200)*(Alela!C3:C200<>"")))=0,"",_xlfn._xlws.SORT(_xlfn._xlws.FILTER(Alela!C3:C200,(Alela!B3:B200<>Alela!C3:C200)*(Alela!C3:C200<>"")),1,1))} -> Adagia, Windswept Bastion | AU2: {=IF(COUNTA(_xlfn._xlws.FILTER(Arcades!C3:C200,(Arcades!B3:B200<>Arcades!C3:C200)*(Arcades!C3:C200<>"")))=0,"",_xlfn._xlws.SORT(_xlfn._xlws.FILTER(Arcades!C3:C200,(Arcades!B3:B200<>Arcades!C3:C200)*(Arcades!C3:C200<>"")),1,1))} -> Alchemist's Refuge | AV2: {=IF(COUNTA(_xlfn._xlws.FILTER(Zedruu!C3:C200,(Zedruu!B3:B200<>Zedruu!C3:C200)*(Zedruu!C3:C200<>"")))=0,"",_xlfn._xlws.SORT(_xlfn._xlws.FILTER(Zedruu!C3:C200,(Zedruu!B3:B200<>Zedruu!C3:C200)*(Zedruu!C3:C200<>"")),1,1))} -> Árbitro Silencioso | AW2: {=IF(COUNTA(_xlfn._xlws.FILTER(Exaltado!C3:C200,(Exaltado!B3:B200<>Exaltado!C3:C200)*(Exaltado!C3:C200<>"")))=0,"",_xlfn._xlws.SORT(_xlfn._xlws.FILTER(Exaltado!C3:C200,(Exaltado!B3:B200<>Exaltado!C3:C200)*(Exaltado!C3:C200<>"")),1,1))} -> #VALUE! | AX2: {=IF(COUNTA(_xlfn._xlws.FILTER(Modular!C3:C200,(Modular!B3:B200<>Modular!C3:C200)*(Modular!C3:C200<>"")))=0,"",_xlfn._xlws.SORT(_xlfn._xlws.FILTER(Modular!C3:C200,(Modular!B3:B200<>Modular!C3:C200)*(Modular!C3:C200<>"")),1,1))} -> Adagia, Windswept Bastion | BB2: {=IF(COUNTA(_xlfn.ANCHORARRAY($U$2))+COUNTA(_xlfn.ANCHORARRAY($V$2))=0,"",_xlfn._xlws.SORT(_xlfn.UNIQUE(IF(ROW(INDIRECT("1:"&(COUNTA(_xlfn.ANCHORARRAY($U$2))+COUNTA(_xlfn.ANCHORARRAY($V$2)))))<=COUNTA(_xlfn.ANCHORARRAY($U$2)),INDEX(_xlfn.ANCHORARRAY($U$2),ROW(INDIRECT("1:"&(COUNTA(_xlfn.ANCHORARRAY($U$2))+COUNTA(_xlfn.ANCHORARRAY($V$2)))))),INDEX(_xlfn.ANCHORARRAY($V$2),ROW(INDIRECT("1:"&(COUNTA(_xlfn.ANCHORARRAY($U$2))+COUNTA(_xlfn.ANCHORARRAY($V$2)))))-COUNTA(_xlfn.ANCHORARRAY($U$2))))),1,1))} -> Artifact Mutation | BC2: {=IF(COUNTA(_xlfn.ANCHORARRAY($W$2))+COUNTA(_xlfn.ANCHORARRAY($X$2))=0,"",_xlfn._xlws.SORT(_xlfn.UNIQUE(IF(ROW(INDIRECT("1:"&(COUNTA(_xlfn.ANCHORARRAY($W$2))+COUNTA(_xlfn.ANCHORARRAY($X$2)))))<=COUNTA(_xlfn.ANCHORARRAY($W$2)),INDEX(_xlfn.ANCHORARRAY($W$2),ROW(INDIRECT("1:"&(COUNTA(_xlfn.ANCHORARRAY($W$2))+COUNTA(_xlfn.ANCHORARRAY($X$2)))))),INDEX(_xlfn.ANCHORARRAY($X$2),ROW(INDIRECT("1:"&(COUNTA(_xlfn.ANCHORARRAY($W$2))+COUNTA(_xlfn.ANCHORARRAY($X$2)))))-COUNTA(_xlfn.ANCHORARRAY($W$2))))),1,1))} -> Adarkar Wastes | BD2: {=IF(COUNTA(_xlfn.ANCHORARRAY($Y$2))+COUNTA(_xlfn.ANCHORARRAY($Z$2))=0,"",_xlfn._xlws.SORT(_xlfn.UNIQUE(IF(ROW(INDIRECT("1:"&(COUNTA(_xlfn.ANCHORARRAY($Y$2))+COUNTA(_xlfn.ANCHORARRAY($Z$2)))))<=COUNTA(_xlfn.ANCHORARRAY($Y$2)),INDEX(_xlfn.ANCHORARRAY($Y$2),ROW(INDIRECT("1:"&(COUNTA(_xlfn.ANCHORARRAY($Y$2))+COUNTA(_xlfn.ANCHORARRAY($Z$2)))))),INDEX(_xlfn.ANCHORARRAY($Z$2),ROW(INDIRECT("1:"&(COUNTA(_xlfn.ANCHORARRAY($Y$2))+COUNTA(_xlfn.ANCHORARRAY($Z$2)))))-COUNTA(_xlfn.ANCHORARRAY($Y$2))))),1,1))} -> Access Tunnel | BE2: {=IF(COUNTA(_xlfn.ANCHORARRAY($AA$2))+COUNTA(_xlfn.ANCHORARRAY($AB$2))=0,"",_xlfn._xlws.SORT(_xlfn.UNIQUE(IF(ROW(INDIRECT("1:"&(COUNTA(_xlfn.ANCHORARRAY($AA$2))+COUNTA(_xlfn.ANCHORARRAY($AB$2)))))<=COUNTA(_xlfn.ANCHORARRAY($AA$2)),INDEX(_xlfn.ANCHORARRAY($AA$2),ROW(INDIRECT("1:"&(COUNTA(_xlfn.ANCHORARRAY($AA$2))+COUNTA(_xlfn.ANCHORARRAY($AB$2)))))),INDEX(_xlfn.ANCHORARRAY($AB$2),ROW(INDIRECT("1:"&(COUNTA(_xlfn.ANCHORARRAY($AA$2))+COUNTA(_xlfn.ANCHORARRAY($AB$2)))))-COUNTA(_xlfn.ANCHORARRAY($AA$2))))),1,1))} -> Ancient Greenwarden | BF2: {=IF(COUNTA(_xlfn.ANCHORARRAY($AC$2))+COUNTA(_xlfn.ANCHORARRAY($AD$2))=0,"",_xlfn._xlws.SORT(_xlfn.UNIQUE(IF(ROW(INDIRECT("1:"&(COUNTA(_xlfn.ANCHORARRAY($AC$2))+COUNTA(_xlfn.ANCHORARRAY($AD$2)))))<=COUNTA(_xlfn.ANCHORARRAY($AC$2)),INDEX(_xlfn.ANCHORARRAY($AC$2),ROW(INDIRECT("1:"&(COUNTA(_xlfn.ANCHORARRAY($AC$2))+COUNTA(_xlfn.ANCHORARRAY($AD$2)))))),INDEX(_xlfn.ANCHORARRAY($AD$2),ROW(INDIRECT("1:"&(COUNTA(_xlfn.ANCHORARRAY($AC$2))+COUNTA(_xlfn.ANCHORARRAY($AD$2)))))-COUNTA(_xlfn.ANCHORARRAY($AC$2))))),1,1))} -> Ancient Tomb | BG2: {=IF(COUNTA(_xlfn.ANCHORARRAY($AE$2))+COUNTA(_xlfn.ANCHORARRAY($AF$2))=0,"",_xlfn._xlws.SORT(_xlfn.UNIQUE(IF(ROW(INDIRECT("1:"&(COUNTA(_xlfn.ANCHORARRAY($AE$2))+COUNTA(_xlfn.ANCHORARRAY($AF$2)))))<=COUNTA(_xlfn.ANCHORARRAY($AE$2)),INDEX(_xlfn.ANCHORARRAY($AE$2),ROW(INDIRECT("1:"&(COUNTA(_xlfn.ANCHORARRAY($AE$2))+COUNTA(_xlfn.ANCHORARRAY($AF$2)))))),INDEX(_xlfn.ANCHORARRAY($AF$2),ROW(INDIRECT("1:"&(COUNTA(_xlfn.ANCHORARRAY($AE$2))+COUNTA(_xlfn.ANCHORARRAY($AF$2)))))-COUNTA(_xlfn.ANCHORARRAY($AE$2))))),1,1))} -> A Joia do Enigma | BH2: {=IF(COUNTA(_xlfn.ANCHORARRAY($AG$2))+COUNTA(_xlfn.ANCHORARRAY($AH$2))=0,"",_xlfn._xlws.SORT(_xlfn.UNIQUE(IF(ROW(INDIRECT("1:"&(COUNTA(_xlfn.ANCHORARRAY($AG$2))+COUNTA(_xlfn.ANCHORARRAY($AH$2)))))<=COUNTA(_xlfn.ANCHORARRAY($AG$2)),INDEX(_xlfn.ANCHORARRAY($AG$2),ROW(INDIRECT("1:"&(COUNTA(_xlfn.ANCHORARRAY($AG$2))+COUNTA(_xlfn.ANCHORARRAY($AH$2)))))),INDEX(_xlfn.ANCHORARRAY($AH$2),ROW(INDIRECT("1:"&(COUNTA(_xlfn.ANCHORARRAY($AG$2))+COUNTA(_xlfn.ANCHORARRAY($AH$2)))))-COUNTA(_xlfn.ANCHORARRAY($AG$2))))),1,1))} -> Arcane Lighthouse | BI2: {=IF(COUNTA(_xlfn.ANCHORARRAY($AI$2))+COUNTA(_xlfn.ANCHORARRAY($AJ$2))=0,"",_xlfn._xlws.SORT(_xlfn.UNIQUE(IF(ROW(INDIRECT("1:"&(COUNTA(_xlfn.ANCHORARRAY($AI$2))+COUNTA(_xlfn.ANCHORARRAY($AJ$2)))))<=COUNTA(_xlfn.ANCHORARRAY($AI$2)),INDEX(_xlfn.ANCHORARRAY($AI$2),ROW(INDIRECT("1:"&(COUNTA(_xlfn.ANCHORARRAY($AI$2))+COUNTA(_xlfn.ANCHORARRAY($AJ$2)))))),INDEX(_xlfn.ANCHORARRAY($AJ$2),ROW(INDIRECT("1:"&(COUNTA(_xlfn.ANCHORARRAY($AI$2))+COUNTA(_xlfn.ANCHORARRAY($AJ$2)))))-COUNTA(_xlfn.ANCHORARRAY($AI$2))))),1,1))} -> Cid, Freeflier Pilot | BJ2: {=IF(COUNTA(_xlfn.ANCHORARRAY($AK$2))+COUNTA(_xlfn.ANCHORARRAY($AL$2))=0,"",_xlfn._xlws.SORT(_xlfn.UNIQUE(IF(ROW(INDIRECT("1:"&(COUNTA(_xlfn.ANCHORARRAY($AK$2))+COUNTA(_xlfn.ANCHORARRAY($AL$2)))))<=COUNTA(_xlfn.ANCHORARRAY($AK$2)),INDEX(_xlfn.ANCHORARRAY($AK$2),ROW(INDIRECT("1:"&(COUNTA(_xlfn.ANCHORARRAY($AK$2))+COUNTA(_xlfn.ANCHORARRAY($AL$2)))))),INDEX(_xlfn.ANCHORARRAY($AL$2),ROW(INDIRECT("1:"&(COUNTA(_xlfn.ANCHORARRAY($AK$2))+COUNTA(_xlfn.ANCHORARRAY($AL$2)))))-COUNTA(_xlfn.ANCHORARRAY($AK$2))))),1,1))} -> Alchemist's Refuge | BK2: {=IF(COUNTA(_xlfn.ANCHORARRAY($AM$2))+COUNTA(_xlfn.ANCHORARRAY($AN$2))=0,"",_xlfn._xlws.SORT(_xlfn.UNIQUE(IF(ROW(INDIRECT("1:"&(COUNTA(_xlfn.ANCHORARRAY($AM$2))+COUNTA(_xlfn.ANCHORARRAY($AN$2)))))<=COUNTA(_xlfn.ANCHORARRAY($AM$2)),INDEX(_xlfn.ANCHORARRAY($AM$2),ROW(INDIRECT("1:"&(COUNTA(_xlfn.ANCHORARRAY($AM$2))+COUNTA(_xlfn.ANCHORARRAY($AN$2)))))),INDEX(_xlfn.ANCHORARRAY($AN$2),ROW(INDIRECT("1:"&(COUNTA(_xlfn.ANCHORARRAY($AM$2))+COUNTA(_xlfn.ANCHORARRAY($AN$2)))))-COUNTA(_xlfn.ANCHORARRAY($AM$2))))),1,1))} -> Caverna das Almas | BL2: {=IF(COUNTA(_xlfn.ANCHORARRAY($AO$2))+COUNTA(_xlfn.ANCHORARRAY($AP$2))=0,"",_xlfn._xlws.SORT(_xlfn.UNIQUE(IF(ROW(INDIRECT("1:"&(COUNTA(_xlfn.ANCHORARRAY($AO$2))+COUNTA(_xlfn.ANCHORARRAY($AP$2)))))<=COUNTA(_xlfn.ANCHORARRAY($AO$2)),INDEX(_xlfn.ANCHORARRAY($AO$2),ROW(INDIRECT("1:"&(COUNTA(_xlfn.ANCHORARRAY($AO$2))+COUNTA(_xlfn.ANCHORARRAY($AP$2)))))),INDEX(_xlfn.ANCHORARRAY($AP$2),ROW(INDIRECT("1:"&(COUNTA(_xlfn.ANCHORARRAY($AO$2))+COUNTA(_xlfn.ANCHORARRAY($AP$2)))))-COUNTA(_xlfn.ANCHORARRAY($AO$2))))),1,1))} -> Afundar em Estupor | BM2: {=IF(COUNTA(_xlfn.ANCHORARRAY($AQ$2))+COUNTA(_xlfn.ANCHORARRAY($AR$2))=0,"",_xlfn._xlws.SORT(_xlfn.UNIQUE(IF(ROW(INDIRECT("1:"&(COUNTA(_xlfn.ANCHORARRAY($AQ$2))+COUNTA(_xlfn.ANCHORARRAY($AR$2)))))<=COUNTA(_xlfn.ANCHORARRAY($AQ$2)),INDEX(_xlfn.ANCHORARRAY($AQ$2),ROW(INDIRECT("1:"&(COUNTA(_xlfn.ANCHORARRAY($AQ$2))+COUNTA(_xlfn.ANCHORARRAY($AR$2)))))),INDEX(_xlfn.ANCHORARRAY($AR$2),ROW(INDIRECT("1:"&(COUNTA(_xlfn.ANCHORARRAY($AQ$2))+COUNTA(_xlfn.ANCHORARRAY($AR$2)))))-COUNTA(_xlfn.ANCHORARRAY($AQ$2))))),1,1))} -> Adagia, Windswept Bastion | BN2: {=IF(COUNTA(_xlfn.ANCHORARRAY($AS$2))+COUNTA(_xlfn.ANCHORARRAY($AT$2))=0,"",_xlfn._xlws.SORT(_xlfn.UNIQUE(IF(ROW(INDIRECT("1:"&(COUNTA(_xlfn.ANCHORARRAY($AS$2))+COUNTA(_xlfn.ANCHORARRAY($AT$2)))))<=COUNTA(_xlfn.ANCHORARRAY($AS$2)),INDEX(_xlfn.ANCHORARRAY($AS$2),ROW(INDIRECT("1:"&(COUNTA(_xlfn.ANCHORARRAY($AS$2))+COUNTA(_xlfn.ANCHORARRAY($AT$2)))))),INDEX(_xlfn.ANCHORARRAY($AT$2),ROW(INDIRECT("1:"&(COUNTA(_xlfn.ANCHORARRAY($AS$2))+COUNTA(_xlfn.ANCHORARRAY($AT$2)))))-COUNTA(_xlfn.ANCHORARRAY($AS$2))))),1,1))} -> Adagia, Windswept Bastion | BO2: {=IF(COUNTA(_xlfn.ANCHORARRAY($AU$2))+COUNTA(_xlfn.ANCHORARRAY($AV$2))=0,"",_xlfn._xlws.SORT(_xlfn.UNIQUE(IF(ROW(INDIRECT("1:"&(COUNTA(_xlfn.ANCHORARRAY($AU$2))+COUNTA(_xlfn.ANCHORARRAY($AV$2)))))<=COUNTA(_xlfn.ANCHORARRAY($AU$2)),INDEX(_xlfn.ANCHORARRAY($AU$2),ROW(INDIRECT("1:"&(COUNTA(_xlfn.ANCHORARRAY($AU$2))+COUNTA(_xlfn.ANCHORARRAY($AV$2)))))),INDEX(_xlfn.ANCHORARRAY($AV$2),ROW(INDIRECT("1:"&(COUNTA(_xlfn.ANCHORARRAY($AU$2))+COUNTA(_xlfn.ANCHORARRAY($AV$2)))))-COUNTA(_xlfn.ANCHORARRAY($AU$2))))),1,1))} -> Alchemist's Refuge | BP2: {=IF(COUNTA(_xlfn.ANCHORARRAY($AW$2))+COUNTA(_xlfn.ANCHORARRAY($AX$2))=0,"",_xlfn._xlws.SORT(_xlfn.UNIQUE(IF(ROW(INDIRECT("1:"&(COUNTA(_xlfn.ANCHORARRAY($AW$2))+COUNTA(_xlfn.ANCHORARRAY($AX$2)))))<=COUNTA(_xlfn.ANCHORARRAY($AW$2)),INDEX(_xlfn.ANCHORARRAY($AW$2),ROW(INDIRECT("1:"&(COUNTA(_xlfn.ANCHORARRAY($AW$2))+COUNTA(_xlfn.ANCHORARRAY($AX$2)))))),INDEX(_xlfn.ANCHORARRAY($AX$2),ROW(INDIRECT("1:"&(COUNTA(_xlfn.ANCHORARRAY($AW$2))+COUNTA(_xlfn.ANCHORARRAY($AX$2)))))-COUNTA(_xlfn.ANCHORARRAY($AW$2))))),1,1))} -> Adagia, Windswept Bastion | BQ2: {=IF(COUNTA(_xlfn.ANCHORARRAY($AY$2))+COUNTA(_xlfn.ANCHORARRAY($AZ$2))=0,"",_xlfn._xlws.SORT(_xlfn.UNIQUE(IF(ROW(INDIRECT("1:"&(COUNTA(_xlfn.ANCHORARRAY($AY$2))+COUNTA(_xlfn.ANCHORARRAY($AZ$2)))))<=COUNTA(_xlfn.ANCHORARRAY($AY$2)),INDEX(_xlfn.ANCHORARRAY($AY$2),ROW(INDIRECT("1:"&(COUNTA(_xlfn.ANCHORARRAY($AY$2))+COUNTA(_xlfn.ANCHORARRAY($AZ$2)))))),INDEX(_xlfn.ANCHORARRAY($AZ$2),ROW(INDIRECT("1:"&(COUNTA(_xlfn.ANCHORARRAY($AY$2))+COUNTA(_xlfn.ANCHORARRAY($AZ$2)))))-COUNTA(_xlfn.ANCHORARRAY($AY$2))))),1,1))} -> #REF! | BS2: {=IF(COUNTA(_xlfn.ANCHORARRAY($BB$2))+COUNTA(_xlfn.ANCHORARRAY($BC$2))=0,"",_xlfn._xlws.SORT(_xlfn.UNIQUE(IF(ROW(INDIRECT("1:"&(COUNTA(_xlfn.ANCHORARRAY($BB$2))+COUNTA(_xlfn.ANCHORARRAY($BC$2)))))<=COUNTA(_xlfn.ANCHORARRAY($BB$2)),INDEX(_xlfn.ANCHORARRAY($BB$2),ROW(INDIRECT("1:"&(COUNTA(_xlfn.ANCHORARRAY($BB$2))+COUNTA(_xlfn.ANCHORARRAY($BC$2)))))),INDEX(_xlfn.ANCHORARRAY($BC$2),ROW(INDIRECT("1:"&(COUNTA(_xlfn.ANCHORARRAY($BB$2))+COUNTA(_xlfn.ANCHORARRAY($BC$2)))))-COUNTA(_xlfn.ANCHORARRAY($BB$2))))),1,1))} -> Adarkar Wastes | BT2: {=IF(COUNTA(_xlfn.ANCHORARRAY($BD$2))+COUNTA(_xlfn.ANCHORARRAY($BE$2))=0,"",_xlfn._xlws.SORT(_xlfn.UNIQUE(IF(ROW(INDIRECT("1:"&(COUNTA(_xlfn.ANCHORARRAY($BD$2))+COUNTA(_xlfn.ANCHORARRAY($BE$2)))))<=COUNTA(_xlfn.ANCHORARRAY($BD$2)),INDEX(_xlfn.ANCHORARRAY($BD$2),ROW(INDIRECT("1:"&(COUNTA(_xlfn.ANCHORARRAY($BD$2))+COUNTA(_xlfn.ANCHORARRAY($BE$2)))))),INDEX(_xlfn.ANCHORARRAY($BE$2),ROW(INDIRECT("1:"&(COUNTA(_xlfn.ANCHORARRAY($BD$2))+COUNTA(_xlfn.ANCHORARRAY($BE$2)))))-COUNTA(_xlfn.ANCHORARRAY($BD$2))))),1,1))} -> Access Tunnel | BU2: {=IF(COUNTA(_xlfn.ANCHORARRAY($BF$2))+COUNTA(_xlfn.ANCHORARRAY($BG$2))=0,"",_xlfn._xlws.SORT(_xlfn.UNIQUE(IF(ROW(INDIRECT("1:"&(COUNTA(_xlfn.ANCHORARRAY($BF$2))+COUNTA(_xlfn.ANCHORARRAY($BG$2)))))<=COUNTA(_xlfn.ANCHORARRAY($BF$2)),INDEX(_xlfn.ANCHORARRAY($BF$2),ROW(INDIRECT("1:"&(COUNTA(_xlfn.ANCHORARRAY($BF$2))+COUNTA(_xlfn.ANCHORARRAY($BG$2)))))),INDEX(_xlfn.ANCHORARRAY($BG$2),ROW(INDIRECT("1:"&(COUNTA(_xlfn.ANCHORARRAY($BF$2))+COUNTA(_xlfn.ANCHORARRAY($BG$2)))))-COUNTA(_xlfn.ANCHORARRAY($BF$2))))),1,1))} -> A Joia do Enigma | BV2: {=IF(COUNTA(_xlfn.ANCHORARRAY($BH$2))+COUNTA(_xlfn.ANCHORARRAY($BI$2))=0,"",_xlfn._xlws.SORT(_xlfn.UNIQUE(IF(ROW(INDIRECT("1:"&(COUNTA(_xlfn.ANCHORARRAY($BH$2))+COUNTA(_xlfn.ANCHORARRAY($BI$2)))))<=COUNTA(_xlfn.ANCHORARRAY($BH$2)),INDEX(_xlfn.ANCHORARRAY($BH$2),ROW(INDIRECT("1:"&(COUNTA(_xlfn.ANCHORARRAY($BH$2))+COUNTA(_xlfn.ANCHORARRAY($BI$2)))))),INDEX(_xlfn.ANCHORARRAY($BI$2),ROW(INDIRECT("1:"&(COUNTA(_xlfn.ANCHORARRAY($BH$2))+COUNTA(_xlfn.ANCHORARRAY($BI$2)))))-COUNTA(_xlfn.ANCHORARRAY($BH$2))))),1,1))} -> Arcane Lighthouse | BW2: {=IF(COUNTA(_xlfn.ANCHORARRAY($BJ$2))+COUNTA(_xlfn.ANCHORARRAY($BK$2))=0,"",_xlfn._xlws.SORT(_xlfn.UNIQUE(IF(ROW(INDIRECT("1:"&(COUNTA(_xlfn.ANCHORARRAY($BJ$2))+COUNTA(_xlfn.ANCHORARRAY($BK$2)))))<=COUNTA(_xlfn.ANCHORARRAY($BJ$2)),INDEX(_xlfn.ANCHORARRAY($BJ$2),ROW(INDIRECT("1:"&(COUNTA(_xlfn.ANCHORARRAY($BJ$2))+COUNTA(_xlfn.ANCHORARRAY($BK$2)))))),INDEX(_xlfn.ANCHORARRAY($BK$2),ROW(INDIRECT("1:"&(COUNTA(_xlfn.ANCHORARRAY($BJ$2))+COUNTA(_xlfn.ANCHORARRAY($BK$2)))))-COUNTA(_xlfn.ANCHORARRAY($BJ$2))))),1,1))} -> Alchemist's Refuge | BX2: {=IF(COUNTA(_xlfn.ANCHORARRAY($BL$2))+COUNTA(_xlfn.ANCHORARRAY($BM$2))=0,"",_xlfn._xlws.SORT(_xlfn.UNIQUE(IF(ROW(INDIRECT("1:"&(COUNTA(_xlfn.ANCHORARRAY($BL$2))+COUNTA(_xlfn.ANCHORARRAY($BM$2)))))<=COUNTA(_xlfn.ANCHORARRAY($BL$2)),INDEX(_xlfn.ANCHORARRAY($BL$2),ROW(INDIRECT("1:"&(COUNTA(_xlfn.ANCHORARRAY($BL$2))+COUNTA(_xlfn.ANCHORARRAY($BM$2)))))),INDEX(_xlfn.ANCHORARRAY($BM$2),ROW(INDIRECT("1:"&(COUNTA(_xlfn.ANCHORARRAY($BL$2))+COUNTA(_xlfn.ANCHORARRAY($BM$2)))))-COUNTA(_xlfn.ANCHORARRAY($BL$2))))),1,1))} -> Adagia, Windswept Bastion | BY2: {=IF(COUNTA(_xlfn.ANCHORARRAY($BN$2))+COUNTA(_xlfn.ANCHORARRAY($BO$2))=0,"",_xlfn._xlws.SORT(_xlfn.UNIQUE(IF(ROW(INDIRECT("1:"&(COUNTA(_xlfn.ANCHORARRAY($BN$2))+COUNTA(_xlfn.ANCHORARRAY($BO$2)))))<=COUNTA(_xlfn.ANCHORARRAY($BN$2)),INDEX(_xlfn.ANCHORARRAY($BN$2),ROW(INDIRECT("1:"&(COUNTA(_xlfn.ANCHORARRAY($BN$2))+COUNTA(_xlfn.ANCHORARRAY($BO$2)))))),INDEX(_xlfn.ANCHORARRAY($BO$2),ROW(INDIRECT("1:"&(COUNTA(_xlfn.ANCHORARRAY($BN$2))+COUNTA(_xlfn.ANCHORARRAY($BO$2)))))-COUNTA(_xlfn.ANCHORARRAY($BN$2))))),1,1))} -> Adagia, Windswept Bastion | BZ2: {=IF(COUNTA(_xlfn.ANCHORARRAY($BP$2))+COUNTA(_xlfn.ANCHORARRAY($BQ$2))=0,"",_xlfn._xlws.SORT(_xlfn.UNIQUE(IF(ROW(INDIRECT("1:"&(COUNTA(_xlfn.ANCHORARRAY($BP$2))+COUNTA(_xlfn.ANCHORARRAY($BQ$2)))))<=COUNTA(_xlfn.ANCHORARRAY($BP$2)),INDEX(_xlfn.ANCHORARRAY($BP$2),ROW(INDIRECT("1:"&(COUNTA(_xlfn.ANCHORARRAY($BP$2))+COUNTA(_xlfn.ANCHORARRAY($BQ$2)))))),INDEX(_xlfn.ANCHORARRAY($BQ$2),ROW(INDIRECT("1:"&(COUNTA(_xlfn.ANCHORARRAY($BP$2))+COUNTA(_xlfn.ANCHORARRAY($BQ$2)))))-COUNTA(_xlfn.ANCHORARRAY($BP$2))))),1,1))} -> Adagia, Windswept Bastion | CB2: {=IF(COUNTA(_xlfn.ANCHORARRAY($BS$2))+COUNTA(_xlfn.ANCHORARRAY($BT$2))=0,"",_xlfn._xlws.SORT(_xlfn.UNIQUE(IF(ROW(INDIRECT("1:"&(COUNTA(_xlfn.ANCHORARRAY($BS$2))+COUNTA(_xlfn.ANCHORARRAY($BT$2)))))<=COUNTA(_xlfn.ANCHORARRAY($BS$2)),INDEX(_xlfn.ANCHORARRAY($BS$2),ROW(INDIRECT("1:"&(COUNTA(_xlfn.ANCHORARRAY($BS$2))+COUNTA(_xlfn.ANCHORARRAY($BT$2)))))),INDEX(_xlfn.ANCHORARRAY($BT$2),ROW(INDIRECT("1:"&(COUNTA(_xlfn.ANCHORARRAY($BS$2))+COUNTA(_xlfn.ANCHORARRAY($BT$2)))))-COUNTA(_xlfn.ANCHORARRAY($BS$2))))),1,1))} -> Access Tunnel | CC2: {=IF(COUNTA(_xlfn.ANCHORARRAY($BU$2))+COUNTA(_xlfn.ANCHORARRAY($BV$2))=0,"",_xlfn._xlws.SORT(_xlfn.UNIQUE(IF(ROW(INDIRECT("1:"&(COUNTA(_xlfn.ANCHORARRAY($BU$2))+COUNTA(_xlfn.ANCHORARRAY($BV$2)))))<=COUNTA(_xlfn.ANCHORARRAY($BU$2)),INDEX(_xlfn.ANCHORARRAY($BU$2),ROW(INDIRECT("1:"&(COUNTA(_xlfn.ANCHORARRAY($BU$2))+COUNTA(_xlfn.ANCHORARRAY($BV$2)))))),INDEX(_xlfn.ANCHORARRAY($BV$2),ROW(INDIRECT("1:"&(COUNTA(_xlfn.ANCHORARRAY($BU$2))+COUNTA(_xlfn.ANCHORARRAY($BV$2)))))-COUNTA(_xlfn.ANCHORARRAY($BU$2))))),1,1))} -> A Joia do Enigma | CD2: {=IF(COUNTA(_xlfn.ANCHORARRAY($BW$2))+COUNTA(_xlfn.ANCHORARRAY($BX$2))=0,"",_xlfn._xlws.SORT(_xlfn.UNIQUE(IF(ROW(INDIRECT("1:"&(COUNTA(_xlfn.ANCHORARRAY($BW$2))+COUNTA(_xlfn.ANCHORARRAY($BX$2)))))<=COUNTA(_xlfn.ANCHORARRAY($BW$2)),INDEX(_xlfn.ANCHORARRAY($BW$2),ROW(INDIRECT("1:"&(COUNTA(_xlfn.ANCHORARRAY($BW$2))+COUNTA(_xlfn.ANCHORARRAY($BX$2)))))),INDEX(_xlfn.ANCHORARRAY($BX$2),ROW(INDIRECT("1:"&(COUNTA(_xlfn.ANCHORARRAY($BW$2))+COUNTA(_xlfn.ANCHORARRAY($BX$2)))))-COUNTA(_xlfn.ANCHORARRAY($BW$2))))),1,1))} -> Adagia, Windswept Bastion | CE2: {=IF(COUNTA(_xlfn.ANCHORARRAY($BY$2))+COUNTA(_xlfn.ANCHORARRAY($BZ$2))=0,"",_xlfn._xlws.SORT(_xlfn.UNIQUE(IF(ROW(INDIRECT("1:"&(COUNTA(_xlfn.ANCHORARRAY($BY$2))+COUNTA(_xlfn.ANCHORARRAY($BZ$2)))))<=COUNTA(_xlfn.ANCHORARRAY($BY$2)),INDEX(_xlfn.ANCHORARRAY($BY$2),ROW(INDIRECT("1:"&(COUNTA(_xlfn.ANCHORARRAY($BY$2))+COUNTA(_xlfn.ANCHORARRAY($BZ$2)))))),INDEX(_xlfn.ANCHORARRAY($BZ$2),ROW(INDIRECT("1:"&(COUNTA(_xlfn.ANCHORARRAY($BY$2))+COUNTA(_xlfn.ANCHORARRAY($BZ$2)))))-COUNTA(_xlfn.ANCHORARRAY($BY$2))))),1,1))} -> Adagia, Windswept Bastion | CG2: {=IF(COUNTA(_xlfn.ANCHORARRAY($CB$2))+COUNTA(_xlfn.ANCHORARRAY($CC$2))=0,"",_xlfn._xlws.SORT(_xlfn.UNIQUE(IF(ROW(INDIRECT("1:"&(COUNTA(_xlfn.ANCHORARRAY($CB$2))+COUNTA(_xlfn.ANCHORARRAY($CC$2)))))<=COUNTA(_xlfn.ANCHORARRAY($CB$2)),INDEX(_xlfn.ANCHORARRAY($CB$2),ROW(INDIRECT("1:"&(COUNTA(_xlfn.ANCHORARRAY($CB$2))+COUNTA(_xlfn.ANCHORARRAY($CC$2)))))),INDEX(_xlfn.ANCHORARRAY($CC$2),ROW(INDIRECT("1:"&(COUNTA(_xlfn.ANCHORARRAY($CB$2))+COUNTA(_xlfn.ANCHORARRAY($CC$2)))))-COUNTA(_xlfn.ANCHORARRAY($CB$2))))),1,1))} -> A Joia do Enigma | CH2: {=IF(COUNTA(_xlfn.ANCHORARRAY($CD$2))+COUNTA(_xlfn.ANCHORARRAY($CE$2))=0,"",_xlfn._xlws.SORT(_xlfn.UNIQUE(IF(ROW(INDIRECT("1:"&(COUNTA(_xlfn.ANCHORARRAY($CD$2))+COUNTA(_xlfn.ANCHORARRAY($CE$2)))))<=COUNTA(_xlfn.ANCHORARRAY($CD$2)),INDEX(_xlfn.ANCHORARRAY($CD$2),ROW(INDIRECT("1:"&(COUNTA(_xlfn.ANCHORARRAY($CD$2))+COUNTA(_xlfn.ANCHORARRAY($CE$2)))))),INDEX(_xlfn.ANCHORARRAY($CE$2),ROW(INDIRECT("1:"&(COUNTA(_xlfn.ANCHORARRAY($CD$2))+COUNTA(_xlfn.ANCHORARRAY($CE$2)))))-COUNTA(_xlfn.ANCHORARRAY($CD$2))))),1,1))} -> Adagia, Windswept Bastion | CJ2: {=IF(COUNTA(_xlfn.ANCHORARRAY($CG$2))+COUNTA(_xlfn.ANCHORARRAY($CH$2))=0,"",_xlfn._xlws.SORT(_xlfn.UNIQUE(IF(ROW(INDIRECT("1:"&(COUNTA(_xlfn.ANCHORARRAY($CG$2))+COUNTA(_xlfn.ANCHORARRAY($CH$2)))))<=COUNTA(_xlfn.ANCHORARRAY($CG$2)),INDEX(_xlfn.ANCHORARRAY($CG$2),ROW(INDIRECT("1:"&(COUNTA(_xlfn.ANCHORARRAY($CG$2))+COUNTA(_xlfn.ANCHORARRAY($CH$2)))))),INDEX(_xlfn.ANCHORARRAY($CH$2),ROW(INDIRECT("1:"&(COUNTA(_xlfn.ANCHORARRAY($CG$2))+COUNTA(_xlfn.ANCHORARRAY($CH$2)))))-COUNTA(_xlfn.ANCHORARRAY($CG$2))))),1,1))} -> A Joia do Enigma
A3: =IFERROR(INDEX($S$3:$S$200, MATCH($C3, $I$3:$I$200, 0)), "") -> 2 | B3: =COUNTIF(U:AX,G3) -> 1 | C3: =IFERROR( INDEX($U$1:$AX$1, MATCH(TRUE, CHOOSE({1;2;3;4;5;6;7;8;9;10;11;12;13;14;15;16;17;18;19;20;21;22;23;24;25;26;27;28;29;30;31;32}, COUNTIFS($U$2:$U$200,$G3)>0, COUNTIFS($V$2:$V$200,$G3)>0, COUNTIFS($W$2:$W$200,$G3)>0, COUNTIFS($X$2:$X$200,$G3)>0, COUNTIFS($Y$2:$Y$200,$G3)>0, COUNTIFS($Z$2:$Z$200,$G3)>0, COUNTIFS($AA$2:$AA$200,$G3)>0, COUNTIFS($AB$2:$AB$200,$G3)>0, COUNTIFS($AC$2:$AC$200,$G3)>0, COUNTIFS($AD$2:$AD$200,$G3)>0, COUNTIFS($AE$2:$AE$200,$G3)>0, COUNTIFS($AF$2:$AF$200,$G3)>0, COUNTIFS($AG$2:$AG$200,$G3)>0, COUNTIFS($AH$2:$AH$200,$G3)>0, COUNTIFS($AI$2:$AI$200,$G3)>0, COUNTIFS($AJ$2:$AJ$200,$G3)>0, COUNTIFS($AK$2:$AK$200,$G3)>0, COUNTIFS($AL$2:$AL$200,$G3)>0, COUNTIFS($AM$2:$AM$200,$G3)>0, COUNTIFS($AN$2:$AN$200,$G3)>0, COUNTIFS($AO$2:$AO$200,$G3)>0, COUNTIFS($AP$2:$AP$200,$G3)>0, COUNTIFS($AQ$2:$AQ$200,$G3)>0, COUNTIFS($AR$2:$AR$200,$G3)>0, COUNTIFS($AS$2:$AS$200,$G3)>0, COUNTIFS($AT$2:$AT$200,$G3)>0, COUNTIFS($AU$2:$AU$200,$G3)>0, COUNTIFS($AV$2:$AV$200,$G3)>0, COUNTIFS($AW$2:$AW$200,$G3)>0, COUNTIFS($AX$2:$AX$200,$G3)>0 ), 0) ), "") -> Rani | D3: {=IFERROR( INDEX( _xlfn._xlws.FILTER($U$1:$AX$1, TRANSPOSE( CHOOSE({1;2;3;4;5;6;7;8;9;10;11;12;13;14;15;16;17;18;19;20;21;22;23;24;25;26;27;28;29;30}, COUNTIFS($U$2:$U$200,$G3)>0, COUNTIFS($V$2:$V$200,$G3)>0, COUNTIFS($W$2:$W$200,$G3)>0, COUNTIFS($X$2:$X$200,$G3)>0, COUNTIFS($Y$2:$Y$200,$G3)>0, COUNTIFS($Z$2:$Z$200,$G3)>0, COUNTIFS($AA$2:$AA$200,$G3)>0, COUNTIFS($AB$2:$AB$200,$G3)>0, COUNTIFS($AC$2:$AC$200,$G3)>0, COUNTIFS($AD$2:$AD$200,$G3)>0, COUNTIFS($AE$2:$AE$200,$G3)>0, COUNTIFS($AF$2:$AF$200,$G3)>0, COUNTIFS($AG$2:$AG$200,$G3)>0, COUNTIFS($AH$2:$AH$200,$G3)>0, COUNTIFS($AI$2:$AI$200,$G3)>0, COUNTIFS($AJ$2:$AJ$200,$G3)>0, COUNTIFS($AK$2:$AK$200,$G3)>0, COUNTIFS($AL$2:$AL$200,$G3)>0, COUNTIFS($AM$2:$AM$200,$G3)>0, COUNTIFS($AN$2:$AN$200,$G3)>0, COUNTIFS($AO$2:$AO$200,$G3)>0, COUNTIFS($AP$2:$AP$200,$G3)>0, COUNTIFS($AQ$2:$AQ$200,$G3)>0, COUNTIFS($AR$2:$AR$200,$G3)>0, COUNTIFS($AS$2:$AS$200,$G3)>0, COUNTIFS($AT$2:$AT$200,$G3)>0, COUNTIFS($AU$2:$AU$200,$G3)>0, COUNTIFS($AV$2:$AV$200,$G3)>0, COUNTIFS($AW$2:$AW$200,$G3)>0, COUNTIFS($AX$2:$AX$200,$G3)>0 )), ), 2 ), "")} | E3: {=IFERROR( INDEX( _xlfn._xlws.FILTER($U$1:$AX$1, TRANSPOSE( CHOOSE({1;2;3;4;5;6;7;8;9;10;11;12;13;14;15;16;17;18;19;20;21;22;23;24;25;26;27;28;29;30}, COUNTIFS($U$2:$U$200,$G3)>0, COUNTIFS($V$2:$V$200,$G3)>0, COUNTIFS($W$2:$W$200,$G3)>0, COUNTIFS($X$2:$X$200,$G3)>0, COUNTIFS($Y$2:$Y$200,$G3)>0, COUNTIFS($Z$2:$Z$200,$G3)>0, COUNTIFS($AA$2:$AA$200,$G3)>0, COUNTIFS($AB$2:$AB$200,$G3)>0, COUNTIFS($AC$2:$AC$200,$G3)>0, COUNTIFS($AD$2:$AD$200,$G3)>0, COUNTIFS($AE$2:$AE$200,$G3)>0, COUNTIFS($AF$2:$AF$200,$G3)>0, COUNTIFS($AG$2:$AG$200,$G3)>0, COUNTIFS($AH$2:$AH$200,$G3)>0, COUNTIFS($AI$2:$AI$200,$G3)>0, COUNTIFS($AJ$2:$AJ$200,$G3)>0, COUNTIFS($AK$2:$AK$200,$G3)>0, COUNTIFS($AL$2:$AL$200,$G3)>0, COUNTIFS($AM$2:$AM$200,$G3)>0, COUNTIFS($AN$2:$AN$200,$G3)>0, COUNTIFS($AO$2:$AO$200,$G3)>0, COUNTIFS($AP$2:$AP$200,$G3)>0, COUNTIFS($AQ$2:$AQ$200,$G3)>0, COUNTIFS($AR$2:$AR$200,$G3)>0, COUNTIFS($AS$2:$AS$200,$G3)>0, COUNTIFS($AT$2:$AT$200,$G3)>0, COUNTIFS($AU$2:$AU$200,$G3)>0, COUNTIFS($AV$2:$AV$200,$G3)>0, COUNTIFS($AW$2:$AW$200,$G3)>0, COUNTIFS($AX$2:$AX$200,$G3)>0 )), ), 3 ), "")} | F3: {=IFERROR( INDEX( _xlfn._xlws.FILTER($U$1:$AX$1, TRANSPOSE( CHOOSE({1;2;3;4;5;6;7;8;9;10;11;12;13;14;15;16;17;18;19;20;21;22;23;24;25;26;27;28;29;30}, COUNTIFS($U$2:$U$200,$G3)>0, COUNTIFS($V$2:$V$200,$G3)>0, COUNTIFS($W$2:$W$200,$G3)>0, COUNTIFS($X$2:$X$200,$G3)>0, COUNTIFS($Y$2:$Y$200,$G3)>0, COUNTIFS($Z$2:$Z$200,$G3)>0, COUNTIFS($AA$2:$AA$200,$G3)>0, COUNTIFS($AB$2:$AB$200,$G3)>0, COUNTIFS($AC$2:$AC$200,$G3)>0, COUNTIFS($AD$2:$AD$200,$G3)>0, COUNTIFS($AE$2:$AE$200,$G3)>0, COUNTIFS($AF$2:$AF$200,$G3)>0, COUNTIFS($AG$2:$AG$200,$G3)>0, COUNTIFS($AH$2:$AH$200,$G3)>0, COUNTIFS($AI$2:$AI$200,$G3)>0, COUNTIFS($AJ$2:$AJ$200,$G3)>0, COUNTIFS($AK$2:$AK$200,$G3)>0, COUNTIFS($AL$2:$AL$200,$G3)>0, COUNTIFS($AM$2:$AM$200,$G3)>0, COUNTIFS($AN$2:$AN$200,$G3)>0, COUNTIFS($AO$2:$AO$200,$G3)>0, COUNTIFS($AP$2:$AP$200,$G3)>0, COUNTIFS($AQ$2:$AQ$200,$G3)>0, COUNTIFS($AR$2:$AR$200,$G3)>0, COUNTIFS($AS$2:$AS$200,$G3)>0, COUNTIFS($AT$2:$AT$200,$G3)>0, COUNTIFS($AU$2:$AU$200,$G3)>0, COUNTIFS($AV$2:$AV$200,$G3)>0, COUNTIFS($AW$2:$AW$200,$G3)>0, COUNTIFS($AX$2:$AX$200,$G3)>0 )), ), 4 ), "")} | G3: Access Tunnel | I3: Narset | J3: =Narset!G2 -> 29 | K3: Sim | L3: Sim | M3: Sim | N3: Não | O3: Não | P3: Mill | Q3: Combate | R3: Mill e Tokens | S3: =IF(J3<6,"5",IF(J3<11,"4",IF(J3<16,"3",IF(J3<31,"2","1")))) -> 2 | U3: Bojuka Bog | V3: Aura Mutation | W3: Aligned Heart | X3: Arwen, Weaver of Hope | Y3: Autoridade dos Cônsules | Z3: Bojuka Bog | AA3: Call to the Kindred | AB3: Grave Pact | AC3: Kozilek, the Broken Reality | AD3: Crisol dos Mundos | AE3: Chimil, o Sol Interior | AF3: Arid Mesa | AG3: Drowned Catacomb | AH3: Bojuka Bog | AI3: Cloud, Midgar Mercenary | AJ3: Elspeth, Sun's Champion | AK3: Obelisco de Obsidiana | AL3: Dionus, Elvish Archdruid | AM3: Mistrise Village | AN3: Jetmir's Garden | AO3: Baral, Chief of Compliance | AP3: Jidoor, Aristocratic Capital // Overture | AQ3: Chandra's Ignition | AR3: Daretti, Ingenious Iconoclast | AS3: Illustrious Wanderglyph | AT3: Lagoa Espelhada | AU3: Teyo, Geometric Tactician | AV3: Emergency Eject | AX3: Ancient Den | BB3: Aura Mutation | BC3: Aligned Heart | BD3: Ascensão do Avernus | BE3: Beast Within | BF3: Crisol dos Mundos | BG3: Amphibian Downpour | BH3: Bojuka Bog | BI3: Cloud, Midgar Mercenary | BJ3: Dionus, Elvish Archdruid | BK3: Emrakul, um Novo Mundo | BL3: Baral, Chief of Compliance | BM3: Bugenhagen, Wise Elder | BN3: Dollmaker's Shop // Porcelain Gallery | BO3: Árbitro Silencioso | BP3: Ancient Den | BS3: Aligned Heart | BT3: Ancient Greenwarden | BU3: Amphibian Downpour | BV3: Bojuka Bog | BW3: Caverna das Almas | BX3: Afundar em Estupor | BY3: Alchemist's Refuge | BZ3: Ancient Den | CB3: Adarkar Wastes | CC3: Amphibian Downpour | CD3: Afundar em Estupor | CE3: Alchemist's Refuge | CG3: Access Tunnel | CH3: Afundar em Estupor | CJ3: Access Tunnel
A4: =IFERROR(INDEX($S$3:$S$200, MATCH($C4, $I$3:$I$200, 0)), "") -> 5 | B4: =COUNTIF(U:AX,G4) -> 3 | C4: =IFERROR( INDEX($U$1:$AX$1, MATCH(TRUE, CHOOSE({1;2;3;4;5;6;7;8;9;10;11;12;13;14;15;16;17;18;19;20;21;22;23;24;25;26;27;28;29;30;31;32}, COUNTIFS($U$2:$U$200,$G4)>0, COUNTIFS($V$2:$V$200,$G4)>0, COUNTIFS($W$2:$W$200,$G4)>0, COUNTIFS($X$2:$X$200,$G4)>0, COUNTIFS($Y$2:$Y$200,$G4)>0, COUNTIFS($Z$2:$Z$200,$G4)>0, COUNTIFS($AA$2:$AA$200,$G4)>0, COUNTIFS($AB$2:$AB$200,$G4)>0, COUNTIFS($AC$2:$AC$200,$G4)>0, COUNTIFS($AD$2:$AD$200,$G4)>0, COUNTIFS($AE$2:$AE$200,$G4)>0, COUNTIFS($AF$2:$AF$200,$G4)>0, COUNTIFS($AG$2:$AG$200,$G4)>0, COUNTIFS($AH$2:$AH$200,$G4)>0, COUNTIFS($AI$2:$AI$200,$G4)>0, COUNTIFS($AJ$2:$AJ$200,$G4)>0, COUNTIFS($AK$2:$AK$200,$G4)>0, COUNTIFS($AL$2:$AL$200,$G4)>0, COUNTIFS($AM$2:$AM$200,$G4)>0, COUNTIFS($AN$2:$AN$200,$G4)>0, COUNTIFS($AO$2:$AO$200,$G4)>0, COUNTIFS($AP$2:$AP$200,$G4)>0, COUNTIFS($AQ$2:$AQ$200,$G4)>0, COUNTIFS($AR$2:$AR$200,$G4)>0, COUNTIFS($AS$2:$AS$200,$G4)>0, COUNTIFS($AT$2:$AT$200,$G4)>0, COUNTIFS($AU$2:$AU$200,$G4)>0, COUNTIFS($AV$2:$AV$200,$G4)>0, COUNTIFS($AW$2:$AW$200,$G4)>0, COUNTIFS($AX$2:$AX$200,$G4)>0 ), 0) ), "") -> Breya | D4: {=IFERROR( INDEX( _xlfn._xlws.FILTER($U$1:$AX$1, TRANSPOSE( CHOOSE({1;2;3;4;5;6;7;8;9;10;11;12;13;14;15;16;17;18;19;20;21;22;23;24;25;26;27;28;29;30}, COUNTIFS($U$2:$U$200,$G4)>0, COUNTIFS($V$2:$V$200,$G4)>0, COUNTIFS($W$2:$W$200,$G4)>0, COUNTIFS($X$2:$X$200,$G4)>0, COUNTIFS($Y$2:$Y$200,$G4)>0, COUNTIFS($Z$2:$Z$200,$G4)>0, COUNTIFS($AA$2:$AA$200,$G4)>0, COUNTIFS($AB$2:$AB$200,$G4)>0, COUNTIFS($AC$2:$AC$200,$G4)>0, COUNTIFS($AD$2:$AD$200,$G4)>0, COUNTIFS($AE$2:$AE$200,$G4)>0, COUNTIFS($AF$2:$AF$200,$G4)>0, COUNTIFS($AG$2:$AG$200,$G4)>0, COUNTIFS($AH$2:$AH$200,$G4)>0, COUNTIFS($AI$2:$AI$200,$G4)>0, COUNTIFS($AJ$2:$AJ$200,$G4)>0, COUNTIFS($AK$2:$AK$200,$G4)>0, COUNTIFS($AL$2:$AL$200,$G4)>0, COUNTIFS($AM$2:$AM$200,$G4)>0, COUNTIFS($AN$2:$AN$200,$G4)>0, COUNTIFS($AO$2:$AO$200,$G4)>0, COUNTIFS($AP$2:$AP$200,$G4)>0, COUNTIFS($AQ$2:$AQ$200,$G4)>0, COUNTIFS($AR$2:$AR$200,$G4)>0, COUNTIFS($AS$2:$AS$200,$G4)>0, COUNTIFS($AT$2:$AT$200,$G4)>0, COUNTIFS($AU$2:$AU$200,$G4)>0, COUNTIFS($AV$2:$AV$200,$G4)>0, COUNTIFS($AW$2:$AW$200,$G4)>0, COUNTIFS($AX$2:$AX$200,$G4)>0 )), ), 2 ), "")} -> Alela | E4: {=IFERROR( INDEX( _xlfn._xlws.FILTER($U$1:$AX$1, TRANSPOSE( CHOOSE({1;2;3;4;5;6;7;8;9;10;11;12;13;14;15;16;17;18;19;20;21;22;23;24;25;26;27;28;29;30}, COUNTIFS($U$2:$U$200,$G4)>0, COUNTIFS($V$2:$V$200,$G4)>0, COUNTIFS($W$2:$W$200,$G4)>0, COUNTIFS($X$2:$X$200,$G4)>0, COUNTIFS($Y$2:$Y$200,$G4)>0, COUNTIFS($Z$2:$Z$200,$G4)>0, COUNTIFS($AA$2:$AA$200,$G4)>0, COUNTIFS($AB$2:$AB$200,$G4)>0, COUNTIFS($AC$2:$AC$200,$G4)>0, COUNTIFS($AD$2:$AD$200,$G4)>0, COUNTIFS($AE$2:$AE$200,$G4)>0, COUNTIFS($AF$2:$AF$200,$G4)>0, COUNTIFS($AG$2:$AG$200,$G4)>0, COUNTIFS($AH$2:$AH$200,$G4)>0, COUNTIFS($AI$2:$AI$200,$G4)>0, COUNTIFS($AJ$2:$AJ$200,$G4)>0, COUNTIFS($AK$2:$AK$200,$G4)>0, COUNTIFS($AL$2:$AL$200,$G4)>0, COUNTIFS($AM$2:$AM$200,$G4)>0, COUNTIFS($AN$2:$AN$200,$G4)>0, COUNTIFS($AO$2:$AO$200,$G4)>0, COUNTIFS($AP$2:$AP$200,$G4)>0, COUNTIFS($AQ$2:$AQ$200,$G4)>0, COUNTIFS($AR$2:$AR$200,$G4)>0, COUNTIFS($AS$2:$AS$200,$G4)>0, COUNTIFS($AT$2:$AT$200,$G4)>0, COUNTIFS($AU$2:$AU$200,$G4)>0, COUNTIFS($AV$2:$AV$200,$G4)>0, COUNTIFS($AW$2:$AW$200,$G4)>0, COUNTIFS($AX$2:$AX$200,$G4)>0 )), ), 3 ), "")} -> Modular | F4: {=IFERROR( INDEX( _xlfn._xlws.FILTER($U$1:$AX$1, TRANSPOSE( CHOOSE({1;2;3;4;5;6;7;8;9;10;11;12;13;14;15;16;17;18;19;20;21;22;23;24;25;26;27;28;29;30}, COUNTIFS($U$2:$U$200,$G4)>0, COUNTIFS($V$2:$V$200,$G4)>0, COUNTIFS($W$2:$W$200,$G4)>0, COUNTIFS($X$2:$X$200,$G4)>0, COUNTIFS($Y$2:$Y$200,$G4)>0, COUNTIFS($Z$2:$Z$200,$G4)>0, COUNTIFS($AA$2:$AA$200,$G4)>0, COUNTIFS($AB$2:$AB$200,$G4)>0, COUNTIFS($AC$2:$AC$200,$G4)>0, COUNTIFS($AD$2:$AD$200,$G4)>0, COUNTIFS($AE$2:$AE$200,$G4)>0, COUNTIFS($AF$2:$AF$200,$G4)>0, COUNTIFS($AG$2:$AG$200,$G4)>0, COUNTIFS($AH$2:$AH$200,$G4)>0, COUNTIFS($AI$2:$AI$200,$G4)>0, COUNTIFS($AJ$2:$AJ$200,$G4)>0, COUNTIFS($AK$2:$AK$200,$G4)>0, COUNTIFS($AL$2:$AL$200,$G4)>0, COUNTIFS($AM$2:$AM$200,$G4)>0, COUNTIFS($AN$2:$AN$200,$G4)>0, COUNTIFS($AO$2:$AO$200,$G4)>0, COUNTIFS($AP$2:$AP$200,$G4)>0, COUNTIFS($AQ$2:$AQ$200,$G4)>0, COUNTIFS($AR$2:$AR$200,$G4)>0, COUNTIFS($AS$2:$AS$200,$G4)>0, COUNTIFS($AT$2:$AT$200,$G4)>0, COUNTIFS($AU$2:$AU$200,$G4)>0, COUNTIFS($AV$2:$AV$200,$G4)>0, COUNTIFS($AW$2:$AW$200,$G4)>0, COUNTIFS($AX$2:$AX$200,$G4)>0 )), ), 4 ), "")} | G4: Adagia, Windswept Bastion | I4: Baylen | J4: =Baylen!G2 -> 27 | K4: Sim | L4: Não | M4: Sim | N4: Não | O4: Sim | P4: Voltron | Q4: Combate | R4: Muitos Tokens | S4: =IF(J4<6,"5",IF(J4<11,"4",IF(J4<16,"3",IF(J4<31,"2","1")))) -> 2 | U4: Broadside Bombardiers | V4: Boros Charm | W4: Clifftop Retreat | X4: Cankerbloom | Y4: Bojuka Bog | Z4: Bothersome Quasit | AA4: Deeproot Historian | AB4: Horizon Explorer | AC4: Mistrise Village | AD4: Delighted Halfling | AE4: Extinguisher Battleship | AF4: Batwing Brume | AG4: Faerie Slumber Party | AH4: Burnt Offering | AI4: Espada da Riqueza e do Poder | AJ4: Freyalise, Llanowar's Fury | AK4: Shaku da Honra Desgastada | AL4: Evendo, Waking Haven | AM4: Planetary Annihilation | AN4: Raffine's Tower | AO4: Careful Study | AP4: Scour for Scrap | AQ4: High-Society Hunter | AR4: Reflecting Pool | AS4: Scattered Groves | AT4: Olho de Ojer Taq | AV4: Homeward Path | AX4: Arcbound Fiend | BB4: Back in Town | BC4: Ardbert, Warrior of Darkness | BD4: Autoridade dos Cônsules | BE4: Call to the Kindred | BF4: Delighted Halfling | BG4: Arid Mesa | BH4: Burnt Offering | BI4: Commodore Guff | BJ4: Evendo, Waking Haven | BK4: Jetmir's Garden | BL4: Careful Study | BM4: Chandra's Ignition | BN4: Illustrious Wanderglyph | BO4: Emergency Eject | BP4: Arcbound Fiend | BS4: Ardbert, Warrior of Darkness | BT4: Ascensão do Avernus | BU4: Ancient Tomb | BV4: Burnt Offering | BW4: Dionus, Elvish Archdruid | BX4: Baral, Chief of Compliance | BY4: Árbitro Silencioso | BZ4: Arcbound Fiend | CB4: Aligned Heart | CC4: Ancient Tomb | CD4: Alchemist's Refuge | CE4: Ancient Den | CG4: Adarkar Wastes | CH4: Alchemist's Refuge | CJ4: Adagia, Windswept Bastion
A5: =IFERROR(INDEX($S$3:$S$200, MATCH($C5, $I$3:$I$200, 0)), "") -> 2 | B5: =COUNTIF(U:AX,G5) -> 1 | C5: =IFERROR( INDEX($U$1:$AX$1, MATCH(TRUE, CHOOSE({1;2;3;4;5;6;7;8;9;10;11;12;13;14;15;16;17;18;19;20;21;22;23;24;25;26;27;28;29;30;31;32}, COUNTIFS($U$2:$U$200,$G5)>0, COUNTIFS($V$2:$V$200,$G5)>0, COUNTIFS($W$2:$W$200,$G5)>0, COUNTIFS($X$2:$X$200,$G5)>0, COUNTIFS($Y$2:$Y$200,$G5)>0, COUNTIFS($Z$2:$Z$200,$G5)>0, COUNTIFS($AA$2:$AA$200,$G5)>0, COUNTIFS($AB$2:$AB$200,$G5)>0, COUNTIFS($AC$2:$AC$200,$G5)>0, COUNTIFS($AD$2:$AD$200,$G5)>0, COUNTIFS($AE$2:$AE$200,$G5)>0, COUNTIFS($AF$2:$AF$200,$G5)>0, COUNTIFS($AG$2:$AG$200,$G5)>0, COUNTIFS($AH$2:$AH$200,$G5)>0, COUNTIFS($AI$2:$AI$200,$G5)>0, COUNTIFS($AJ$2:$AJ$200,$G5)>0, COUNTIFS($AK$2:$AK$200,$G5)>0, COUNTIFS($AL$2:$AL$200,$G5)>0, COUNTIFS($AM$2:$AM$200,$G5)>0, COUNTIFS($AN$2:$AN$200,$G5)>0, COUNTIFS($AO$2:$AO$200,$G5)>0, COUNTIFS($AP$2:$AP$200,$G5)>0, COUNTIFS($AQ$2:$AQ$200,$G5)>0, COUNTIFS($AR$2:$AR$200,$G5)>0, COUNTIFS($AS$2:$AS$200,$G5)>0, COUNTIFS($AT$2:$AT$200,$G5)>0, COUNTIFS($AU$2:$AU$200,$G5)>0, COUNTIFS($AV$2:$AV$200,$G5)>0, COUNTIFS($AW$2:$AW$200,$G5)>0, COUNTIFS($AX$2:$AX$200,$G5)>0 ), 0) ), "") -> Narset | D5: {=IFERROR( INDEX( _xlfn._xlws.FILTER($U$1:$AX$1, TRANSPOSE( CHOOSE({1;2;3;4;5;6;7;8;9;10;11;12;13;14;15;16;17;18;19;20;21;22;23;24;25;26;27;28;29;30}, COUNTIFS($U$2:$U$200,$G5)>0, COUNTIFS($V$2:$V$200,$G5)>0, COUNTIFS($W$2:$W$200,$G5)>0, COUNTIFS($X$2:$X$200,$G5)>0, COUNTIFS($Y$2:$Y$200,$G5)>0, COUNTIFS($Z$2:$Z$200,$G5)>0, COUNTIFS($AA$2:$AA$200,$G5)>0, COUNTIFS($AB$2:$AB$200,$G5)>0, COUNTIFS($AC$2:$AC$200,$G5)>0, COUNTIFS($AD$2:$AD$200,$G5)>0, COUNTIFS($AE$2:$AE$200,$G5)>0, COUNTIFS($AF$2:$AF$200,$G5)>0, COUNTIFS($AG$2:$AG$200,$G5)>0, COUNTIFS($AH$2:$AH$200,$G5)>0, COUNTIFS($AI$2:$AI$200,$G5)>0, COUNTIFS($AJ$2:$AJ$200,$G5)>0, COUNTIFS($AK$2:$AK$200,$G5)>0, COUNTIFS($AL$2:$AL$200,$G5)>0, COUNTIFS($AM$2:$AM$200,$G5)>0, COUNTIFS($AN$2:$AN$200,$G5)>0, COUNTIFS($AO$2:$AO$200,$G5)>0, COUNTIFS($AP$2:$AP$200,$G5)>0, COUNTIFS($AQ$2:$AQ$200,$G5)>0, COUNTIFS($AR$2:$AR$200,$G5)>0, COUNTIFS($AS$2:$AS$200,$G5)>0, COUNTIFS($AT$2:$AT$200,$G5)>0, COUNTIFS($AU$2:$AU$200,$G5)>0, COUNTIFS($AV$2:$AV$200,$G5)>0, COUNTIFS($AW$2:$AW$200,$G5)>0, COUNTIFS($AX$2:$AX$200,$G5)>0 )), ), 2 ), "")} | E5: {=IFERROR( INDEX( _xlfn._xlws.FILTER($U$1:$AX$1, TRANSPOSE( CHOOSE({1;2;3;4;5;6;7;8;9;10;11;12;13;14;15;16;17;18;19;20;21;22;23;24;25;26;27;28;29;30}, COUNTIFS($U$2:$U$200,$G5)>0, COUNTIFS($V$2:$V$200,$G5)>0, COUNTIFS($W$2:$W$200,$G5)>0, COUNTIFS($X$2:$X$200,$G5)>0, COUNTIFS($Y$2:$Y$200,$G5)>0, COUNTIFS($Z$2:$Z$200,$G5)>0, COUNTIFS($AA$2:$AA$200,$G5)>0, COUNTIFS($AB$2:$AB$200,$G5)>0, COUNTIFS($AC$2:$AC$200,$G5)>0, COUNTIFS($AD$2:$AD$200,$G5)>0, COUNTIFS($AE$2:$AE$200,$G5)>0, COUNTIFS($AF$2:$AF$200,$G5)>0, COUNTIFS($AG$2:$AG$200,$G5)>0, COUNTIFS($AH$2:$AH$200,$G5)>0, COUNTIFS($AI$2:$AI$200,$G5)>0, COUNTIFS($AJ$2:$AJ$200,$G5)>0, COUNTIFS($AK$2:$AK$200,$G5)>0, COUNTIFS($AL$2:$AL$200,$G5)>0, COUNTIFS($AM$2:$AM$200,$G5)>0, COUNTIFS($AN$2:$AN$200,$G5)>0, COUNTIFS($AO$2:$AO$200,$G5)>0, COUNTIFS($AP$2:$AP$200,$G5)>0, COUNTIFS($AQ$2:$AQ$200,$G5)>0, COUNTIFS($AR$2:$AR$200,$G5)>0, COUNTIFS($AS$2:$AS$200,$G5)>0, COUNTIFS($AT$2:$AT$200,$G5)>0, COUNTIFS($AU$2:$AU$200,$G5)>0, COUNTIFS($AV$2:$AV$200,$G5)>0, COUNTIFS($AW$2:$AW$200,$G5)>0, COUNTIFS($AX$2:$AX$200,$G5)>0 )), ), 3 ), "")} | F5: {=IFERROR( INDEX( _xlfn._xlws.FILTER($U$1:$AX$1, TRANSPOSE( CHOOSE({1;2;3;4;5;6;7;8;9;10;11;12;13;14;15;16;17;18;19;20;21;22;23;24;25;26;27;28;29;30}, COUNTIFS($U$2:$U$200,$G5)>0, COUNTIFS($V$2:$V$200,$G5)>0, COUNTIFS($W$2:$W$200,$G5)>0, COUNTIFS($X$2:$X$200,$G5)>0, COUNTIFS($Y$2:$Y$200,$G5)>0, COUNTIFS($Z$2:$Z$200,$G5)>0, COUNTIFS($AA$2:$AA$200,$G5)>0, COUNTIFS($AB$2:$AB$200,$G5)>0, COUNTIFS($AC$2:$AC$200,$G5)>0, COUNTIFS($AD$2:$AD$200,$G5)>0, COUNTIFS($AE$2:$AE$200,$G5)>0, COUNTIFS($AF$2:$AF$200,$G5)>0, COUNTIFS($AG$2:$AG$200,$G5)>0, COUNTIFS($AH$2:$AH$200,$G5)>0, COUNTIFS($AI$2:$AI$200,$G5)>0, COUNTIFS($AJ$2:$AJ$200,$G5)>0, COUNTIFS($AK$2:$AK$200,$G5)>0, COUNTIFS($AL$2:$AL$200,$G5)>0, COUNTIFS($AM$2:$AM$200,$G5)>0, COUNTIFS($AN$2:$AN$200,$G5)>0, COUNTIFS($AO$2:$AO$200,$G5)>0, COUNTIFS($AP$2:$AP$200,$G5)>0, COUNTIFS($AQ$2:$AQ$200,$G5)>0, COUNTIFS($AR$2:$AR$200,$G5)>0, COUNTIFS($AS$2:$AS$200,$G5)>0, COUNTIFS($AT$2:$AT$200,$G5)>0, COUNTIFS($AU$2:$AU$200,$G5)>0, COUNTIFS($AV$2:$AV$200,$G5)>0, COUNTIFS($AW$2:$AW$200,$G5)>0, COUNTIFS($AX$2:$AX$200,$G5)>0 )), ), 4 ), "")} | G5: Adarkar Wastes | I5: Tayam | J5: =Tayam!G2 -> 31 | K5: Sim | L5: Não | M5: Não | N5: Sim | O5: Sim | P5: Combate | Q5: Combo | R5: Counters, tudo drop 3- | S5: =IF(J5<6,"5",IF(J5<11,"4",IF(J5<16,"3",IF(J5<31,"2","1")))) -> 1 | U5: Emberwilde Captain | V5: Brushland | W5: Full Throttle | X5: Canopy Vista | Y5: Enduring Innocence | Z5: Counterspell | AA5: Harvest Season | AB5: Jadar, Ghoulcaller of Nephalia | AC5: Mox Tantalite | AD5: Entomb | AE5: Gerrard's Hourglass Pendant | AF5: Luxury Suite | AG5: Louisoix's Sacrifice | AH5: Diário de Tarrian | AI5: Espada de Banquete e Fome | AJ5: Karn Liberated | AK5: Uthros, Titanic Godcore | AL5: Nissa, Resurgent Animist | AM5: Ulamog, o Profanador | AN5: Sliver Gravemother | AO5: Collector's Vault | AP5: Season of Weaving | AQ5: Jenova, Ancient Calamity | AS5: Stridehangar Automaton | AT5: Renewed Solidarity | AX5: Arcbound Overseer | BB5: Bojuka Bog | BC5: Arwen, Weaver of Hope | BD5: Bojuka Bog | BE5: Deeproot Historian | BF5: Emrakul, um Novo Mundo | BG5: Batwing Brume | BH5: Creeping Tar Pit | BI5: Elspeth, Sun's Champion | BJ5: Matoya, Archon Elder | BK5: Mistrise Village | BL5: Collector's Vault | BM5: Daretti, Ingenious Iconoclast | BN5: Lagoa Espelhada | BO5: Homeward Path | BP5: Arcbound Overseer | BS5: Artifact Mutation | BT5: Autoridade dos Cônsules | BU5: Arid Mesa | BV5: Cid, Freeflier Pilot | BW5: Emrakul, um Novo Mundo | BX5: Bugenhagen, Wise Elder | BY5: Dollmaker's Shop // Porcelain Gallery | BZ5: Arcbound Overseer | CB5: Ancient Greenwarden | CC5: Arcane Lighthouse | CD5: Baral, Chief of Compliance | CE5: Árbitro Silencioso | CG5: Aligned Heart | CH5: Ancient Den | CJ5: Adarkar Wastes
