Workbook

Sheet COMPRAS
A1: Total: | B1: =C2+C8+C13+C18+C23+C28+C32+C34+C38+C50 -> 0 | E1: Deck | F1: =A2 -> Marcelo | G1: =B3 -> Overrun | H1: =B4 -> Base | I1: =B5 -> 0 | J1: =B6 -> Liga | L1: =A8 -> Interessantes | M1: =B9 -> Valor | N1: =B10 -> Liga | O1: =B11 -> Loja 1 | Q1: =A13 -> Player 3 | R1: =B14 -> Rayearth | S1: =B15 -> Mineral | T1: =B16 -> CardTutor | V1: =A18 -> Player 4 | W1: =B19 -> Rayearth | X1: =B20 -> Mineral | Y1: =B21 -> CardTutor | AA1: =A23 -> Player 5 | AB1: =B24 -> Rayearth | AC1: =B25 -> Mineral | AD1: =B26 -> CardTutor | AF1: =A28 -> Player 6 | AG1: =B29 -> Rayearth | AH1: =B30 -> Mineral | AI1: =B31 -> CardTutor
A2: Marcelo | B2: Total Lojas: | C2: =SUM(C3:C6) -> 0
A3: =COUNTA(F2:F216) -> 0 | B3: Overrun | C3: =SUM(G:G) -> 0
B4: Base | C4: =SUM(H:H) -> 0
C5: =SUM(I:I) -> 0
B6: Liga | C6: =SUM(J:J) -> 0
A8: Interessantes | B8: Total Lojas: | C8: =SUM(C9:C11) -> 0
A9: =COUNTA(L2:L173) -> 0 | B9: Valor | C9: =SUM(M:M) -> 0
B10: Liga | C10: =SUM(N:N) -> 0
B11: Loja 1 | C11: =SUM(O:O) -> 0
A13: Player 3 | B13: Total Lojas: | C13: =SUM(C14:C16) -> 0
A14: =COUNTA(Q2:Q173) -> 0 | B14: Rayearth | C14: =SUM(R:R) -> 0
B15: Mineral | C15: =SUM(S:S) -> 0
B16: CardTutor | C16: =SUM(T:T) -> 0
A18: Player 4 | B18: Total Lojas: | C18: =SUM(C19:C21) -> 0
A19: =COUNTA(V2:V173) -> 0 | B19: Rayearth | C19: =SUM(W1:W9973) -> 0
B20: Mineral | C20: =SUM(X1:X9978) -> 0
B21: CardTutor | C21: =SUM(Y:Y) -> 0
A23: Player 5 | B23: Total Lojas: | C23: =SUM(C24:C26) -> 0
A24: =COUNTA(V7:V178) -> 0 | B24: Rayearth | C24: =SUM(AB:AB) -> 0
B25: Mineral | C25: =SUM(AC:AC) -> 0
B26: CardTutor | C26: =SUM(AD:AD) -> 0
A28: Player 6 | B28: Total Lojas: | C28: =SUM(C29:C31) -> 0
A29: =COUNTA(V11:V183) -> 0 | B29: Rayearth | C29: =SUM(AG:AG) -> 0
B30: Mineral | C30: =SUM(AH:AH) -> 0
B31: CardTutor | C31: =SUM(AI:AI) -> 0

Sheet STATS
A1: Dia | B1: Player 1 | C1: Deck 1 | D1: Player 2 | E1: Deck 2 | F1: Player 3 | G1: Deck 3 | H1: Player 4 | I1: Deck 4 | J1: Vitória | M1: Deck | N1: Partidas | O1: Winrate | Q1: Player | R1: Partidas | S1: Winrate
A2: 45587 | B2: Marcelo | C2: Elfos | D2: Vivian | E2: Zimone | F2: Renato | G2: Raffine | H2: Dexter | I2: Kaalia | J2: Marcelo | K2: Elfos | M2: Akiri | N2: =COUNTIF(C:C,M2)+COUNTIF(E:E,M2)+COUNTIF(G:G,M2)+COUNTIF(I:I,M2) -> 2 | O2: =IF(N2>=10,(COUNTIF(K:K,M2)/N2),"Insuficiente") -> Insuficiente | Q2: Marcelo | R2: =COUNTIF(B:B,Q2)+COUNTIF(D:D,Q2)+COUNTIF(F:F,Q2)+COUNTIF(H:H,Q2) -> 11 | S2: =IF(R2>=10, (COUNTIF(J:J,Q2)/R2), "Insuficiente") -> 0.36363636
A3: 45594 | B3: Marcelo | C3: Breya | D3: Vivian | E3: Zimone | F3: Renato | G3: Raffine | H3: Dexter | I3: Tovolar | J3: Vivian | K3: Zimone | M3: Arcades | N3: =COUNTIF(C:C,M3)+COUNTIF(E:E,M3)+COUNTIF(G:G,M3)+COUNTIF(I:I,M3) -> 1 | O3: =IF(N3>=10,(COUNTIF(K:K,M3)/N3),"Insuficiente") -> Insuficiente | Q3: Vivian | R3: =COUNTIF(B:B,Q3)+COUNTIF(D:D,Q3)+COUNTIF(F:F,Q3)+COUNTIF(H:H,Q3) -> 11 | S3: =IF(R3>=10, (COUNTIF(J:J,Q3)/R3), "Insuficiente") -> 0.27272727
A4: 45594 | B4: Marcelo | C4: Trakiri | D4: Vivian | E4: Zimone | F4: Renato | G4: Raffine | H4: Hamster | I4: Muzzio | J4: Marcelo | K4: Trakiri | M4: Baylen | N4: =COUNTIF(C:C,M4)+COUNTIF(E:E,M4)+COUNTIF(G:G,M4)+COUNTIF(I:I,M4) -> 1 | O4: =IF(N4>=10,(COUNTIF(K:K,M4)/N4),"Insuficiente") -> Insuficiente | Q4: Renato | R4: =COUNTIF(B:B,Q4)+COUNTIF(D:D,Q4)+COUNTIF(F:F,Q4)+COUNTIF(H:H,Q4) -> 6 | S4: =IF(R4>=10, (COUNTIF(J:J,Q4)/R4), "Insuficiente") -> Insuficiente
A5: 45594 | B5: Marcelo | C5: Akiri | D5: Vivian | E5: Zimone | F5: Renato | G5: Baylen | H5: Hamster | I5: Kumena | J5: Marcelo | K5: Akiri | M5: Breya | N5: =COUNTIF(C:C,M5)+COUNTIF(E:E,M5)+COUNTIF(G:G,M5)+COUNTIF(I:I,M5) -> 1 | O5: =IF(N5>=10,(COUNTIF(K:K,M5)/N5),"Insuficiente") -> Insuficiente | Q5: Dexter | R5: =COUNTIF(B:B,Q5)+COUNTIF(D:D,Q5)+COUNTIF(F:F,Q5)+COUNTIF(H:H,Q5) -> 5 | S5: =IF(R5>=10, (COUNTIF(J:J,Q5)/R5), "Insuficiente") -> Insuficiente
A6: 45597 | B6: Marcelo | C6: Inalla | D6: Vivian | E6: Zimone | F6: Renato | G6: Raffine | H6: João | I6: Winota | J6: João | K6: Winota | M6: Elfos | N6: =COUNTIF(C:C,M6)+COUNTIF(E:E,M6)+COUNTIF(G:G,M6)+COUNTIF(I:I,M6) -> 1 | O6: =IF(N6>=10,(COUNTIF(K:K,M6)/N6),"Insuficiente") -> Insuficiente | Q6: Hamster | R6: =COUNTIF(B:B,Q6)+COUNTIF(D:D,Q6)+COUNTIF(F:F,Q6)+COUNTIF(H:H,Q6) -> 2 | S6: =IF(R6>=10, (COUNTIF(J:J,Q6)/R6), "Insuficiente") -> Insuficiente
A7: 45597 | B7: Marcelo | C7: Yuriko | D7: Vivian | E7: Zimone | F7: Renato | G7: Raffine | H7: João | I7: Winota | J7: Vivian | K7: Zimone | M7: FF Counters | N7: =COUNTIF(C:C,M7)+COUNTIF(E:E,M7)+COUNTIF(G:G,M7)+COUNTIF(I:I,M7) -> 2 | O7: =IF(N7>=10,(COUNTIF(K:K,M7)/N7),"Insuficiente") -> Insuficiente | Q7: Talita | R7: =COUNTIF(B:B,Q7)+COUNTIF(D:D,Q7)+COUNTIF(F:F,Q7)+COUNTIF(H:H,Q7) -> 3 | S7: =IF(R7>=10, (COUNTIF(J:J,Q7)/R7), "Insuficiente") -> Insuficiente
A8: 45599 | B8: Marcelo | C8: Narset | D8: Vivian | E8: Arcades | F8: Dexter | G8: Who Villains | H8: Talita | I8: Who Time | J8: Vivian | K8: Arcades | M8: Hashaton | N8: =COUNTIF(C:C,M8)+COUNTIF(E:E,M8)+COUNTIF(G:G,M8)+COUNTIF(I:I,M8) -> 1 | O8: =IF(N8>=10,(COUNTIF(K:K,M8)/N8),"Insuficiente") -> Insuficiente | Q8: João | R8: =COUNTIF(B:B,Q8)+COUNTIF(D:D,Q8)+COUNTIF(F:F,Q8)+COUNTIF(H:H,Q8) -> 4 | S8: =IF(R8>=10, (COUNTIF(J:J,Q8)/R8), "Insuficiente") -> Insuficiente
A9: 45599 | B9: Marcelo | C9: Thantis | D9: Vivian | E9: Akiri | F9: Dexter | G9: Who Villains | H9: Talita | I9: Ladinos | J9: Talita | K9: Ladinos | M9: Inalla | N9: =COUNTIF(C:C,M9)+COUNTIF(E:E,M9)+COUNTIF(G:G,M9)+COUNTIF(I:I,M9) -> 1 | O9: =IF(N9>=10,(COUNTIF(K:K,M9)/N9),"Insuficiente") -> Insuficiente | Q9: Philips | R9: =COUNTIF(B:B,Q9)+COUNTIF(D:D,Q9)+COUNTIF(F:F,Q9)+COUNTIF(H:H,Q9) -> 2 | S9: =IF(R9>=10, (COUNTIF(J:J,Q9)/R9), "Insuficiente") -> Insuficiente
A10: 45835 | B10: Marcelo | C10: Zedruu | D10: Vivian | E10: Jhoira | F10: Dexter | G10: Who Villains | H10: Talita | I10: Who Time | J10: Dexter | K10: Who Villains | M10: Jhoira | N10: =COUNTIF(C:C,M10)+COUNTIF(E:E,M10)+COUNTIF(G:G,M10)+COUNTIF(I:I,M10) -> 1 | O10: =IF(N10>=10,(COUNTIF(K:K,M10)/N10),"Insuficiente") -> Insuficiente
A11: 45864 | B11: Marcelo | C11: Muzzio | D11: Vivian | E11: Zimone | F11: Philips | G11: Hashaton | H11: João | I11: FF Counters | J11: Marcelo | K11: Muzzio | M11: Kaalia | N11: =COUNTIF(C:C,M11)+COUNTIF(E:E,M11)+COUNTIF(G:G,M11)+COUNTIF(I:I,M11) -> 2 | O11: =IF(N11>=10,(COUNTIF(K:K,M11)/N11),"Insuficiente") -> Insuficiente
A12: 45864 | B12: Marcelo | C12: Sisay | D12: Vivian | E12: Zimone | F12: Philips | G12: Kaalia | H12: João | I12: FF Counters | J12: Philips | K12: Kaalia | M12: Kumena | N12: =COUNTIF(C:C,M12)+COUNTIF(E:E,M12)+COUNTIF(G:G,M12)+COUNTIF(I:I,M12) -> 1 | O12: =IF(N12>=10,(COUNTIF(K:K,M12)/N12),"Insuficiente") -> Insuficiente
M13: Ladinos | N13: =COUNTIF(C:C,M13)+COUNTIF(E:E,M13)+COUNTIF(G:G,M13)+COUNTIF(I:I,M13) -> 1 | O13: =IF(N13>=10,(COUNTIF(K:K,M13)/N13),"Insuficiente") -> Insuficiente
M14: Muzzio | N14: =COUNTIF(C:C,M14)+COUNTIF(E:E,M14)+COUNTIF(G:G,M14)+COUNTIF(I:I,M14) -> 2 | O14: =IF(N14>=10,(COUNTIF(K:K,M14)/N14),"Insuficiente") -> Insuficiente
M15: Narset | N15: =COUNTIF(C:C,M15)+COUNTIF(E:E,M15)+COUNTIF(G:G,M15)+COUNTIF(I:I,M15) -> 1 | O15: =IF(N15>=10,(COUNTIF(K:K,M15)/N15),"Insuficiente") -> Insuficiente
M16: Raffine | N16: =COUNTIF(C:C,M16)+COUNTIF(E:E,M16)+COUNTIF(G:G,M16)+COUNTIF(I:I,M16) -> 5 | O16: =IF(N16>=10,(COUNTIF(K:K,M16)/N16),"Insuficiente") -> Insuficiente
M17: Sisay | N17: =COUNTIF(C:C,M17)+COUNTIF(E:E,M17)+COUNTIF(G:G,M17)+COUNTIF(I:I,M17) -> 1 | O17: =IF(N17>=10,(COUNTIF(K:K,M17)/N17),"Insuficiente") -> Insuficiente
M18: Thantis | N18: =COUNTIF(C:C,M18)+COUNTIF(E:E,M18)+COUNTIF(G:G,M18)+COUNTIF(I:I,M18) -> 1 | O18: =IF(N18>=10,(COUNTIF(K:K,M18)/N18),"Insuficiente") -> Insuficiente
M19: Tovolar | N19: =COUNTIF(C:C,M19)+COUNTIF(E:E,M19)+COUNTIF(G:G,M19)+COUNTIF(I:I,M19) -> 1 | O19: =IF(N19>=10,(COUNTIF(K:K,M19)/N19),"Insuficiente") -> Insuficiente
M20: Trakiri | N20: =COUNTIF(C:C,M20)+COUNTIF(E:E,M20)+COUNTIF(G:G,M20)+COUNTIF(I:I,M20) -> 1 | O20: =IF(N20>=10,(COUNTIF(K:K,M20)/N20),"Insuficiente") -> Insuficiente
M21: Who Time | N21: =COUNTIF(C:C,M21)+COUNTIF(E:E,M21)+COUNTIF(G:G,M21)+COUNTIF(I:I,M21) -> 2 | O21: =IF(N21>=10,(COUNTIF(K:K,M21)/N21),"Insuficiente") -> Insuficiente
M22: Who Villains | N22: =COUNTIF(C:C,M22)+COUNTIF(E:E,M22)+COUNTIF(G:G,M22)+COUNTIF(I:I,M22) -> 3 | O22: =IF(N22>=10,(COUNTIF(K:K,M22)/N22),"Insuficiente") -> Insuficiente
M23: Winota | N23: =COUNTIF(C:C,M23)+COUNTIF(E:E,M23)+COUNTIF(G:G,M23)+COUNTIF(I:I,M23) -> 2 | O23: =IF(N23>=10,(COUNTIF(K:K,M23)/N23),"Insuficiente") -> Insuficiente
M24: Yuriko | N24: =COUNTIF(C:C,M24)+COUNTIF(E:E,M24)+COUNTIF(G:G,M24)+COUNTIF(I:I,M24) -> 1 | O24: =IF(N24>=10,(COUNTIF(K:K,M24)/N24),"Insuficiente") -> Insuficiente
... M26: Zimone | N26: =COUNTIF(C:C,M26)+COUNTIF(E:E,M26)+COUNTIF(G:G,M26)+COUNTIF(I:I,M26) -> 8 | O26: =IF(N26>=10,(COUNTIF(K:K,M26)/N26),"Insuficiente") -> Insuficiente

Sheet WATCH
A1: Carta | B1: Identidade | G1: Tipo | H1: Categoria | I1: Classe | J1: Formato | K1: Deck
A5: Weathered Runestone | B5: Não | C5: Não | D5: Não | E5: Não | F5: Não | G5: Artefato | H5: Stax | I5: Cemitério
A6: Shivan Harvest | B6: Não | C6: Não | D6: Sim | E6: Não | F6: Não | G6: Encantamento | H6: Remoção | I6: Terreno
A7: Scouting Trek | B7: Não | C7: Não | D7: Não | E7: Não | F7: Sim | G7: Feitiço | H7: Combo | I7: Tutor
A8: Overabundance | B8: Não | C8: Não | D8: Sim | E8: Não | F8: Não | G8: Encantamento | H8: Ramp | I8: Punição
A9: Spreading Plague | B9: Não | C9: Não | D9: Não | E9: Sim | F9: Não | G9: Encantamento | H9: Stax | I9: Criaturas
A10: Explosão da Alma | B10: Não | C10: Não | D10: Sim | E10: Não | F10: Não | G10: Instantânea | H10: Wincon | I10: Dano
A11: Obsidian Fireheat | B11: Não | C11: Não | D11: Sim | E11: Não | F11: Não | G11: Criatura | H11: Wincon | I11: Punição
A12: Interdict | B12: Não | C12: Sim | D12: Não | E12: Não | F12: Não | G12: Instantânea | H12: Anule | I12: Habilidade
A13: Mogg Infestation | B13: Não | C13: Não | D13: Sim | E13: Não | F13: Não | G13: Feitiço | H13: Remoção | I13: Criaturas
A14: Life // Death | B14: Não | C14: Não | D14: Não | E14: Não | F14: Sim | G14: Feitiço | H14: Combo | I14: Terreno
A15: Debt of Loyalt | B15: Sim | C15: Não | D15: Não | E15: Não | F15: Não | G15: Instantânea | H15: Remoção | I15: Roubo
A16: Yavimaya Hollow | B16: Não | C16: Não | D16: Não | E16: Não | F16: Sim | G16: Terreno | H16: Proteção | I16: Criaturas
... A26: Preferência de Cineréia | B26: Não | C26: Não | D26: Sim | E26: Não | F26: Não | G26: Encantamento | H26: Stax | I26: Criaturas
A27: Temporada da Multiplicação
A28: Final de Devastação
A29: The Great Henge
A30: Intervenção Heróica
A31: Presa-Gélida de Ohran
A32: Altar de Ashnod
A33: Ornato de Esmeralda
A34: Ornato de Azeviche
A35: Ornato de Rubi
A36: Ornato de Safira
A37: Ornato de Pérola
A38: Espada da Animista
... A74: Arachnogenesis

Sheet RESUMO
A1: Prioridade | B1: Faltam | C1: Deck 1 | D1: Deck 2 | E1: Deck 3 | F1: Deck 4 | G1: Carta | J1: Alterações | K1: Cores | P1: =COUNTA(I3:I5000) & " Decks" -> 30 Decks | U1: Piratas | V1: Baylen | W1: Narset | X1: Tayam | Y1: Carlos | Z1: Rani | AA1: Kumena | AB1: Zimone | AC1: JhoiraB | AD1: Gritrog | AE1: Muzzio | AF1: VialIshai | AG1: Yuriko | AH1: Inalla | AI1: Akiri | AJ1: Sisay | AK1: Thrakiri | AL1: Elfos | AM1: Jhoira | AN1: Fractius | AO1: Rielle | AP1: Oona | AQ1: Kresh | AR1: Breya | AS1: OWA | AT1: Alela | AU1: Arcades | AV1: Zedruu | AW1: Exaltado | AX1: Modular
A2: =IFERROR(INDEX($S$3:$S$200, MATCH($C2, $I$3:$I$200, 0)), "") -> 3 | B2: =COUNTIF(U:AX,G2) -> 1 | C2: =IFERROR( INDEX($U$1:$AX$1, MATCH(TRUE, CHOOSE({1;2;3;4;5;6;7;8;9;10;11;12;13;14;15;16;17;18;19;20;21;22;23;24;25;26;27;28;29;30;31;32}, COUNTIFS($U$2:$U$200,$G2)>0, COUNTIFS($V$2:$V$200,$G2)>0, COUNTIFS($W$2:$W$200,$G2)>0, COUNTIFS($X$2:$X$200,$G2)>0, COUNTIFS($Y$2:$Y$200,$G2)>0, COUNTIFS($Z$2:$Z$200,$G2)>0, COUNTIFS($AA$2:$AA$200,$G2)>0, COUNTIFS($AB$2:$AB$200,$G2)>0, COUNTIFS($AC$2:$AC$200,$G2)>0, COUNTIFS($AD$2:$AD$200,$G2)>0, COUNTIFS($AE$2:$AE$200,$G2)>0, COUNTIFS($AF$2:$AF$200,$G2)>0, COUNTIFS($AG$2:$AG$200,$G2)>0, COUNTIFS($AH$2:$AH$200,$G2)>0, COUNTIFS($AI$2:$AI$200,$G2)>0, COUNTIFS($AJ$2:$AJ$200,$G2)>0, COUNTIFS($AK$2:$AK$200,$G2)>0, COUNTIFS($AL$2:$AL$200,$G2)>0, COUNTIFS($AM$2:$AM$200,$G2)>0, COUNTIFS($AN$2:$AN$200,$G2)>0, COUNTIFS($AO$2:$AO$200,$G2)>0, COUNTIFS($AP$2:$AP$200,$G2)>0, COUNTIFS($AQ$2:$AQ$200,$G2)>0, COUNTIFS($AR$2:$AR$200,$G2)>0, COUNTIFS($AS$2:$AS$200,$G2)>0, COUNTIFS($AT$2:$AT$200,$G2)>0, COUNTIFS($AU$2:$AU$200,$G2)>0, COUNTIFS($AV$2:$AV$200,$G2)>0, COUNTIFS($AW$2:$AW$200,$G2)>0, COUNTIFS($AX$2:$AX$200,$G2)>0 ), 0) ), "") -> Muzzio | D2: {=IFERROR( INDEX( _xlfn._xlws.FILTER($U$1:$AX$1, TRANSPOSE( CHOOSE({1;2;3;4;5;6;7;8;9;10;11;12;13;14;15;16;17;18;19;20;21;22;23;24;25;26;27;28;29;30}, COUNTIFS($U$2:$U$200,$G2)>0, COUNTIFS($V$2:$V$200,$G2)>0, COUNTIFS($W$2:$W$200,$G2)>0, COUNTIFS($X$2:$X$200,$G2)>0, COUNTIFS($Y$2:$Y$200,$G2)>0, COUNTIFS($Z$2:$Z$200,$G2)>0, COUNTIFS($AA$2:$AA$200,$G2)>0, COUNTIFS($AB$2:$AB$200,$G2)>0, COUNTIFS($AC$2:$AC$200,$G2)>0, COUNTIFS($AD$2:$AD$200,$G2)>0, COUNTIFS($AE$2:$AE$200,$G2)>0, COUNTIFS($AF$2:$AF$200,$G2)>0, COUNTIFS($AG$2:$AG$200,$G2)>0, COUNTIFS($AH$2:$AH$200,$G2)>0, COUNTIFS($AI$2:$AI$200,$G2)>0, COUNTIFS($AJ$2:$AJ$200,$G2)>0, COUNTIFS($AK$2:$AK$200,$G2)>0, COUNTIFS($AL$2:$AL$200,$G2)>0, COUNTIFS($AM$2:$AM$200,$G2)>0, COUNTIFS($AN$2:$AN$200,$G2)>0, COUNTIFS($AO$2:$AO$200,$G2)>0, COUNTIFS($AP$2:$AP$200,$G2)>0, COUNTIFS($AQ$2:$AQ$200,$G2)>0, COUNTIFS($AR$2:$AR$200,$G2)>0, COUNTIFS($AS$2:$AS$200,$G2)>0, COUNTIFS($AT$2:$AT$200,$G2)>0, COUNTIFS($AU$2:$AU$200,$G2)>0, COUNTIFS($AV$2:$AV$200,$G2)>0, COUNTIFS($AW$2:$AW$200,$G2)>0, COUNTIFS($AX$2:$AX$200,$G2)>0 )), ), 2 ), "")} | E2: {=IFERROR( INDEX( _xlfn._xlws.FILTER($U$1:$AX$1, TRANSPOSE( CHOOSE({1;2;3;4;5;6;7;8;9;10;11;12;13;14;15;16;17;18;19;20;21;22;23;24;25;26;27;28;29;30}, COUNTIFS($U$2:$U$200,$G2)>0, COUNTIFS($V$2:$V$200,$G2)>0, COUNTIFS($W$2:$W$200,$G2)>0, COUNTIFS($X$2:$X$200,$G2)>0, COUNTIFS($Y$2:$Y$200,$G2)>0, COUNTIFS($Z$2:$Z$200,$G2)>0, COUNTIFS($AA$2:$AA$200,$G2)>0, COUNTIFS($AB$2:$AB$200,$G2)>0, COUNTIFS($AC$2:$AC$200,$G2)>0, COUNTIFS($AD$2:$AD$200,$G2)>0, COUNTIFS($AE$2:$AE$200,$G2)>0, COUNTIFS($AF$2:$AF$200,$G2)>0, COUNTIFS($AG$2:$AG$200,$G2)>0, COUNTIFS($AH$2:$AH$200,$G2)>0, COUNTIFS($AI$2:$AI$200,$G2)>0, COUNTIFS($AJ$2:$AJ$200,$G2)>0, COUNTIFS($AK$2:$AK$200,$G2)>0, COUNTIFS($AL$2:$AL$200,$G2)>0, COUNTIFS($AM$2:$AM$200,$G2)>0, COUNTIFS($AN$2:$AN$200,$G2)>0, COUNTIFS($AO$2:$AO$200,$G2)>0, COUNTIFS($AP$2:$AP$200,$G2)>0, COUNTIFS($AQ$2:$AQ$200,$G2)>0, COUNTIFS($AR$2:$AR$200,$G2)>0, COUNTIFS($AS$2:$AS$200,$G2)>0, COUNTIFS($AT$2:$AT$200,$G2)>0, COUNTIFS($AU$2:$AU$200,$G2)>0, COUNTIFS($AV$2:$AV$200,$G2)>0, COUNTIFS($AW$2:$AW$200,$G2)>0, COUNTIFS($AX$2:$AX$200,$G2)>0 )), ), 3 ), "")} | F2: {=IFERROR( INDEX( _xlfn._xlws.FILTER($U$1:$AX$1, TRANSPOSE( CHOOSE({1;2;3;4;5;6;7;8;9;10;11;12;13;14;15;16;17;18;19;20;21;22;23;24;25;26;27;28;29;30}, COUNTIFS($U$2:$U$200,$G2)>0, COUNTIFS($V$2:$V$200,$G2)>0, COUNTIFS($W$2:$W$200,$G2)>0, COUNTIFS($X$2:$X$200,$G2)>0, COUNTIFS($Y$2:$Y$200,$G2)>0, COUNTIFS($Z$2:$Z$200,$G2)>0, COUNTIFS($AA$2:$AA$200,$G2)>0, COUNTIFS($AB$2:$AB$200,$G2)>0, COUNTIFS($AC$2:$AC$200,$G2)>0, COUNTIFS($AD$2:$AD$200,$G2)>0, COUNTIFS($AE$2:$AE$200,$G2)>0, COUNTIFS($AF$2:$AF$200,$G2)>0, COUNTIFS($AG$2:$AG$200,$G2)>0, COUNTIFS($AH$2:$AH$200,$G2)>0, COUNTIFS($AI$2:$AI$200,$G2)>0, COUNTIFS($AJ$2:$AJ$200,$G2)>0, COUNTIFS($AK$2:$AK$200,$G2)>0, COUNTIFS($AL$2:$AL$200,$G2)>0, COUNTIFS($AM$2:$AM$200,$G2)>0, COUNTIFS($AN$2:$AN$200,$G2)>0, COUNTIFS($AO$2:$AO$200,$G2)>0, COUNTIFS($AP$2:$AP$200,$G2)>0, COUNTIFS($AQ$2:$AQ$200,$G2)>0, COUNTIFS($AR$2:$AR$200,$G2)>0, COUNTIFS($AS$2:$AS$200,$G2)>0, COUNTIFS($AT$2:$AT$200,$G2)>0, COUNTIFS($AU$2:$AU$200,$G2)>0, COUNTIFS($AV$2:$AV$200,$G2)>0, COUNTIFS($AW$2:$AW$200,$G2)>0, COUNTIFS($AX$2:$AX$200,$G2)>0 )), ), 4 ), "")} | G2: {=IF(COUNTA(_xlfn.ANCHORARRAY($BT$2))+COUNTA(_xlfn.ANCHORARRAY($BO$2))=0,"",_xlfn._xlws.SORT(_xlfn.UNIQUE(IF(ROW(INDIRECT("1:"&(COUNTA(_xlfn.ANCHORARRAY($BT$2))+COUNTA(_xlfn.ANCHORARRAY($BO$2)))))<=COUNTA(_xlfn.ANCHORARRAY($BT$2)),INDEX(_xlfn.ANCHORARRAY($BT$2),ROW(INDIRECT("1:"&(COUNTA(_xlfn.ANCHORARRAY($BT$2))+COUNTA(_xlfn.ANCHORARRAY($BO$2)))))),INDEX(_xlfn.ANCHORARRAY($BO$2),ROW(INDIRECT("1:"&(COUNTA(_xlfn.ANCHORARRAY($BT$2))+COUNTA(_xlfn.ANCHORARRAY($BO$2)))))-COUNTA(_xlfn.ANCHORARRAY($BT$2))))),1,1))} -> A Joia do Enigma | I2: Total | J2: =SUM(J3:J30) -> 357 | K2: =COUNTIF(K3:K5000,"Sim") -> 16 | L2: =COUNTIF(L3:L5000,"Sim") -> 22 | M2: =COUNTIF(M3:M5000,"Sim") -> 17 | N2: =COUNTIF(N3:N5000,"Sim") -> 17 | O2: =COUNTIF(O3:O5000,"Sim") -> 14 | P2: Wincon | Q2: Sub Plan | R2: Descrição | S2: Prioridade | U2: {=IF(COUNTA(_xlfn._xlws.FILTER(Piratas!C3:C200,(Piratas!B3:B200<>Piratas!C3:C200)*(Piratas!C3:C200<>"")))=0,"",_xlfn._xlws.SORT(_xlfn._xlws.FILTER(Piratas!C3:C200,(Piratas!B3:B200<>Piratas!C3:C200)*(Piratas!C3:C200<>"")),1,1))} -> Back in Town | V2: {=IF(COUNTA(_xlfn._xlws.FILTER(Baylen!C3:C200,(Baylen!B3:B200<>Baylen!C3:C200)*(Baylen!C3:C200<>"")))=0,"",_xlfn._xlws.SORT(_xlfn._xlws.FILTER(Baylen!C3:C200,(Baylen!B3:B200<>Baylen!C3:C200)*(Baylen!C3:C200<>"")),1,1))} -> Artifact Mutation | W2: {=IF(COUNTA(_xlfn._xlws.FILTER(Narset!C3:C200,(Narset!B3:B200<>Narset!C3:C200)*(Narset!C3:C200<>"")))=0,"",_xlfn._xlws.SORT(_xlfn._xlws.FILTER(Narset!C3:C200,(Narset!B3:B200<>Narset!C3:C200)*(Narset!C3:C200<>"")),1,1))} -> Adarkar Wastes | X2: {=IF(COUNTA(_xlfn._xlws.FILTER(Tayam!C3:C200,(Tayam!B3:B200<>Tayam!C3:C200)*(Tayam!C3:C200<>"")))=0,"",_xlfn._xlws.SORT(_xlfn._xlws.FILTER(Tayam!C3:C200,(Tayam!B3:B200<>Tayam!C3:C200)*(Tayam!C3:C200<>"")),1,1))} -> Ardbert, Warrior of Darkness | Y2: {=IF(COUNTA(_xlfn._xlws.FILTER(Carlos!C3:C200,(Carlos!B3:B200<>Carlos!C3:C200)*(Carlos!C3:C200<>"")))=0,"",_xlfn._xlws.SORT(_xlfn._xlws.FILTER(Carlos!C3:C200,(Carlos!B3:B200<>Carlos!C3:C200)*(Carlos!C3:C200<>"")),1,1))} -> Ascensão do Avernus | Z2: {=IF(COUNTA(_xlfn._xlws.FILTER(Rani!C3:C200,(Rani!B3:B200<>Rani!C3:C200)*(Rani!C3:C200<>"")))=0,"",_xlfn._xlws.SORT(_xlfn._xlws.FILTER(Rani!C3:C200,(Rani!B3:B200<>Rani!C3:C200)*(Rani!C3:C200<>"")),1,1))} -> Access Tunnel | AA2: {=IF(COUNTA(_xlfn._xlws.FILTER(Kumena!C3:C200,(Kumena!B3:B200<>Kumena!C3:C200)*(Kumena!C3:C200<>"")))=0,"",_xlfn._xlws.SORT(_xlfn._xlws.FILTER(Kumena!C3:C200,(Kumena!B3:B200<>Kumena!C3:C200)*(Kumena!C3:C200<>"")),1,1))} -> Beast Within | AB2: {=IF(COUNTA(_xlfn._xlws.FILTER(Zimone!C3:C200,(Zimone!B3:B200<>Zimone!C3:C200)*(Zimone!C3:C200<>"")))=0,"",_xlfn._xlws.SORT(_xlfn._xlws.FILTER(Zimone!C3:C200,(Zimone!B3:B200<>Zimone!C3:C200)*(Zimone!C3:C200<>"")),1,1))} -> Ancient Greenwarden | AC2: {=IF(COUNTA(_xlfn._xlws.FILTER(JhoiraB!C3:C200,(JhoiraB!B3:B200<>JhoiraB!C3:C200)*(JhoiraB!C3:C200<>"")))=0,"",_xlfn._xlws.SORT(_xlfn._xlws.FILTER(JhoiraB!C3:C200,(JhoiraB!B3:B200<>JhoiraB!C3:C200)*(JhoiraB!C3:C200<>"")),1,1))} -> Emrakul, um Novo Mundo | AD2: {=IF(COUNTA(_xlfn._xlws.FILTER(Gitrog!C3:C200,(Gitrog!B3:B200<>Gitrog!C3:C200)*(Gitrog!C3:C200<>"")))=0,"",_xlfn._xlws.SORT(_xlfn._xlws.FILTER(Gitrog!C3:C200,(Gitrog!B3:B200<>Gitrog!C3:C200)*(Gitrog!C3:C200<>"")),1,1))} -> Ancient Tomb | AE2: {=IF(COUNTA(_xlfn._xlws.FILTER(Muzzio!C3:C200,(Muzzio!B3:B200<>Muzzio!C3:C200)*(Muzzio!C3:C200<>"")))=0,"",_xlfn._xlws.SORT(_xlfn._xlws.FILTER(Muzzio!C3:C200,(Muzzio!B3:B200<>Muzzio!C3:C200)*(Muzzio!C3:C200<>"")),1,1))} -> A Joia do Enigma | AF2: {=IF(COUNTA(_xlfn._xlws.FILTER(VialIshai!C3:C200,(VialIshai!B3:B200<>VialIshai!C3:C200)*(VialIshai!C3:C200<>"")))=0,"",_xlfn._xlws.SORT(_xlfn._xlws.FILTER(VialIshai!C3:C200,(VialIshai!B3:B200<>VialIshai!C3:C200)*(VialIshai!C3:C200<>"")),1,1))} -> Amphibian Downpour | AG2: {=IF(COUNTA(_xlfn._xlws.FILTER(Yuriko!C3:C200,(Yuriko!B3:B200<>Yuriko!C3:C200)*(Yuriko!C3:C200<>"")))=0,"",_xlfn._xlws.SORT(_xlfn._xlws.FILTER(Yuriko!C3:C200,(Yuriko!B3:B200<>Yuriko!C3:C200)*(Yuriko!C3:C200<>"")),1,1))} -> Creeping Tar Pit | AH2: {=IF(COUNTA(_xlfn._xlws.FILTER(Inalla!C3:C200,(Inalla!B3:B200<>Inalla!C3:C200)*(Inalla!C3:C200<>"")))=0,"",_xlfn._xlws.SORT(_xlfn._xlws.FILTER(Inalla!C3:C200,(Inalla!B3:B200<>Inalla!C3:C200)*(Inalla!C3:C200<>"")),1,1))} -> Arcane Lighthouse | AI2: {=IF(COUNTA(_xlfn._xlws.FILTER(Akiri!C3:C200,(Akiri!B3:B200<>Akiri!C3:C200)*(Akiri!C3:C200<>"")))=0,"",_xlfn._xlws.SORT(_xlfn._xlws.FILTER(Akiri!C3:C200,(Akiri!B3:B200<>Akiri!C3:C200)*(Akiri!C3:C200<>"")),1,1))} -> Cid, Freeflier Pilot | AJ2: {=IF(COUNTA(_xlfn._xlws.FILTER(Sisay!C3:C200,(Sisay!B3:B200<>Sisay!C3:C200)*(Sisay!C3:C200<>"")))=0,"",_xlfn._xlws.SORT(_xlfn._xlws.FILTER(Sisay!C3:C200,(Sisay!B3:B200<>Sisay!C3:C200)*(Sisay!C3:C200<>"")),1,1))} -> Commodore Guff | AK2: {=IF(COUNTA(_xlfn._xlws.FILTER(Thrakiri!C3:C200,(Thrakiri!B3:B200<>Thrakiri!C3:C200)*(Thrakiri!C3:C200<>"")))=0,"",_xlfn._xlws.SORT(_xlfn._xlws.FILTER(Thrakiri!C3:C200,(Thrakiri!B3:B200<>Thrakiri!C3:C200)*(Thrakiri!C3:C200<>"")),1,1))} -> Matoya, Archon Elder | AL2: {=IF(COUNTA(_xlfn._xlws.FILTER(Elfos!C3:C200,(Elfos!B3:B200<>Elfos!C3:C200)*(Elfos!C3:C200<>"")))=0,"",_xlfn._xlws.SORT(_xlfn._xlws.FILTER(Elfos!C3:C200,(Elfos!B3:B200<>Elfos!C3:C200)*(Elfos!C3:C200<>"")),1,1))} -> Alchemist's Refuge | AM2: {=IF(COUNTA(_xlfn._xlws.FILTER(Jhoira!C3:C200,(Jhoira!B3:B200<>Jhoira!C3:C200)*(Jhoira!C3:C200<>"")))=0,"",_xlfn._xlws.SORT(_xlfn._xlws.FILTER(Jhoira!C3:C200,(Jhoira!B3:B200<>Jhoira!C3:C200)*(Jhoira!C3:C200<>"")),1,1))} -> Emrakul, um Novo Mundo | AN2: {=IF(COUNTA(_xlfn._xlws.FILTER(Fractius!C3:C200,(Fractius!B3:B200<>Fractius!C3:C200)*(Fractius!C3:C200<>"")))=0,"",_xlfn._xlws.SORT(_xlfn._xlws.FILTER(Fractius!C3:C200,(Fractius!B3:B200<>Fractius!C3:C200)*(Fractius!C3:C200<>"")),1,1))} -> Caverna das Almas | AO2: {=IF(COUNTA(_xlfn._xlws.FILTER(Rielle!C3:C200,(Rielle!B3:B200<>Rielle!C3:C200)*(Rielle!C3:C200<>"")))=0,"",_xlfn._xlws.SORT(_xlfn._xlws.FILTER(Rielle!C3:C200,(Rielle!B3:B200<>Rielle!C3:C200)*(Rielle!C3:C200<>"")),1,1))} -> Afundar em Estupor | AP2: {=IF(COUNTA(_xlfn._xlws.FILTER(Oona!C3:C200,(Oona!B3:B200<>Oona!C3:C200)*(Oona!C3:C200<>"")))=0,"",_xlfn._xlws.SORT(_xlfn._xlws.FILTER(Oona!C3:C200,(Oona!B3:B200<>Oona!C3:C200)*(Oona!C3:C200<>"")),1,1))} -> Invasion of Segovia | AQ2: {=IF(COUNTA(_xlfn._xlws.FILTER(Kresh!C3:C200,(Kresh!B3:B200<>Kresh!C3:C200)*(Kresh!C3:C200<>"")))=0,"",_xlfn._xlws.SORT(_xlfn._xlws.FILTER(Kresh!C3:C200,(Kresh!B3:B200<>Kresh!C3:C200)*(Kresh!C3:C200<>"")),1,1))} -> Bugenhagen, Wise Elder | AR2: {=IF(COUNTA(_xlfn._xlws.FILTER(Breya!C3:C200,(Breya!B3:B200<>Breya!C3:C200)*(Breya!C3:C200<>"")))=0,"",_xlfn._xlws.SORT(_xlfn._xlws.FILTER(Breya!C3:C200,(Breya!B3:B200<>Breya!C3:C200)*(Breya!C3:C200<>"")),1,1))} -> Adagia, Windswept Bastion | AS2: {=IF(COUNTA(_xlfn._xlws.FILTER(OWA!C3:C200,(OWA!B3:B200<>OWA!C3:C200)*(OWA!C3:C200<>"")))=0,"",_xlfn._xlws.SORT(_xlfn._xlws.FILTER(OWA!C3:C200,(OWA!B3:B200<>OWA!C3:C200)*(OWA!C3:C200<>"")),1,1))} -> Dollmaker's Shop // Porcelain Gallery | AT2: {=IF(COUNTA(_xlfn._xlws.FILTER(Alela!C3:C200,(Alela!B3:B200<>Alela!C3:C200)*(Alela!C3:C200<>"")))=0,"",_xlfn._xlws.SORT(_xlfn._xlws.FILTER(Alela!C3:C200,(Alela!B3:B200<>Alela!C3:C200)*(Alela!C3:C200<>"")),1,1))} -> Adagia, Windswept Bastion | AU2: {=IF(COUNTA(_xlfn._xlws.FILTER(Arcades!C3:C200,(Arcades!B3:B200<>Arcades!C3:C200)*(Arcades!C3:C200<>"")))=0,"",_xlfn._xlws.SORT(_xlfn._xlws.FILTER(Arcades!C3:C200,(Arcades!B3:B200<>Arcades!C3:C200)*(Arcades!C3:C200<>"")),1,1))} -> Alchemist's Refuge | AV2: {=IF(COUNTA(_xlfn._xlws.FILTER(Zedruu!C3:C200,(Zedruu!B3:B200<>Zedruu!C3:C200)*(Zedruu!C3:C200<>"")))=0,"",_xlfn._xlws.SORT(_xlfn._xlws.FILTER(Zedruu!C3:C200,(Zedruu!B3:B200<>Zedruu!C3:C200)*(Zedruu!C3:C200<>"")),1,1))} -> Árbitro Silencioso | AW2: {=IF(COUNTA(_xlfn._xlws.FILTER(Exaltado!C3:C200,(Exaltado!B3:B200<>Exaltado!C3:C200)*(Exaltado!C3:C200<>"")))=0,"",_xlfn._xlws.SORT(_xlfn._xlws.FILTER(Exaltado!C3:C200,(Exaltado!B3:B200<>Exaltado!C3:C200)*(Exaltado!C3:C200<>"")),1,1))} -> #VALUE! | AX2: {=IF(COUNTA(_xlfn._xlws.FILTER(Modular!C3:C200,(Modular!B3:B200<>Modular!C3:C200)*(Modular!C3:C200<>"")))=0,"",_xlfn._xlws.SORT(_xlfn._xlws.FILTER(Modular!C3:C200,(Modular!B3:B200<>Modular!C3:C200)*(Modular!C3:C200<>"")),1,1))} -> Adagia, Windswept Bastion | AZ2: {=IF(COUNTA(_xlfn._xlws.FILTER(Thrakiri!C3:C103,(Thrakiri!B3:B103<>Thrakiri!C3:C103)*(Thrakiri!C3:C103<>"")))+COUNTA(_xlfn._xlws.FILTER(Gitrog!C3:C102,(Gitrog!B3:B102<>Gitrog!C3:C102)*(Gitrog!C3:C102<>"")))+COUNTA(_xlfn._xlws.FILTER(Elfos!C3:C103,(Elfos!B3:B103<>Elfos!C3:C103)*(Elfos!C3:C103<>"")))=0,"",_xlfn._xlws.SORT(_xlfn.UNIQUE(IF(ROW(INDIRECT("1:"&(COUNTA(_xlfn._xlws.FILTER(Thrakiri!C3:C103,(Thrakiri!B3:B103<>Thrakiri!C3:C103)*(Thrakiri!C3:C103<>"")))+COUNTA(_xlfn._xlws.FILTER(Gitrog!C3:C102,(Gitrog!B3:B102<>Gitrog!C3:C102)*(Gitrog!C3:C102<>"")))+COUNTA(_xlfn._xlws.FILTER(Elfos!C3:C103,(Elfos!B3:B103<>Elfos!C3:C103)*(Elfos!C3:C103<>""))))))<=COUNTA(_xlfn._xlws.FILTER(Thrakiri!C3:C103,(Thrakiri!B3:B103<>Thrakiri!C3:C103)*(Thrakiri!C3:C103<>""))),INDEX(_xlfn._xlws.FILTER(Thrakiri!C3:C103,(Thrakiri!B3:B103<>Thrakiri!C3:C103)*(Thrakiri!C3:C103<>"")),ROW(INDIRECT("1:"&(COUNTA(_xlfn._xlws.FILTER(Thrakiri!C3:C103,(Thrakiri!B3:B103<>Thrakiri!C3:C103)*(Thrakiri!C3:C103<>"")))+COUNTA(_xlfn._xlws.FILTER(Gitrog!C3:C102,(Gitrog!B3:B102<>Gitrog!C3:C102)*(Gitrog!C3:C102<>"")))+COUNTA(_xlfn._xlws.FILTER(Elfos!C3:C103,(Elfos!B3:B103<>Elfos!C3:C103)*(Elfos!C3:C103<>""))))))),IF(ROW(INDIRECT("1:"&(COUNTA(_xlfn._xlws.FILTER(Thrakiri!C3:C103,(Thrakiri!B3:B103<>Thrakiri!C3:C103)*(Thrakiri!C3:C103<>"")))+COUNTA(_xlfn._xlws.FILTER(Gitrog!C3:C102,(Gitrog!B3:B102<>Gitrog!C3:C102)*(Gitrog!C3:C102<>"")))+COUNTA(_xlfn._xlws.FILTER(Elfos!C3:C103,(Elfos!B3:B103<>Elfos!C3:C103)*(Elfos!C3:C103<>""))))))<=COUNTA(_xlfn._xlws.FILTER(Thrakiri!C3:C103,(Thrakiri!B3:B103<>Thrakiri!C3:C103)*(Thrakiri!C3:C103<>"")))+COUNTA(_xlfn._xlws.FILTER(Gitrog!C3:C102,(Gitrog!B3:B102<>Gitrog!C3:C102)*(Gitrog!C3:C102<>""))),INDEX(_xlfn._xlws.FILTER(Gitrog!C3:C102,(Gitrog!B3:B102<>Gitrog!C3:C102)*(Gitrog!C3:C102<>"")),ROW(INDIRECT("1:"&(COUNTA(_xlfn._xlws.FILTER(Thrakiri!C3:C103,(Thrakiri!B3:B103<>Thrakiri!C3:C103)*(Thrakiri!C3:C103<>"")))+COUNTA(_xlfn._xlws.FILTER(Gitrog!C3:C102,(Gitrog!B3:B102<>Gitrog!C3:C102)*(Gitrog!C3:C102<>"")))+COUNTA(_xlfn._xlws.FILTER(Elfos!C3:C103,(Elfos!B3:B103<>Elfos!C3:C103)*(Elfos!C3:C103<>""))))))-COUNTA(_xlfn._xlws.FILTER(Thrakiri!C3:C103,(Thrakiri!B3:B103<>Thrakiri!C3:C103)*(Thrakiri!C3:C103<>"")))),INDEX(_xlfn._xlws.FILTER(Elfos!C3:C103,(Elfos!B3:B103<>Elfos!C3:C103)*(Elfos!C3:C103<>"")),ROW(INDIRECT("1:"&(COUNTA(_xlfn._xlws.FILTER(Thrakiri!C3:C103,(Thrakiri!B3:B103<>Thrakiri!C3:C103)*(Thrakiri!C3:C103<>"")))+COUNTA(_xlfn._xlws.FILTER(Gitrog!C3:C102,(Gitrog!B3:B102<>Gitrog!C3:C102)*(Gitrog!C3:C102<>"")))+COUNTA(_xlfn._xlws.FILTER(Elfos!C3:C103,(Elfos!B3:B103<>Elfos!C3:C103)*(Elfos!C3:C103<>""))))))-COUNTA(_xlfn._xlws.FILTER(Thrakiri!C3:C103,(Thrakiri!B3:B103<>Thrakiri!C3:C103)*(Thrakiri!C3:C103<>"")))-COUNTA(_xlfn._xlws.FILTER(Gitrog!C3:C102,(Gitrog!B3:B102<>Gitrog!C3:C102)*(Gitrog!C3:C102<>"")))))),1,-1)))} -> Alchemist's Refuge | BA2: {=IF(COUNTA(_xlfn._xlws.FILTER(Jhoira!C3:C101,(Jhoira!B3:B101<>Jhoira!C3:C101)*(Jhoira!C3:C101<>"")))+COUNTA(_xlfn._xlws.FILTER(Fractius!C3:C102,(Fractius!B3:B102<>Fractius!C3:C102)*(Fractius!C3:C102<>"")))+COUNTA(_xlfn._xlws.FILTER(Muzzio!C3:C102,(Muzzio!B3:B102<>Muzzio!C3:C102)*(Muzzio!C3:C102<>"")))=0,"",_xlfn._xlws.SORT(_xlfn.UNIQUE(IF(ROW(INDIRECT("1:"&(COUNTA(_xlfn._xlws.FILTER(Jhoira!C3:C101,(Jhoira!B3:B101<>Jhoira!C3:C101)*(Jhoira!C3:C101<>"")))+COUNTA(_xlfn._xlws.FILTER(Fractius!C3:C102,(Fractius!B3:B102<>Fractius!C3:C102)*(Fractius!C3:C102<>"")))+COUNTA(_xlfn._xlws.FILTER(Muzzio!C3:C102,(Muzzio!B3:B102<>Muzzio!C3:C102)*(Muzzio!C3:C102<>""))))))<=COUNTA(_xlfn._xlws.FILTER(Jhoira!C3:C101,(Jhoira!B3:B101<>Jhoira!C3:C101)*(Jhoira!C3:C101<>""))),INDEX(_xlfn._xlws.FILTER(Jhoira!C3:C101,(Jhoira!B3:B101<>Jhoira!C3:C101)*(Jhoira!C3:C101<>"")),ROW(INDIRECT("1:"&(COUNTA(_xlfn._xlws.FILTER(Jhoira!C3:C101,(Jhoira!B3:B101<>Jhoira!C3:C101)*(Jhoira!C3:C101<>"")))+COUNTA(_xlfn._xlws.FILTER(Fractius!C3:C102,(Fractius!B3:B102<>Fractius!C3:C102)*(Fractius!C3:C102<>"")))+COUNTA(_xlfn._xlws.FILTER(Muzzio!C3:C102,(Muzzio!B3:B102<>Muzzio!C3:C102)*(Muzzio!C3:C102<>""))))))),IF(ROW(INDIRECT("1:"&(COUNTA(_xlfn._xlws.FILTER(Jhoira!C3:C101,(Jhoira!B3:B101<>Jhoira!C3:C101)*(Jhoira!C3:C101<>"")))+COUNTA(_xlfn._xlws.FILTER(Fractius!C3:C102,(Fractius!B3:B102<>Fractius!C3:C102)*(Fractius!C3:C102<>"")))+COUNTA(_xlfn._xlws.FILTER(Muzzio!C3:C102,(Muzzio!B3:B102<>Muzzio!C3:C102)*(Muzzio!C3:C102<>""))))))<=COUNTA(_xlfn._xlws.FILTER(Jhoira!C3:C101,(Jhoira!B3:B101<>Jhoira!C3:C101)*(Jhoira!C3:C101<>"")))+COUNTA(_xlfn._xlws.FILTER(Fractius!C3:C102,(Fractius!B3:B102<>Fractius!C3:C102)*(Fractius!C3:C102<>""))),INDEX(_xlfn._xlws.FILTER(Fractius!C3:C102,(Fractius!B3:B102<>Fractius!C3:C102)*(Fractius!C3:C102<>"")),ROW(INDIRECT("1:"&(COUNTA(_xlfn._xlws.FILTER(Jhoira!C3:C101,(Jhoira!B3:B101<>Jhoira!C3:C101)*(Jhoira!C3:C101<>"")))+COUNTA(_xlfn._xlws.FILTER(Fractius!C3:C102,(Fractius!B3:B102<>Fractius!C3:C102)*(Fractius!C3:C102<>"")))+COUNTA(_xlfn._xlws.FILTER(Muzzio!C3:C102,(Muzzio!B3:B102<>Muzzio!C3:C102)*(Muzzio!C3:C102<>""))))))-COUNTA(_xlfn._xlws.FILTER(Jhoira!C3:C101,(Jhoira!B3:B101<>Jhoira!C3:C101)*(Jhoira!C3:C101<>"")))),INDEX(_xlfn._xlws.FILTER(Muzzio!C3:C102,(Muzzio!B3:B102<>Muzzio!C3:C102)*(Muzzio!C3:C102<>"")),ROW(INDIRECT("1:"&(COUNTA(_xlfn._xlws.FILTER(Jhoira!C3:C101,(Jhoira!B3:B101<>Jhoira!C3:C101)*(Jhoira!C3:C101<>"")))+COUNTA(_xlfn._xlws.FILTER(Fractius!C3:C102,(Fractius!B3:B102<>Fractius!C3:C102)*(Fractius!C3:C102<>"")))+COUNTA(_xlfn._xlws.FILTER(Muzzio!C3:C102,(Muzzio!B3:B102<>Muzzio!C3:C102)*(Muzzio!C3:C102<>""))))))-COUNTA(_xlfn._xlws.FILTER(Jhoira!C3:C101,(Jhoira!B3:B101<>Jhoira!C3:C101)*(Jhoira!C3:C101<>"")))-COUNTA(_xlfn._xlws.FILTER(Fractius!C3:C102,(Fractius!B3:B102<>Fractius!C3:C102)*(Fractius!C3:C102<>"")))))),1,-1)))} -> A Joia do Enigma | BB2: {=IF(COUNTA(_xlfn._xlws.FILTER(Rielle!C3:C102,(Rielle!B3:B102<>Rielle!C3:C102)*(Rielle!C3:C102<>"")))+COUNTA(_xlfn._xlws.FILTER(Alela!C3:C102,(Alela!B3:B102<>Alela!C3:C102)*(Alela!C3:C102<>"")))+COUNTA(_xlfn._xlws.FILTER(Arcades!C3:C102,(Arcades!B3:B102<>Arcades!C3:C102)*(Arcades!C3:C102<>"")))=0,"",_xlfn._xlws.SORT(_xlfn.UNIQUE(IF(ROW(INDIRECT("1:"&(COUNTA(_xlfn._xlws.FILTER(Rielle!C3:C102,(Rielle!B3:B102<>Rielle!C3:C102)*(Rielle!C3:C102<>"")))+COUNTA(_xlfn._xlws.FILTER(Alela!C3:C102,(Alela!B3:B102<>Alela!C3:C102)*(Alela!C3:C102<>"")))+COUNTA(_xlfn._xlws.FILTER(Arcades!C3:C102,(Arcades!B3:B102<>Arcades!C3:C102)*(Arcades!C3:C102<>""))))))<=COUNTA(_xlfn._xlws.FILTER(Rielle!C3:C102,(Rielle!B3:B102<>Rielle!C3:C102)*(Rielle!C3:C102<>""))),INDEX(_xlfn._xlws.FILTER(Rielle!C3:C102,(Rielle!B3:B102<>Rielle!C3:C102)*(Rielle!C3:C102<>"")),ROW(INDIRECT("1:"&(COUNTA(_xlfn._xlws.FILTER(Rielle!C3:C102,(Rielle!B3:B102<>Rielle!C3:C102)*(Rielle!C3:C102<>"")))+COUNTA(_xlfn._xlws.FILTER(Alela!C3:C102,(Alela!B3:B102<>Alela!C3:C102)*(Alela!C3:C102<>"")))+COUNTA(_xlfn._xlws.FILTER(Arcades!C3:C102,(Arcades!B3:B102<>Arcades!C3:C102)*(Arcades!C3:C102<>""))))))),IF(ROW(INDIRECT("1:"&(COUNTA(_xlfn._xlws.FILTER(Rielle!C3:C102,(Rielle!B3:B102<>Rielle!C3:C102)*(Rielle!C3:C102<>"")))+COUNTA(_xlfn._xlws.FILTER(Alela!C3:C102,(Alela!B3:B102<>Alela!C3:C102)*(Alela!C3:C102<>"")))+COUNTA(_xlfn._xlws.FILTER(Arcades!C3:C102,(Arcades!B3:B102<>Arcades!C3:C102)*(Arcades!C3:C102<>""))))))<=COUNTA(_xlfn._xlws.FILTER(Rielle!C3:C102,(Rielle!B3:B102<>Rielle!C3:C102)*(Rielle!C3:C102<>"")))+COUNTA(_xlfn._xlws.FILTER(Alela!C3:C102,(Alela!B3:B102<>Alela!C3:C102)*(Alela!C3:C102<>""))),INDEX(_xlfn._xlws.FILTER(Alela!C3:C102,(Alela!B3:B102<>Alela!C3:C102)*(Alela!C3:C102<>"")),ROW(INDIRECT("1:"&(COUNTA(_xlfn._xlws.FILTER(Rielle!C3:C102,(Rielle!B3:B102<>Rielle!C3:C102)*(Rielle!C3:C102<>"")))+COUNTA(_xlfn._xlws.FILTER(Alela!C3:C102,(Alela!B3:B102<>Alela!C3:C102)*(Alela!C3:C102<>"")))+COUNTA(_xlfn._xlws.FILTER(Arcades!C3:C102,(Arcades!B3:B102<>Arcades!C3:C102)*(Arcades!C3:C102<>""))))))-COUNTA(_xlfn._xlws.FILTER(Rielle!C3:C102,(Rielle!B3:B102<>Rielle!C3:C102)*(Rielle!C3:C102<>"")))),INDEX(_xlfn._xlws.FILTER(Arcades!C3:C102,(Arcades!B3:B102<>Arcades!C3:C102)*(Arcades!C3:C102<>"")),ROW(INDIRECT("1:"&(COUNTA(_xlfn._xlws.FILTER(Rielle!C3:C102,(Rielle!B3:B102<>Rielle!C3:C102)*(Rielle!C3:C102<>"")))+COUNTA(_xlfn._xlws.FILTER(Alela!C3:C102,(Alela!B3:B102<>Alela!C3:C102)*(Alela!C3:C102<>"")))+COUNTA(_xlfn._xlws.FILTER(Arcades!C3:C102,(Arcades!B3:B102<>Arcades!C3:C102)*(Arcades!C3:C102<>""))))))-COUNTA(_xlfn._xlws.FILTER(Rielle!C3:C102,(Rielle!B3:B102<>Rielle!C3:C102)*(Rielle!C3:C102<>"")))-COUNTA(_xlfn._xlws.FILTER(Alela!C3:C102,(Alela!B3:B102<>Alela!C3:C102)*(Alela!C3:C102<>"")))))),1,-1)))} -> Adagia, Windswept Bastion | BC2: {=IF(COUNTA(_xlfn._xlws.FILTER(VialIshai!C3:C103,(VialIshai!B3:B103<>VialIshai!C3:C103)*(VialIshai!C3:C103<>"")))+COUNTA(_xlfn._xlws.FILTER(Yuriko!C3:C102,(Yuriko!B3:B102<>Yuriko!C3:C102)*(Yuriko!C3:C102<>"")))+COUNTA(_xlfn._xlws.FILTER(Zedruu!C3:C102,(Zedruu!B3:B102<>Zedruu!C3:C102)*(Zedruu!C3:C102<>"")))=0,"",_xlfn._xlws.SORT(_xlfn.UNIQUE(IF(ROW(INDIRECT("1:"&(COUNTA(_xlfn._xlws.FILTER(VialIshai!C3:C103,(VialIshai!B3:B103<>VialIshai!C3:C103)*(VialIshai!C3:C103<>"")))+COUNTA(_xlfn._xlws.FILTER(Yuriko!C3:C102,(Yuriko!B3:B102<>Yuriko!C3:C102)*(Yuriko!C3:C102<>"")))+COUNTA(_xlfn._xlws.FILTER(Zedruu!C3:C102,(Zedruu!B3:B102<>Zedruu!C3:C102)*(Zedruu!C3:C102<>""))))))<=COUNTA(_xlfn._xlws.FILTER(VialIshai!C3:C103,(VialIshai!B3:B103<>VialIshai!C3:C103)*(VialIshai!C3:C103<>""))),INDEX(_xlfn._xlws.FILTER(VialIshai!C3:C103,(VialIshai!B3:B103<>VialIshai!C3:C103)*(VialIshai!C3:C103<>"")),ROW(INDIRECT("1:"&(COUNTA(_xlfn._xlws.FILTER(VialIshai!C3:C103,(VialIshai!B3:B103<>VialIshai!C3:C103)*(VialIshai!C3:C103<>"")))+COUNTA(_xlfn._xlws.FILTER(Yuriko!C3:C102,(Yuriko!B3:B102<>Yuriko!C3:C102)*(Yuriko!C3:C102<>"")))+COUNTA(_xlfn._xlws.FILTER(Zedruu!C3:C102,(Zedruu!B3:B102<>Zedruu!C3:C102)*(Zedruu!C3:C102<>""))))))),IF(ROW(INDIRECT("1:"&(COUNTA(_xlfn._xlws.FILTER(VialIshai!C3:C103,(VialIshai!B3:B103<>VialIshai!C3:C103)*(VialIshai!C3:C103<>"")))+COUNTA(_xlfn._xlws.FILTER(Yuriko!C3:C102,(Yuriko!B3:B102<>Yuriko!C3:C102)*(Yuriko!C3:C102<>"")))+COUNTA(_xlfn._xlws.FILTER(Zedruu!C3:C102,(Zedruu!B3:B102<>Zedruu!C3:C102)*(Zedruu!C3:C102<>""))))))<=COUNTA(_xlfn._xlws.FILTER(VialIshai!C3:C103,(VialIshai!B3:B103<>VialIshai!C3:C103)*(VialIshai!C3:C103<>"")))+COUNTA(_xlfn._xlws.FILTER(Yuriko!C3:C102,(Yuriko!B3:B102<>Yuriko!C3:C102)*(Yuriko!C3:C102<>""))),INDEX(_xlfn._xlws.FILTER(Yuriko!C3:C102,(Yuriko!B3:B102<>Yuriko!C3:C102)*(Yuriko!C3:C102<>"")),ROW(INDIRECT("1:"&(COUNTA(_xlfn._xlws.FILTER(VialIshai!C3:C103,(VialIshai!B3:B103<>VialIshai!C3:C103)*(VialIshai!C3:C103<>"")))+COUNTA(_xlfn._xlws.FILTER(Yuriko!C3:C102,(Yuriko!B3:B102<>Yuriko!C3:C102)*(Yuriko!C3:C102<>"")))+COUNTA(_xlfn._xlws.FILTER(Zedruu!C3:C102,(Zedruu!B3:B102<>Zedruu!C3:C102)*(Zedruu!C3:C102<>""))))))-COUNTA(_xlfn._xlws.FILTER(VialIshai!C3:C103,(VialIshai!B3:B103<>VialIshai!C3:C103)*(VialIshai!C3:C103<>"")))),INDEX(_xlfn._xlws.FILTER(Zedruu!C3:C102,(Zedruu!B3:B102<>Zedruu!C3:C102)*(Zedruu!C3:C102<>"")),ROW(INDIRECT("1:"&(COUNTA(_xlfn._xlws.FILTER(VialIshai!C3:C103,(VialIshai!B3:B103<>VialIshai!C3:C103)*(VialIshai!C3:C103<>"")))+COUNTA(_xlfn._xlws.FILTER(Yuriko!C3:C102,(Yuriko!B3:B102<>Yuriko!C3:C102)*(Yuriko!C3:C102<>"")))+COUNTA(_xlfn._xlws.FILTER(Zedruu!C3:C102,(Zedruu!B3:B102<>Zedruu!C3:C102)*(Zedruu!C3:C102<>""))))))-COUNTA(_xlfn._xlws.FILTER(VialIshai!C3:C103,(VialIshai!B3:B103<>VialIshai!C3:C103)*(VialIshai!C3:C103<>"")))-COUNTA(_xlfn._xlws.FILTER(Yuriko!C3:C102,(Yuriko!B3:B102<>Yuriko!C3:C102)*(Yuriko!C3:C102<>"")))))),1,-1)))} -> Amphibian Downpour | BD2: {=IF(COUNTA(_xlfn._xlws.FILTER(Inalla!C3:C102,(Inalla!B3:B102<>Inalla!C3:C102)*(Inalla!C3:C102<>"")))+COUNTA(_xlfn._xlws.FILTER(Carlos!C3:C102,(Carlos!B3:B102<>Carlos!C3:C102)*(Carlos!C3:C102<>"")))+COUNTA(_xlfn._xlws.FILTER(Oona!C3:C102,(Oona!B3:B102<>Oona!C3:C102)*(Oona!C3:C102<>"")))=0,"",_xlfn._xlws.SORT(_xlfn.UNIQUE(IF(ROW(INDIRECT("1:"&(COUNTA(_xlfn._xlws.FILTER(Inalla!C3:C102,(Inalla!B3:B102<>Inalla!C3:C102)*(Inalla!C3:C102<>"")))+COUNTA(_xlfn._xlws.FILTER(Carlos!C3:C102,(Carlos!B3:B102<>Carlos!C3:C102)*(Carlos!C3:C102<>"")))+COUNTA(_xlfn._xlws.FILTER(Oona!C3:C102,(Oona!B3:B102<>Oona!C3:C102)*(Oona!C3:C102<>""))))))<=COUNTA(_xlfn._xlws.FILTER(Inalla!C3:C102,(Inalla!B3:B102<>Inalla!C3:C102)*(Inalla!C3:C102<>""))),INDEX(_xlfn._xlws.FILTER(Inalla!C3:C102,(Inalla!B3:B102<>Inalla!C3:C102)*(Inalla!C3:C102<>"")),ROW(INDIRECT("1:"&(COUNTA(_xlfn._xlws.FILTER(Inalla!C3:C102,(Inalla!B3:B102<>Inalla!C3:C102)*(Inalla!C3:C102<>"")))+COUNTA(_xlfn._xlws.FILTER(Carlos!C3:C102,(Carlos!B3:B102<>Carlos!C3:C102)*(Carlos!C3:C102<>"")))+COUNTA(_xlfn._xlws.FILTER(Oona!C3:C102,(Oona!B3:B102<>Oona!C3:C102)*(Oona!C3:C102<>""))))))),IF(ROW(INDIRECT("1:"&(COUNTA(_xlfn._xlws.FILTER(Inalla!C3:C102,(Inalla!B3:B102<>Inalla!C3:C102)*(Inalla!C3:C102<>"")))+COUNTA(_xlfn._xlws.FILTER(Carlos!C3:C102,(Carlos!B3:B102<>Carlos!C3:C102)*(Carlos!C3:C102<>"")))+COUNTA(_xlfn._xlws.FILTER(Oona!C3:C102,(Oona!B3:B102<>Oona!C3:C102)*(Oona!C3:C102<>""))))))<=COUNTA(_xlfn._xlws.FILTER(Inalla!C3:C102,(Inalla!B3:B102<>Inalla!C3:C102)*(Inalla!C3:C102<>"")))+COUNTA(_xlfn._xlws.FILTER(Carlos!C3:C102,(Carlos!B3:B102<>Carlos!C3:C102)*(Carlos!C3:C102<>""))),INDEX(_xlfn._xlws.FILTER(Carlos!C3:C102,(Carlos!B3:B102<>Carlos!C3:C102)*(Carlos!C3:C102<>"")),ROW(INDIRECT("1:"&(COUNTA(_xlfn._xlws.FILTER(Inalla!C3:C102,(Inalla!B3:B102<>Inalla!C3:C102)*(Inalla!C3:C102<>"")))+COUNTA(_xlfn._xlws.FILTER(Carlos!C3:C102,(Carlos!B3:B102<>Carlos!C3:C102)*(Carlos!C3:C102<>"")))+COUNTA(_xlfn._xlws.FILTER(Oona!C3:C102,(Oona!B3:B102<>Oona!C3:C102)*(Oona!C3:C102<>""))))))-COUNTA(_xlfn._xlws.FILTER(Inalla!C3:C102,(Inalla!B3:B102<>Inalla!C3:C102)*(Inalla!C3:C102<>"")))),INDEX(_xlfn._xlws.FILTER(Oona!C3:C102,(Oona!B3:B102<>Oona!C3:C102)*(Oona!C3:C102<>"")),ROW(INDIRECT("1:"&(COUNTA(_xlfn._xlws.FILTER(Inalla!C3:C102,(Inalla!B3:B102<>Inalla!C3:C102)*(Inalla!C3:C102<>"")))+COUNTA(_xlfn._xlws.FILTER(Carlos!C3:C102,(Carlos!B3:B102<>Carlos!C3:C102)*(Carlos!C3:C102<>"")))+COUNTA(_xlfn._xlws.FILTER(Oona!C3:C102,(Oona!B3:B102<>Oona!C3:C102)*(Oona!C3:C102<>""))))))-COUNTA(_xlfn._xlws.FILTER(Inalla!C3:C102,(Inalla!B3:B102<>Inalla!C3:C102)*(Inalla!C3:C102<>"")))-COUNTA(_xlfn._xlws.FILTER(Carlos!C3:C102,(Carlos!B3:B102<>Carlos!C3:C102)*(Carlos!C3:C102<>"")))))),1,-1)))} -> Arcane Lighthouse | BE2: {=IF(COUNTA(_xlfn._xlws.FILTER(Kresh!C3:C102,(Kresh!B3:B102<>Kresh!C3:C102)*(Kresh!C3:C102<>"")))+COUNTA(_xlfn._xlws.FILTER(Akiri!C3:C102,(Akiri!B3:B102<>Akiri!C3:C102)*(Akiri!C3:C102<>"")))+COUNTA(_xlfn._xlws.FILTER(Breya!C3:C102,(Breya!B3:B102<>Breya!C3:C102)*(Breya!C3:C102<>"")))=0,"",_xlfn._xlws.SORT(_xlfn.UNIQUE(IF(ROW(INDIRECT("1:"&(COUNTA(_xlfn._xlws.FILTER(Kresh!C3:C102,(Kresh!B3:B102<>Kresh!C3:C102)*(Kresh!C3:C102<>"")))+COUNTA(_xlfn._xlws.FILTER(Akiri!C3:C102,(Akiri!B3:B102<>Akiri!C3:C102)*(Akiri!C3:C102<>"")))+COUNTA(_xlfn._xlws.FILTER(Breya!C3:C102,(Breya!B3:B102<>Breya!C3:C102)*(Breya!C3:C102<>""))))))<=COUNTA(_xlfn._xlws.FILTER(Kresh!C3:C102,(Kresh!B3:B102<>Kresh!C3:C102)*(Kresh!C3:C102<>""))),INDEX(_xlfn._xlws.FILTER(Kresh!C3:C102,(Kresh!B3:B102<>Kresh!C3:C102)*(Kresh!C3:C102<>"")),ROW(INDIRECT("1:"&(COUNTA(_xlfn._xlws.FILTER(Kresh!C3:C102,(Kresh!B3:B102<>Kresh!C3:C102)*(Kresh!C3:C102<>"")))+COUNTA(_xlfn._xlws.FILTER(Akiri!C3:C102,(Akiri!B3:B102<>Akiri!C3:C102)*(Akiri!C3:C102<>"")))+COUNTA(_xlfn._xlws.FILTER(Breya!C3:C102,(Breya!B3:B102<>Breya!C3:C102)*(Breya!C3:C102<>""))))))),IF(ROW(INDIRECT("1:"&(COUNTA(_xlfn._xlws.FILTER(Kresh!C3:C102,(Kresh!B3:B102<>Kresh!C3:C102)*(Kresh!C3:C102<>"")))+COUNTA(_xlfn._xlws.FILTER(Akiri!C3:C102,(Akiri!B3:B102<>Akiri!C3:C102)*(Akiri!C3:C102<>"")))+COUNTA(_xlfn._xlws.FILTER(Breya!C3:C102,(Breya!B3:B102<>Breya!C3:C102)*(Breya!C3:C102<>""))))))<=COUNTA(_xlfn._xlws.FILTER(Kresh!C3:C102,(Kresh!B3:B102<>Kresh!C3:C102)*(Kresh!C3:C102<>"")))+COUNTA(_xlfn._xlws.FILTER(Akiri!C3:C102,(Akiri!B3:B102<>Akiri!C3:C102)*(Akiri!C3:C102<>""))),INDEX(_xlfn._xlws.FILTER(Akiri!C3:C102,(Akiri!B3:B102<>Akiri!C3:C102)*(Akiri!C3:C102<>"")),ROW(INDIRECT("1:"&(COUNTA(_xlfn._xlws.FILTER(Kresh!C3:C102,(Kresh!B3:B102<>Kresh!C3:C102)*(Kresh!C3:C102<>"")))+COUNTA(_xlfn._xlws.FILTER(Akiri!C3:C102,(Akiri!B3:B102<>Akiri!C3:C102)*(Akiri!C3:C102<>"")))+COUNTA(_xlfn._xlws.FILTER(Breya!C3:C102,(Breya!B3:B102<>Breya!C3:C102)*(Breya!C3:C102<>""))))))-COUNTA(_xlfn._xlws.FILTER(Kresh!C3:C102,(Kresh!B3:B102<>Kresh!C3:C102)*(Kresh!C3:C102<>"")))),INDEX(_xlfn._xlws.FILTER(Breya!C3:C102,(Breya!B3:B102<>Breya!C3:C102)*(Breya!C3:C102<>"")),ROW(INDIRECT("1:"&(COUNTA(_xlfn._xlws.FILTER(Kresh!C3:C102,(Kresh!B3:B102<>Kresh!C3:C102)*(Kresh!C3:C102<>"")))+COUNTA(_xlfn._xlws.FILTER(Akiri!C3:C102,(Akiri!B3:B102<>Akiri!C3:C102)*(Akiri!C3:C102<>"")))+COUNTA(_xlfn._xlws.FILTER(Breya!C3:C102,(Breya!B3:B102<>Breya!C3:C102)*(Breya!C3:C102<>""))))))-COUNTA(_xlfn._xlws.FILTER(Kresh!C3:C102,(Kresh!B3:B102<>Kresh!C3:C102)*(Kresh!C3:C102<>"")))-COUNTA(_xlfn._xlws.FILTER(Akiri!C3:C102,(Akiri!B3:B102<>Akiri!C3:C102)*(Akiri!C3:C102<>"")))))),1,-1)))} -> Adagia, Windswept Bastion | BF2: {=IF(COUNTA(_xlfn._xlws.FILTER(Rani!C3:C102,(Rani!B3:B102<>Rani!C3:C102)*(Rani!C3:C102<>"")))+COUNTA(_xlfn._xlws.FILTER(Sisay!C3:C102,(Sisay!B3:B102<>Sisay!C3:C102)*(Sisay!C3:C102<>"")))+COUNTA(_xlfn._xlws.FILTER(OWA!C3:C103,(OWA!B3:B103<>OWA!C3:C103)*(OWA!C3:C103<>"")))=0,"",_xlfn._xlws.SORT(_xlfn.UNIQUE(IF(ROW(INDIRECT("1:"&(COUNTA(_xlfn._xlws.FILTER(Rani!C3:C102,(Rani!B3:B102<>Rani!C3:C102)*(Rani!C3:C102<>"")))+COUNTA(_xlfn._xlws.FILTER(Sisay!C3:C102,(Sisay!B3:B102<>Sisay!C3:C102)*(Sisay!C3:C102<>"")))+COUNTA(_xlfn._xlws.FILTER(OWA!C3:C103,(OWA!B3:B103<>OWA!C3:C103)*(OWA!C3:C103<>""))))))<=COUNTA(_xlfn._xlws.FILTER(Rani!C3:C102,(Rani!B3:B102<>Rani!C3:C102)*(Rani!C3:C102<>""))),INDEX(_xlfn._xlws.FILTER(Rani!C3:C102,(Rani!B3:B102<>Rani!C3:C102)*(Rani!C3:C102<>"")),ROW(INDIRECT("1:"&(COUNTA(_xlfn._xlws.FILTER(Rani!C3:C102,(Rani!B3:B102<>Rani!C3:C102)*(Rani!C3:C102<>"")))+COUNTA(_xlfn._xlws.FILTER(Sisay!C3:C102,(Sisay!B3:B102<>Sisay!C3:C102)*(Sisay!C3:C102<>"")))+COUNTA(_xlfn._xlws.FILTER(OWA!C3:C103,(OWA!B3:B103<>OWA!C3:C103)*(OWA!C3:C103<>""))))))),IF(ROW(INDIRECT("1:"&(COUNTA(_xlfn._xlws.FILTER(Rani!C3:C102,(Rani!B3:B102<>Rani!C3:C102)*(Rani!C3:C102<>"")))+COUNTA(_xlfn._xlws.FILTER(Sisay!C3:C102,(Sisay!B3:B102<>Sisay!C3:C102)*(Sisay!C3:C102<>"")))+COUNTA(_xlfn._xlws.FILTER(OWA!C3:C103,(OWA!B3:B103<>OWA!C3:C103)*(OWA!C3:C103<>""))))))<=COUNTA(_xlfn._xlws.FILTER(Rani!C3:C102,(Rani!B3:B102<>Rani!C3:C102)*(Rani!C3:C102<>"")))+COUNTA(_xlfn._xlws.FILTER(Sisay!C3:C102,(Sisay!B3:B102<>Sisay!C3:C102)*(Sisay!C3:C102<>""))),INDEX(_xlfn._xlws.FILTER(Sisay!C3:C102,(Sisay!B3:B102<>Sisay!C3:C102)*(Sisay!C3:C102<>"")),ROW(INDIRECT("1:"&(COUNTA(_xlfn._xlws.FILTER(Rani!C3:C102,(Rani!B3:B102<>Rani!C3:C102)*(Rani!C3:C102<>"")))+COUNTA(_xlfn._xlws.FILTER(Sisay!C3:C102,(Sisay!B3:B102<>Sisay!C3:C102)*(Sisay!C3:C102<>"")))+COUNTA(_xlfn._xlws.FILTER(OWA!C3:C103,(OWA!B3:B103<>OWA!C3:C103)*(OWA!C3:C103<>""))))))-COUNTA(_xlfn._xlws.FILTER(Rani!C3:C102,(Rani!B3:B102<>Rani!C3:C102)*(Rani!C3:C102<>"")))),INDEX(_xlfn._xlws.FILTER(OWA!C3:C103,(OWA!B3:B103<>OWA!C3:C103)*(OWA!C3:C103<>"")),ROW(INDIRECT("1:"&(COUNTA(_xlfn._xlws.FILTER(Rani!C3:C102,(Rani!B3:B102<>Rani!C3:C102)*(Rani!C3:C102<>"")))+COUNTA(_xlfn._xlws.FILTER(Sisay!C3:C102,(Sisay!B3:B102<>Sisay!C3:C102)*(Sisay!C3:C102<>"")))+COUNTA(_xlfn._xlws.FILTER(OWA!C3:C103,(OWA!B3:B103<>OWA!C3:C103)*(OWA!C3:C103<>""))))))-COUNTA(_xlfn._xlws.FILTER(Rani!C3:C102,(Rani!B3:B102<>Rani!C3:C102)*(Rani!C3:C102<>"")))-COUNTA(_xlfn._xlws.FILTER(Sisay!C3:C102,(Sisay!B3:B102<>Sisay!C3:C102)*(Sisay!C3:C102<>"")))))),1,-1)))} -> Access Tunnel | BG2: {=IF(COUNTA(_xlfn._xlws.FILTER(Narset!C3:C102,(Narset!B3:B102<>Narset!C3:C102)*(Narset!C3:C102<>"")))+COUNTA(_xlfn._xlws.FILTER(Kumena!C3:C102,(Kumena!B3:B102<>Kumena!C3:C102)*(Kumena!C3:C102<>"")))+COUNTA(_xlfn._xlws.FILTER(Zimone!C3:C102,(Zimone!B3:B102<>Zimone!C3:C102)*(Zimone!C3:C102<>"")))=0,"",_xlfn._xlws.SORT(_xlfn.UNIQUE(IF(ROW(INDIRECT("1:"&(COUNTA(_xlfn._xlws.FILTER(Narset!C3:C102,(Narset!B3:B102<>Narset!C3:C102)*(Narset!C3:C102<>"")))+COUNTA(_xlfn._xlws.FILTER(Kumena!C3:C102,(Kumena!B3:B102<>Kumena!C3:C102)*(Kumena!C3:C102<>"")))+COUNTA(_xlfn._xlws.FILTER(Zimone!C3:C102,(Zimone!B3:B102<>Zimone!C3:C102)*(Zimone!C3:C102<>""))))))<=COUNTA(_xlfn._xlws.FILTER(Narset!C3:C102,(Narset!B3:B102<>Narset!C3:C102)*(Narset!C3:C102<>""))),INDEX(_xlfn._xlws.FILTER(Narset!C3:C102,(Narset!B3:B102<>Narset!C3:C102)*(Narset!C3:C102<>"")),ROW(INDIRECT("1:"&(COUNTA(_xlfn._xlws.FILTER(Narset!C3:C102,(Narset!B3:B102<>Narset!C3:C102)*(Narset!C3:C102<>"")))+COUNTA(_xlfn._xlws.FILTER(Kumena!C3:C102,(Kumena!B3:B102<>Kumena!C3:C102)*(Kumena!C3:C102<>"")))+COUNTA(_xlfn._xlws.FILTER(Zimone!C3:C102,(Zimone!B3:B102<>Zimone!C3:C102)*(Zimone!C3:C102<>""))))))),IF(ROW(INDIRECT("1:"&(COUNTA(_xlfn._xlws.FILTER(Narset!C3:C102,(Narset!B3:B102<>Narset!C3:C102)*(Narset!C3:C102<>"")))+COUNTA(_xlfn._xlws.FILTER(Kumena!C3:C102,(Kumena!B3:B102<>Kumena!C3:C102)*(Kumena!C3:C102<>"")))+COUNTA(_xlfn._xlws.FILTER(Zimone!C3:C102,(Zimone!B3:B102<>Zimone!C3:C102)*(Zimone!C3:C102<>""))))))<=COUNTA(_xlfn._xlws.FILTER(Narset!C3:C102,(Narset!B3:B102<>Narset!C3:C102)*(Narset!C3:C102<>"")))+COUNTA(_xlfn._xlws.FILTER(Kumena!C3:C102,(Kumena!B3:B102<>Kumena!C3:C102)*(Kumena!C3:C102<>""))),INDEX(_xlfn._xlws.FILTER(Kumena!C3:C102,(Kumena!B3:B102<>Kumena!C3:C102)*(Kumena!C3:C102<>"")),ROW(INDIRECT("1:"&(COUNTA(_xlfn._xlws.FILTER(Narset!C3:C102,(Narset!B3:B102<>Narset!C3:C102)*(Narset!C3:C102<>"")))+COUNTA(_xlfn._xlws.FILTER(Kumena!C3:C102,(Kumena!B3:B102<>Kumena!C3:C102)*(Kumena!C3:C102<>"")))+COUNTA(_xlfn._xlws.FILTER(Zimone!C3:C102,(Zimone!B3:B102<>Zimone!C3:C102)*(Zimone!C3:C102<>""))))))-COUNTA(_xlfn._xlws.FILTER(Narset!C3:C102,(Narset!B3:B102<>Narset!C3:C102)*(Narset!C3:C102<>"")))),INDEX(_xlfn._xlws.FILTER(Zimone!C3:C102,(Zimone!B3:B102<>Zimone!C3:C102)*(Zimone!C3:C102<>"")),ROW(INDIRECT("1:"&(COUNTA(_xlfn._xlws.FILTER(Narset!C3:C102,(Narset!B3:B102<>Narset!C3:C102)*(Narset!C3:C102<>"")))+COUNTA(_xlfn._xlws.FILTER(Kumena!C3:C102,(Kumena!B3:B102<>Kumena!C3:C102)*(Kumena!C3:C102<>"")))+COUNTA(_xlfn._xlws.FILTER(Zimone!C3:C102,(Zimone!B3:B102<>Zimone!C3:C102)*(Zimone!C3:C102<>""))))))-COUNTA(_xlfn._xlws.FILTER(Narset!C3:C102,(Narset!B3:B102<>Narset!C3:C102)*(Narset!C3:C102<>"")))-COUNTA(_xlfn._xlws.FILTER(Kumena!C3:C102,(Kumena!B3:B102<>Kumena!C3:C102)*(Kumena!C3:C102<>"")))))),1,-1)))} -> Adarkar Wastes | BH2: {=IF(COUNTA(_xlfn._xlws.FILTER(Baylen!C3:C102,(Baylen!B3:B102<>Baylen!C3:C102)*(Baylen!C3:C102<>"")))+COUNTA(_xlfn._xlws.FILTER(Tayam!C3:C101,(Tayam!B3:B101<>Tayam!C3:C101)*(Tayam!C3:C101<>"")))+COUNTA(_xlfn._xlws.FILTER(JhoiraB!C3:C101,(JhoiraB!B3:B101<>JhoiraB!C3:C101)*(JhoiraB!C3:C101<>"")))=0,"",_xlfn._xlws.SORT(_xlfn.UNIQUE(IF(ROW(INDIRECT("1:"&(COUNTA(_xlfn._xlws.FILTER(Baylen!C3:C102,(Baylen!B3:B102<>Baylen!C3:C102)*(Baylen!C3:C102<>"")))+COUNTA(_xlfn._xlws.FILTER(Tayam!C3:C101,(Tayam!B3:B101<>Tayam!C3:C101)*(Tayam!C3:C101<>"")))+COUNTA(_xlfn._xlws.FILTER(JhoiraB!C3:C101,(JhoiraB!B3:B101<>JhoiraB!C3:C101)*(JhoiraB!C3:C101<>""))))))<=COUNTA(_xlfn._xlws.FILTER(Baylen!C3:C102,(Baylen!B3:B102<>Baylen!C3:C102)*(Baylen!C3:C102<>""))),INDEX(_xlfn._xlws.FILTER(Baylen!C3:C102,(Baylen!B3:B102<>Baylen!C3:C102)*(Baylen!C3:C102<>"")),ROW(INDIRECT("1:"&(COUNTA(_xlfn._xlws.FILTER(Baylen!C3:C102,(Baylen!B3:B102<>Baylen!C3:C102)*(Baylen!C3:C102<>"")))+COUNTA(_xlfn._xlws.FILTER(Tayam!C3:C101,(Tayam!B3:B101<>Tayam!C3:C101)*(Tayam!C3:C101<>"")))+COUNTA(_xlfn._xlws.FILTER(JhoiraB!C3:C101,(JhoiraB!B3:B101<>JhoiraB!C3:C101)*(JhoiraB!C3:C101<>""))))))),IF(ROW(INDIRECT("1:"&(COUNTA(_xlfn._xlws.FILTER(Baylen!C3:C102,(Baylen!B3:B102<>Baylen!C3:C102)*(Baylen!C3:C102<>"")))+COUNTA(_xlfn._xlws.FILTER(Tayam!C3:C101,(Tayam!B3:B101<>Tayam!C3:C101)*(Tayam!C3:C101<>"")))+COUNTA(_xlfn._xlws.FILTER(JhoiraB!C3:C101,(JhoiraB!B3:B101<>JhoiraB!C3:C101)*(JhoiraB!C3:C101<>""))))))<=COUNTA(_xlfn._xlws.FILTER(Baylen!C3:C102,(Baylen!B3:B102<>Baylen!C3:C102)*(Baylen!C3:C102<>"")))+COUNTA(_xlfn._xlws.FILTER(Tayam!C3:C101,(Tayam!B3:B101<>Tayam!C3:C101)*(Tayam!C3:C101<>""))),INDEX(_xlfn._xlws.FILTER(Tayam!C3:C101,(Tayam!B3:B101<>Tayam!C3:C101)*(Tayam!C3:C101<>"")),ROW(INDIRECT("1:"&(COUNTA(_xlfn._xlws.FILTER(Baylen!C3:C102,(Baylen!B3:B102<>Baylen!C3:C102)*(Baylen!C3:C102<>"")))+COUNTA(_xlfn._xlws.FILTER(Tayam!C3:C101,(Tayam!B3:B101<>Tayam!C3:C101)*(Tayam!C3:C101<>"")))+COUNTA(_xlfn._xlws.FILTER(JhoiraB!C3:C101,(JhoiraB!B3:B101<>JhoiraB!C3:C101)*(JhoiraB!C3:C101<>""))))))-COUNTA(_xlfn._xlws.FILTER(Baylen!C3:C102,(Baylen!B3:B102<>Baylen!C3:C102)*(Baylen!C3:C102<>"")))),INDEX(_xlfn._xlws.FILTER(JhoiraB!C3:C101,(JhoiraB!B3:B101<>JhoiraB!C3:C101)*(JhoiraB!C3:C101<>"")),ROW(INDIRECT("1:"&(COUNTA(_xlfn._xlws.FILTER(Baylen!C3:C102,(Baylen!B3:B102<>Baylen!C3:C102)*(Baylen!C3:C102<>"")))+COUNTA(_xlfn._xlws.FILTER(Tayam!C3:C101,(Tayam!B3:B101<>Tayam!C3:C101)*(Tayam!C3:C101<>"")))+COUNTA(_xlfn._xlws.FILTER(JhoiraB!C3:C101,(JhoiraB!B3:B101<>JhoiraB!C3:C101)*(JhoiraB!C3:C101<>""))))))-COUNTA(_xlfn._xlws.FILTER(Baylen!C3:C102,(Baylen!B3:B102<>Baylen!C3:C102)*(Baylen!C3:C102<>"")))-COUNTA(_xlfn._xlws.FILTER(Tayam!C3:C101,(Tayam!B3:B101<>Tayam!C3:C101)*(Tayam!C3:C101<>"")))))),1,-1)))} -> Ardbert, Warrior of Darkness | BI2: {=IF(COUNTA(_xlfn._xlws.FILTER(Piratas!C3:C102,(Piratas!B3:B102<>Piratas!C3:C102)*(Piratas!C3:C102<>"")))+COUNTA(_xlfn._xlws.FILTER(#REF!,(#REF!<>#REF!)*(#REF!<>"")))+COUNTA(_xlfn._xlws.FILTER(Modular!C3:C101,(Modular!B3:B101<>Modular!C3:C101)*(Modular!C3:C101<>"")))=0,"",_xlfn._xlws.SORT(_xlfn.UNIQUE(IF(ROW(INDIRECT("1:"&(COUNTA(_xlfn._xlws.FILTER(Piratas!C3:C102,(Piratas!B3:B102<>Piratas!C3:C102)*(Piratas!C3:C102<>"")))+COUNTA(_xlfn._xlws.FILTER(#REF!,(#REF!<>#REF!)*(#REF!<>"")))+COUNTA(_xlfn._xlws.FILTER(Modular!C3:C101,(Modular!B3:B101<>Modular!C3:C101)*(Modular!C3:C101<>""))))))<=COUNTA(_xlfn._xlws.FILTER(Piratas!C3:C102,(Piratas!B3:B102<>Piratas!C3:C102)*(Piratas!C3:C102<>""))),INDEX(_xlfn._xlws.FILTER(Piratas!C3:C102,(Piratas!B3:B102<>Piratas!C3:C102)*(Piratas!C3:C102<>"")),ROW(INDIRECT("1:"&(COUNTA(_xlfn._xlws.FILTER(Piratas!C3:C102,(Piratas!B3:B102<>Piratas!C3:C102)*(Piratas!C3:C102<>"")))+COUNTA(_xlfn._xlws.FILTER(#REF!,(#REF!<>#REF!)*(#REF!<>"")))+COUNTA(_xlfn._xlws.FILTER(Modular!C3:C101,(Modular!B3:B101<>Modular!C3:C101)*(Modular!C3:C101<>""))))))),IF(ROW(INDIRECT("1:"&(COUNTA(_xlfn._xlws.FILTER(Piratas!C3:C102,(Piratas!B3:B102<>Piratas!C3:C102)*(Piratas!C3:C102<>"")))+COUNTA(_xlfn._xlws.FILTER(#REF!,(#REF!<>#REF!)*(#REF!<>"")))+COUNTA(_xlfn._xlws.FILTER(Modular!C3:C101,(Modular!B3:B101<>Modular!C3:C101)*(Modular!C3:C101<>""))))))<=COUNTA(_xlfn._xlws.FILTER(Piratas!C3:C102,(Piratas!B3:B102<>Piratas!C3:C102)*(Piratas!C3:C102<>"")))+COUNTA(_xlfn._xlws.FILTER(#REF!,(#REF!<>#REF!)*(#REF!<>""))),INDEX(_xlfn._xlws.FILTER(#REF!,(#REF!<>#REF!)*(#REF!<>"")),ROW(INDIRECT("1:"&(COUNTA(_xlfn._xlws.FILTER(Piratas!C3:C102,(Piratas!B3:B102<>Piratas!C3:C102)*(Piratas!C3:C102<>"")))+COUNTA(_xlfn._xlws.FILTER(#REF!,(#REF!<>#REF!)*(#REF!<>"")))+COUNTA(_xlfn._xlws.FILTER(Modular!C3:C101,(Modular!B3:B101<>Modular!C3:C101)*(Modular!C3:C101<>""))))))-COUNTA(_xlfn._xlws.FILTER(Piratas!C3:C102,(Piratas!B3:B102<>Piratas!C3:C102)*(Piratas!C3:C102<>"")))),INDEX(_xlfn._xlws.FILTER(Modular!C3:C101,(Modular!B3:B101<>Modular!C3:C101)*(Modular!C3:C101<>"")),ROW(INDIRECT("1:"&(COUNTA(_xlfn._xlws.FILTER(Piratas!C3:C102,(Piratas!B3:B102<>Piratas!C3:C102)*(Piratas!C3:C102<>"")))+COUNTA(_xlfn._xlws.FILTER(#REF!,(#REF!<>#REF!)*(#REF!<>"")))+COUNTA(_xlfn._xlws.FILTER(Modular!C3:C101,(Modular!B3:B101<>Modular!C3:C101)*(Modular!C3:C101<>""))))))-COUNTA(_xlfn._xlws.FILTER(Piratas!C3:C102,(Piratas!B3:B102<>Piratas!C3:C102)*(Piratas!C3:C102<>"")))-COUNTA(_xlfn._xlws.FILTER(#REF!,(#REF!<>#REF!)*(#REF!<>"")))))),1,-1)))} -> Adagia, Windswept Bastion | BK2: {=IF(COUNTA(_xlfn.ANCHORARRAY($AZ$2))+COUNTA(_xlfn.ANCHORARRAY($BA$2))=0,"",_xlfn._xlws.SORT(_xlfn.UNIQUE(IF(ROW(INDIRECT("1:"&(COUNTA(_xlfn.ANCHORARRAY($AZ$2))+COUNTA(_xlfn.ANCHORARRAY($BA$2)))))<=COUNTA(_xlfn.ANCHORARRAY($AZ$2)),INDEX(_xlfn.ANCHORARRAY($AZ$2),ROW(INDIRECT("1:"&(COUNTA(_xlfn.ANCHORARRAY($AZ$2))+COUNTA(_xlfn.ANCHORARRAY($BA$2)))))),INDEX(_xlfn.ANCHORARRAY($BA$2),ROW(INDIRECT("1:"&(COUNTA(_xlfn.ANCHORARRAY($AZ$2))+COUNTA(_xlfn.ANCHORARRAY($BA$2)))))-COUNTA(_xlfn.ANCHORARRAY($AZ$2))))),1,1))} -> A Joia do Enigma | BL2: {=IF(COUNTA(_xlfn.ANCHORARRAY($BB$2))+COUNTA(_xlfn.ANCHORARRAY($BC$2))=0,"",_xlfn._xlws.SORT(_xlfn.UNIQUE(IF(ROW(INDIRECT("1:"&(COUNTA(_xlfn.ANCHORARRAY($BB$2))+COUNTA(_xlfn.ANCHORARRAY($BC$2)))))<=COUNTA(_xlfn.ANCHORARRAY($BB$2)),INDEX(_xlfn.ANCHORARRAY($BB$2),ROW(INDIRECT("1:"&(COUNTA(_xlfn.ANCHORARRAY($BB$2))+COUNTA(_xlfn.ANCHORARRAY($BC$2)))))),INDEX(_xlfn.ANCHORARRAY($BC$2),ROW(INDIRECT("1:"&(COUNTA(_xlfn.ANCHORARRAY($BB$2))+COUNTA(_xlfn.ANCHORARRAY($BC$2)))))-COUNTA(_xlfn.ANCHORARRAY($BB$2))))),1,1))} -> Adagia, Windswept Bastion | BM2: {=IF(COUNTA(_xlfn.ANCHORARRAY($BD$2))+COUNTA(_xlfn.ANCHORARRAY($BE$2))=0,"",_xlfn._xlws.SORT(_xlfn.UNIQUE(IF(ROW(INDIRECT("1:"&(COUNTA(_xlfn.ANCHORARRAY($BD$2))+COUNTA(_xlfn.ANCHORARRAY($BE$2)))))<=COUNTA(_xlfn.ANCHORARRAY($BD$2)),INDEX(_xlfn.ANCHORARRAY($BD$2),ROW(INDIRECT("1:"&(COUNTA(_xlfn.ANCHORARRAY($BD$2))+COUNTA(_xlfn.ANCHORARRAY($BE$2)))))),INDEX(_xlfn.ANCHORARRAY($BE$2),ROW(INDIRECT("1:"&(COUNTA(_xlfn.ANCHORARRAY($BD$2))+COUNTA(_xlfn.ANCHORARRAY($BE$2)))))-COUNTA(_xlfn.ANCHORARRAY($BD$2))))),1,1))} -> Adagia, Windswept Bastion | BN2: {=IF(COUNTA(_xlfn.ANCHORARRAY($BF$2))+COUNTA(_xlfn.ANCHORARRAY($BG$2))=0,"",_xlfn._xlws.SORT(_xlfn.UNIQUE(IF(ROW(INDIRECT("1:"&(COUNTA(_xlfn.ANCHORARRAY($BF$2))+COUNTA(_xlfn.ANCHORARRAY($BG$2)))))<=COUNTA(_xlfn.ANCHORARRAY($BF$2)),INDEX(_xlfn.ANCHORARRAY($BF$2),ROW(INDIRECT("1:"&(COUNTA(_xlfn.ANCHORARRAY($BF$2))+COUNTA(_xlfn.ANCHORARRAY($BG$2)))))),INDEX(_xlfn.ANCHORARRAY($BG$2),ROW(INDIRECT("1:"&(COUNTA(_xlfn.ANCHORARRAY($BF$2))+COUNTA(_xlfn.ANCHORARRAY($BG$2)))))-COUNTA(_xlfn.ANCHORARRAY($BF$2))))),1,1))} -> Access Tunnel | BO2: {=IF(COUNTA(_xlfn.ANCHORARRAY($BH$2))+COUNTA(_xlfn.ANCHORARRAY($BI$2))=0,"",_xlfn._xlws.SORT(_xlfn.UNIQUE(IF(ROW(INDIRECT("1:"&(COUNTA(_xlfn.ANCHORARRAY($BH$2))+COUNTA(_xlfn.ANCHORARRAY($BI$2)))))<=COUNTA(_xlfn.ANCHORARRAY($BH$2)),INDEX(_xlfn.ANCHORARRAY($BH$2),ROW(INDIRECT("1:"&(COUNTA(_xlfn.ANCHORARRAY($BH$2))+COUNTA(_xlfn.ANCHORARRAY($BI$2)))))),INDEX(_xlfn.ANCHORARRAY($BI$2),ROW(INDIRECT("1:"&(COUNTA(_xlfn.ANCHORARRAY($BH$2))+COUNTA(_xlfn.ANCHORARRAY($BI$2)))))-COUNTA(_xlfn.ANCHORARRAY($BH$2))))),1,1))} -> Adagia, Windswept Bastion | BQ2: {=IF(COUNTA(_xlfn.ANCHORARRAY($BK$2))+COUNTA(_xlfn.ANCHORARRAY($BL$2))=0,"",_xlfn._xlws.SORT(_xlfn.UNIQUE(IF(ROW(INDIRECT("1:"&(COUNTA(_xlfn.ANCHORARRAY($BK$2))+COUNTA(_xlfn.ANCHORARRAY($BL$2)))))<=COUNTA(_xlfn.ANCHORARRAY($BK$2)),INDEX(_xlfn.ANCHORARRAY($BK$2),ROW(INDIRECT("1:"&(COUNTA(_xlfn.ANCHORARRAY($BK$2))+COUNTA(_xlfn.ANCHORARRAY($BL$2)))))),INDEX(_xlfn.ANCHORARRAY($BL$2),ROW(INDIRECT("1:"&(COUNTA(_xlfn.ANCHORARRAY($BK$2))+COUNTA(_xlfn.ANCHORARRAY($BL$2)))))-COUNTA(_xlfn.ANCHORARRAY($BK$2))))),1,1))} -> A Joia do Enigma | BR2: {=IF(COUNTA(_xlfn.ANCHORARRAY($BM$2))+COUNTA(_xlfn.ANCHORARRAY($BN$2))=0,"",_xlfn._xlws.SORT(_xlfn.UNIQUE(IF(ROW(INDIRECT("1:"&(COUNTA(_xlfn.ANCHORARRAY($BM$2))+COUNTA(_xlfn.ANCHORARRAY($BN$2)))))<=COUNTA(_xlfn.ANCHORARRAY($BM$2)),INDEX(_xlfn.ANCHORARRAY($BM$2),ROW(INDIRECT("1:"&(COUNTA(_xlfn.ANCHORARRAY($BM$2))+COUNTA(_xlfn.ANCHORARRAY($BN$2)))))),INDEX(_xlfn.ANCHORARRAY($BN$2),ROW(INDIRECT("1:"&(COUNTA(_xlfn.ANCHORARRAY($BM$2))+COUNTA(_xlfn.ANCHORARRAY($BN$2)))))-COUNTA(_xlfn.ANCHORARRAY($BM$2))))),1,1))} -> Access Tunnel | BT2: {=IF(COUNTA(_xlfn.ANCHORARRAY($BQ$2))+COUNTA(_xlfn.ANCHORARRAY($BR$2))=0,"",_xlfn._xlws.SORT(_xlfn.UNIQUE(IF(ROW(INDIRECT("1:"&(COUNTA(_xlfn.ANCHORARRAY($BQ$2))+COUNTA(_xlfn.ANCHORARRAY($BR$2)))))<=COUNTA(_xlfn.ANCHORARRAY($BQ$2)),INDEX(_xlfn.ANCHORARRAY($BQ$2),ROW(INDIRECT("1:"&(COUNTA(_xlfn.ANCHORARRAY($BQ$2))+COUNTA(_xlfn.ANCHORARRAY($BR$2)))))),INDEX(_xlfn.ANCHORARRAY($BR$2),ROW(INDIRECT("1:"&(COUNTA(_xlfn.ANCHORARRAY($BQ$2))+COUNTA(_xlfn.ANCHORARRAY($BR$2)))))-COUNTA(_xlfn.ANCHORARRAY($BQ$2))))),1,1))} -> A Joia do Enigma
