Workbook

Sheet COMPRAS
A1: Total: | B1: =C2+C7+C12+C17+C22+C27+C32+C37+C42+C55 -> 0 | E1: =A2 -> Marcelo | F1: =B3 -> MTG Cards Games | G1: =B4 -> Legacy | H1: =B5 -> Mana Vai | J1: =A7 -> Interessantes | K1: =B8 -> Liga | L1: =B9 -> Legacy | M1: =B10 -> Overrun | O1: =A12 -> Jonathan | P1: =B13 -> Liga | Q1: =B14 -> Legacy | R1: =B15 -> Overrun | T1: =A17 -> Hamster | U1: =B18 -> Liga | V1: =B19 -> Legacy | W1: =B20 -> Overrun
A2: Marcelo | B2: Total Lojas: | C2: =SUM(C3:C5) -> 0
A3: =COUNTA(E2:E175) -> 0 | B3: MTG Cards Games | C3: =SUM(F:F) -> 0
B4: Legacy | C4: =SUM(G:G) -> 0
B5: Mana Vai | C5: =SUM(H:H) -> 0
A7: Interessantes | B7: Total Lojas: | C7: =SUM(C9:C10) -> 0
A8: =COUNTA(J2:J193) -> 0 | B8: Liga | C8: =SUM(K:K) -> 0
B9: Legacy | C9: =SUM(L:L) -> 0
B10: Overrun | C10: =SUM(M:M) -> 0
A12: Jonathan | B12: Total Lojas: | C12: =SUM(C14:C15) -> 0
A13: =COUNTA(O2:O193) -> 0 | B13: Liga | C13: =SUM(P2:P993) -> 0
B14: Legacy | C14: =SUM(Q2:Q9993) -> 0
B15: Overrun | C15: =SUM(R2:R9993) -> 0
A17: Hamster | B17: Total Lojas: | C17: =SUM(C19:C20) -> 0
A18: =COUNTA(T2:T193) -> 0 | B18: Liga | C18: =SUM(U1:U9993) -> 0
B19: Legacy | C19: =SUM(V1:V9998) -> 0
B20: Overrun | C20: =SUM(W1:W9993) -> 0

Sheet RESUMO
A1: Fractius | E1: Vida | I1: Fadas | M1: Knights | Q1: Modular | U1: Allyes
A3: Total | B3: {=_xlfn._xlws.SORT(C3:C86,1,-1,0)} -> #REF! | C3: =IF(#REF!="Não",#REF!, " ") -> #REF! | E3: Total | F3: {=_xlfn._xlws.SORT(G3:G86,1,-1,0)} -> #REF! | G3: =IF(#REF!="Não",#REF!, " ") -> #REF! | I3: Total | J3: {=_xlfn._xlws.SORT(K3:K86,1,-1,0)} -> #REF! | K3: =IF(#REF!="Não",#REF!, " ") -> #REF! | M3: Total | N3: {=_xlfn._xlws.SORT(O3:O86,1,-1,0)} -> #REF! | O3: =IF(#REF!="Não",#REF!, " ") -> #REF! | Q3: Total | R3: {=_xlfn._xlws.SORT(S3:S86,1,-1,0)} -> #REF! | S3: =IF(#REF!="Não",#REF!, " ") -> #REF! | U3: Total | V3: {=_xlfn._xlws.SORT(W3:W86,1,-1,0)} -> #REF! | W3: =IF(#REF!="Não",#REF!, " ") -> #REF!
A4: =#REF! -> #REF! | B4: #REF! | C4: =IF(#REF!="Não",#REF!, " ") -> #REF! | E4: =#REF! -> #REF! | F4: #REF! | G4: =IF(#REF!="Não",#REF!, " ") -> #REF! | I4: =#REF! -> #REF! | J4: #REF! | K4: =IF(#REF!="Não",#REF!, " ") -> #REF! | M4: =#REF! -> #REF! | N4: #REF! | O4: =IF(#REF!="Não",#REF!, " ") -> #REF! | Q4: =#REF! -> #REF! | R4: #REF! | S4: =IF(#REF!="Não",#REF!, " ") -> #REF! | U4: =#REF! -> #REF! | V4: #REF! | W4: =IF(#REF!="Não",#REF!, " ") -> #REF!
B5: #REF! | C5: =IF(#REF!="Não",#REF!, " ") -> #REF! | F5: #REF! | G5: =IF(#REF!="Não",#REF!, " ") -> #REF! | J5: #REF! | K5: =IF(#REF!="Não",#REF!, " ") -> #REF! | N5: #REF! | O5: =IF(#REF!="Não",#REF!, " ") -> #REF! | R5: #REF! | S5: =IF(#REF!="Não",#REF!, " ") -> #REF! | V5: #REF! | W5: =IF(#REF!="Não",#REF!, " ") -> #REF!
B6: #REF! | C6: =IF(#REF!="Não",#REF!, " ") -> #REF! | F6: #REF! | G6: =IF(#REF!="Não",#REF!, " ") -> #REF! | J6: #REF! | K6: =IF(#REF!="Não",#REF!, " ") -> #REF! | N6: #REF! | O6: =IF(#REF!="Não",#REF!, " ") -> #REF! | R6: #REF! | S6: =IF(#REF!="Não",#REF!, " ") -> #REF! | V6: #REF! | W6: =IF(#REF!="Não",#REF!, " ") -> #REF!
B7: #REF! | C7: =IF(#REF!="Não",#REF!, " ") -> #REF! | F7: #REF! | G7: =IF(#REF!="Não",#REF!, " ") -> #REF! | J7: #REF! | K7: =IF(#REF!="Não",#REF!, " ") -> #REF! | N7: #REF! | O7: =IF(#REF!="Não",#REF!, " ") -> #REF! | R7: #REF! | S7: =IF(#REF!="Não",#REF!, " ") -> #REF! | V7: #REF! | W7: =IF(#REF!="Não",#REF!, " ") -> #REF!
B8: #REF! | C8: =IF(#REF!="Não",#REF!, " ") -> #REF! | F8: #REF! | G8: =IF(#REF!="Não",#REF!, " ") -> #REF! | J8: #REF! | K8: =IF(#REF!="Não",#REF!, " ") -> #REF! | N8: #REF! | O8: =IF(#REF!="Não",#REF!, " ") -> #REF! | R8: #REF! | S8: =IF(#REF!="Não",#REF!, " ") -> #REF! | V8: #REF! | W8: =IF(#REF!="Não",#REF!, " ") -> #REF!
B9: #REF! | C9: =IF(#REF!="Não",#REF!, " ") -> #REF! | F9: #REF! | G9: =IF(#REF!="Não",#REF!, " ") -> #REF! | J9: #REF! | K9: =IF(#REF!="Não",#REF!, " ") -> #REF! | N9: #REF! | O9: =IF(#REF!="Não",#REF!, " ") -> #REF! | R9: #REF! | S9: =IF(#REF!="Não",#REF!, " ") -> #REF! | V9: #REF! | W9: =IF(#REF!="Não",#REF!, " ") -> #REF!
B10: #REF! | C10: =IF(#REF!="Não",#REF!, " ") -> #REF! | F10: #REF! | G10: =IF(#REF!="Não",#REF!, " ") -> #REF! | J10: #REF! | K10: =IF(#REF!="Não",#REF!, " ") -> #REF! | N10: #REF! | O10: =IF(#REF!="Não",#REF!, " ") -> #REF! | R10: #REF! | S10: =IF(#REF!="Não",#REF!, " ") -> #REF! | V10: #REF! | W10: =IF(#REF!="Não",#REF!, " ") -> #REF!
B11: #REF! | C11: =IF(#REF!="Não",#REF!, " ") -> #REF! | F11: #REF! | G11: =IF(#REF!="Não",#REF!, " ") -> #REF! | J11: #REF! | K11: =IF(#REF!="Não",#REF!, " ") -> #REF! | N11: #REF! | O11: =IF(#REF!="Não",#REF!, " ") -> #REF! | R11: #REF! | S11: =IF(#REF!="Não",#REF!, " ") -> #REF! | V11: #REF! | W11: =IF(#REF!="Não",#REF!, " ") -> #REF!
B12: #REF! | C12: =IF(#REF!="Não",#REF!, " ") -> #REF! | F12: #REF! | G12: =IF(#REF!="Não",#REF!, " ") -> #REF! | J12: #REF! | K12: =IF(#REF!="Não",#REF!, " ") -> #REF! | N12: #REF! | O12: =IF(#REF!="Não",#REF!, " ") -> #REF! | R12: #REF! | S12: =IF(#REF!="Não",#REF!, " ") -> #REF! | V12: #REF! | W12: =IF(#REF!="Não",#REF!, " ") -> #REF!
B13: #REF! | C13: =IF(#REF!="Não",#REF!, " ") -> #REF! | F13: #REF! | G13: =IF(#REF!="Não",#REF!, " ") -> #REF! | J13: #REF! | K13: =IF(#REF!="Não",#REF!, " ") -> #REF! | N13: #REF! | O13: =IF(#REF!="Não",#REF!, " ") -> #REF! | R13: #REF! | S13: =IF(#REF!="Não",#REF!, " ") -> #REF! | V13: #REF! | W13: =IF(#REF!="Não",#REF!, " ") -> #REF!
B14: #REF! | C14: =IF(#REF!="Não",#REF!, " ") -> #REF! | F14: #REF! | G14: =IF(#REF!="Não",#REF!, " ") -> #REF! | J14: #REF! | K14: =IF(#REF!="Não",#REF!, " ") -> #REF! | N14: #REF! | O14: =IF(#REF!="Não",#REF!, " ") -> #REF! | R14: #REF! | S14: =IF(#REF!="Não",#REF!, " ") -> #REF! | V14: #REF! | W14: =IF(#REF!="Não",#REF!, " ") -> #REF!
B15: #REF! | C15: =IF(#REF!="Não",#REF!, " ") -> #REF! | F15: #REF! | G15: =IF(#REF!="Não",#REF!, " ") -> #REF! | J15: #REF! | K15: =IF(#REF!="Não",#REF!, " ") -> #REF! | N15: #REF! | O15: =IF(#REF!="Não",#REF!, " ") -> #REF! | R15: #REF! | S15: =IF(#REF!="Não",#REF!, " ") -> #REF! | V15: #REF! | W15: =IF(#REF!="Não",#REF!, " ") -> #REF!
B16: #REF! | C16: =IF(#REF!="Não",#REF!, " ") -> #REF! | F16: #REF! | G16: =IF(#REF!="Não",#REF!, " ") -> #REF! | J16: #REF! | K16: =IF(#REF!="Não",#REF!, " ") -> #REF! | N16: #REF! | O16: =IF(#REF!="Não",#REF!, " ") -> #REF! | R16: #REF! | S16: =IF(#REF!="Não",#REF!, " ") -> #REF! | V16: #REF! | W16: =IF(#REF!="Não",#REF!, " ") -> #REF!
... B86: #REF! | C86: =IF(#REF!="Não",#REF!, " ") -> #REF! | F86: #REF! | G86: =IF(#REF!="Não",#REF!, " ") -> #REF! | J86: #REF! | K86: =IF(#REF!="Não",#REF!, " ") -> #REF! | N86: #REF! | O86: =IF(#REF!="Não",#REF!, " ") -> #REF! | R86: #REF! | S86: =IF(#REF!="Não",#REF!, " ") -> #REF! | V86: #REF! | W86: =IF(#REF!="Não",#REF!, " ") -> #REF!
O87: =IF(#REF!="Não",#REF!, " ") -> #REF!
O88: =IF(#REF!="Não",#REF!, " ") -> #REF!

Sheet RESUMO (2)
A1: Temur Control | E1: Jund Pioneer | I1: Jund Food | M1: ElfoNeer
A3: Total | B3: {=_xlfn._xlws.SORT(C3:C86,1,-1,0)} -> #REF! | C3: =IF(#REF!="Não",#REF!, " ") -> #REF! | F3: {=_xlfn._xlws.SORT(G3:G86,1,-1,0)} -> #REF! | G3: =IF(#REF!="Não",#REF!, " ") -> #REF! | J3: {=_xlfn._xlws.SORT(K3:K86,1,-1,0)} -> Woodland Cemetery | K3: =IF('Jund Food'!D3="Não",'Jund Food'!C3, " ") | N3: {=_xlfn._xlws.SORT(O3:O86,1,-1,0)} -> Tamiyo's Safekeeping | O3: =IF(ElfoNeer!D3="Não",ElfoNeer!C3, " ") -> Lair of the Hydra
A4: =#REF! -> #REF! | B4: #REF! | C4: =IF(#REF!="Não",#REF!, " ") -> #REF! | F4: #REF! | G4: =IF(#REF!="Não",#REF!, " ") -> #REF! | J4: Woodland Cemetery | K4: =IF('Jund Food'!D4="Não",'Jund Food'!C4, " ") -> Blood Crypt | N4: Tamiyo's Safekeeping | O4: =IF(ElfoNeer!D4="Não",ElfoNeer!C4, " ") -> Lair of the Hydra
B5: #REF! | C5: =IF(#REF!="Não",#REF!, " ") -> #REF! | F5: #REF! | G5: =IF(#REF!="Não",#REF!, " ") -> #REF! | J5: Stomping Ground | K5: =IF('Jund Food'!D5="Não",'Jund Food'!C5, " ") -> Blood Crypt | N5: Portal to Phyrexia | O5: =IF(ElfoNeer!D5="Não",ElfoNeer!C5, " ")
B6: #REF! | C6: =IF(#REF!="Não",#REF!, " ") -> #REF! | F6: #REF! | G6: =IF(#REF!="Não",#REF!, " ") -> #REF! | J6: Stomping Ground | K6: =IF('Jund Food'!D6="Não",'Jund Food'!C6, " ") | N6: Portal to Phyrexia | O6: =IF(ElfoNeer!D6="Não",ElfoNeer!C6, " ")
B7: #REF! | C7: =IF(#REF!="Não",#REF!, " ") -> #REF! | F7: #REF! | G7: =IF(#REF!="Não",#REF!, " ") -> #REF! | J7: Rootbound Crag | K7: =IF('Jund Food'!D7="Não",'Jund Food'!C7, " ") | N7: Patch Up | O7: =IF(ElfoNeer!D7="Não",ElfoNeer!C7, " ")
B8: #REF! | C8: =IF(#REF!="Não",#REF!, " ") -> #REF! | F8: #REF! | G8: =IF(#REF!="Não",#REF!, " ") -> #REF! | J8: Rootbound Crag | K8: =IF('Jund Food'!D8="Não",'Jund Food'!C8, " ") | N8: Patch Up | O8: =IF(ElfoNeer!D8="Não",ElfoNeer!C8, " ")
B9: #REF! | C9: =IF(#REF!="Não",#REF!, " ") -> #REF! | F9: #REF! | G9: =IF(#REF!="Não",#REF!, " ") -> #REF! | J9: Questing Beast | K9: =IF('Jund Food'!D9="Não",'Jund Food'!C9, " ") | N9: Patch Up | O9: =IF(ElfoNeer!D9="Não",ElfoNeer!C9, " ")
B10: #REF! | C10: =IF(#REF!="Não",#REF!, " ") -> #REF! | F10: #REF! | G10: =IF(#REF!="Não",#REF!, " ") -> #REF! | J10: Questing Beast | K10: =IF('Jund Food'!D10="Não",'Jund Food'!C10, " ") -> Stomping Ground | N10: Paradox Engine | O10: =IF(ElfoNeer!D10="Não",ElfoNeer!C10, " ")
B11: #REF! | C11: =IF(#REF!="Não",#REF!, " ") -> #REF! | F11: #REF! | G11: =IF(#REF!="Não",#REF!, " ") -> #REF! | J11: Korvold, Fae-Cursed King | K11: =IF('Jund Food'!D11="Não",'Jund Food'!C11, " ") -> Stomping Ground | N11: Leaf-Crowned Visionary | O11: =IF(ElfoNeer!D11="Não",ElfoNeer!C11, " ")
B12: #REF! | C12: =IF(#REF!="Não",#REF!, " ") -> #REF! | F12: #REF! | G12: =IF(#REF!="Não",#REF!, " ") -> #REF! | J12: Korvold, Fae-Cursed King | K12: =IF('Jund Food'!D12="Não",'Jund Food'!C12, " ") -> Darkbore Pathway | N12: Lair of the Hydra | O12: =IF(ElfoNeer!D12="Não",ElfoNeer!C12, " ")
B13: #REF! | C13: =IF(#REF!="Não",#REF!, " ") -> #REF! | F13: #REF! | G13: =IF(#REF!="Não",#REF!, " ") -> #REF! | J13: Korvold, Fae-Cursed King | K13: =IF('Jund Food'!D13="Não",'Jund Food'!C13, " ") -> Darkbore Pathway | N13: Lair of the Hydra | O13: =IF(ElfoNeer!D13="Não",ElfoNeer!C13, " ")
B14: #REF! | C14: =IF(#REF!="Não",#REF!, " ") -> #REF! | F14: #REF! | G14: =IF(#REF!="Não",#REF!, " ") -> #REF! | J14: Korvold, Fae-Cursed King | K14: =IF('Jund Food'!D14="Não",'Jund Food'!C14, " ") -> Cragcrown Pathway | N14: Extraction Specialist | O14: =IF(ElfoNeer!D14="Não",ElfoNeer!C14, " ")
B15: #REF! | C15: =IF(#REF!="Não",#REF!, " ") -> #REF! | F15: #REF! | G15: =IF(#REF!="Não",#REF!, " ") -> #REF! | J15: Go Blank | K15: =IF('Jund Food'!D15="Não",'Jund Food'!C15, " ") -> Blightstep Pathway | N15: Extraction Specialist | O15: =IF(ElfoNeer!D15="Não",ElfoNeer!C15, " ")
B16: #REF! | C16: =IF(#REF!="Não",#REF!, " ") -> #REF! | F16: #REF! | G16: =IF(#REF!="Não",#REF!, " ") -> #REF! | J16: Fable of the Mirror-Breaker | K16: =IF('Jund Food'!D16="Não",'Jund Food'!C16, " ") -> Woodland Cemetery | N16: Elvish Mystic | O16: =IF(ElfoNeer!D16="Não",ElfoNeer!C16, " ")
B17: #REF! | C17: =IF(#REF!="Não",#REF!, " ") -> #REF! | F17: #REF! | G17: =IF(#REF!="Não",#REF!, " ") -> #REF! | J17: Fable of the Mirror-Breaker | K17: =IF('Jund Food'!D17="Não",'Jund Food'!C17, " ") -> Woodland Cemetery | N17: Assassin's Trophy | O17: =IF(ElfoNeer!D17="Não",ElfoNeer!C17, " ")
B18: #REF! | C18: =IF(#REF!="Não",#REF!, " ") -> #REF! | F18: #REF! | G18: =IF(#REF!="Não",#REF!, " ") -> #REF! | J18: Fable of the Mirror-Breaker | K18: =IF('Jund Food'!D18="Não",'Jund Food'!C18, " ") -> Rootbound Crag | O18: =IF(ElfoNeer!D18="Não",ElfoNeer!C18, " ")
B19: #REF! | C19: =IF(#REF!="Não",#REF!, " ") -> #REF! | F19: #REF! | G19: =IF(#REF!="Não",#REF!, " ") -> #REF! | J19: Fable of the Mirror-Breaker | K19: =IF('Jund Food'!D19="Não",'Jund Food'!C19, " ") -> Rootbound Crag | O19: =IF(ElfoNeer!D19="Não",ElfoNeer!C19, " ")
B20: #REF! | C20: =IF(#REF!="Não",#REF!, " ") -> #REF! | F20: #REF! | G20: =IF(#REF!="Não",#REF!, " ") -> #REF! | J20: Dragonskull Summit | K20: =IF('Jund Food'!D20="Não",'Jund Food'!C20, " ") -> Dragonskull Summit | O20: =IF(ElfoNeer!D20="Não",ElfoNeer!C20, " ")
B21: #REF! | C21: =IF(#REF!="Não",#REF!, " ") -> #REF! | F21: #REF! | G21: =IF(#REF!="Não",#REF!, " ") -> #REF! | J21: Darkbore Pathway | K21: =IF('Jund Food'!D21="Não",'Jund Food'!C21, " ") | O21: =IF(ElfoNeer!D21="Não",ElfoNeer!C21, " ")
B22: #REF! | C22: =IF(#REF!="Não",#REF!, " ") -> #REF! | F22: #REF! | G22: =IF(#REF!="Não",#REF!, " ") -> #REF! | J22: Darkbore Pathway | K22: =IF('Jund Food'!D22="Não",'Jund Food'!C22, " ") | O22: =IF(ElfoNeer!D22="Não",ElfoNeer!C22, " ")
B23: #REF! | C23: =IF(#REF!="Não",#REF!, " ") -> #REF! | F23: #REF! | G23: =IF(#REF!="Não",#REF!, " ") -> #REF! | J23: Damping Sphere | K23: =IF('Jund Food'!D23="Não",'Jund Food'!C23, " ") | O23: =IF(ElfoNeer!D23="Não",ElfoNeer!C23, " ")
B24: #REF! | C24: =IF(#REF!="Não",#REF!, " ") -> #REF! | F24: #REF! | G24: =IF(#REF!="Não",#REF!, " ") -> #REF! | J24: Damping Sphere | K24: =IF('Jund Food'!D24="Não",'Jund Food'!C24, " ") | O24: =IF(ElfoNeer!D24="Não",ElfoNeer!C24, " ")
B25: #REF! | C25: =IF(#REF!="Não",#REF!, " ") -> #REF! | F25: #REF! | G25: =IF(#REF!="Não",#REF!, " ") -> #REF! | J25: Damping Sphere | K25: =IF('Jund Food'!D25="Não",'Jund Food'!C25, " ") | O25: =IF(ElfoNeer!D25="Não",ElfoNeer!C25, " ") -> Elvish Mystic
B26: #REF! | C26: =IF(#REF!="Não",#REF!, " ") -> #REF! | F26: #REF! | G26: =IF(#REF!="Não",#REF!, " ") -> #REF! | J26: Cragcrown Pathway | K26: =IF('Jund Food'!D26="Não",'Jund Food'!C26, " ") | O26: =IF(ElfoNeer!D26="Não",ElfoNeer!C26, " ")
B27: #REF! | C27: =IF(#REF!="Não",#REF!, " ") -> #REF! | F27: #REF! | G27: =IF(#REF!="Não",#REF!, " ") -> #REF! | J27: Blood Crypt | K27: =IF('Jund Food'!D27="Não",'Jund Food'!C27, " ") | O27: =IF(ElfoNeer!D27="Não",ElfoNeer!C27, " ")
B28: #REF! | C28: =IF(#REF!="Não",#REF!, " ") -> #REF! | F28: #REF! | G28: =IF(#REF!="Não",#REF!, " ") -> #REF! | J28: Blood Crypt | K28: =IF('Jund Food'!D28="Não",'Jund Food'!C28, " ") | O28: =IF(ElfoNeer!D28="Não",ElfoNeer!C28, " ")
B29: #REF! | C29: =IF(#REF!="Não",#REF!, " ") -> #REF! | F29: #REF! | G29: =IF(#REF!="Não",#REF!, " ") -> #REF! | J29: Blightstep Pathway | K29: =IF('Jund Food'!D29="Não",'Jund Food'!C29, " ") | O29: =IF(ElfoNeer!D29="Não",ElfoNeer!C29, " ")
B30: #REF! | C30: =IF(#REF!="Não",#REF!, " ") -> #REF! | F30: #REF! | G30: =IF(#REF!="Não",#REF!, " ") -> #REF! | K30: =IF('Jund Food'!D30="Não",'Jund Food'!C30, " ") | O30: =IF(ElfoNeer!D30="Não",ElfoNeer!C30, " ")
B31: #REF! | C31: =IF(#REF!="Não",#REF!, " ") -> #REF! | F31: #REF! | G31: =IF(#REF!="Não",#REF!, " ") -> #REF! | K31: =IF('Jund Food'!D31="Não",'Jund Food'!C31, " ") | O31: =IF(ElfoNeer!D31="Não",ElfoNeer!C31, " ")
B32: #REF! | C32: =IF(#REF!="Não",#REF!, " ") -> #REF! | F32: #REF! | G32: =IF(#REF!="Não",#REF!, " ") -> #REF! | K32: =IF('Jund Food'!D32="Não",'Jund Food'!C32, " ") | O32: =IF(ElfoNeer!D32="Não",ElfoNeer!C32, " ")
B33: #REF! | C33: =IF(#REF!="Não",#REF!, " ") -> #REF! | F33: #REF! | G33: =IF(#REF!="Não",#REF!, " ") -> #REF! | K33: =IF('Jund Food'!D33="Não",'Jund Food'!C33, " ") | O33: =IF(ElfoNeer!D33="Não",ElfoNeer!C33, " ")
B34: #REF! | C34: =IF(#REF!="Não",#REF!, " ") -> #REF! | F34: #REF! | G34: =IF(#REF!="Não",#REF!, " ") -> #REF! | K34: =IF('Jund Food'!D34="Não",'Jund Food'!C34, " ") | O34: =IF(ElfoNeer!D34="Não",ElfoNeer!C34, " ")
B35: #REF! | C35: =IF(#REF!="Não",#REF!, " ") -> #REF! | F35: #REF! | G35: =IF(#REF!="Não",#REF!, " ") -> #REF! | K35: =IF('Jund Food'!D35="Não",'Jund Food'!C35, " ") | O35: =IF(ElfoNeer!D35="Não",ElfoNeer!C35, " ")
B36: #REF! | C36: =IF(#REF!="Não",#REF!, " ") -> #REF! | F36: #REF! | G36: =IF(#REF!="Não",#REF!, " ") -> #REF! | K36: =IF('Jund Food'!D36="Não",'Jund Food'!C36, " ") | O36: =IF(ElfoNeer!D36="Não",ElfoNeer!C36, " ")
B37: #REF! | C37: =IF(#REF!="Não",#REF!, " ") -> #REF! | F37: #REF! | G37: =IF(#REF!="Não",#REF!, " ") -> #REF! | K37: =IF('Jund Food'!D37="Não",'Jund Food'!C37, " ") -> Fable of the Mirror-Breaker | O37: =IF(ElfoNeer!D37="Não",ElfoNeer!C37, " ")
B38: #REF! | C38: =IF(#REF!="Não",#REF!, " ") -> #REF! | F38: #REF! | G38: =IF(#REF!="Não",#REF!, " ") -> #REF! | K38: =IF('Jund Food'!D38="Não",'Jund Food'!C38, " ") -> Fable of the Mirror-Breaker | O38: =IF(ElfoNeer!D38="Não",ElfoNeer!C38, " ")
B39: #REF! | C39: =IF(#REF!="Não",#REF!, " ") -> #REF! | F39: #REF! | G39: =IF(#REF!="Não",#REF!, " ") -> #REF! | K39: =IF('Jund Food'!D39="Não",'Jund Food'!C39, " ") -> Fable of the Mirror-Breaker | O39: =IF(ElfoNeer!D39="Não",ElfoNeer!C39, " ") -> Leaf-Crowned Visionary
B40: #REF! | C40: =IF(#REF!="Não",#REF!, " ") -> #REF! | F40: #REF! | G40: =IF(#REF!="Não",#REF!, " ") -> #REF! | K40: =IF('Jund Food'!D40="Não",'Jund Food'!C40, " ") -> Fable of the Mirror-Breaker | O40: =IF(ElfoNeer!D40="Não",ElfoNeer!C40, " ")
B41: #REF! | C41: =IF(#REF!="Não",#REF!, " ") -> #REF! | F41: #REF! | G41: =IF(#REF!="Não",#REF!, " ") -> #REF! | K41: =IF('Jund Food'!D41="Não",'Jund Food'!C41, " ") | O41: =IF(ElfoNeer!D41="Não",ElfoNeer!C41, " ")
...

Sheet HardenedScalesEx
A1: Hardened Scales - Explorer
A2: Função | B2: Carta Atual | C2: Carta Ideal | D2: Carta Final
A3: Terreno | B3: Overgrown Tomb | C3: Overgrown Tomb | D3: =IF(B3=C3, "Sim", "Não") -> Sim | F3: Mudanças Faltando | G3: =COUNTIF(D3:D99,"Não") -> 16 | I3: Feral Encounter
A4: Terreno | B4: Overgrown Tomb | C4: Overgrown Tomb | D4: =IF(B4=C4, "Sim", "Não") -> Sim | F4: Total de Cartas | G4: =SUM(G7:G21) -> 35 | I4: Elvish Archivist
A5: Terreno | B5: Overgrown Tomb | C5: Overgrown Tomb | D5: =IF(B5=C5, "Sim", "Não") -> Sim | I5: Tarrian's Soulcleaver
A6: Terreno | B6: Overgrown Tomb | C6: Overgrown Tomb | D6: =IF(B6=C6, "Sim", "Não") -> Sim | F6: Funções
A7: Terreno | D7: =IF(B7=C7, "Sim", "Não") -> Sim | F7: Terreno | G7: =COUNTIF(A:A,F7) -> 20
A8: Terreno | D8: =IF(B8=C8, "Sim", "Não") -> Sim | F8: Valor | G8: =COUNTIF(A:A,F8) -> 0
A9: Terreno | D9: =IF(B9=C9, "Sim", "Não") -> Sim | F9: Combo | G9: =COUNTIF(A:A,F9) -> 0
A10: Terreno | D10: =IF(B10=C10, "Sim", "Não") -> Sim | F10: Tutor | G10: =COUNTIF(A:A,F10) -> 0
A11: Terreno | D11: =IF(B11=C11, "Sim", "Não") -> Sim | F11: Sideboard | G11: =COUNTIF(A:A,F11) -> 15
A12: Terreno | D12: =IF(B12=C12, "Sim", "Não") -> Sim
A13: Terreno | D13: =IF(B13=C13, "Sim", "Não") -> Sim
A14: Terreno | D14: =IF(B14=C14, "Sim", "Não") -> Sim
A15: Terreno | D15: =IF(B15=C15, "Sim", "Não") -> Sim
A16: Terreno | D16: =IF(B16=C16, "Sim", "Não") -> Sim
A17: Terreno | D17: =IF(B17=C17, "Sim", "Não") -> Sim
A18: Terreno | B18: Forest | C18: Forest | D18: =IF(B18=C18, "Sim", "Não") -> Sim
A19: Terreno | B19: Forest | C19: Forest | D19: =IF(B19=C19, "Sim", "Não") -> Sim
A20: Terreno | B20: Forest | C20: Forest | D20: =IF(B20=C20, "Sim", "Não") -> Sim
A21: Terreno | B21: Forest | C21: Forest | D21: =IF(B21=C21, "Sim", "Não") -> Sim
A22: Terreno | B22: Forest | C22: Forest | D22: =IF(B22=C22, "Sim", "Não") -> Sim
B23: Hardened Scales | C23: Hardened Scales | D23: =IF(B23=C23, "Sim", "Não") -> Sim
B24: Hardened Scales | C24: Hardened Scales | D24: =IF(B24=C24, "Sim", "Não") -> Sim
B25: Hardened Scales | C25: Hardened Scales | D25: =IF(B25=C25, "Sim", "Não") -> Sim
B26: Hardened Scales | C26: Hardened Scales | D26: =IF(B26=C26, "Sim", "Não") -> Sim
B27: The Ozolith | C27: The Ozolith | D27: =IF(B27=C27, "Sim", "Não") -> Sim
B28: The Ozolith | C28: The Ozolith | D28: =IF(B28=C28, "Sim", "Não") -> Sim
B29: Ozolith, the Shattered Spire | C29: Ozolith, the Shattered Spire | D29: =IF(B29=C29, "Sim", "Não") -> Sim
B30: Ozolith, the Shattered Spire | C30: Ozolith, the Shattered Spire | D30: =IF(B30=C30, "Sim", "Não") -> Sim
B31: Hangarback Walker | C31: Hangarback Walker | D31: =IF(B31=C31, "Sim", "Não") -> Sim
B32: Hangarback Walker | C32: Hangarback Walker | D32: =IF(B32=C32, "Sim", "Não") -> Sim
B33: Hangarback Walker | C33: Hangarback Walker | D33: =IF(B33=C33, "Sim", "Não") -> Sim
B34: Hangarback Walker | C34: Hangarback Walker | D34: =IF(B34=C34, "Sim", "Não") -> Sim
... B39: Animation Module | C39: Animation Module | D39: =IF(B39=C39, "Sim", "Não") -> Sim
C40: Animation Module | D40: =IF(B40=C40, "Sim", "Não") -> Não
B41: Iron Apprentice | C41: Iron Apprentice | D41: =IF(B41=C41, "Sim", "Não") -> Sim
B42: Iron Apprentice | C42: Iron Apprentice | D42: =IF(B42=C42, "Sim", "Não") -> Sim
B43: Iron Apprentice | C43: Iron Apprentice | D43: =IF(B43=C43, "Sim", "Não") -> Sim
B44: Iron Apprentice | C44: Iron Apprentice | D44: =IF(B44=C44, "Sim", "Não") -> Sim
...

Sheet Jund Food
A1: Jund Food - Pioneer
A2: Função | B2: Carta Atual | C2: Carta Ideal | D2: Carta Final
A3: Terreno | B3: Blood Crypt | C3: Blood Crypt | D3: =IF(B3=C3, "Sim", "Não") -> Sim | F3: Mudanças Faltando | G3: =COUNTIF(D3:D103,"Não") -> 27
A4: Terreno | C4: Blood Crypt | D4: =IF(B4=C4, "Sim", "Não") -> Não | F4: Total de Cartas | G4: =SUM(G7:G24) -> 75
A5: Terreno | C5: Blood Crypt | D5: =IF(B5=C5, "Sim", "Não") -> Não
A6: Terreno | B6: Overgrown Tomb | C6: Overgrown Tomb | D6: =IF(B6=C6, "Sim", "Não") -> Sim | F6: Funções
A7: Terreno | B7: Overgrown Tomb | C7: Overgrown Tomb | D7: =IF(B7=C7, "Sim", "Não") -> Sim | F7: Terreno | G7: =COUNTIF(A:A,F7) -> 22
A8: Terreno | B8: Overgrown Tomb | C8: Overgrown Tomb | D8: =IF(B8=C8, "Sim", "Não") -> Sim | F8: Valor | G8: =COUNTIF(A:A,F8) -> 16
A9: Terreno | B9: Overgrown Tomb | C9: Overgrown Tomb | D9: =IF(B9=C9, "Sim", "Não") -> Sim | F9: Remoção | G9: =COUNTIF(A:A,F9) -> 7
A10: Terreno | C10: Stomping Ground | D10: =IF(B10=C10, "Sim", "Não") -> Não | F10: Draw | G10: =COUNTIF(A:A,F10) -> 8
A11: Terreno | C11: Stomping Ground | D11: =IF(B11=C11, "Sim", "Não") -> Não | F11: Finalizador | G11: =COUNTIF(A:A,F11) -> 7
A12: Terreno | C12: Darkbore Pathway | D12: =IF(B12=C12, "Sim", "Não") -> Não | F12: Sideboard | G12: =COUNTIF(A:A,F12) -> 15
A13: Terreno | C13: Darkbore Pathway | D13: =IF(B13=C13, "Sim", "Não") -> Não
A14: Terreno | C14: Cragcrown Pathway | D14: =IF(B14=C14, "Sim", "Não") -> Não
A15: Terreno | C15: Blightstep Pathway | D15: =IF(B15=C15, "Sim", "Não") -> Não
A16: Terreno | C16: Woodland Cemetery | D16: =IF(B16=C16, "Sim", "Não") -> Não
A17: Terreno | C17: Woodland Cemetery | D17: =IF(B17=C17, "Sim", "Não") -> Não
A18: Terreno | C18: Rootbound Crag | D18: =IF(B18=C18, "Sim", "Não") -> Não
A19: Terreno | C19: Rootbound Crag | D19: =IF(B19=C19, "Sim", "Não") -> Não
A20: Terreno | C20: Dragonskull Summit | D20: =IF(B20=C20, "Sim", "Não") -> Não
A21: Terreno | B21: Mountain | C21: Mountain | D21: =IF(B21=C21, "Sim", "Não") -> Sim
A22: Terreno | B22: Swamp | C22: Swamp | D22: =IF(B22=C22, "Sim", "Não") -> Sim
A23: Terreno | B23: Forest | C23: Forest | D23: =IF(B23=C23, "Sim", "Não") -> Sim
A24: Terreno | B24: Forest | C24: Forest | D24: =IF(B24=C24, "Sim", "Não") -> Sim
A25: Valor | B25: Cauldron Familiar | C25: Cauldron Familiar | D25: =IF(B25=C25, "Sim", "Não") -> Sim
A26: Valor | B26: Cauldron Familiar | C26: Cauldron Familiar | D26: =IF(B26=C26, "Sim", "Não") -> Sim
A27: Valor | B27: Cauldron Familiar | C27: Cauldron Familiar | D27: =IF(B27=C27, "Sim", "Não") -> Sim
A28: Valor | B28: Cauldron Familiar | C28: Cauldron Familiar | D28: =IF(B28=C28, "Sim", "Não") -> Sim
A29: Valor | B29: Witch's Oven | C29: Witch's Oven | D29: =IF(B29=C29, "Sim", "Não") -> Sim
A30: Valor | B30: Witch's Oven | C30: Witch's Oven | D30: =IF(B30=C30, "Sim", "Não") -> Sim
A31: Valor | B31: Witch's Oven | C31: Witch's Oven | D31: =IF(B31=C31, "Sim", "Não") -> Sim
A32: Valor | B32: Witch's Oven | C32: Witch's Oven | D32: =IF(B32=C32, "Sim", "Não") -> Sim
... A36: Valor | B36: Gilded Goose | C36: Gilded Goose | D36: =IF(B36=C36, "Sim", "Não") -> Sim
A37: Valor | C37: Fable of the Mirror-Breaker | D37: =IF(B37=C37, "Sim", "Não") -> Não
A38: Valor | C38: Fable of the Mirror-Breaker | D38: =IF(B38=C38, "Sim", "Não") -> Não
A39: Valor | C39: Fable of the Mirror-Breaker | D39: =IF(B39=C39, "Sim", "Não") -> Não
A40: Valor | C40: Fable of the Mirror-Breaker | D40: =IF(B40=C40, "Sim", "Não") -> Não
A41: Finalizador | B41: Mayhem Devil | C41: Mayhem Devil | D41: =IF(B41=C41, "Sim", "Não") -> Sim
A42: Finalizador | B42: Mayhem Devil | C42: Mayhem Devil | D42: =IF(B42=C42, "Sim", "Não") -> Sim
A43: Finalizador | B43: Mayhem Devil | C43: Mayhem Devil | D43: =IF(B43=C43, "Sim", "Não") -> Sim
...

Sheet Planilha1

Sheet ElfoNeer
A1: Elfos - Pioneer
A2: Função | B2: Carta Atual | C2: Carta Ideal | D2: Carta Final
A3: Terreno | B3: Forest | C3: Lair of the Hydra | D3: =IF(B3=C3, "Sim", "Não") -> Não | F3: Mudanças Faltando | G3: =COUNTIF(D3:D99,"Não") -> 15
A4: Terreno | B4: Forest | C4: Lair of the Hydra | D4: =IF(B4=C4, "Sim", "Não") -> Não | F4: Total de Cartas | G4: =SUM(G7:G21) -> 75
A5: Terreno | B5: Overgrown Tomb | C5: Overgrown Tomb | D5: =IF(B5=C5, "Sim", "Não") -> Sim
A6: Terreno | B6: Overgrown Tomb | C6: Overgrown Tomb | D6: =IF(B6=C6, "Sim", "Não") -> Sim | F6: Funções
A7: Terreno | B7: Overgrown Tomb | C7: Overgrown Tomb | D7: =IF(B7=C7, "Sim", "Não") -> Sim | F7: Terreno | G7: =COUNTIF(A:A,F7) -> 19
A8: Terreno | B8: Overgrown Tomb | C8: Overgrown Tomb | D8: =IF(B8=C8, "Sim", "Não") -> Sim | F8: Mana | G8: =COUNTIF(A:A,F8) -> 18
A9: Terreno | B9: Temple Garden | C9: Temple Garden | D9: =IF(B9=C9, "Sim", "Não") -> Sim | F9: Wincon | G9: =COUNTIF(A:A,F9) -> 4
A10: Terreno | B10: Temple Garden | C10: Temple Garden | D10: =IF(B10=C10, "Sim", "Não") -> Sim | F10: Draw | G10: =COUNTIF(A:A,F10) -> 16
A11: Terreno | B11: Brushland | C11: Brushland | D11: =IF(B11=C11, "Sim", "Não") -> Sim | F11: Combo | G11: =COUNTIF(A:A,F11) -> 3
A12: Terreno | B12: Nykthos, Shrine to Nyx | C12: Nykthos, Shrine to Nyx | D12: =IF(B12=C12, "Sim", "Não") -> Sim | F12: Sideboard | G12: =COUNTIF(A:A,F12) -> 15
A13: Terreno | B13: Sunpetal Grove | C13: Sunpetal Grove | D13: =IF(B13=C13, "Sim", "Não") -> Sim
A14: Terreno | B14: Sunpetal Grove | C14: Sunpetal Grove | D14: =IF(B14=C14, "Sim", "Não") -> Sim
A15: Terreno | B15: Woodland Cemetery | C15: Woodland Cemetery | D15: =IF(B15=C15, "Sim", "Não") -> Sim
A16: Terreno | B16: Unclaimed Territory | C16: Unclaimed Territory | D16: =IF(B16=C16, "Sim", "Não") -> Sim
A17: Terreno | B17: Unclaimed Territory | C17: Unclaimed Territory | D17: =IF(B17=C17, "Sim", "Não") -> Sim
A18: Terreno | B18: Unclaimed Territory | C18: Unclaimed Territory | D18: =IF(B18=C18, "Sim", "Não") -> Sim
A19: Terreno | B19: Unclaimed Territory | C19: Unclaimed Territory | D19: =IF(B19=C19, "Sim", "Não") -> Sim
A20: Terreno | B20: Forest | C20: Forest | D20: =IF(B20=C20, "Sim", "Não") -> Sim
A21: Terreno | B21: Forest | C21: Forest | D21: =IF(B21=C21, "Sim", "Não") -> Sim
A22: Mana | B22: Elvish Mystic | C22: Elvish Mystic | D22: =IF(B22=C22, "Sim", "Não") -> Sim
A23: Mana | B23: Elvish Mystic | C23: Elvish Mystic | D23: =IF(B23=C23, "Sim", "Não") -> Sim
A24: Mana | B24: Elvish Mystic | C24: Elvish Mystic | D24: =IF(B24=C24, "Sim", "Não") -> Sim
A25: Mana | C25: Elvish Mystic | D25: =IF(B25=C25, "Sim", "Não") -> Não
A26: Mana | B26: Jaspera Sentinel | C26: Jaspera Sentinel | D26: =IF(B26=C26, "Sim", "Não") -> Sim
A27: Mana | B27: Jaspera Sentinel | C27: Jaspera Sentinel | D27: =IF(B27=C27, "Sim", "Não") -> Sim
A28: Mana | B28: Jaspera Sentinel | C28: Jaspera Sentinel | D28: =IF(B28=C28, "Sim", "Não") -> Sim
A29: Mana | B29: Jaspera Sentinel | C29: Jaspera Sentinel | D29: =IF(B29=C29, "Sim", "Não") -> Sim
A30: Mana | B30: Llanowar Elves | C30: Llanowar Elves | D30: =IF(B30=C30, "Sim", "Não") -> Sim
A31: Mana | B31: Llanowar Elves | C31: Llanowar Elves | D31: =IF(B31=C31, "Sim", "Não") -> Sim
A32: Mana | B32: Llanowar Elves | C32: Llanowar Elves | D32: =IF(B32=C32, "Sim", "Não") -> Sim
A33: Mana | B33: Llanowar Elves | C33: Llanowar Elves | D33: =IF(B33=C33, "Sim", "Não") -> Sim
A34: Mana | B34: Paradise Druid | C34: Paradise Druid | D34: =IF(B34=C34, "Sim", "Não") -> Sim
A35: Mana | B35: Paradise Druid | C35: Paradise Druid | D35: =IF(B35=C35, "Sim", "Não") -> Sim
A36: Mana | B36: Paradise Druid | C36: Paradise Druid | D36: =IF(B36=C36, "Sim", "Não") -> Sim
A37: Draw | B37: Leaf-Crowned Visionary | C37: Leaf-Crowned Visionary | D37: =IF(B37=C37, "Sim", "Não") -> Sim
... A62: Combo | B62: Paradox Engine | C62: Paradox Engine | D62: =IF(B62=C62, "Sim", "Não") -> Sim
A63: Sideboard | C63: Tamiyo's Safekeeping | D63: =IF(B63=C63, "Sim", "Não") -> Não
A64: Sideboard | C64: Tamiyo's Safekeeping | D64: =IF(B64=C64, "Sim", "Não") -> Não
...

Sheet CoCo Army
A1: CoCo Army - Modern
A2: Função | B2: Carta Atual | C2: Carta Ideal | D2: Carta Final
A3: Terreno | C3: Lair of the Hydra | D3: =IF(B3=C3, "Sim", "Não") -> Não | F3: Mudanças Faltando | G3: =COUNTIF(D3:D99,"Não") -> 58
A4: Terreno | C4: Lair of the Hydra | D4: =IF(B4=C4, "Sim", "Não") -> Não | F4: Total de Cartas | G4: =SUM(G7:G21) -> 75
A5: Terreno | C5: Temple Garden | D5: =IF(B5=C5, "Sim", "Não") -> Não
A6: Terreno | C6: Temple Garden | D6: =IF(B6=C6, "Sim", "Não") -> Não | F6: Funções
A7: Terreno | C7: Brushland | D7: =IF(B7=C7, "Sim", "Não") -> Não | F7: Terreno | G7: =COUNTIF(A:A,F7) -> 23
A8: Terreno | C8: Brushland | D8: =IF(B8=C8, "Sim", "Não") -> Não | F8: ETB | G8: =COUNTIF(A:A,F8) -> 12
A9: Terreno | C9: Sunpetal Grove | D9: =IF(B9=C9, "Sim", "Não") -> Não | F9: Combo | G9: =COUNTIF(A:A,F9) -> 9
A10: Terreno | C10: Sunpetal Grove | D10: =IF(B10=C10, "Sim", "Não") -> Não | F10: Draw | G10: =COUNTIF(A:A,F10) -> 16
A11: Terreno | D11: =IF(B11=C11, "Sim", "Não") -> Sim | F11: Sideboard | G11: =COUNTIF(A:A,F11) -> 15
A12: Terreno | D12: =IF(B12=C12, "Sim", "Não") -> Sim
A13: Terreno | D13: =IF(B13=C13, "Sim", "Não") -> Sim
A14: Terreno | D14: =IF(B14=C14, "Sim", "Não") -> Sim
A15: Terreno | D15: =IF(B15=C15, "Sim", "Não") -> Sim
A16: Terreno | D16: =IF(B16=C16, "Sim", "Não") -> Sim
A17: Terreno | D17: =IF(B17=C17, "Sim", "Não") -> Sim
A18: Terreno | D18: =IF(B18=C18, "Sim", "Não") -> Sim
A19: Terreno | D19: =IF(B19=C19, "Sim", "Não") -> Sim
A20: Terreno | D20: =IF(B20=C20, "Sim", "Não") -> Sim
A21: Terreno | D21: =IF(B21=C21, "Sim", "Não") -> Sim
A22: Terreno | D22: =IF(B22=C22, "Sim", "Não") -> Sim
A23: Terreno | D23: =IF(B23=C23, "Sim", "Não") -> Sim
... A25: Terreno | D25: =IF(B25=C25, "Sim", "Não") -> Sim
A26: Draw | C26: Llanowar Visionary | D26: =IF(B26=C26, "Sim", "Não") -> Não
A27: Draw | C27: Llanowar Visionary | D27: =IF(B27=C27, "Sim", "Não") -> Não
A28: Draw | C28: Llanowar Visionary | D28: =IF(B28=C28, "Sim", "Não") -> Não
A29: Draw | C29: Llanowar Visionary | D29: =IF(B29=C29, "Sim", "Não") -> Não
A30: Draw | C30: Collected Company | D30: =IF(B30=C30, "Sim", "Não") -> Não
A31: Draw | C31: Collected Company | D31: =IF(B31=C31, "Sim", "Não") -> Não
A32: Draw | C32: Collected Company | D32: =IF(B32=C32, "Sim", "Não") -> Não
A33: Draw | C33: Collected Company | D33: =IF(B33=C33, "Sim", "Não") -> Não
A34: Draw | C34: Wall of Omens | D34: =IF(B34=C34, "Sim", "Não") -> Não
A35: Draw | C35: Wall of Omens | D35: =IF(B35=C35, "Sim", "Não") -> Não
A36: Draw | C36: Wall of Omens | D36: =IF(B36=C36, "Sim", "Não") -> Não
A37: Draw | C37: Wall of Omens | D37: =IF(B37=C37, "Sim", "Não") -> Não
... A46: ETB | C46: Champion of Lambholt | D46: =IF(B46=C46, "Sim", "Não") -> Não
A47: ETB | C47: Champion of Lambholt | D47: =IF(B47=C47, "Sim", "Não") -> Não | F47: .
A48: ETB | C48: Champion of Lambholt | D48: =IF(B48=C48, "Sim", "Não") -> Não
A49: ETB | C49: Champion of Lambholt | D49: =IF(B49=C49, "Sim", "Não") -> Não
...

Sheet AbzanCoCoCo
A1: Abzan CoCoCo - Modern
A2: Função | B2: Carta Atual | C2: Carta Ideal | D2: Carta Final
A3: Terreno | B3: Verdant Catacombs | C3: Verdant Catacombs | D3: =IF(B3=C3, "Sim", "Não") -> Sim | F3: Mudanças Faltando | G3: =COUNTIF(D3:D99,"Não") -> 13
A4: Terreno | B4: Verdant Catacombs | C4: Verdant Catacombs | D4: =IF(B4=C4, "Sim", "Não") -> Sim | F4: Total de Cartas | G4: =SUM(G7:G21) -> 75
A5: Terreno | B5: Verdant Catacombs | C5: Verdant Catacombs | D5: =IF(B5=C5, "Sim", "Não") -> Sim
A6: Terreno | B6: Verdant Catacombs | C6: Verdant Catacombs | D6: =IF(B6=C6, "Sim", "Não") -> Sim | F6: Funções
A7: Terreno | B7: Temple Garden | C7: Temple Garden | D7: =IF(B7=C7, "Sim", "Não") -> Sim | E7: Trakiri | F7: Terreno | G7: =COUNTIF(A:A,F7) -> 22
A8: Terreno | B8: Temple Garden | C8: Temple Garden | D8: =IF(B8=C8, "Sim", "Não") -> Sim | F8: Valor | G8: =COUNTIF(A:A,F8) -> 10
A9: Terreno | B9: Godless Shrine | C9: Godless Shrine | D9: =IF(B9=C9, "Sim", "Não") -> Sim | E9: Alela | F9: Combo | G9: =COUNTIF(A:A,F9) -> 20
A10: Terreno | B10: Isolated Chapel | C10: Isolated Chapel | D10: =IF(B10=C10, "Sim", "Não") -> Sim | F10: Draw | G10: =COUNTIF(A:A,F10) -> 8
A11: Terreno | B11: Isolated Chapel | C11: Isolated Chapel | D11: =IF(B11=C11, "Sim", "Não") -> Sim | E11: OwA | F11: Sideboard | G11: =COUNTIF(A:A,F11) -> 15
A12: Terreno | B12: Woodland Cemetery | C12: Woodland Cemetery | D12: =IF(B12=C12, "Sim", "Não") -> Sim | E12: Sapo
A13: Terreno | B13: Woodland Cemetery | C13: Woodland Cemetery | D13: =IF(B13=C13, "Sim", "Não") -> Sim | E13: OwA
A14: Terreno | B14: Sunpetal Grove | C14: Sunpetal Grove | D14: =IF(B14=C14, "Sim", "Não") -> Sim | E14: OwA
A15: Terreno | B15: Sunpetal Grove | C15: Sunpetal Grove | D15: =IF(B15=C15, "Sim", "Não") -> Sim | E15: Trakiri
A16: Terreno | B16: Forest | C16: Forest | D16: =IF(B16=C16, "Sim", "Não") -> Sim
A17: Terreno | B17: Forest | C17: Forest | D17: =IF(B17=C17, "Sim", "Não") -> Sim
A18: Terreno | B18: Forest | C18: Forest | D18: =IF(B18=C18, "Sim", "Não") -> Sim
A19: Terreno | B19: Forest | C19: Forest | D19: =IF(B19=C19, "Sim", "Não") -> Sim
A20: Terreno | B20: Forest | C20: Forest | D20: =IF(B20=C20, "Sim", "Não") -> Sim
A21: Terreno | B21: Swamp | C21: Swamp | D21: =IF(B21=C21, "Sim", "Não") -> Sim
A22: Terreno | B22: Swamp | C22: Swamp | D22: =IF(B22=C22, "Sim", "Não") -> Sim
A23: Terreno | B23: Plains | C23: Plains | D23: =IF(B23=C23, "Sim", "Não") -> Sim
A24: Terreno | B24: Plains | C24: Plains | D24: =IF(B24=C24, "Sim", "Não") -> Sim
A25: Valor | B25: Gilded Goose | C25: Gilded Goose | D25: =IF(B25=C25, "Sim", "Não") -> Sim
A26: Valor | B26: Gilded Goose | C26: Gilded Goose | D26: =IF(B26=C26, "Sim", "Não") -> Sim
A27: Valor | B27: Gilded Goose | C27: Gilded Goose | D27: =IF(B27=C27, "Sim", "Não") -> Sim
A28: Valor | B28: Gilded Goose | C28: Gilded Goose | D28: =IF(B28=C28, "Sim", "Não") -> Sim | E28: Sapo
A29: Draw | B29: Collected Company | C29: Collected Company | D29: =IF(B29=C29, "Sim", "Não") -> Sim
A30: Draw | B30: Collected Company | C30: Collected Company | D30: =IF(B30=C30, "Sim", "Não") -> Sim
A31: Draw | B31: Collected Company | C31: Collected Company | D31: =IF(B31=C31, "Sim", "Não") -> Sim
A32: Draw | B32: Collected Company | C32: Collected Company | D32: =IF(B32=C32, "Sim", "Não") -> Sim
A33: Draw | B33: Trail of Crumbs | C33: Trail of Crumbs | D33: =IF(B33=C33, "Sim", "Não") -> Sim
A34: Draw | B34: Trail of Crumbs | C34: Trail of Crumbs | D34: =IF(B34=C34, "Sim", "Não") -> Sim
A35: Draw | B35: Trail of Crumbs | C35: Trail of Crumbs | D35: =IF(B35=C35, "Sim", "Não") -> Sim
A36: Draw | B36: Trail of Crumbs | C36: Trail of Crumbs | D36: =IF(B36=C36, "Sim", "Não") -> Sim
A37: Valor | B37: Witch's Oven | C37: Witch's Oven | D37: =IF(B37=C37, "Sim", "Não") -> Sim
A38: Valor | B38: Witch's Oven | C38: Witch's Oven | D38: =IF(B38=C38, "Sim", "Não") -> Sim
A39: Valor | B39: Witch's Oven | C39: Witch's Oven | D39: =IF(B39=C39, "Sim", "Não") -> Sim
A40: Valor | B40: Witch's Oven | C40: Witch's Oven | D40: =IF(B40=C40, "Sim", "Não") -> Sim
...

Sheet AbzanCoCoCo (2)
A1: Abzan CoCoCo
A2: Função | B2: Carta Atual | C2: Carta Ideal | D2: Carta Final
A3: Terreno | C3: Overgrown Tomb | D3: =IF(B3=C3, "Sim", "Não") -> Não | F3: Mudanças Faltando | G3: =COUNTIF(D3:D99,"Não") -> 75
A4: Terreno | C4: Overgrown Tomb | D4: =IF(B4=C4, "Sim", "Não") -> Não | F4: Total de Cartas | G4: =SUM(G7:G21) -> 75
A5: Terreno | C5: Overgrown Tomb | D5: =IF(B5=C5, "Sim", "Não") -> Não
A6: Terreno | C6: Overgrown Tomb | D6: =IF(B6=C6, "Sim", "Não") -> Não | F6: Funções
A7: Terreno | C7: Temple Garden | D7: =IF(B7=C7, "Sim", "Não") -> Não | F7: Terreno | G7: =COUNTIF(A:A,F7) -> 21
A8: Terreno | C8: Temple Garden | D8: =IF(B8=C8, "Sim", "Não") -> Não | F8: Valor | G8: =COUNTIF(A:A,F8) -> 9
A9: Terreno | C9: Godless Shrine | D9: =IF(B9=C9, "Sim", "Não") -> Não | F9: Combo | G9: =COUNTIF(A:A,F9) -> 20
A10: Terreno | C10: Isolated Chapel | D10: =IF(B10=C10, "Sim", "Não") -> Não | F10: Draw | G10: =COUNTIF(A:A,F10) -> 10
A11: Terreno | C11: Isolated Chapel | D11: =IF(B11=C11, "Sim", "Não") -> Não | F11: Sideboard | G11: =COUNTIF(A:A,F11) -> 15
A12: Terreno | C12: Woodland Cemetery | D12: =IF(B12=C12, "Sim", "Não") -> Não
A13: Terreno | C13: Woodland Cemetery | D13: =IF(B13=C13, "Sim", "Não") -> Não
A14: Terreno | C14: Sunpetal Grove | D14: =IF(B14=C14, "Sim", "Não") -> Não
A15: Terreno | C15: Sunpetal Grove | D15: =IF(B15=C15, "Sim", "Não") -> Não
A16: Terreno | C16: Forest | D16: =IF(B16=C16, "Sim", "Não") -> Não
A17: Terreno | C17: Forest | D17: =IF(B17=C17, "Sim", "Não") -> Não
A18: Terreno | C18: Forest | D18: =IF(B18=C18, "Sim", "Não") -> Não
A19: Terreno | C19: Forest | D19: =IF(B19=C19, "Sim", "Não") -> Não
A20: Terreno | C20: Swamp | D20: =IF(B20=C20, "Sim", "Não") -> Não
A21: Terreno | C21: Swamp | D21: =IF(B21=C21, "Sim", "Não") -> Não
A22: Terreno | C22: Plains | D22: =IF(B22=C22, "Sim", "Não") -> Não
A23: Terreno | C23: Plains | D23: =IF(B23=C23, "Sim", "Não") -> Não
... A77: Sideboard | C77: Knight of Autumn | D77: =IF(B77=C77, "Sim", "Não") -> Não

Sheet AbzanCoCoCo (3)
A1: Abzan CoCoCo - Modern
A2: Função | B2: Carta Atual | C2: Carta Ideal | D2: Carta Final
A3: Terreno | B3: Overgrown Tomb | C3: Overgrown Tomb | D3: =IF(B3=C3, "Sim", "Não") -> Sim | F3: Mudanças Faltando | G3: =COUNTIF(D3:D99,"Não") -> 21 | I3: Lonis, Cryptozoologist
A4: Terreno | B4: Overgrown Tomb | C4: Overgrown Tomb | D4: =IF(B4=C4, "Sim", "Não") -> Sim | F4: Total de Cartas | G4: =SUM(G7:G21) -> 75 | I4: Old Rutstein
A5: Terreno | B5: Overgrown Tomb | C5: Overgrown Tomb | D5: =IF(B5=C5, "Sim", "Não") -> Sim | I5: Polukranos Reborn
A6: Terreno | B6: Overgrown Tomb | C6: Overgrown Tomb | D6: =IF(B6=C6, "Sim", "Não") -> Sim | F6: Funções | I6: Thalia, Heretic Cathar
A7: Terreno | B7: Temple Garden | C7: Temple Garden | D7: =IF(B7=C7, "Sim", "Não") -> Sim | F7: Terreno | G7: =COUNTIF(A:A,F7) -> 20 | I7: Sarinth Steelseeker
A8: Terreno | B8: Temple Garden | C8: Temple Garden | D8: =IF(B8=C8, "Sim", "Não") -> Sim | F8: Valor | G8: =COUNTIF(A:A,F8) -> 20 | I8: Suture Priest
A9: Terreno | B9: Godless Shrine | C9: Godless Shrine | D9: =IF(B9=C9, "Sim", "Não") -> Sim | F9: Combo | G9: =COUNTIF(A:A,F9) -> 10 | I9: Corpse Knight
A10: Terreno | B10: Plains | C10: Indatha Triome | D10: =IF(B10=C10, "Sim", "Não") -> Não | F10: Tutor | G10: =COUNTIF(A:A,F10) -> 10 | I10: Elas-il Kor, Sadistic Pilgrim
A11: Terreno | B11: Woodland Cemetery | C11: Verdant Catacombs | D11: =IF(B11=C11, "Sim", "Não") -> Não | F11: Sideboard | G11: =COUNTIF(A:A,F11) -> 15 | I11: Essence Warden
A12: Terreno | B12: Woodland Cemetery | C12: Verdant Catacombs | D12: =IF(B12=C12, "Sim", "Não") -> Não | I12: Soul's Attendant
A13: Terreno | B13: Sunpetal Grove | C13: Windswept Heath | D13: =IF(B13=C13, "Sim", "Não") -> Não | I13: Soul Warden
A14: Terreno | B14: Sunpetal Grove | C14: Windswept Heath | D14: =IF(B14=C14, "Sim", "Não") -> Não | I14: Reckless Fireweaver
A15: Terreno | B15: Isolated Chapel | C15: Marsh Flats | D15: =IF(B15=C15, "Sim", "Não") -> Não | I15: Liliana, Heretical Healer
A16: Terreno | B16: Isolated Chapel | C16: Marsh Flats | D16: =IF(B16=C16, "Sim", "Não") -> Não
A17: Terreno | B17: Dryad Arbor | C17: Dryad Arbor | D17: =IF(B17=C17, "Sim", "Não") -> Sim
A18: Terreno | B18: Forest | C18: Boseiju, Who Endures | D18: =IF(B18=C18, "Sim", "Não") -> Não
A19: Terreno | B19: Forest | C19: Forest | D19: =IF(B19=C19, "Sim", "Não") -> Sim
A20: Terreno | B20: Forest | C20: Forest | D20: =IF(B20=C20, "Sim", "Não") -> Sim
A21: Terreno | B21: Swamp | C21: Swamp | D21: =IF(B21=C21, "Sim", "Não") -> Sim
A22: Terreno | B22: Plains | C22: Plains | D22: =IF(B22=C22, "Sim", "Não") -> Sim
A23: Tutor | B23: Invasion of Ikoria | C23: Invasion of Ikoria | D23: =IF(B23=C23, "Sim", "Não") -> Sim | E23: Ecological Apreciation
A24: Tutor | B24: Invasion of Ikoria | C24: Invasion of Ikoria | D24: =IF(B24=C24, "Sim", "Não") -> Sim
A25: Tutor | B25: Collected Company | C25: Collected Company | D25: =IF(B25=C25, "Sim", "Não") -> Sim
A26: Tutor | B26: Collected Company | C26: Collected Company | D26: =IF(B26=C26, "Sim", "Não") -> Sim
A27: Tutor | B27: Collected Company | C27: Collected Company | D27: =IF(B27=C27, "Sim", "Não") -> Sim
A28: Tutor | B28: Collected Company | C28: Collected Company | D28: =IF(B28=C28, "Sim", "Não") -> Sim
A29: Tutor | B29: Chord of Calling | C29: Chord of Calling | D29: =IF(B29=C29, "Sim", "Não") -> Sim
A30: Tutor | B30: Chord of Calling | C30: Chord of Calling | D30: =IF(B30=C30, "Sim", "Não") -> Sim
A31: Tutor | B31: Chord of Calling | C31: Chord of Calling | D31: =IF(B31=C31, "Sim", "Não") -> Sim
A32: Tutor | B32: Chord of Calling | C32: Chord of Calling | D32: =IF(B32=C32, "Sim", "Não") -> Sim
A33: Valor | B33: Skyclave Apparition | C33: Skyclave Apparition | D33: =IF(B33=C33, "Sim", "Não") -> Sim
A34: Valor | B34: Skyclave Apparition | C34: Skyclave Apparition | D34: =IF(B34=C34, "Sim", "Não") -> Sim
A35: Valor | B35: Skyclave Apparition | C35: Skyclave Apparition | D35: =IF(B35=C35, "Sim", "Não") -> Sim
... A44: Valor | B44: Swamp | C44: Academy Manufactor | D44: =IF(B44=C44, "Sim", "Não") -> Não
A45: Valor | B45: Academy Manufactor | C45: Academy Manufactor | D45: =IF(B45=C45, "Sim", "Não") -> Sim | E45: Empurrão Fatal
A46: Valor | B46: Cauldron Familiar | C46: Academy Manufactor | D46: =IF(B46=C46, "Sim", "Não") -> Não
A47: Valor | B47: Viscera Seer | C47: Gala Greeters | D47: =IF(B47=C47, "Sim", "Não") -> Não
A48: Valor | B48: Rosie Cotton of South Lane | C48: Gala Greeters | D48: =IF(B48=C48, "Sim", "Não") -> Não
...

Sheet AbzanCoCoCo (4)
A1: 4c CoCoCo - Modern
A2: Função | B2: Carta Atual | C2: Carta Ideal | D2: Carta Final
A3: Terreno | B3: Overgrown Tomb | C3: Overgrown Tomb | D3: =IF(B3=C3, "Sim", "Não") -> Sim | F3: Mudanças Faltando | G3: =COUNTIF(D3:D99,"Não") -> 16 | I3: Necromentia
A4: Terreno | B4: Overgrown Tomb | C4: Overgrown Tomb | D4: =IF(B4=C4, "Sim", "Não") -> Sim | F4: Total de Cartas | G4: =SUM(G7:G21) -> 75 | I4: Old Rutstein
A5: Terreno | B5: Breeding Pool | C5: Breeding Pool | D5: =IF(B5=C5, "Sim", "Não") -> Sim | I5: Unmmored Ego
A6: Terreno | B6: Forest | C6: Breeding Pool | D6: =IF(B6=C6, "Sim", "Não") -> Não | F6: Funções | I6: Reckless Fireweaver
A7: Terreno | B7: Temple Garden | C7: Temple Garden | D7: =IF(B7=C7, "Sim", "Não") -> Sim | F7: Terreno | G7: =COUNTIF(A:A,F7) -> 21 | I7: Orcish Bowmasters
A8: Terreno | B8: Temple Garden | C8: Temple Garden | D8: =IF(B8=C8, "Sim", "Não") -> Sim | F8: Valor | G8: =COUNTIF(A:A,F8) -> 20 | I8: Voice of Resurgence
A9: Terreno | B9: Spara's Headquarters | C9: Spara's Headquarters | D9: =IF(B9=C9, "Sim", "Não") -> Sim | F9: Combo | G9: =COUNTIF(A:A,F9) -> 10 | I9: Eidolon of Rethoric
A10: Terreno | B10: Passagem Fabulosa | C10: Indatha Triome | D10: =IF(B10=C10, "Sim", "Não") -> Não | F10: Tutor | G10: =COUNTIF(A:A,F10) -> 9 | I10: Ranger-Captain of Eos
A11: Terreno | B11: Hinterland Harbor | C11: Misty Rainforest | D11: =IF(B11=C11, "Sim", "Não") -> Não | F11: Sideboard | G11: =COUNTIF(A:A,F11) -> 15
A12: Terreno | B12: Hinterland Harbor | C12: Misty Rainforest | D12: =IF(B12=C12, "Sim", "Não") -> Não
A13: Terreno | B13: Overgrown Tomb | C13: Verdant Catacombs | D13: =IF(B13=C13, "Sim", "Não") -> Não
A14: Terreno | B14: Overgrown Tomb | C14: Verdant Catacombs | D14: =IF(B14=C14, "Sim", "Não") -> Não
A15: Terreno | B15: Woodland Cemetery | C15: Verdant Catacombs | D15: =IF(B15=C15, "Sim", "Não") -> Não
A16: Terreno | B16: Woodland Cemetery | C16: Windswept Heath | D16: =IF(B16=C16, "Sim", "Não") -> Não
A17: Terreno | B17: Sunpetal Grove | C17: Windswept Heath | D17: =IF(B17=C17, "Sim", "Não") -> Não
A18: Terreno | B18: Sunpetal Grove | C18: Windswept Heath | D18: =IF(B18=C18, "Sim", "Não") -> Não
A19: Terreno | B19: City of Brass | C19: Windswept Heath | D19: =IF(B19=C19, "Sim", "Não") -> Não
A20: Terreno | B20: Gingerbread Cabin | C20: Gingerbread Cabin | D20: =IF(B20=C20, "Sim", "Não") -> Sim
A21: Terreno | B21: Dryad Arbor | C21: Dryad Arbor | D21: =IF(B21=C21, "Sim", "Não") -> Sim
A22: Terreno | B22: Plains | C22: Plains | D22: =IF(B22=C22, "Sim", "Não") -> Sim
A23: Terreno | B23: Swamp | C23: Swamp | D23: =IF(B23=C23, "Sim", "Não") -> Sim
... A77: Sideboard | B77: Scavenging Ooze | C77: Scavenging Ooze | D77: =IF(B77=C77, "Sim", "Não") -> Sim

Sheet AbzanCoCoCo (5)
A1: 4c CoCoCo - Modern
A2: Função | B2: Carta Atual | C2: Carta Ideal | D2: Carta Final
A3: Terreno | B3: Overgrown Tomb | C3: Overgrown Tomb | D3: =IF(B3=C3, "Sim", "Não") -> Sim | F3: Mudanças Faltando | G3: =COUNTIF(D3:D99,"Não") -> 16 | I3: Boromir, Warden of the Tower
A4: Terreno | B4: Overgrown Tomb | C4: Overgrown Tomb | D4: =IF(B4=C4, "Sim", "Não") -> Sim | F4: Total de Cartas | G4: =SUM(G7:G21) -> 75 | I4: Old Rutstein
A5: Terreno | B5: Breeding Pool | C5: Breeding Pool | D5: =IF(B5=C5, "Sim", "Não") -> Sim | I5: Especialista em Resgates
A6: Terreno | B6: Temple Garden | C6: Temple Garden | D6: =IF(B6=C6, "Sim", "Não") -> Sim | F6: Funções | I6: Reckless Fireweaver
A7: Terreno | B7: Yavimaya, Cradle of Growth | C7: Yavimaya, Cradle of Growth | D7: =IF(B7=C7, "Sim", "Não") -> Sim | F7: Terreno | G7: =COUNTIF(A:A,F7) -> 21 | I7: Orcish Bowmasters
A8: Terreno | B8: Spara's Headquarters | C8: Spara's Headquarters | D8: =IF(B8=C8, "Sim", "Não") -> Sim | F8: Valor | G8: =COUNTIF(A:A,F8) -> 20 | I8: Voice of Resurgence
A9: Terreno | B9: Forest | C9: Urza's Saga | D9: =IF(B9=C9, "Sim", "Não") -> Não | F9: Combo | G9: =COUNTIF(A:A,F9) -> 10 | I9: Eidolon of Rethoric
A10: Terreno | B10: Overgrown Tomb | C10: Urza's Saga | D10: =IF(B10=C10, "Sim", "Não") -> Não | F10: Tutor | G10: =COUNTIF(A:A,F10) -> 9 | I10: Ranger-Captain of Eos
A11: Terreno | B11: Overgrown Tomb | C11: Misty Rainforest | D11: =IF(B11=C11, "Sim", "Não") -> Não | F11: Sideboard | G11: =COUNTIF(A:A,F11) -> 15
A12: Terreno | B12: Hinterland Harbor | C12: Misty Rainforest | D12: =IF(B12=C12, "Sim", "Não") -> Não
A13: Terreno | B13: Verdant Catacombs | C13: Verdant Catacombs | D13: =IF(B13=C13, "Sim", "Não") -> Sim
A14: Terreno | B14: Temple Garden | C14: Verdant Catacombs | D14: =IF(B14=C14, "Sim", "Não") -> Não
A15: Terreno | B15: Verdant Catacombs | C15: Verdant Catacombs | D15: =IF(B15=C15, "Sim", "Não") -> Sim
A16: Terreno | B16: Windswept Heath | C16: Windswept Heath | D16: =IF(B16=C16, "Sim", "Não") -> Sim
A17: Terreno | B17: Windswept Heath | C17: Windswept Heath | D17: =IF(B17=C17, "Sim", "Não") -> Sim
A18: Terreno | B18: Windswept Heath | C18: Windswept Heath | D18: =IF(B18=C18, "Sim", "Não") -> Sim
A19: Terreno | B19: Windswept Heath | C19: Windswept Heath | D19: =IF(B19=C19, "Sim", "Não") -> Sim
A20: Terreno | B20: Gingerbread Cabin | C20: Gingerbread Cabin | D20: =IF(B20=C20, "Sim", "Não") -> Sim
A21: Terreno | B21: Dryad Arbor | C21: Dryad Arbor | D21: =IF(B21=C21, "Sim", "Não") -> Sim
A22: Terreno | B22: Forest | C22: Forest | D22: =IF(B22=C22, "Sim", "Não") -> Sim
A23: Terreno | B23: Forest | C23: Forest | D23: =IF(B23=C23, "Sim", "Não") -> Sim
... A77: Sideboard | B77: Scavenging Ooze | C77: Soul-Guide Lantern | D77: =IF(B77=C77, "Sim", "Não") -> Não

Sheet 4c Tolkien Company
A1: 4c CoCoCo - Modern
A2: Função | B2: Carta Atual | C2: Carta Ideal | D2: Carta Final
A3: Terreno | B3: Overgrown Tomb | C3: Overgrown Tomb | D3: =IF(B3=C3, "Sim", "Não") -> Sim | F3: Mudanças Faltando | G3: =COUNTIF(D3:D99,"Não") -> 6 | I3: Boromir, Warden of the Tower
A4: Terreno | B4: Breeding Pool | C4: Breeding Pool | D4: =IF(B4=C4, "Sim", "Não") -> Sim | F4: Total de Cartas | G4: =SUM(G7:G21) -> 75 | I4: Old Rutstein
A5: Terreno | B5: Temple Garden | C5: Temple Garden | D5: =IF(B5=C5, "Sim", "Não") -> Sim | I5: Especialista em Resgates
A6: Terreno | B6: Yavimaya, Cradle of Growth | C6: Yavimaya, Cradle of Growth | D6: =IF(B6=C6, "Sim", "Não") -> Sim | F6: Funções | I6: Reckless Fireweaver
A7: Terreno | B7: Urza's Saga | C7: Urza's Saga | D7: =IF(B7=C7, "Sim", "Não") -> Sim | F7: Terreno | G7: =COUNTIF(A:A,F7) -> 20 | I7: Orcish Bowmasters
A8: Terreno | B8: Urza's Saga | C8: Urza's Saga | D8: =IF(B8=C8, "Sim", "Não") -> Sim | F8: Valor | G8: =COUNTIF(A:A,F8) -> 22 | I8: Voice of Resurgence
A9: Terreno | B9: Misty Rainforest | C9: Misty Rainforest | D9: =IF(B9=C9, "Sim", "Não") -> Sim | F9: Combo | G9: =COUNTIF(A:A,F9) -> 10 | I9: Eidolon of Rethoric
A10: Terreno | B10: Misty Rainforest | C10: Misty Rainforest | D10: =IF(B10=C10, "Sim", "Não") -> Sim | F10: Tutor | G10: =COUNTIF(A:A,F10) -> 8 | I10: Ranger-Captain of Eos
A11: Terreno | B11: Verdant Catacombs | C11: Verdant Catacombs | D11: =IF(B11=C11, "Sim", "Não") -> Sim | F11: Sideboard | G11: =COUNTIF(A:A,F11) -> 15
A12: Terreno | B12: Verdant Catacombs | C12: Verdant Catacombs | D12: =IF(B12=C12, "Sim", "Não") -> Sim
A13: Terreno | B13: Verdant Catacombs | C13: Verdant Catacombs | D13: =IF(B13=C13, "Sim", "Não") -> Sim
A14: Terreno | B14: Windswept Heath | C14: Windswept Heath | D14: =IF(B14=C14, "Sim", "Não") -> Sim
A15: Terreno | B15: Windswept Heath | C15: Windswept Heath | D15: =IF(B15=C15, "Sim", "Não") -> Sim
A16: Terreno | B16: Windswept Heath | C16: Windswept Heath | D16: =IF(B16=C16, "Sim", "Não") -> Sim
A17: Terreno | B17: Windswept Heath | C17: Windswept Heath | D17: =IF(B17=C17, "Sim", "Não") -> Sim
A18: Terreno | B18: Gingerbread Cabin | C18: Gingerbread Cabin | D18: =IF(B18=C18, "Sim", "Não") -> Sim
A19: Terreno | B19: Gingerbread Cabin | C19: Gingerbread Cabin | D19: =IF(B19=C19, "Sim", "Não") -> Sim
A20: Terreno | B20: Dryad Arbor | C20: Dryad Arbor | D20: =IF(B20=C20, "Sim", "Não") -> Sim
A21: Terreno | B21: Forest | C21: Forest | D21: =IF(B21=C21, "Sim", "Não") -> Sim
A22: Terreno | B22: Forest | C22: Forest | D22: =IF(B22=C22, "Sim", "Não") -> Sim
A23: Tutor | B23: Collected Company | C23: Collected Company | D23: =IF(B23=C23, "Sim", "Não") -> Sim
... A77: Sideboard | B77: Scavenging Ooze | C77: Scavenging Ooze | D77: =IF(B77=C77, "Sim", "Não") -> Sim

Sheet 5c Tolkien Company
A1: 5c CoCoCo - Modern
A2: Função | B2: Carta Atual | C2: Carta Ideal | D2: Carta Final
A3: Terreno | C3: Overgrown Tomb | D3: =IF(B3=C3, "Sim", "Não") -> Não | F3: Mudanças Faltando | G3: =COUNTIF(D3:D99,"Não") -> 68 | I3: Boromir, Warden of the Tower
A4: Terreno | C4: Breeding Pool | D4: =IF(B4=C4, "Sim", "Não") -> Não | F4: Total de Cartas | G4: =SUM(G7:G21) -> 75 | I4: Old Rutstein
A5: Terreno | C5: Temple Garden | D5: =IF(B5=C5, "Sim", "Não") -> Não | I5: Especialista em Resgates
A6: Terreno | C6: Stomping Ground | D6: =IF(B6=C6, "Sim", "Não") -> Não | F6: Funções | I6: Reckless Fireweaver
A7: Terreno | C7: Yavimaya, Cradle of Growth | D7: =IF(B7=C7, "Sim", "Não") -> Não | F7: Terreno | G7: =COUNTIF(A:A,F7) -> 20 | I7: Orcish Bowmasters
A8: Terreno | C8: Urza's Saga | D8: =IF(B8=C8, "Sim", "Não") -> Não | F8: Valor | G8: =COUNTIF(A:A,F8) -> 22 | I8: Voice of Resurgence
A9: Terreno | C9: Urza's Saga | D9: =IF(B9=C9, "Sim", "Não") -> Não | F9: Combo | G9: =COUNTIF(A:A,F9) -> 7 | I9: Eidolon of Rethoric
A10: Terreno | C10: Misty Rainforest | D10: =IF(B10=C10, "Sim", "Não") -> Não | F10: Tutor | G10: =COUNTIF(A:A,F10) -> 11 | I10: Ranger-Captain of Eos
A11: Terreno | C11: Misty Rainforest | D11: =IF(B11=C11, "Sim", "Não") -> Não | F11: Sideboard | G11: =COUNTIF(A:A,F11) -> 15
A12: Terreno | C12: Verdant Catacombs | D12: =IF(B12=C12, "Sim", "Não") -> Não
A13: Terreno | C13: Verdant Catacombs | D13: =IF(B13=C13, "Sim", "Não") -> Não
A14: Terreno | C14: Verdant Catacombs | D14: =IF(B14=C14, "Sim", "Não") -> Não
A15: Terreno | C15: Windswept Heath | D15: =IF(B15=C15, "Sim", "Não") -> Não
A16: Terreno | C16: Windswept Heath | D16: =IF(B16=C16, "Sim", "Não") -> Não
A17: Terreno | C17: Windswept Heath | D17: =IF(B17=C17, "Sim", "Não") -> Não
A18: Terreno | C18: Windswept Heath | D18: =IF(B18=C18, "Sim", "Não") -> Não
A19: Terreno | C19: Gingerbread Cabin | D19: =IF(B19=C19, "Sim", "Não") -> Não
A20: Terreno | C20: Dryad Arbor | D20: =IF(B20=C20, "Sim", "Não") -> Não
A21: Terreno | C21: Forest | D21: =IF(B21=C21, "Sim", "Não") -> Não
A22: Terreno | C22: Forest | D22: =IF(B22=C22, "Sim", "Não") -> Não
A23: Tutor | C23: Collected Company | D23: =IF(B23=C23, "Sim", "Não") -> Não
... A67: Sideboard | C67: Desprezador de Mágica | D67: =IF(B67=C67, "Sim", "Não") -> Não
A68: Sideboard | B68: Desprezador de Mágicas | C68: Desprezador de Mágica | D68: =IF(B68=C68, "Sim", "Não") -> Não
A69: Sideboard | B69: Voz da Ressurgência | C69: Voz da Ressurgência | D69: =IF(B69=C69, "Sim", "Não") -> Sim
A70: Sideboard | B70: Voz da Ressurgência | C70: Voz da Ressurgência | D70: =IF(B70=C70, "Sim", "Não") -> Sim
A71: Sideboard | B71: Voz da Ressurgência | C71: Voz da Ressurgência | D71: =IF(B71=C71, "Sim", "Não") -> Sim
A72: Sideboard | B72: Lavinia, Azorius Renegade | C72: Haywire Mite | D72: =IF(B72=C72, "Sim", "Não") -> Não
A73: Sideboard | B73: Phyrexian Revoker | C73: Haywire Mite | D73: =IF(B73=C73, "Sim", "Não") -> Não
A74: Sideboard | B74: Phyrexian Revoker | C74: Phyrexian Revoker | D74: =IF(B74=C74, "Sim", "Não") -> Sim
A75: Sideboard | B75: Pithing Needle | C75: Pithing Needle | D75: =IF(B75=C75, "Sim", "Não") -> Sim
A76: Sideboard | B76: Scavenging Ooze | C76: Scavenging Ooze | D76: =IF(B76=C76, "Sim", "Não") -> Sim
A77: Sideboard | B77: Scavenging Ooze | C77: Scavenging Ooze | D77: =IF(B77=C77, "Sim", "Não") -> Sim

Sheet CoCo Slivers
A1: CoCo Slivers
A2: Função | B2: Carta Atual | C2: Carta Ideal | D2: Carta Final
A3: Terreno | B3: Sliver Hive | C3: Sliver Hive | D3: =IF(B3=C3, "Sim", "Não") -> Sim | F3: Mudanças Faltando | G3: =COUNTIF(D3:D99,"Não") -> 15
A4: Terreno | B4: Sliver Hive | C4: Sliver Hive | D4: =IF(B4=C4, "Sim", "Não") -> Sim | F4: Total de Cartas | G4: =SUM(G7:G21) -> 35
A5: Terreno | B5: Sliver Hive | C5: Sliver Hive | D5: =IF(B5=C5, "Sim", "Não") -> Sim
A6: Terreno | B6: Temple Garden | C6: Temple Garden | D6: =IF(B6=C6, "Sim", "Não") -> Sim | F6: Funções
A7: Terreno | B7: Breeding Pool | C7: Breeding Pool | D7: =IF(B7=C7, "Sim", "Não") -> Sim | F7: Terreno | G7: =COUNTIF(A:A,F7) -> 20
A8: Terreno | B8: Godless Shrine | C8: Godless Shrine | D8: =IF(B8=C8, "Sim", "Não") -> Sim | F8: Valor | G8: =COUNTIF(A:A,F8) -> 0
A9: Terreno | B9: Hallowed Fountain | C9: Hallowed Fountain | D9: =IF(B9=C9, "Sim", "Não") -> Sim | F9: Combo | G9: =COUNTIF(A:A,F9) -> 0
A10: Terreno | B10: Stomping Ground | C10: Stomping Ground | D10: =IF(B10=C10, "Sim", "Não") -> Sim | F10: Tutor | G10: =COUNTIF(A:A,F10) -> 0
A11: Terreno | B11: Overgrown Tomb | C11: Overgrown Tomb | D11: =IF(B11=C11, "Sim", "Não") -> Sim | F11: Sideboard | G11: =COUNTIF(A:A,F11) -> 15
A12: Terreno | B12: Windswept Heath | C12: Windswept Heath | D12: =IF(B12=C12, "Sim", "Não") -> Sim
A13: Terreno | B13: Windswept Heath | C13: Windswept Heath | D13: =IF(B13=C13, "Sim", "Não") -> Sim
A14: Terreno | B14: Windswept Heath | C14: Windswept Heath | D14: =IF(B14=C14, "Sim", "Não") -> Sim
A15: Terreno | B15: Windswept Heath | C15: Windswept Heath | D15: =IF(B15=C15, "Sim", "Não") -> Sim
A16: Terreno | B16: Misty Rainforest | C16: Misty Rainforest | D16: =IF(B16=C16, "Sim", "Não") -> Sim
A17: Terreno | B17: Misty Rainforest | C17: Misty Rainforest | D17: =IF(B17=C17, "Sim", "Não") -> Sim
A18: Terreno | B18: Verdant Catacombs | C18: Verdant Catacombs | D18: =IF(B18=C18, "Sim", "Não") -> Sim
A19: Terreno | B19: Verdant Catacombs | C19: Verdant Catacombs | D19: =IF(B19=C19, "Sim", "Não") -> Sim
A20: Terreno | B20: Verdant Catacombs | C20: Verdant Catacombs | D20: =IF(B20=C20, "Sim", "Não") -> Sim
A21: Terreno | B21: Forest | C21: Forest | D21: =IF(B21=C21, "Sim", "Não") -> Sim
A22: Terreno | B22: Forest | C22: Forest | D22: =IF(B22=C22, "Sim", "Não") -> Sim
A23: Draw | B23: Collected Company | C23: Collected Company | D23: =IF(B23=C23, "Sim", "Não") -> Sim
... A41: Ninhada | B41: Leeching Sliver | C41: Leeching Sliver | D41: =IF(B41=C41, "Sim", "Não") -> Sim
A42: Ninhada | C42: Leeching Sliver | D42: =IF(B42=C42, "Sim", "Não") -> Não
A43: Ninhada | B43: Diffusion Sliver | C43: Diffusion Sliver | D43: =IF(B43=C43, "Sim", "Não") -> Sim
A44: Ninhada | B44: Diffusion Sliver | C44: Diffusion Sliver | D44: =IF(B44=C44, "Sim", "Não") -> Sim
A45: Ninhada | B45: Diffusion Sliver | C45: Diffusion Sliver | D45: =IF(B45=C45, "Sim", "Não") -> Sim
A46: Ninhada | B46: Diffusion Sliver | C46: Diffusion Sliver | D46: =IF(B46=C46, "Sim", "Não") -> Sim
A47: Ninhada | B47: Cloudshredder Sliver | C47: Cloudshredder Sliver | D47: =IF(B47=C47, "Sim", "Não") -> Sim
A48: Ninhada | B48: Cloudshredder Sliver | C48: Cloudshredder Sliver | D48: =IF(B48=C48, "Sim", "Não") -> Sim
A49: Ninhada | C49: Cloudshredder Sliver | D49: =IF(B49=C49, "Sim", "Não") -> Não
A50: Ninhada | C50: Cloudshredder Sliver | D50: =IF(B50=C50, "Sim", "Não") -> Não
A51: Ninhada | B51: Striking Sliver | C51: Striking Sliver | D51: =IF(B51=C51, "Sim", "Não") -> Sim
A52: Ninhada | B52: Striking Sliver | C52: Striking Sliver | D52: =IF(B52=C52, "Sim", "Não") -> Sim
A53: Ninhada | C53: Unsettled Mariner | D53: =IF(B53=C53, "Sim", "Não") -> Não
A54: Ninhada | C54: Unsettled Mariner | D54: =IF(B54=C54, "Sim", "Não") -> Não
A55: Ninhada | C55: Unsettled Mariner | D55: =IF(B55=C55, "Sim", "Não") -> Não
A56: Ninhada | C56: Unsettled Mariner | D56: =IF(B56=C56, "Sim", "Não") -> Não
A57: Ninhada | B57: Sedge Sliver | C57: Sedge Sliver | D57: =IF(B57=C57, "Sim", "Não") -> Sim
...

Sheet CoCo Knights
A1: Cavalgada Naya
A2: Função | B2: Carta Atual | C2: Carta Ideal | D2: Carta Final
A3: Terreno | B3: Unclaimed Territory | C3: Unclaimed Territory | D3: =IF(B3=C3, "Sim", "Não") -> Sim | F3: Mudanças Faltando | G3: =COUNTIF(D3:D99,"Não") -> 56
A4: Terreno | B4: Unclaimed Territory | C4: Unclaimed Territory | D4: =IF(B4=C4, "Sim", "Não") -> Sim | F4: Total de Cartas | G4: =SUM(G7:G21) -> 75
A5: Terreno | B5: Unclaimed Territory | C5: Unclaimed Territory | D5: =IF(B5=C5, "Sim", "Não") -> Sim
A6: Terreno | C6: Ghost Quarter | D6: =IF(B6=C6, "Sim", "Não") -> Não | F6: Funções
A7: Terreno | C7: Ghost Quarter | D7: =IF(B7=C7, "Sim", "Não") -> Não | F7: Terreno | G7: =COUNTIF(A:A,F7) -> 22
A8: Terreno | C8: Ghost Quarter | D8: =IF(B8=C8, "Sim", "Não") -> Não | F8: Draw | G8: =COUNTIF(A:A,F8) -> 8
A9: Terreno | B9: Temple Garden | C9: Temple Garden | D9: =IF(B9=C9, "Sim", "Não") -> Sim | F9: Cavalgada | G9: =COUNTIF(A:A,F9) -> 30
A10: Terreno | B10: Temple Garden | C10: Temple Garden | D10: =IF(B10=C10, "Sim", "Não") -> Sim | F10: Tutor | G10: =COUNTIF(A:A,F10) -> 0
A11: Terreno | C11: Sacred Foundry | D11: =IF(B11=C11, "Sim", "Não") -> Não | F11: Sideboard | G11: =COUNTIF(A:A,F11) -> 15
A12: Terreno | B12: Sacred Foundry | C12: Sacred Foundry | D12: =IF(B12=C12, "Sim", "Não") -> Sim
A13: Terreno | B13: Mountain | C13: Mountain | D13: =IF(B13=C13, "Sim", "Não") -> Sim
A14: Terreno | B14: Forest | C14: Forest | D14: =IF(B14=C14, "Sim", "Não") -> Sim
A15: Terreno | B15: Plains | C15: Plains | D15: =IF(B15=C15, "Sim", "Não") -> Sim
A16: Terreno | B16: Plains | C16: Plains | D16: =IF(B16=C16, "Sim", "Não") -> Sim
A17: Terreno | B17: Plains | C17: Plains | D17: =IF(B17=C17, "Sim", "Não") -> Sim
A18: Terreno | B18: Windswept Heath | C18: Windswept Heath | D18: =IF(B18=C18, "Sim", "Não") -> Sim
A19: Terreno | B19: Windswept Heath | C19: Windswept Heath | D19: =IF(B19=C19, "Sim", "Não") -> Sim
A20: Terreno | B20: Windswept Heath | C20: Windswept Heath | D20: =IF(B20=C20, "Sim", "Não") -> Sim
A21: Terreno | B21: Windswept Heath | C21: Windswept Heath | D21: =IF(B21=C21, "Sim", "Não") -> Sim
A22: Terreno | C22: Arid Mesa | D22: =IF(B22=C22, "Sim", "Não") -> Não
