Workbook

Sheet COMPRAS
A1: Total: | B1: =C2+C8+C13+C18+C23+C28+C32+C34+C39+C51 -> 1564 | E1: Deck | F1: =A2 -> Marcelo | G1: =B3 -> Liga | H1: =B4 -> Polar Jogos | I1: =B5 -> Epic | J1: =B6 -> Overrun | L1: =A8 -> Interessantes | M1: =B9 -> Valor | N1: =B10 -> Liga | O1: =B11 -> Loja 1 | Q1: =A13 -> Player 3 | R1: =B14 -> Rayearth | S1: =B15 -> Mineral | T1: =B16 -> CardTutor | V1: =A18 -> Player 4 | W1: =B19 -> Rayearth | X1: =B20 -> Mineral | Y1: =B21 -> CardTutor | AA1: =A23 -> Player 5 | AB1: =B24 -> Rayearth | AC1: =B25 -> Mineral | AD1: =B26 -> CardTutor | AF1: =A28 -> Player 6 | AG1: =B29 -> Rayearth | AH1: =B30 -> Mineral | AI1: =B31 -> CardTutor
A2: Marcelo | B2: Total Lojas: | C2: =SUM(C4:C6) -> 0 | L2: Temporada da Multiplicação | M2: 80
A3: =COUNTA(F2:F218) -> 0 | B3: Liga | C3: =SUM(G:G) -> 0 | L3: Final de Devastação | M3: 80
B4: Polar Jogos | C4: =SUM(H:H) -> 0 | L4: O Grande Círculo | M4: 80
B5: Epic | C5: =SUM(I:I) -> 0 | L5: Intervenção Heróica | M5: 20
B6: Overrun | C6: =SUM(J:J) -> 0 | L6: Presa-Gélida de Ohran | M6: 30
L7: Altar de Ashnod | M7: 30
A8: Interessantes | B8: Total Lojas: | C8: =SUM(C9:C11) -> 1564 | L8: Ornato de Esmeralda | M8: 5
A9: =COUNTA(L2:L174) -> 49 | B9: Valor | C9: =SUM(M:M) -> 1564 | L9: Ornato de Azeviche | M9: 5
B10: Liga | C10: =SUM(N:N) -> 0 | L10: Ornato de Rubi | M10: 5
B11: Loja 1 | C11: =SUM(O:O) -> 0 | L11: Ornato de Safira | M11: 5
L12: Ornato de Pérola | M12: 5
A13: Player 3 | B13: Total Lojas: | C13: =SUM(C14:C16) -> 0 | L13: Espada da Animista | M13: 10
A14: =COUNTA(Q2:Q174) -> 0 | B14: Rayearth | C14: =SUM(R:R) -> 0 | L14: Fontes Rejuvenescedoras | M14: 30
B15: Mineral | C15: =SUM(S:S) -> 0 | L15: Lugar de Espectador | M15: 30
B16: CardTutor | C16: =SUM(T:T) -> 0 | L16: Centro de Treinamento | M16: 30
L17: Estádio da Submata | M17: 30
A18: Player 4 | B18: Total Lojas: | C18: =SUM(C19:C21) -> 0 | L18: Câmara dos Campeões | M18: 30
A19: =COUNTA(V2:V174) -> 0 | B19: Rayearth | C19: =SUM(W1:W9974) -> 0 | L19: Lentes Extraplanares | M19: 10
B20: Mineral | C20: =SUM(X1:X9979) -> 0 | L20: Synapse Sliver | M20: 40
B21: CardTutor | C21: =SUM(Y:Y) -> 0 | L21: Spark Double | M21: 15
L22: Windfall | M22: 5
A23: Player 5 | B23: Total Lojas: | C23: =SUM(C24:C26) -> 0 | L23: Three Visits | M23: 5
A24: =COUNTA(V7:V179) -> 0 | B24: Rayearth | C24: =SUM(AB:AB) -> 0 | L24: The Chain Veil | M24: 80
B25: Mineral | C25: =SUM(AC:AC) -> 0 | L25: Silent Arbiter | M25: 10
B26: CardTutor | C26: =SUM(AD:AD) -> 0 | L26: Vanquisher's Banner | M26: 20
L27: Arcane Lighthouse | M27: 10
A28: Player 6 | B28: Total Lojas: | C28: =SUM(C29:C31) -> 0 | L28: Cascade Bluffs | M28: 10
A29: =COUNTA(V11:V184) -> 0 | B29: Rayearth | C29: =SUM(AG:AG) -> 0 | L29: Mystic Gate | M29: 10
B30: Mineral | C30: =SUM(AH:AH) -> 0 | L30: Rugged Prairie | M30: 10
B31: CardTutor | C31: =SUM(AI:AI) -> 0 | L31: Urza's Mine | M31: 3
L32: Urza's Powerplant | M32: 3
L33: Urza's Tower | M33: 3
L34: Captura de Jhinzou | M34: 50
L35: Bribery | M35: 30
L36: Cyclonic Rift | M36: 40
L37: Steelshaper's Gift | M37: 10
L38: Treasure Nabber | M38: 5
L39: Heliode, Coroa de Sol | M39: 30
L40: Dízimo Sufocante | M40: 30
...

Sheet RESUMO
A1: Thrakiri | E1: Gitrog | I1: Elfos | M1: Jhoira | Q1: Fractius | U1: Muzzio
A3: Total | B3: {=_xlfn._xlws.SORT(C3:C101,1,-1,0)} -> #REF! | C3: =IF(#REF!="Não",#REF!, " ") -> #REF! | E3: Total | F3: {=_xlfn._xlws.SORT(G3:G101,1,-1,0)} -> #REF! | G3: =IF(#REF!="Não",#REF!, " ") -> #REF! | I3: Total | J3: {=_xlfn._xlws.SORT(K3:K101,1,-1,0)} -> #REF! | K3: =IF(#REF!="Não",#REF!, " ") -> #REF! | M3: Total | N3: {=_xlfn._xlws.SORT(O3:O101,1,-1,0)} -> #REF! | O3: =IF(#REF!="Não",#REF!, " ") -> #REF! | Q3: Total | R3: {=_xlfn._xlws.SORT(S3:S101,1,-1,0)} -> #REF! | S3: =IF(#REF!="Não",#REF!, " ") -> #REF! | U3: Total | V3: {=_xlfn._xlws.SORT(W3:W101,1,-1,0)} -> #REF! | W3: =IF(#REF!="Não",#REF!, " ") -> #REF!
A4: =#REF! -> #REF! | B4: #REF! | C4: =IF(#REF!="Não",#REF!, " ") -> #REF! | E4: =#REF! -> #REF! | F4: #REF! | G4: =IF(#REF!="Não",#REF!, " ") -> #REF! | I4: =#REF! -> #REF! | J4: #REF! | K4: =IF(#REF!="Não",#REF!, " ") -> #REF! | M4: =#REF! -> #REF! | N4: #REF! | O4: =IF(#REF!="Não",#REF!, " ") -> #REF! | Q4: =#REF! -> #REF! | R4: #REF! | S4: =IF(#REF!="Não",#REF!, " ") -> #REF! | U4: =#REF! -> #REF! | V4: #REF! | W4: =IF(#REF!="Não",#REF!, " ") -> #REF!
B5: #REF! | C5: =IF(#REF!="Não",#REF!, " ") -> #REF! | F5: #REF! | G5: =IF(#REF!="Não",#REF!, " ") -> #REF! | J5: #REF! | K5: =IF(#REF!="Não",#REF!, " ") -> #REF! | N5: #REF! | O5: =IF(#REF!="Não",#REF!, " ") -> #REF! | R5: #REF! | S5: =IF(#REF!="Não",#REF!, " ") -> #REF! | V5: #REF! | W5: =IF(#REF!="Não",#REF!, " ") -> #REF!
B6: #REF! | C6: =IF(#REF!="Não",#REF!, " ") -> #REF! | F6: #REF! | G6: =IF(#REF!="Não",#REF!, " ") -> #REF! | J6: #REF! | K6: =IF(#REF!="Não",#REF!, " ") -> #REF! | N6: #REF! | O6: =IF(#REF!="Não",#REF!, " ") -> #REF! | R6: #REF! | S6: =IF(#REF!="Não",#REF!, " ") -> #REF! | V6: #REF! | W6: =IF(#REF!="Não",#REF!, " ") -> #REF!
B7: #REF! | C7: =IF(#REF!="Não",#REF!, " ") -> #REF! | F7: #REF! | G7: =IF(#REF!="Não",#REF!, " ") -> #REF! | J7: #REF! | K7: =IF(#REF!="Não",#REF!, " ") -> #REF! | N7: #REF! | O7: =IF(#REF!="Não",#REF!, " ") -> #REF! | R7: #REF! | S7: =IF(#REF!="Não",#REF!, " ") -> #REF! | V7: #REF! | W7: =IF(#REF!="Não",#REF!, " ") -> #REF!
B8: #REF! | C8: =IF(#REF!="Não",#REF!, " ") -> #REF! | F8: #REF! | G8: =IF(#REF!="Não",#REF!, " ") -> #REF! | J8: #REF! | K8: =IF(#REF!="Não",#REF!, " ") -> #REF! | N8: #REF! | O8: =IF(#REF!="Não",#REF!, " ") -> #REF! | R8: #REF! | S8: =IF(#REF!="Não",#REF!, " ") -> #REF! | V8: #REF! | W8: =IF(#REF!="Não",#REF!, " ") -> #REF!
B9: #REF! | C9: =IF(#REF!="Não",#REF!, " ") -> #REF! | F9: #REF! | G9: =IF(#REF!="Não",#REF!, " ") -> #REF! | J9: #REF! | K9: =IF(#REF!="Não",#REF!, " ") -> #REF! | N9: #REF! | O9: =IF(#REF!="Não",#REF!, " ") -> #REF! | R9: #REF! | S9: =IF(#REF!="Não",#REF!, " ") -> #REF! | V9: #REF! | W9: =IF(#REF!="Não",#REF!, " ") -> #REF!
B10: #REF! | C10: =IF(#REF!="Não",#REF!, " ") -> #REF! | F10: #REF! | G10: =IF(#REF!="Não",#REF!, " ") -> #REF! | J10: #REF! | K10: =IF(#REF!="Não",#REF!, " ") -> #REF! | N10: #REF! | O10: =IF(#REF!="Não",#REF!, " ") -> #REF! | R10: #REF! | S10: =IF(#REF!="Não",#REF!, " ") -> #REF! | V10: #REF! | W10: =IF(#REF!="Não",#REF!, " ") -> #REF!
B11: #REF! | C11: =IF(#REF!="Não",#REF!, " ") -> #REF! | F11: #REF! | G11: =IF(#REF!="Não",#REF!, " ") -> #REF! | J11: #REF! | K11: =IF(#REF!="Não",#REF!, " ") -> #REF! | N11: #REF! | O11: =IF(#REF!="Não",#REF!, " ") -> #REF! | R11: #REF! | S11: =IF(#REF!="Não",#REF!, " ") -> #REF! | V11: #REF! | W11: =IF(#REF!="Não",#REF!, " ") -> #REF!
B12: #REF! | C12: =IF(#REF!="Não",#REF!, " ") -> #REF! | F12: #REF! | G12: =IF(#REF!="Não",#REF!, " ") -> #REF! | J12: #REF! | K12: =IF(#REF!="Não",#REF!, " ") -> #REF! | N12: #REF! | O12: =IF(#REF!="Não",#REF!, " ") -> #REF! | R12: #REF! | S12: =IF(#REF!="Não",#REF!, " ") -> #REF! | V12: #REF! | W12: =IF(#REF!="Não",#REF!, " ") -> #REF!
B13: #REF! | C13: =IF(#REF!="Não",#REF!, " ") -> #REF! | F13: #REF! | G13: =IF(#REF!="Não",#REF!, " ") -> #REF! | J13: #REF! | K13: =IF(#REF!="Não",#REF!, " ") -> #REF! | N13: #REF! | O13: =IF(#REF!="Não",#REF!, " ") -> #REF! | R13: #REF! | S13: =IF(#REF!="Não",#REF!, " ") -> #REF! | V13: #REF! | W13: =IF(#REF!="Não",#REF!, " ") -> #REF!
B14: #REF! | C14: =IF(#REF!="Não",#REF!, " ") -> #REF! | F14: #REF! | G14: =IF(#REF!="Não",#REF!, " ") -> #REF! | J14: #REF! | K14: =IF(#REF!="Não",#REF!, " ") -> #REF! | N14: #REF! | O14: =IF(#REF!="Não",#REF!, " ") -> #REF! | R14: #REF! | S14: =IF(#REF!="Não",#REF!, " ") -> #REF! | V14: #REF! | W14: =IF(#REF!="Não",#REF!, " ") -> #REF!
B15: #REF! | C15: =IF(#REF!="Não",#REF!, " ") -> #REF! | F15: #REF! | G15: =IF(#REF!="Não",#REF!, " ") -> #REF! | J15: #REF! | K15: =IF(#REF!="Não",#REF!, " ") -> #REF! | N15: #REF! | O15: =IF(#REF!="Não",#REF!, " ") -> #REF! | R15: #REF! | S15: =IF(#REF!="Não",#REF!, " ") -> #REF! | V15: #REF! | W15: =IF(#REF!="Não",#REF!, " ") -> #REF!
B16: #REF! | C16: =IF(#REF!="Não",#REF!, " ") -> #REF! | F16: #REF! | G16: =IF(#REF!="Não",#REF!, " ") -> #REF! | J16: #REF! | K16: =IF(#REF!="Não",#REF!, " ") -> #REF! | N16: #REF! | O16: =IF(#REF!="Não",#REF!, " ") -> #REF! | R16: #REF! | S16: =IF(#REF!="Não",#REF!, " ") -> #REF! | V16: #REF! | W16: =IF(#REF!="Não",#REF!, " ") -> #REF!
... B101: #REF! | C101: =IF(#REF!="Não",#REF!, " ") -> #REF! | F101: #REF! | G101: =IF(#REF!="Não",#REF!, " ") -> #REF! | J101: #REF! | K101: =IF(#REF!="Não",#REF!, " ") -> #REF! | N101: #REF! | O101: =IF(#REF!="Não",#REF!, " ") -> #REF! | R101: #REF! | S101: =IF(#REF!="Não",#REF!, " ") -> #REF! | V101: #REF! | W101: =IF(#REF!="Não",#REF!, " ") -> #REF!
C102: =IF(#REF!="Não",#REF!, " ") -> #REF!

Sheet RESUMO2
A1: Rielle | E1: Alela | I1: Arcades | M1: Vial Ishai | Q1: Yuriko | U1: Zedruu
A3: Total | B3: {=_xlfn._xlws.SORT(C3:C101,1,-1,0)} -> #REF! | C3: =IF(#REF!="Não",#REF!, " ") -> #REF! | E3: Total | F3: {=_xlfn._xlws.SORT(G3:G101,1,-1,0)} -> #REF! | G3: =IF(#REF!="Não",#REF!, " ") -> #REF! | I3: Total | J3: {=_xlfn._xlws.SORT(K3:K101,1,-1,0)} -> #REF! | K3: =IF(#REF!="Não",#REF!, " ") -> #REF! | M3: Total | N3: {=_xlfn._xlws.SORT(O3:O101,1,-1,0)} -> #REF! | O3: =IF(#REF!="Não",#REF!, " ") -> #REF! | Q3: Total | R3: {=_xlfn._xlws.SORT(S3:S101,1,-1,0)} -> #REF! | S3: =IF(#REF!="Não",#REF!, " ") -> #REF! | U3: Total | V3: {=_xlfn._xlws.SORT(W3:W101,1,-1,0)} -> #REF! | W3: =IF(#REF!="Não",#REF!, " ") -> #REF!
A4: =#REF! -> #REF! | B4: #REF! | C4: =IF(#REF!="Não",#REF!, " ") -> #REF! | E4: =#REF! -> #REF! | F4: #REF! | G4: =IF(#REF!="Não",#REF!, " ") -> #REF! | I4: =#REF! -> #REF! | J4: #REF! | K4: =IF(#REF!="Não",#REF!, " ") -> #REF! | M4: =#REF! -> #REF! | N4: #REF! | O4: =IF(#REF!="Não",#REF!, " ") -> #REF! | Q4: =#REF! -> #REF! | R4: #REF! | S4: =IF(#REF!="Não",#REF!, " ") -> #REF! | U4: =#REF! -> #REF! | V4: #REF! | W4: =IF(#REF!="Não",#REF!, " ") -> #REF!
B5: #REF! | C5: =IF(#REF!="Não",#REF!, " ") -> #REF! | F5: #REF! | G5: =IF(#REF!="Não",#REF!, " ") -> #REF! | J5: #REF! | K5: =IF(#REF!="Não",#REF!, " ") -> #REF! | N5: #REF! | O5: =IF(#REF!="Não",#REF!, " ") -> #REF! | R5: #REF! | S5: =IF(#REF!="Não",#REF!, " ") -> #REF! | V5: #REF! | W5: =IF(#REF!="Não",#REF!, " ") -> #REF!
B6: #REF! | C6: =IF(#REF!="Não",#REF!, " ") -> #REF! | F6: #REF! | G6: =IF(#REF!="Não",#REF!, " ") -> #REF! | J6: #REF! | K6: =IF(#REF!="Não",#REF!, " ") -> #REF! | N6: #REF! | O6: =IF(#REF!="Não",#REF!, " ") -> #REF! | R6: #REF! | S6: =IF(#REF!="Não",#REF!, " ") -> #REF! | V6: #REF! | W6: =IF(#REF!="Não",#REF!, " ") -> #REF!
B7: #REF! | C7: =IF(#REF!="Não",#REF!, " ") -> #REF! | F7: #REF! | G7: =IF(#REF!="Não",#REF!, " ") -> #REF! | J7: #REF! | K7: =IF(#REF!="Não",#REF!, " ") -> #REF! | N7: #REF! | O7: =IF(#REF!="Não",#REF!, " ") -> #REF! | R7: #REF! | S7: =IF(#REF!="Não",#REF!, " ") -> #REF! | V7: #REF! | W7: =IF(#REF!="Não",#REF!, " ") -> #REF!
B8: #REF! | C8: =IF(#REF!="Não",#REF!, " ") -> #REF! | F8: #REF! | G8: =IF(#REF!="Não",#REF!, " ") -> #REF! | J8: #REF! | K8: =IF(#REF!="Não",#REF!, " ") -> #REF! | N8: #REF! | O8: =IF(#REF!="Não",#REF!, " ") -> #REF! | R8: #REF! | S8: =IF(#REF!="Não",#REF!, " ") -> #REF! | V8: #REF! | W8: =IF(#REF!="Não",#REF!, " ") -> #REF!
B9: #REF! | C9: =IF(#REF!="Não",#REF!, " ") -> #REF! | F9: #REF! | G9: =IF(#REF!="Não",#REF!, " ") -> #REF! | J9: #REF! | K9: =IF(#REF!="Não",#REF!, " ") -> #REF! | N9: #REF! | O9: =IF(#REF!="Não",#REF!, " ") -> #REF! | R9: #REF! | S9: =IF(#REF!="Não",#REF!, " ") -> #REF! | V9: #REF! | W9: =IF(#REF!="Não",#REF!, " ") -> #REF!
B10: #REF! | C10: =IF(#REF!="Não",#REF!, " ") -> #REF! | F10: #REF! | G10: =IF(#REF!="Não",#REF!, " ") -> #REF! | J10: #REF! | K10: =IF(#REF!="Não",#REF!, " ") -> #REF! | N10: #REF! | O10: =IF(#REF!="Não",#REF!, " ") -> #REF! | R10: #REF! | S10: =IF(#REF!="Não",#REF!, " ") -> #REF! | V10: #REF! | W10: =IF(#REF!="Não",#REF!, " ") -> #REF!
B11: #REF! | C11: =IF(#REF!="Não",#REF!, " ") -> #REF! | F11: #REF! | G11: =IF(#REF!="Não",#REF!, " ") -> #REF! | J11: #REF! | K11: =IF(#REF!="Não",#REF!, " ") -> #REF! | N11: #REF! | O11: =IF(#REF!="Não",#REF!, " ") -> #REF! | R11: #REF! | S11: =IF(#REF!="Não",#REF!, " ") -> #REF! | V11: #REF! | W11: =IF(#REF!="Não",#REF!, " ") -> #REF!
B12: #REF! | C12: =IF(#REF!="Não",#REF!, " ") -> #REF! | F12: #REF! | G12: =IF(#REF!="Não",#REF!, " ") -> #REF! | J12: #REF! | K12: =IF(#REF!="Não",#REF!, " ") -> #REF! | N12: #REF! | O12: =IF(#REF!="Não",#REF!, " ") -> #REF! | R12: #REF! | S12: =IF(#REF!="Não",#REF!, " ") -> #REF! | V12: #REF! | W12: =IF(#REF!="Não",#REF!, " ") -> #REF!
B13: #REF! | C13: =IF(#REF!="Não",#REF!, " ") -> #REF! | F13: #REF! | G13: =IF(#REF!="Não",#REF!, " ") -> #REF! | J13: #REF! | K13: =IF(#REF!="Não",#REF!, " ") -> #REF! | N13: #REF! | O13: =IF(#REF!="Não",#REF!, " ") -> #REF! | R13: #REF! | S13: =IF(#REF!="Não",#REF!, " ") -> #REF! | V13: #REF! | W13: =IF(#REF!="Não",#REF!, " ") -> #REF!
B14: #REF! | C14: =IF(#REF!="Não",#REF!, " ") -> #REF! | F14: #REF! | G14: =IF(#REF!="Não",#REF!, " ") -> #REF! | J14: #REF! | K14: =IF(#REF!="Não",#REF!, " ") -> #REF! | N14: #REF! | O14: =IF(#REF!="Não",#REF!, " ") -> #REF! | R14: #REF! | S14: =IF(#REF!="Não",#REF!, " ") -> #REF! | V14: #REF! | W14: =IF(#REF!="Não",#REF!, " ") -> #REF!
B15: #REF! | C15: =IF(#REF!="Não",#REF!, " ") -> #REF! | F15: #REF! | G15: =IF(#REF!="Não",#REF!, " ") -> #REF! | J15: #REF! | K15: =IF(#REF!="Não",#REF!, " ") -> #REF! | N15: #REF! | O15: =IF(#REF!="Não",#REF!, " ") -> #REF! | R15: #REF! | S15: =IF(#REF!="Não",#REF!, " ") -> #REF! | V15: #REF! | W15: =IF(#REF!="Não",#REF!, " ") -> #REF!
B16: #REF! | C16: =IF(#REF!="Não",#REF!, " ") -> #REF! | F16: #REF! | G16: =IF(#REF!="Não",#REF!, " ") -> #REF! | J16: #REF! | K16: =IF(#REF!="Não",#REF!, " ") -> #REF! | N16: #REF! | O16: =IF(#REF!="Não",#REF!, " ") -> #REF! | R16: #REF! | S16: =IF(#REF!="Não",#REF!, " ") -> #REF! | V16: #REF! | W16: =IF(#REF!="Não",#REF!, " ") -> #REF!
... B101: #REF! | C101: =IF(#REF!="Não",#REF!, " ") -> #REF! | F101: #REF! | G101: =IF(#REF!="Não",#REF!, " ") -> #REF! | J101: #REF! | K101: =IF(#REF!="Não",#REF!, " ") -> #REF! | N101: #REF! | O101: =IF(#REF!="Não",#REF!, " ") -> #REF! | R101: #REF! | S101: =IF(#REF!="Não",#REF!, " ") -> #REF! | V101: #REF! | W101: =IF(#REF!="Não",#REF!, " ") -> #REF!
O102: =IF(#REF!="Não",#REF!, " ") -> #REF! | S102: =IF(#REF!="Não",#REF!, " ") -> #REF!
O103: =IF(#REF!="Não",#REF!, " ") -> #REF! | S103: =IF(#REF!="Não",#REF!, " ") -> #REF!
O104: =IF(#REF!="Não",#REF!, " ") -> #REF! | S104: =IF(#REF!="Não",#REF!, " ") -> #REF!
O105: =IF(#REF!="Não",#REF!, " ") -> #REF! | S105: =IF(#REF!="Não",#REF!, " ") -> #REF!
S106: =IF(#REF!="Não",#REF!, " ") -> #REF!

Sheet RESUMO3
A1: Inalla | E1: Carlos | I1: Oona | M1: Kresh | Q1: Akiri | U1: Breya
A3: Total | B3: {=_xlfn._xlws.SORT(C3:C101,1,-1,0)} -> #REF! | C3: =IF(#REF!="Não",#REF!, "") -> #REF! | E3: Total | F3: {=_xlfn._xlws.SORT(G3:G101,1,-1,0)} -> #REF! | G3: =IF(#REF!="Não",#REF!, " ") -> #REF! | I3: Total | J3: {=_xlfn._xlws.SORT(K3:K101,1,-1,0)} -> Spell Stutter | K3: =IF(Oona!D3="Não",Oona!C3, " ") | M3: Total | N3: {=_xlfn._xlws.SORT(O3:O101,1,-1,0)} -> #REF! | O3: =IF(#REF!="Não",#REF!, " ") -> #REF! | Q3: Total | R3: {=_xlfn._xlws.SORT(S3:S101,1,-1,0)} -> #REF! | S3: =IF(#REF!="Não",#REF!, " ") -> #REF! | U3: Total | V3: {=_xlfn._xlws.SORT(W3:W101,1,-1,0)} -> #REF! | W3: =IF(#REF!="Não",#REF!, " ") -> #REF!
A4: =#REF! -> #REF! | B4: #REF! | C4: =IF(#REF!="Não",#REF!, "") -> #REF! | E4: =#REF! -> #REF! | F4: #REF! | G4: =IF(#REF!="Não",#REF!, " ") -> #REF! | I4: =Oona!G3 -> 1 | K4: =IF(Oona!D4="Não",Oona!C4, " ") | M4: =#REF! -> #REF! | N4: #REF! | O4: =IF(#REF!="Não",#REF!, " ") -> #REF! | Q4: =#REF! -> #REF! | R4: #REF! | S4: =IF(#REF!="Não",#REF!, " ") -> #REF! | U4: =#REF! -> #REF! | V4: #REF! | W4: =IF(#REF!="Não",#REF!, " ") -> #REF!
B5: #REF! | C5: =IF(#REF!="Não",#REF!, "") -> #REF! | F5: #REF! | G5: =IF(#REF!="Não",#REF!, " ") -> #REF! | K5: =IF(Oona!D5="Não",Oona!C5, " ") | N5: #REF! | O5: =IF(#REF!="Não",#REF!, " ") -> #REF! | R5: #REF! | S5: =IF(#REF!="Não",#REF!, " ") -> #REF! | V5: #REF! | W5: =IF(#REF!="Não",#REF!, " ") -> #REF!
B6: #REF! | C6: =IF(#REF!="Não",#REF!, "") -> #REF! | F6: #REF! | G6: =IF(#REF!="Não",#REF!, " ") -> #REF! | K6: =IF(Oona!D6="Não",Oona!C6, " ") | N6: #REF! | O6: =IF(#REF!="Não",#REF!, " ") -> #REF! | R6: #REF! | S6: =IF(#REF!="Não",#REF!, " ") -> #REF! | V6: #REF! | W6: =IF(#REF!="Não",#REF!, " ") -> #REF!
B7: #REF! | C7: =IF(#REF!="Não",#REF!, "") -> #REF! | F7: #REF! | G7: =IF(#REF!="Não",#REF!, " ") -> #REF! | K7: =IF(Oona!D7="Não",Oona!C7, " ") | N7: #REF! | O7: =IF(#REF!="Não",#REF!, " ") -> #REF! | R7: #REF! | S7: =IF(#REF!="Não",#REF!, " ") -> #REF! | V7: #REF! | W7: =IF(#REF!="Não",#REF!, " ") -> #REF!
B8: #REF! | C8: =IF(#REF!="Não",#REF!, "") -> #REF! | F8: #REF! | G8: =IF(#REF!="Não",#REF!, " ") -> #REF! | K8: =IF(Oona!D8="Não",Oona!C8, " ") | N8: #REF! | O8: =IF(#REF!="Não",#REF!, " ") -> #REF! | R8: #REF! | S8: =IF(#REF!="Não",#REF!, " ") -> #REF! | V8: #REF! | W8: =IF(#REF!="Não",#REF!, " ") -> #REF!
B9: #REF! | C9: =IF(#REF!="Não",#REF!, "") -> #REF! | F9: #REF! | G9: =IF(#REF!="Não",#REF!, " ") -> #REF! | K9: =IF(Oona!D9="Não",Oona!C9, " ") | N9: #REF! | O9: =IF(#REF!="Não",#REF!, " ") -> #REF! | R9: #REF! | S9: =IF(#REF!="Não",#REF!, " ") -> #REF! | V9: #REF! | W9: =IF(#REF!="Não",#REF!, " ") -> #REF!
B10: #REF! | C10: =IF(#REF!="Não",#REF!, "") -> #REF! | F10: #REF! | G10: =IF(#REF!="Não",#REF!, " ") -> #REF! | K10: =IF(Oona!D10="Não",Oona!C10, " ") | N10: #REF! | O10: =IF(#REF!="Não",#REF!, " ") -> #REF! | R10: #REF! | S10: =IF(#REF!="Não",#REF!, " ") -> #REF! | V10: #REF! | W10: =IF(#REF!="Não",#REF!, " ") -> #REF!
B11: #REF! | C11: =IF(#REF!="Não",#REF!, "") -> #REF! | F11: #REF! | G11: =IF(#REF!="Não",#REF!, " ") -> #REF! | K11: =IF(Oona!D11="Não",Oona!C11, " ") | N11: #REF! | O11: =IF(#REF!="Não",#REF!, " ") -> #REF! | R11: #REF! | S11: =IF(#REF!="Não",#REF!, " ") -> #REF! | V11: #REF! | W11: =IF(#REF!="Não",#REF!, " ") -> #REF!
B12: #REF! | C12: =IF(#REF!="Não",#REF!, "") -> #REF! | F12: #REF! | G12: =IF(#REF!="Não",#REF!, " ") -> #REF! | K12: =IF(Oona!D12="Não",Oona!C12, " ") | N12: #REF! | O12: =IF(#REF!="Não",#REF!, " ") -> #REF! | R12: #REF! | S12: =IF(#REF!="Não",#REF!, " ") -> #REF! | V12: #REF! | W12: =IF(#REF!="Não",#REF!, " ") -> #REF!
B13: #REF! | C13: =IF(#REF!="Não",#REF!, "") -> #REF! | F13: #REF! | G13: =IF(#REF!="Não",#REF!, " ") -> #REF! | K13: =IF(Oona!D13="Não",Oona!C13, " ") | N13: #REF! | O13: =IF(#REF!="Não",#REF!, " ") -> #REF! | R13: #REF! | S13: =IF(#REF!="Não",#REF!, " ") -> #REF! | V13: #REF! | W13: =IF(#REF!="Não",#REF!, " ") -> #REF!
B14: #REF! | C14: =IF(#REF!="Não",#REF!, "") -> #REF! | F14: #REF! | G14: =IF(#REF!="Não",#REF!, " ") -> #REF! | K14: =IF(Oona!D14="Não",Oona!C14, " ") | N14: #REF! | O14: =IF(#REF!="Não",#REF!, " ") -> #REF! | R14: #REF! | S14: =IF(#REF!="Não",#REF!, " ") -> #REF! | V14: #REF! | W14: =IF(#REF!="Não",#REF!, " ") -> #REF!
B15: #REF! | C15: =IF(#REF!="Não",#REF!, "") -> #REF! | F15: #REF! | G15: =IF(#REF!="Não",#REF!, " ") -> #REF! | K15: =IF(Oona!D15="Não",Oona!C15, " ") | N15: #REF! | O15: =IF(#REF!="Não",#REF!, " ") -> #REF! | R15: #REF! | S15: =IF(#REF!="Não",#REF!, " ") -> #REF! | V15: #REF! | W15: =IF(#REF!="Não",#REF!, " ") -> #REF!
B16: #REF! | C16: =IF(#REF!="Não",#REF!, "") -> #REF! | F16: #REF! | G16: =IF(#REF!="Não",#REF!, " ") -> #REF! | K16: =IF(Oona!D16="Não",Oona!C16, " ") | N16: #REF! | O16: =IF(#REF!="Não",#REF!, " ") -> #REF! | R16: #REF! | S16: =IF(#REF!="Não",#REF!, " ") -> #REF! | V16: #REF! | W16: =IF(#REF!="Não",#REF!, " ") -> #REF!
... B59: #REF! | C59: =IF(#REF!="Não",#REF!, "") -> #REF! | F59: #REF! | G59: =IF(#REF!="Não",#REF!, " ") -> #REF! | K59: =IF(Oona!D59="Não",Oona!C59, " ") | N59: #REF! | O59: =IF(#REF!="Não",#REF!, " ") -> #REF! | R59: #REF! | S59: =IF(#REF!="Não",#REF!, " ") -> #REF! | V59: #REF! | W59: =IF(#REF!="Não",#REF!, " ") -> #REF!
B60: #REF! | C60: =IF(#REF!="Não",#REF!, "") -> #REF! | F60: #REF! | G60: =IF(#REF!="Não",#REF!, " ") -> #REF! | K60: =IF(Oona!D61="Não",Oona!C61, " ") | N60: #REF! | O60: =IF(#REF!="Não",#REF!, " ") -> #REF! | R60: #REF! | S60: =IF(#REF!="Não",#REF!, " ") -> #REF! | V60: #REF! | W60: =IF(#REF!="Não",#REF!, " ") -> #REF!
B61: #REF! | C61: =IF(#REF!="Não",#REF!, "") -> #REF! | F61: #REF! | G61: =IF(#REF!="Não",#REF!, " ") -> #REF! | K61: =IF(Oona!D62="Não",Oona!C62, " ") | N61: #REF! | O61: =IF(#REF!="Não",#REF!, " ") -> #REF! | R61: #REF! | S61: =IF(#REF!="Não",#REF!, " ") -> #REF! | V61: #REF! | W61: =IF(#REF!="Não",#REF!, " ") -> #REF!
B62: #REF! | C62: =IF(#REF!="Não",#REF!, "") -> #REF! | F62: #REF! | G62: =IF(#REF!="Não",#REF!, " ") -> #REF! | K62: =IF(Oona!D86="Não",Oona!C86, " ") | N62: #REF! | O62: =IF(#REF!="Não",#REF!, " ") -> #REF! | R62: #REF! | S62: =IF(#REF!="Não",#REF!, " ") -> #REF! | V62: #REF! | W62: =IF(#REF!="Não",#REF!, " ") -> #REF!
B63: #REF! | C63: =IF(#REF!="Não",#REF!, "") -> #REF! | F63: #REF! | G63: =IF(#REF!="Não",#REF!, " ") -> #REF! | K63: =IF(Oona!D84="Não",Oona!C84, " ") | N63: #REF! | O63: =IF(#REF!="Não",#REF!, " ") -> #REF! | R63: #REF! | S63: =IF(#REF!="Não",#REF!, " ") -> #REF! | V63: #REF! | W63: =IF(#REF!="Não",#REF!, " ") -> #REF!
B64: #REF! | C64: =IF(#REF!="Não",#REF!, "") -> #REF! | F64: #REF! | G64: =IF(#REF!="Não",#REF!, " ") -> #REF! | K64: =IF(Oona!D63="Não",Oona!C63, " ") | N64: #REF! | O64: =IF(#REF!="Não",#REF!, " ") -> #REF! | R64: #REF! | S64: =IF(#REF!="Não",#REF!, " ") -> #REF! | V64: #REF! | W64: =IF(#REF!="Não",#REF!, " ") -> #REF!
B65: #REF! | C65: =IF(#REF!="Não",#REF!, "") -> #REF! | F65: #REF! | G65: =IF(#REF!="Não",#REF!, " ") -> #REF! | K65: =IF(Oona!D60="Não",Oona!C60, " ") | N65: #REF! | O65: =IF(#REF!="Não",#REF!, " ") -> #REF! | R65: #REF! | S65: =IF(#REF!="Não",#REF!, " ") -> #REF! | V65: #REF! | W65: =IF(#REF!="Não",#REF!, " ") -> #REF!
B66: #REF! | C66: =IF(#REF!="Não",#REF!, "") -> #REF! | F66: #REF! | G66: =IF(#REF!="Não",#REF!, " ") -> #REF! | K66: =IF(Oona!D64="Não",Oona!C64, " ") | N66: #REF! | O66: =IF(#REF!="Não",#REF!, " ") -> #REF! | R66: #REF! | S66: =IF(#REF!="Não",#REF!, " ") -> #REF! | V66: #REF! | W66: =IF(#REF!="Não",#REF!, " ") -> #REF!
B67: #REF! | C67: =IF(#REF!="Não",#REF!, "") -> #REF! | F67: #REF! | G67: =IF(#REF!="Não",#REF!, " ") -> #REF! | K67: =IF(Oona!D75="Não",Oona!C75, " ") | N67: #REF! | O67: =IF(#REF!="Não",#REF!, " ") -> #REF! | R67: #REF! | S67: =IF(#REF!="Não",#REF!, " ") -> #REF! | V67: #REF! | W67: =IF(#REF!="Não",#REF!, " ") -> #REF!
B68: #REF! | C68: =IF(#REF!="Não",#REF!, "") -> #REF! | F68: #REF! | G68: =IF(#REF!="Não",#REF!, " ") -> #REF! | K68: =IF(Oona!D65="Não",Oona!C65, " ") | N68: #REF! | O68: =IF(#REF!="Não",#REF!, " ") -> #REF! | R68: #REF! | S68: =IF(#REF!="Não",#REF!, " ") -> #REF! | V68: #REF! | W68: =IF(#REF!="Não",#REF!, " ") -> #REF!
B69: #REF! | C69: =IF(#REF!="Não",#REF!, "") -> #REF! | F69: #REF! | G69: =IF(#REF!="Não",#REF!, " ") -> #REF! | K69: =IF(Oona!D66="Não",Oona!C66, " ") | N69: #REF! | O69: =IF(#REF!="Não",#REF!, " ") -> #REF! | R69: #REF! | S69: =IF(#REF!="Não",#REF!, " ") -> #REF! | V69: #REF! | W69: =IF(#REF!="Não",#REF!, " ") -> #REF!
B70: #REF! | C70: =IF(#REF!="Não",#REF!, "") -> #REF! | F70: #REF! | G70: =IF(#REF!="Não",#REF!, " ") -> #REF! | K70: =IF(Oona!D67="Não",Oona!C67, " ") -> Spell Stutter | N70: #REF! | O70: =IF(#REF!="Não",#REF!, " ") -> #REF! | R70: #REF! | S70: =IF(#REF!="Não",#REF!, " ") -> #REF! | V70: #REF! | W70: =IF(#REF!="Não",#REF!, " ") -> #REF!
B71: #REF! | C71: =IF(#REF!="Não",#REF!, "") -> #REF! | F71: #REF! | G71: =IF(#REF!="Não",#REF!, " ") -> #REF! | K71: =IF(Oona!D68="Não",Oona!C68, " ") | N71: #REF! | O71: =IF(#REF!="Não",#REF!, " ") -> #REF! | R71: #REF! | S71: =IF(#REF!="Não",#REF!, " ") -> #REF! | V71: #REF! | W71: =IF(#REF!="Não",#REF!, " ") -> #REF!
B72: #REF! | C72: =IF(#REF!="Não",#REF!, "") -> #REF! | F72: #REF! | G72: =IF(#REF!="Não",#REF!, " ") -> #REF! | K72: =IF(Oona!D69="Não",Oona!C69, " ") | N72: #REF! | O72: =IF(#REF!="Não",#REF!, " ") -> #REF! | R72: #REF! | S72: =IF(#REF!="Não",#REF!, " ") -> #REF! | V72: #REF! | W72: =IF(#REF!="Não",#REF!, " ") -> #REF!
B73: #REF! | C73: =IF(#REF!="Não",#REF!, "") -> #REF! | F73: #REF! | G73: =IF(#REF!="Não",#REF!, " ") -> #REF! | K73: =IF(Oona!D70="Não",Oona!C70, " ") | N73: #REF! | O73: =IF(#REF!="Não",#REF!, " ") -> #REF! | R73: #REF! | S73: =IF(#REF!="Não",#REF!, " ") -> #REF! | V73: #REF! | W73: =IF(#REF!="Não",#REF!, " ") -> #REF!
B74: #REF! | C74: =IF(#REF!="Não",#REF!, "") -> #REF! | F74: #REF! | G74: =IF(#REF!="Não",#REF!, " ") -> #REF! | K74: =IF(Oona!D71="Não",Oona!C71, " ") | N74: #REF! | O74: =IF(#REF!="Não",#REF!, " ") -> #REF! | R74: #REF! | S74: =IF(#REF!="Não",#REF!, " ") -> #REF! | V74: #REF! | W74: =IF(#REF!="Não",#REF!, " ") -> #REF!
B75: #REF! | C75: =IF(#REF!="Não",#REF!, "") -> #REF! | F75: #REF! | G75: =IF(#REF!="Não",#REF!, " ") -> #REF! | K75: =IF(Oona!D72="Não",Oona!C72, " ") | N75: #REF! | O75: =IF(#REF!="Não",#REF!, " ") -> #REF! | R75: #REF! | S75: =IF(#REF!="Não",#REF!, " ") -> #REF! | V75: #REF! | W75: =IF(#REF!="Não",#REF!, " ") -> #REF!
B76: #REF! | C76: =IF(#REF!="Não",#REF!, "") -> #REF! | F76: #REF! | G76: =IF(#REF!="Não",#REF!, " ") -> #REF! | K76: =IF(Oona!D74="Não",Oona!C74, " ") | N76: #REF! | O76: =IF(#REF!="Não",#REF!, " ") -> #REF! | R76: #REF! | S76: =IF(#REF!="Não",#REF!, " ") -> #REF! | V76: #REF! | W76: =IF(#REF!="Não",#REF!, " ") -> #REF!
B77: #REF! | C77: =IF(#REF!="Não",#REF!, "") -> #REF! | F77: #REF! | G77: =IF(#REF!="Não",#REF!, " ") -> #REF! | K77: =IF(Oona!D76="Não",Oona!C76, " ") | N77: #REF! | O77: =IF(#REF!="Não",#REF!, " ") -> #REF! | R77: #REF! | S77: =IF(#REF!="Não",#REF!, " ") -> #REF! | V77: #REF! | W77: =IF(#REF!="Não",#REF!, " ") -> #REF!
B78: #REF! | C78: =IF(#REF!="Não",#REF!, "") -> #REF! | F78: #REF! | G78: =IF(#REF!="Não",#REF!, " ") -> #REF! | K78: =IF(Oona!D77="Não",Oona!C77, " ") | N78: #REF! | O78: =IF(#REF!="Não",#REF!, " ") -> #REF! | R78: #REF! | S78: =IF(#REF!="Não",#REF!, " ") -> #REF! | V78: #REF! | W78: =IF(#REF!="Não",#REF!, " ") -> #REF!
B79: #REF! | C79: =IF(#REF!="Não",#REF!, "") -> #REF! | F79: #REF! | G79: =IF(#REF!="Não",#REF!, " ") -> #REF! | K79: =IF(Oona!D78="Não",Oona!C78, " ") | N79: #REF! | O79: =IF(#REF!="Não",#REF!, " ") -> #REF! | R79: #REF! | S79: =IF(#REF!="Não",#REF!, " ") -> #REF! | V79: #REF! | W79: =IF(#REF!="Não",#REF!, " ") -> #REF!
B80: #REF! | C80: =IF(#REF!="Não",#REF!, "") -> #REF! | F80: #REF! | G80: =IF(#REF!="Não",#REF!, " ") -> #REF! | K80: =IF(Oona!D79="Não",Oona!C79, " ") | N80: #REF! | O80: =IF(#REF!="Não",#REF!, " ") -> #REF! | R80: #REF! | S80: =IF(#REF!="Não",#REF!, " ") -> #REF! | V80: #REF! | W80: =IF(#REF!="Não",#REF!, " ") -> #REF!
B81: #REF! | C81: =IF(#REF!="Não",#REF!, "") -> #REF! | F81: #REF! | G81: =IF(#REF!="Não",#REF!, " ") -> #REF! | K81: =IF(Oona!D80="Não",Oona!C80, " ") | N81: #REF! | O81: =IF(#REF!="Não",#REF!, " ") -> #REF! | R81: #REF! | S81: =IF(#REF!="Não",#REF!, " ") -> #REF! | V81: #REF! | W81: =IF(#REF!="Não",#REF!, " ") -> #REF!
B82: #REF! | C82: =IF(#REF!="Não",#REF!, "") -> #REF! | F82: #REF! | G82: =IF(#REF!="Não",#REF!, " ") -> #REF! | K82: =IF(Oona!D81="Não",Oona!C81, " ") | N82: #REF! | O82: =IF(#REF!="Não",#REF!, " ") -> #REF! | R82: #REF! | S82: =IF(#REF!="Não",#REF!, " ") -> #REF! | V82: #REF! | W82: =IF(#REF!="Não",#REF!, " ") -> #REF!
B83: #REF! | C83: =IF(#REF!="Não",#REF!, "") -> #REF! | F83: #REF! | G83: =IF(#REF!="Não",#REF!, " ") -> #REF! | K83: =IF(Oona!D82="Não",Oona!C82, " ") | N83: #REF! | O83: =IF(#REF!="Não",#REF!, " ") -> #REF! | R83: #REF! | S83: =IF(#REF!="Não",#REF!, " ") -> #REF! | V83: #REF! | W83: =IF(#REF!="Não",#REF!, " ") -> #REF!
...

Sheet RESUMO4
A1: Thantis | E1: Jodah | I1: OWA | M1: Narset Mill | Q1: Kumena | U1: Narset Tokens
A3: Total | B3: {=_xlfn._xlws.SORT(C3:C101,1,-1,0)} -> #REF! | C3: =IF(#REF!="Não",#REF!, "") -> #REF! | E3: Total | F3: {=_xlfn._xlws.SORT(G3:G101,1,-1,0)} -> #REF! | G3: =IF(#REF!="Não",#REF!, "") -> #REF! | I3: Total | J3: {=_xlfn._xlws.SORT(K3:K101,1,-1,0)} -> #REF! | K3: =IF(#REF!="Não",#REF!, "") -> #REF! | M3: Total | N3: {=_xlfn._xlws.SORT(O3:O101,1,-1,0)} -> #REF! | O3: =IF(#REF!="Não",#REF!,"") -> #REF! | Q3: Total | R3: {=_xlfn._xlws.SORT(S3:S101,1,-1,0)} -> #REF! | S3: =IF(#REF!="Não",#REF!,"") -> #REF! | U3: Total | V3: {=_xlfn._xlws.SORT(W3:W101,1,-1,0)} -> #REF! | W3: =IF(#REF!="Não",#REF!,"") -> #REF!
A4: =#REF! -> #REF! | B4: #REF! | C4: =IF(#REF!="Não",#REF!, "") -> #REF! | E4: =#REF! -> #REF! | F4: #REF! | G4: =IF(#REF!="Não",#REF!, "") -> #REF! | I4: =#REF! -> #REF! | J4: #REF! | K4: =IF(#REF!="Não",#REF!, "") -> #REF! | M4: =#REF! -> #REF! | N4: #REF! | O4: =IF(#REF!="Não",#REF!,"") -> #REF! | Q4: =#REF! -> #REF! | R4: #REF! | S4: =IF(#REF!="Não",#REF!,"") -> #REF! | U4: =#REF! -> #REF! | V4: #REF! | W4: =IF(#REF!="Não",#REF!,"") -> #REF!
B5: #REF! | C5: =IF(#REF!="Não",#REF!, "") -> #REF! | F5: #REF! | G5: =IF(#REF!="Não",#REF!, "") -> #REF! | J5: #REF! | K5: =IF(#REF!="Não",#REF!, "") -> #REF! | N5: #REF! | O5: =IF(#REF!="Não",#REF!,"") -> #REF! | R5: #REF! | S5: =IF(#REF!="Não",#REF!,"") -> #REF! | V5: #REF! | W5: =IF(#REF!="Não",#REF!,"") -> #REF!
B6: #REF! | C6: =IF(#REF!="Não",#REF!, "") -> #REF! | F6: #REF! | G6: =IF(#REF!="Não",#REF!, "") -> #REF! | J6: #REF! | K6: =IF(#REF!="Não",#REF!, "") -> #REF! | N6: #REF! | O6: =IF(#REF!="Não",#REF!,"") -> #REF! | R6: #REF! | S6: =IF(#REF!="Não",#REF!,"") -> #REF! | V6: #REF! | W6: =IF(#REF!="Não",#REF!,"") -> #REF!
B7: #REF! | C7: =IF(#REF!="Não",#REF!, "") -> #REF! | F7: #REF! | G7: =IF(#REF!="Não",#REF!, "") -> #REF! | J7: #REF! | K7: =IF(#REF!="Não",#REF!, "") -> #REF! | N7: #REF! | O7: =IF(#REF!="Não",#REF!,"") -> #REF! | R7: #REF! | S7: =IF(#REF!="Não",#REF!,"") -> #REF! | V7: #REF! | W7: =IF(#REF!="Não",#REF!,"") -> #REF!
B8: #REF! | C8: =IF(#REF!="Não",#REF!, "") -> #REF! | F8: #REF! | G8: =IF(#REF!="Não",#REF!, "") -> #REF! | J8: #REF! | K8: =IF(#REF!="Não",#REF!, "") -> #REF! | N8: #REF! | O8: =IF(#REF!="Não",#REF!,"") -> #REF! | R8: #REF! | S8: =IF(#REF!="Não",#REF!,"") -> #REF! | V8: #REF! | W8: =IF(#REF!="Não",#REF!,"") -> #REF!
B9: #REF! | C9: =IF(#REF!="Não",#REF!, "") -> #REF! | F9: #REF! | G9: =IF(#REF!="Não",#REF!, "") -> #REF! | J9: #REF! | K9: =IF(#REF!="Não",#REF!, "") -> #REF! | N9: #REF! | O9: =IF(#REF!="Não",#REF!,"") -> #REF! | R9: #REF! | S9: =IF(#REF!="Não",#REF!,"") -> #REF! | V9: #REF! | W9: =IF(#REF!="Não",#REF!,"") -> #REF!
B10: #REF! | C10: =IF(#REF!="Não",#REF!, "") -> #REF! | F10: #REF! | G10: =IF(#REF!="Não",#REF!, "") -> #REF! | J10: #REF! | K10: =IF(#REF!="Não",#REF!, "") -> #REF! | N10: #REF! | O10: =IF(#REF!="Não",#REF!,"") -> #REF! | R10: #REF! | S10: =IF(#REF!="Não",#REF!,"") -> #REF! | V10: #REF! | W10: =IF(#REF!="Não",#REF!,"") -> #REF!
B11: #REF! | C11: =IF(#REF!="Não",#REF!, "") -> #REF! | F11: #REF! | G11: =IF(#REF!="Não",#REF!, "") -> #REF! | J11: #REF! | K11: =IF(#REF!="Não",#REF!, "") -> #REF! | N11: #REF! | O11: =IF(#REF!="Não",#REF!,"") -> #REF! | R11: #REF! | S11: =IF(#REF!="Não",#REF!,"") -> #REF! | V11: #REF! | W11: =IF(#REF!="Não",#REF!,"") -> #REF!
B12: #REF! | C12: =IF(#REF!="Não",#REF!, "") -> #REF! | F12: #REF! | G12: =IF(#REF!="Não",#REF!, "") -> #REF! | J12: #REF! | K12: =IF(#REF!="Não",#REF!, "") -> #REF! | N12: #REF! | O12: =IF(#REF!="Não",#REF!,"") -> #REF! | R12: #REF! | S12: =IF(#REF!="Não",#REF!,"") -> #REF! | V12: #REF! | W12: =IF(#REF!="Não",#REF!,"") -> #REF!
B13: #REF! | C13: =IF(#REF!="Não",#REF!, "") -> #REF! | F13: #REF! | G13: =IF(#REF!="Não",#REF!, "") -> #REF! | J13: #REF! | K13: =IF(#REF!="Não",#REF!, "") -> #REF! | N13: #REF! | O13: =IF(#REF!="Não",#REF!,"") -> #REF! | R13: #REF! | S13: =IF(#REF!="Não",#REF!,"") -> #REF! | V13: #REF! | W13: =IF(#REF!="Não",#REF!,"") -> #REF!
B14: #REF! | C14: =IF(#REF!="Não",#REF!, "") -> #REF! | F14: #REF! | G14: =IF(#REF!="Não",#REF!, "") -> #REF! | J14: #REF! | K14: =IF(#REF!="Não",#REF!, "") -> #REF! | N14: #REF! | O14: =IF(#REF!="Não",#REF!,"") -> #REF! | R14: #REF! | S14: =IF(#REF!="Não",#REF!,"") -> #REF! | V14: #REF! | W14: =IF(#REF!="Não",#REF!,"") -> #REF!
B15: #REF! | C15: =IF(#REF!="Não",#REF!, "") -> #REF! | F15: #REF! | G15: =IF(#REF!="Não",#REF!, "") -> #REF! | J15: #REF! | K15: =IF(#REF!="Não",#REF!, "") -> #REF! | N15: #REF! | O15: =IF(#REF!="Não",#REF!,"") -> #REF! | R15: #REF! | S15: =IF(#REF!="Não",#REF!,"") -> #REF! | V15: #REF! | W15: =IF(#REF!="Não",#REF!,"") -> #REF!
B16: #REF! | C16: =IF(#REF!="Não",#REF!, "") -> #REF! | F16: #REF! | G16: =IF(#REF!="Não",#REF!, "") -> #REF! | J16: #REF! | K16: =IF(#REF!="Não",#REF!, "") -> #REF! | N16: #REF! | O16: =IF(#REF!="Não",#REF!,"") -> #REF! | R16: #REF! | S16: =IF(#REF!="Não",#REF!,"") -> #REF! | V16: #REF! | W16: =IF(#REF!="Não",#REF!,"") -> #REF!
... B101: #REF! | C101: =IF(#REF!="Não",#REF!, "") -> #REF! | F101: #REF! | G101: =IF(#REF!="Não",#REF!, "") -> #REF! | J101: #REF! | K101: =IF(#REF!="Não",#REF!, "") -> #REF! | N101: #REF! | O101: =IF(#REF!="Não",#REF!,"") -> #REF! | R101: #REF! | S101: =IF(#REF!="Não",#REF!,"") -> #REF! | V101: #REF! | W101: =IF(#REF!="Não",#REF!,"") -> #REF!
C102: =IF(#REF!="Não",#REF!, "") -> #REF! | G102: =IF(#REF!="Não",#REF!, "") -> #REF! | K102: =IF(#REF!="Não",#REF!, "") -> #REF! | O102: =IF(#REF!="Não",#REF!,"") -> #REF! | W102: =IF(#REF!="Não",#REF!,"") -> #REF!
C103: =IF(#REF!="Não",#REF!, "") -> #REF! | G103: =IF(#REF!="Não",#REF!, "") -> #REF! | K103: =IF(#REF!="Não",#REF!, "") -> #REF! | O103: =IF(#REF!="Não",#REF!,"") -> #REF! | S103: =IF(#REF!="Não",#REF!,"") -> #REF! | W103: =IF(#REF!="Não",#REF!,"") -> #REF!
G104: =IF(#REF!="Não",#REF!, "") -> #REF! | K104: =IF(#REF!="Não",#REF!, "") -> #REF! | O104: =IF(#REF!="Não",#REF!,"") -> #REF! | S104: =IF(#REF!="Não",#REF!,"") -> #REF! | W104: =IF(#REF!="Não",#REF!,"") -> #REF!
G105: =IF(#REF!="Não",#REF!, "") -> #REF! | K105: =IF(#REF!="Não",#REF!, "") -> #REF! | O105: =IF(#REF!="Não",#REF!,"") -> #REF! | S105: =IF(#REF!="Não",#REF!,"") -> #REF! | W105: =IF(#REF!="Não",#REF!,"") -> #REF!
G106: =IF(#REF!="Não",#REF!, "") -> #REF! | K106: =IF(#REF!="Não",#REF!, "") -> #REF! | O106: =IF(#REF!="Não",#REF!,"") -> #REF! | S106: =IF(#REF!="Não",#REF!,"") -> #REF! | W106: =IF(#REF!="Não",#REF!,"") -> #REF!
G107: =IF(#REF!="Não",#REF!, "") -> #REF! | K107: =IF(#REF!="Não",#REF!, "") -> #REF! | O107: =IF(#REF!="Não",#REF!,"") -> #REF! | S107: =IF(#REF!="Não",#REF!,"") -> #REF! | W107: =IF(#REF!="Não",#REF!,"") -> #REF!
G108: =IF(#REF!="Não",#REF!, "") -> #REF! | K108: =IF(#REF!="Não",#REF!, "") -> #REF! | O108: =IF(#REF!="Não",#REF!,"") -> #REF! | S108: =IF(#REF!="Não",#REF!,"") -> #REF! | W108: =IF(#REF!="Não",#REF!,"") -> #REF!
G109: =IF(#REF!="Não",#REF!, "") -> #REF! | K109: =IF(#REF!="Não",#REF!, "") -> #REF! | O109: =IF(#REF!="Não",#REF!,"") -> #REF! | S109: =IF(#REF!="Não",#REF!,"") -> #REF! | W109: =IF(#REF!="Não",#REF!,"") -> #REF!
G110: =IF(#REF!="Não",#REF!, "") -> #REF! | K110: =IF(#REF!="Não",#REF!, "") -> #REF! | O110: =IF(#REF!="Não",#REF!,"") -> #REF! | S110: =IF(#REF!="Não",#REF!,"") -> #REF! | W110: =IF(#REF!="Não",#REF!,"") -> #REF!
G111: =IF(#REF!="Não",#REF!, "") -> #REF! | K111: =IF(#REF!="Não",#REF!, "") -> #REF! | O111: =IF(#REF!="Não",#REF!,"") -> #REF! | S111: =IF(#REF!="Não",#REF!,"") -> #REF! | W111: =IF(#REF!="Não",#REF!,"") -> #REF!
G112: =IF(#REF!="Não",#REF!, "") -> #REF! | K112: =IF(#REF!="Não",#REF!, "") -> #REF! | O112: =IF(#REF!="Não",#REF!,"") -> #REF! | S112: =IF(#REF!="Não",#REF!,"") -> #REF! | W112: =IF(#REF!="Não",#REF!,"") -> #REF!
G113: =IF(#REF!="Não",#REF!, "") -> #REF! | K113: =IF(#REF!="Não",#REF!, "") -> #REF! | O113: =IF(#REF!="Não",#REF!,"") -> #REF! | S113: =IF(#REF!="Não",#REF!,"") -> #REF! | W113: =IF(#REF!="Não",#REF!,"") -> #REF!
G114: =IF(#REF!="Não",#REF!, "") -> #REF! | K114: =IF(#REF!="Não",#REF!, "") -> #REF! | O114: =IF(#REF!="Não",#REF!,"") -> #REF! | S114: =IF(#REF!="Não",#REF!,"") -> #REF! | W114: =IF(#REF!="Não",#REF!,"") -> #REF!
G115: =IF(#REF!="Não",#REF!, "") -> #REF! | K115: =IF(#REF!="Não",#REF!, "") -> #REF! | O115: =IF(#REF!="Não",#REF!,"") -> #REF! | S115: =IF(#REF!="Não",#REF!,"") -> #REF! | W115: =IF(#REF!="Não",#REF!,"") -> #REF!
... G189: =IF(#REF!="Não",#REF!, "") -> #REF! | K189: =IF(#REF!="Não",#REF!, "") -> #REF! | O189: =IF(#REF!="Não",#REF!,"") -> #REF! | S189: =IF(#REF!="Não",#REF!,"") -> #REF! | W189: =IF(#REF!="Não",#REF!,"") -> #REF!
G190: =IF(#REF!="Não",#REF!, "") -> #REF! | K190: =IF(#REF!="Não",#REF!, "") -> #REF!
G191: =IF(#REF!="Não",#REF!, "") -> #REF! | K191: =IF(#REF!="Não",#REF!, "") -> #REF!
G192: =IF(#REF!="Não",#REF!, "") -> #REF! | K192: =IF(#REF!="Não",#REF!, "") -> #REF!
G193: =IF(#REF!="Não",#REF!, "") -> #REF! | K193: =IF(#REF!="Não",#REF!, "") -> #REF!
G194: =IF(#REF!="Não",#REF!, "") -> #REF! | K194: =IF(#REF!="Não",#REF!, "") -> #REF!
G195: =IF(#REF!="Não",#REF!, "") -> #REF! | K195: =IF(#REF!="Não",#REF!, "") -> #REF!
G196: =IF(#REF!="Não",#REF!, "") -> #REF! | K196: =IF(#REF!="Não",#REF!, "") -> #REF!
G197: =IF(#REF!="Não",#REF!, "") -> #REF! | K197: =IF(#REF!="Não",#REF!, "") -> #REF!
G198: =IF(#REF!="Não",#REF!, "") -> #REF! | K198: =IF(#REF!="Não",#REF!, "") -> #REF!
...

Sheet TDB
B1: Turma do Bairro
A2: Cód | B2: Função | C2: Ideia | D2: Foto | E2: Carta Atual | F2: Carta Ideal | G2: Carta Final
A3: T1 | B3: Terreno | C3: Praça dos Heróis | D3: Ok | E3: Território Arriscado | G3: =IF(E3=F3, "Sim", "Não") -> Não | I3: Mudanças Faltando | J3: =COUNTIF(G3:G104,"Não") -> 38
A4: T2 | B4: Terreno | C4: Cidadela de Bronze | D4: Ok | E4: Alturas Instáveis | G4: =IF(E4=F4, "Sim", "Não") -> Não | I4: Total de Cartas | J4: =SUM(J7:J26) -> 99
A5: T3 | B5: Terreno | C5: Ancient Ziggurat | D5: Ok | E5: Salão dos Jogos | G5: =IF(E5=F5, "Sim", "Não") -> Não
A6: T4 | B6: Terreno | C6: Reliquary | D6: Ok | E6: Elevador Sem Memórias | G6: =IF(E6=F6, "Sim", "Não") -> Não | I6: Funções
A7: T5 | B7: Terreno | C7: Command Tower | D7: Ok | E7: Refúgio de Verão | G7: =IF(E7=F7, "Sim", "Não") -> Não | I7: Terreno | J7: =COUNTIF(B:B,I7) -> 36
A8: T6 | B8: Terreno | C8: Pomar | D8: Ok | E8: Território do Pudim | G8: =IF(E8=F8, "Sim", "Não") -> Não | I8: Ramp | J8: =COUNTIF(B:B,I8) -> 10
A9: T7 | B9: Terreno | C9: Rakdos | D9: Ok | E9: Padaria do dia Seguinte | G9: =IF(E9=F9, "Sim", "Não") -> Não | I9: Draw | J9: =COUNTIF(B:B,I9) -> 10
A10: T8 | B10: Terreno | C10: Izzet | D10: Ok | E10: Unesp, Fonte de Conhecimento | G10: =IF(E10=F10, "Sim", "Não") -> Não | I10: Remoção | J10: =COUNTIF(B:B,I10) -> 8
A11: T9 | B11: Terreno | C11: Simic | D11: Ok | E11: Banheiro Comunitário | G11: =IF(E11=F11, "Sim", "Não") -> Não | I11: Membros | J11: =COUNTIF(B:B,I11) -> 25
A12: T10 | B12: Terreno | C12: Golgari | D12: Ok | E12: BK, Território Congelante | G12: =IF(E12=F12, "Sim", "Não") -> Não | I12: Aventuras | J12: =COUNTIF(B:B,I12) -> 10
A13: T11 | B13: Terreno | C13: Azorius | D13: Ok | E13: Armaggedon, Loja e Espetinhos | G13: =IF(E13=F13, "Sim", "Não") -> Não
A14: T12 | B14: Terreno | C14: Orzhov | D14: Ok | E14: Espetaria Cobiçada | G14: =IF(E14=F14, "Sim", "Não") -> Não
A15: T13 | B15: Terreno | C15: Selesnya | D15: Ok | E15: Salão do Conclave | G15: =IF(E15=F15, "Sim", "Não") -> Não
A16: T14 | B16: Terreno | C16: Boros | D16: Ok | E16: MC, Lugar de Gente Estranha | G16: =IF(E16=F16, "Sim", "Não") -> Não
A17: T15 | B17: Terreno | C17: Dimir | D17: Ok | E17: Zona de Conflito | G17: =IF(E17=F17, "Sim", "Não") -> Não
A18: T16 | B18: Terreno | C18: Gruul | D18: Ok | E18: Airbnb, Terreno Selvagem | G18: =IF(E18=F18, "Sim", "Não") -> Não
A19: T17 | B19: Terreno | C19: Grixis | D19: Ok | E19: Casa do Hamster | G19: =IF(E19=F19, "Sim", "Não") -> Não
A20: T18 | B20: Terreno | C20: Naya | D20: Ok | E20: Casa do JonathaN | G20: =IF(E20=F20, "Sim", "Não") -> Não
A21: T19 | B21: Terreno | C21: Jund | D21: Ok | E21: Casa dos Ambrózios | G21: =IF(E21=F21, "Sim", "Não") -> Não
A22: T20 | B22: Terreno | C22: Esper | D22: Ok | E22: Casa dos Scalvis-Mor | G22: =IF(E22=F22, "Sim", "Não") -> Não
A23: T21 | B23: Terreno | C23: Bant | D23: Ok | E23: Casa dos Agudenses | G23: =IF(E23=F23, "Sim", "Não") -> Não
A24: T22 | B24: Terreno | C24: Temur | D24: Ok | E24: Praia da Escadaria | G24: =IF(E24=F24, "Sim", "Não") -> Não
... A38: T36 | B38: Terreno | C38: Básico | D38: Ok | E38: Floresta | G38: =IF(E38=F38, "Sim", "Não") -> Não
A39: R1 | B39: Ramp | C39: Food | D39: Ok | E39: Reunir para Descansar | F39: Reunir para Descansar | G39: =IF(E39=F39, "Sim", "Não") -> Sim
A40: R2 | B40: Ramp | C40: Food | D40: Ok | E40: Reunir as Poderosas | F40: Reunir as Poderosas | G40: =IF(E40=F40, "Sim", "Não") -> Sim
A41: R3 | B41: Ramp | C41: Food | D41: Ok | E41: Reunir após a Festa | F41: Reunir após a Festa | G41: =IF(E41=F41, "Sim", "Não") -> Sim
A42: R4 | B42: Ramp | C42: Food | D42: Ok | E42: Reunir para Reunir depois | F42: Reunir para Reunir depois | G42: =IF(E42=F42, "Sim", "Não") -> Sim
A43: R5 | B43: Ramp | C43: Food | D43: Ok | E43: Reunir em Julho | F43: Reunir em Julho | G43: =IF(E43=F43, "Sim", "Não") -> Sim
A44: R6 | B44: Ramp | C44: Rock | D44: Ok | E44: Reunir para Presentear | F44: Reunir para Presentear | G44: =IF(E44=F44, "Sim", "Não") -> Sim
A45: R7 | B45: Ramp | C45: Rock | D45: Ok | E45: Reunir para Torcer | F45: Reunir para Torcer | G45: =IF(E45=F45, "Sim", "Não") -> Sim
A46: R8 | B46: Ramp | C46: Rock | D46: Ok | E46: Reunir com os Nerds | F46: Reunir com os Nerds | G46: =IF(E46=F46, "Sim", "Não") -> Sim
A47: R9 | B47: Ramp | C47: Rock | D47: Ok | E47: Reunir para Suar | F47: Reunir para Suar | G47: =IF(E47=F47, "Sim", "Não") -> Sim
A48: R10 | B48: Ramp | C48: Rock | D48: Ok | E48: Reunir para Jogar | F48: Reunir para Jogar | G48: =IF(E48=F48, "Sim", "Não") -> Sim
A49: D1 | B49: Draw | C49: Arena | D49: Ok | E49: Nós Vestimos a Toga, Vol. 1 | F49: Nós Vestimos a Toga, Vol. 1 | G49: =IF(E49=F49, "Sim", "Não") -> Sim
A50: D2 | B50: Draw | C50: Arena | D50: Ok | E50: Nós Vestimos a Toga, Vol. 2 | F50: Nós Vestimos a Toga, Vol. 2 | G50: =IF(E50=F50, "Sim", "Não") -> Sim
... A101: A10 | B101: Aventuras | C101: Turno | D101: Ok | E101: O Dia do Ídolo | F101: O Dia do Ídolo | G101: =IF(E101=F101, "Sim", "Não") -> Sim

Sheet Oona
A1: Oona
A2: Função | B2: Carta Atual | C2: Carta Ideal | D2: Carta Final
A3: Terreno | B3: Command Tower | C3: Command Tower | D3: =IF(B3=C3, "Sim", "Não") -> Sim | F3: Mudanças Faltando | G3: =COUNTIF(D3:D105,"Não") -> 1
A4: Terreno | B4: Reliquary Tower | C4: Reliquary Tower | D4: =IF(B4=C4, "Sim", "Não") -> Sim | F4: Total de Cartas | G4: =SUM(G7:G25) -> 99
A5: Terreno | B5: Myriad Landscape | C5: Myriad Landscape | D5: =IF(B5=C5, "Sim", "Não") -> Sim
A6: Terreno | B6: Exotic Orchard | C6: Exotic Orchard | D6: =IF(B6=C6, "Sim", "Não") -> Sim | F6: Funções
A7: Terreno | B7: Dreadship Reef | C7: Dreadship Reef | D7: =IF(B7=C7, "Sim", "Não") -> Sim | F7: Terreno | G7: =COUNTIF(A:A,F7) -> 34
A8: Terreno | B8: Mage-Ring Network | C8: Mage-Ring Network | D8: =IF(B8=C8, "Sim", "Não") -> Sim | F8: Ramp | G8: =COUNTIF(A:A,F8) -> 22
A9: Terreno | B9: Buried Ruin | C9: Buried Ruin | D9: =IF(B9=C9, "Sim", "Não") -> Sim | F9: Combo | G9: =COUNTIF(A:A,F9) -> 3
A10: Terreno | B10: Hall of Tagsin | C10: Hall of Tagsin | D10: =IF(B10=C10, "Sim", "Não") -> Sim | F10: Remoção | G10: =COUNTIF(A:A,F10) -> 10
A11: Terreno | B11: Mystic Sanctuary | C11: Mystic Sanctuary | D11: =IF(B11=C11, "Sim", "Não") -> Sim | F11: Anule | G11: =COUNTIF(A:A,F11) -> 10
A12: Terreno | B12: Castle Vantress | C12: Castle Vantress | D12: =IF(B12=C12, "Sim", "Não") -> Sim | F12: Valor | G12: =COUNTIF(A:A,F12) -> 7
A13: Terreno | B13: Bojuka Bog | C13: Bojuka Bog | D13: =IF(B13=C13, "Sim", "Não") -> Sim | F13: Draw | G13: =COUNTIF(A:A,F13) -> 6
A14: Terreno | B14: Island | C14: Island | D14: =IF(B14=C14, "Sim", "Não") -> Sim | F14: Tutor | G14: =COUNTIF(A:A,F14) -> 7
A15: Terreno | B15: Island | C15: Island | D15: =IF(B15=C15, "Sim", "Não") -> Sim
A16: Terreno | B16: Island | C16: Island | D16: =IF(B16=C16, "Sim", "Não") -> Sim
A17: Terreno | B17: Island | C17: Island | D17: =IF(B17=C17, "Sim", "Não") -> Sim
A18: Terreno | B18: Island | C18: Island | D18: =IF(B18=C18, "Sim", "Não") -> Sim
A19: Terreno | B19: Island | C19: Island | D19: =IF(B19=C19, "Sim", "Não") -> Sim
A20: Terreno | B20: Island | C20: Island | D20: =IF(B20=C20, "Sim", "Não") -> Sim
A21: Terreno | B21: Island | C21: Island | D21: =IF(B21=C21, "Sim", "Não") -> Sim
A22: Terreno | B22: Island | C22: Island | D22: =IF(B22=C22, "Sim", "Não") -> Sim
A23: Terreno | B23: Island | C23: Island | D23: =IF(B23=C23, "Sim", "Não") -> Sim
A24: Terreno | B24: Island | C24: Island | D24: =IF(B24=C24, "Sim", "Não") -> Sim
A25: Terreno | B25: Island | C25: Island | D25: =IF(B25=C25, "Sim", "Não") -> Sim
A26: Terreno | B26: Island | C26: Island | D26: =IF(B26=C26, "Sim", "Não") -> Sim
... A101: Tutor | B101: Whir of Invention | C101: Whir of Invention | D101: =IF(B101=C101, "Sim", "Não") -> Sim

Sheet VialIshai
A1: Vial Smasher e Ishai
A2: Função | B2: Carta Atual | C2: Carta Ideal | D2: Carta Final
A3: Terreno | B3: Command Tower | C3: Command Tower | D3: =IF(B3=C3, "Sim", "Não") -> Sim | F3: Mudanças Faltando | G3: =COUNTIF(D3:D105,"Não") -> 1
A4: Terreno | B4: Exotic Orchard | C4: Exotic Orchard | D4: =IF(B4=C4, "Sim", "Não") -> Sim | F4: Total de Cartas | G4: =SUM(G7:G25) -> 98
A5: Terreno | B5: Reliquary Tower | C5: Reliquary Tower | D5: =IF(B5=C5, "Sim", "Não") -> Sim
A6: Terreno | B6: Calciform Pools | C6: Calciform Pools | D6: =IF(B6=C6, "Sim", "Não") -> Sim | F6: Funções
A7: Terreno | B7: Dreadship Reef | C7: Dreadship Reef | D7: =IF(B7=C7, "Sim", "Não") -> Sim | F7: Terreno | G7: =COUNTIF(A:A,F7) -> 35
A8: Terreno | B8: Molten Slagheap | C8: Molten Slagheap | D8: =IF(B8=C8, "Sim", "Não") -> Sim | F8: Anule | G8: =COUNTIF(A:A,F8) -> 10
A9: Terreno | B9: Arcane Lighthouse | C9: Arcane Lighthouse | D9: =IF(B9=C9, "Sim", "Não") -> Sim | F9: Ramp | G9: =COUNTIF(A:A,F9) -> 7
A10: Terreno | B10: Bojuka Bog | C10: Bojuka Bog | D10: =IF(B10=C10, "Sim", "Não") -> Sim | F10: Survive | G10: =COUNTIF(A:A,F10) -> 10
A11: Terreno | B11: Cascading Cataracts | C11: Cascading Cataracts | D11: =IF(B11=C11, "Sim", "Não") -> Sim | F11: Draw | G11: =COUNTIF(A:A,F11) -> 11
A12: Terreno | B12: Núcleo de Mirrodin | C12: Núcleo de Mirrodin | D12: =IF(B12=C12, "Sim", "Não") -> Sim | F12: Remoção | G12: =COUNTIF(A:A,F12) -> 11
A13: Terreno | B13: Passagem Fabulosa | C13: Passagem Fabulosa | D13: =IF(B13=C13, "Sim", "Não") -> Sim | F13: Global | G13: =COUNTIF(A:A,F13) -> 7
A14: Terreno | B14: Grande Coliseu | C14: Grande Coliseu | D14: =IF(B14=C14, "Sim", "Não") -> Sim | F14: Big Draw | G14: =COUNTIF(A:A,F14) -> 7
A15: Terreno | B15: Nomad Outpost | C15: Nomad Outpost | D15: =IF(B15=C15, "Sim", "Não") -> Sim
A16: Terreno | B16: Mystic Monastery | C16: Mystic Monastery | D16: =IF(B16=C16, "Sim", "Não") -> Sim
A17: Terreno | B17: Arcane Sanctum | C17: Arcane Sanctum | D17: =IF(B17=C17, "Sim", "Não") -> Sim
A18: Terreno | B18: Crumbling Necropolis | C18: Crumbling Necropolis | D18: =IF(B18=C18, "Sim", "Não") -> Sim
A19: Terreno | B19: Silundi Vision | C19: Silundi Vision | D19: =IF(B19=C19, "Sim", "Não") -> Sim
A20: Terreno | B20: Ondu Inversion | C20: Ondu Inversion | D20: =IF(B20=C20, "Sim", "Não") -> Sim
A21: Terreno | B21: Morphic Pool | C21: Morphic Pool | D21: =IF(B21=C21, "Sim", "Não") -> Sim
A22: Terreno | B22: Sea of Clouds | C22: Sea of Clouds | D22: =IF(B22=C22, "Sim", "Não") -> Sim
A23: Terreno | B23: Ilha | C23: Ilha | D23: =IF(B23=C23, "Sim", "Não") -> Sim
A24: Terreno | B24: Ilha | C24: Ilha | D24: =IF(B24=C24, "Sim", "Não") -> Sim
A25: Terreno | B25: Ilha | C25: Ilha | D25: =IF(B25=C25, "Sim", "Não") -> Sim
A26: Terreno | B26: Ilha | C26: Ilha | D26: =IF(B26=C26, "Sim", "Não") -> Sim
... A100: Survive | B100: Aetherize | C100: Aetherize | D100: =IF(B100=C100, "Sim", "Não") -> Sim
