Workbook

Sheet COMPRAS
A1: Total: | B1: =C2+C8+C13+C18+C23+C28+C32+C34+C38+C50 -> 0 | E1: Deck | F1: =A2 -> Marcelo | G1: =B3 -> Mega | H1: =B4 -> Overrun | I1: =B5 -> Mundo TCG | J1: =B6 -> Liga | L1: =A8 -> Interessantes | M1: =B9 -> Valor | N1: =B10 -> Liga | O1: =B11 -> Loja 1 | Q1: =A13 -> Player 3 | R1: =B14 -> Rayearth | S1: =B15 -> Mineral | T1: =B16 -> CardTutor | V1: =A18 -> Player 4 | W1: =B19 -> Rayearth | X1: =B20 -> Mineral | Y1: =B21 -> CardTutor | AA1: =A23 -> Player 5 | AB1: =B24 -> Rayearth | AC1: =B25 -> Mineral | AD1: =B26 -> CardTutor | AF1: =A28 -> Player 6 | AG1: =B29 -> Rayearth | AH1: =B30 -> Mineral | AI1: =B31 -> CardTutor
A2: Marcelo | B2: Total Lojas: | C2: =SUM(C3:C6) -> 0 | E2: Rani | F2: Shield Roxo
A3: =COUNTA(F2:F217) -> 2 | B3: Mega | C3: =SUM(G:G) -> 0 | E3: Bichão | F3: Shield Vermelho Crimson?
B4: Overrun | C4: =SUM(H:H) -> 0
B5: Mundo TCG | C5: =SUM(I:I) -> 0
B6: Liga | C6: =SUM(J:J) -> 0
A8: Interessantes | B8: Total Lojas: | C8: =SUM(C9:C11) -> 0
A9: =COUNTA(L2:L173) -> 0 | B9: Valor | C9: =SUM(M:M) -> 0
B10: Liga | C10: =SUM(N:N) -> 0
B11: Loja 1 | C11: =SUM(O:O) -> 0
A13: Player 3 | B13: Total Lojas: | C13: =SUM(C14:C16) -> 0
A14: =COUNTA(Q2:Q173) -> 0 | B14: Rayearth | C14: =SUM(R:R) -> 0
B15: Mineral | C15: =SUM(S:S) -> 0
B16: CardTutor | C16: =SUM(T:T) -> 0
A18: Player 4 | B18: Total Lojas: | C18: =SUM(C19:C21) -> 0
A19: =COUNTA(V2:V173) -> 0 | B19: Rayearth | C19: =SUM(W1:W9973) -> 0
B20: Mineral | C20: =SUM(X1:X9978) -> 0
B21: CardTutor | C21: =SUM(Y:Y) -> 0
A23: Player 5 | B23: Total Lojas: | C23: =SUM(C24:C26) -> 0
A24: =COUNTA(V7:V178) -> 0 | B24: Rayearth | C24: =SUM(AB:AB) -> 0
B25: Mineral | C25: =SUM(AC:AC) -> 0
B26: CardTutor | C26: =SUM(AD:AD) -> 0
A28: Player 6 | B28: Total Lojas: | C28: =SUM(C29:C31) -> 0
A29: =COUNTA(V11:V183) -> 0 | B29: Rayearth | C29: =SUM(AG:AG) -> 0
B30: Mineral | C30: =SUM(AH:AH) -> 0
B31: CardTutor | C31: =SUM(AI:AI) -> 0

Sheet STATS
A1: Dia | B1: Player 1 | C1: Deck 1 | D1: Player 2 | E1: Deck 2 | F1: Player 3 | G1: Deck 3 | H1: Player 4 | I1: Deck 4 | J1: Vitória | M1: Deck | N1: Partidas | O1: Winrate | Q1: Player | R1: Partidas | S1: Winrate
A2: 45587 | B2: Marcelo | C2: Elfos | D2: Vivian | E2: Zimone | F2: Renato | G2: Raffine | H2: Dexter | I2: Kaalia | J2: Marcelo | K2: Elfos | M2: Akiri | N2: =COUNTIF(C:C,M2)+COUNTIF(E:E,M2)+COUNTIF(G:G,M2)+COUNTIF(I:I,M2) -> 2 | O2: =IF(N2>=10,(COUNTIF(K:K,M2)/N2),"Insuficiente") -> Insuficiente | Q2: Marcelo | R2: =COUNTIF(B:B,Q2)+COUNTIF(D:D,Q2)+COUNTIF(F:F,Q2)+COUNTIF(H:H,Q2) -> 11 | S2: =IF(R2>=10, (COUNTIF(J:J,Q2)/R2), "Insuficiente") -> 0.36363636
A3: 45594 | B3: Marcelo | C3: Breya | D3: Vivian | E3: Zimone | F3: Renato | G3: Raffine | H3: Dexter | I3: Tovolar | J3: Vivian | K3: Zimone | M3: Arcades | N3: =COUNTIF(C:C,M3)+COUNTIF(E:E,M3)+COUNTIF(G:G,M3)+COUNTIF(I:I,M3) -> 1 | O3: =IF(N3>=10,(COUNTIF(K:K,M3)/N3),"Insuficiente") -> Insuficiente | Q3: Vivian | R3: =COUNTIF(B:B,Q3)+COUNTIF(D:D,Q3)+COUNTIF(F:F,Q3)+COUNTIF(H:H,Q3) -> 11 | S3: =IF(R3>=10, (COUNTIF(J:J,Q3)/R3), "Insuficiente") -> 0.27272727
A4: 45594 | B4: Marcelo | C4: Trakiri | D4: Vivian | E4: Zimone | F4: Renato | G4: Raffine | H4: Hamster | I4: Muzzio | J4: Marcelo | K4: Trakiri | M4: Baylen | N4: =COUNTIF(C:C,M4)+COUNTIF(E:E,M4)+COUNTIF(G:G,M4)+COUNTIF(I:I,M4) -> 1 | O4: =IF(N4>=10,(COUNTIF(K:K,M4)/N4),"Insuficiente") -> Insuficiente | Q4: Renato | R4: =COUNTIF(B:B,Q4)+COUNTIF(D:D,Q4)+COUNTIF(F:F,Q4)+COUNTIF(H:H,Q4) -> 6 | S4: =IF(R4>=10, (COUNTIF(J:J,Q4)/R4), "Insuficiente") -> Insuficiente
A5: 45594 | B5: Marcelo | C5: Akiri | D5: Vivian | E5: Zimone | F5: Renato | G5: Baylen | H5: Hamster | I5: Kumena | J5: Marcelo | K5: Akiri | M5: Breya | N5: =COUNTIF(C:C,M5)+COUNTIF(E:E,M5)+COUNTIF(G:G,M5)+COUNTIF(I:I,M5) -> 1 | O5: =IF(N5>=10,(COUNTIF(K:K,M5)/N5),"Insuficiente") -> Insuficiente | Q5: Dexter | R5: =COUNTIF(B:B,Q5)+COUNTIF(D:D,Q5)+COUNTIF(F:F,Q5)+COUNTIF(H:H,Q5) -> 5 | S5: =IF(R5>=10, (COUNTIF(J:J,Q5)/R5), "Insuficiente") -> Insuficiente
A6: 45597 | B6: Marcelo | C6: Inalla | D6: Vivian | E6: Zimone | F6: Renato | G6: Raffine | H6: João | I6: Winota | J6: João | K6: Winota | M6: Elfos | N6: =COUNTIF(C:C,M6)+COUNTIF(E:E,M6)+COUNTIF(G:G,M6)+COUNTIF(I:I,M6) -> 1 | O6: =IF(N6>=10,(COUNTIF(K:K,M6)/N6),"Insuficiente") -> Insuficiente | Q6: Hamster | R6: =COUNTIF(B:B,Q6)+COUNTIF(D:D,Q6)+COUNTIF(F:F,Q6)+COUNTIF(H:H,Q6) -> 2 | S6: =IF(R6>=10, (COUNTIF(J:J,Q6)/R6), "Insuficiente") -> Insuficiente
A7: 45597 | B7: Marcelo | C7: Yuriko | D7: Vivian | E7: Zimone | F7: Renato | G7: Raffine | H7: João | I7: Winota | J7: Vivian | K7: Zimone | M7: FF Counters | N7: =COUNTIF(C:C,M7)+COUNTIF(E:E,M7)+COUNTIF(G:G,M7)+COUNTIF(I:I,M7) -> 2 | O7: =IF(N7>=10,(COUNTIF(K:K,M7)/N7),"Insuficiente") -> Insuficiente | Q7: Talita | R7: =COUNTIF(B:B,Q7)+COUNTIF(D:D,Q7)+COUNTIF(F:F,Q7)+COUNTIF(H:H,Q7) -> 3 | S7: =IF(R7>=10, (COUNTIF(J:J,Q7)/R7), "Insuficiente") -> Insuficiente
A8: 45599 | B8: Marcelo | C8: Narset | D8: Vivian | E8: Arcades | F8: Dexter | G8: Who Villains | H8: Talita | I8: Who Time | J8: Vivian | K8: Arcades | M8: Hashaton | N8: =COUNTIF(C:C,M8)+COUNTIF(E:E,M8)+COUNTIF(G:G,M8)+COUNTIF(I:I,M8) -> 1 | O8: =IF(N8>=10,(COUNTIF(K:K,M8)/N8),"Insuficiente") -> Insuficiente | Q8: João | R8: =COUNTIF(B:B,Q8)+COUNTIF(D:D,Q8)+COUNTIF(F:F,Q8)+COUNTIF(H:H,Q8) -> 4 | S8: =IF(R8>=10, (COUNTIF(J:J,Q8)/R8), "Insuficiente") -> Insuficiente
A9: 45599 | B9: Marcelo | C9: Thantis | D9: Vivian | E9: Akiri | F9: Dexter | G9: Who Villains | H9: Talita | I9: Ladinos | J9: Talita | K9: Ladinos | M9: Inalla | N9: =COUNTIF(C:C,M9)+COUNTIF(E:E,M9)+COUNTIF(G:G,M9)+COUNTIF(I:I,M9) -> 1 | O9: =IF(N9>=10,(COUNTIF(K:K,M9)/N9),"Insuficiente") -> Insuficiente | Q9: Philips | R9: =COUNTIF(B:B,Q9)+COUNTIF(D:D,Q9)+COUNTIF(F:F,Q9)+COUNTIF(H:H,Q9) -> 2 | S9: =IF(R9>=10, (COUNTIF(J:J,Q9)/R9), "Insuficiente") -> Insuficiente
A10: 45835 | B10: Marcelo | C10: Zedruu | D10: Vivian | E10: Jhoira | F10: Dexter | G10: Who Villains | H10: Talita | I10: Who Time | J10: Dexter | K10: Who Villains | M10: Jhoira | N10: =COUNTIF(C:C,M10)+COUNTIF(E:E,M10)+COUNTIF(G:G,M10)+COUNTIF(I:I,M10) -> 1 | O10: =IF(N10>=10,(COUNTIF(K:K,M10)/N10),"Insuficiente") -> Insuficiente
A11: 45864 | B11: Marcelo | C11: Muzzio | D11: Vivian | E11: Zimone | F11: Philips | G11: Hashaton | H11: João | I11: FF Counters | J11: Marcelo | K11: Muzzio | M11: Kaalia | N11: =COUNTIF(C:C,M11)+COUNTIF(E:E,M11)+COUNTIF(G:G,M11)+COUNTIF(I:I,M11) -> 2 | O11: =IF(N11>=10,(COUNTIF(K:K,M11)/N11),"Insuficiente") -> Insuficiente
A12: 45864 | B12: Marcelo | C12: Sisay | D12: Vivian | E12: Zimone | F12: Philips | G12: Kaalia | H12: João | I12: FF Counters | J12: Philips | K12: Kaalia | M12: Kumena | N12: =COUNTIF(C:C,M12)+COUNTIF(E:E,M12)+COUNTIF(G:G,M12)+COUNTIF(I:I,M12) -> 1 | O12: =IF(N12>=10,(COUNTIF(K:K,M12)/N12),"Insuficiente") -> Insuficiente
M13: Ladinos | N13: =COUNTIF(C:C,M13)+COUNTIF(E:E,M13)+COUNTIF(G:G,M13)+COUNTIF(I:I,M13) -> 1 | O13: =IF(N13>=10,(COUNTIF(K:K,M13)/N13),"Insuficiente") -> Insuficiente
M14: Muzzio | N14: =COUNTIF(C:C,M14)+COUNTIF(E:E,M14)+COUNTIF(G:G,M14)+COUNTIF(I:I,M14) -> 2 | O14: =IF(N14>=10,(COUNTIF(K:K,M14)/N14),"Insuficiente") -> Insuficiente
M15: Narset | N15: =COUNTIF(C:C,M15)+COUNTIF(E:E,M15)+COUNTIF(G:G,M15)+COUNTIF(I:I,M15) -> 1 | O15: =IF(N15>=10,(COUNTIF(K:K,M15)/N15),"Insuficiente") -> Insuficiente
M16: Raffine | N16: =COUNTIF(C:C,M16)+COUNTIF(E:E,M16)+COUNTIF(G:G,M16)+COUNTIF(I:I,M16) -> 5 | O16: =IF(N16>=10,(COUNTIF(K:K,M16)/N16),"Insuficiente") -> Insuficiente
M17: Sisay | N17: =COUNTIF(C:C,M17)+COUNTIF(E:E,M17)+COUNTIF(G:G,M17)+COUNTIF(I:I,M17) -> 1 | O17: =IF(N17>=10,(COUNTIF(K:K,M17)/N17),"Insuficiente") -> Insuficiente
M18: Thantis | N18: =COUNTIF(C:C,M18)+COUNTIF(E:E,M18)+COUNTIF(G:G,M18)+COUNTIF(I:I,M18) -> 1 | O18: =IF(N18>=10,(COUNTIF(K:K,M18)/N18),"Insuficiente") -> Insuficiente
M19: Tovolar | N19: =COUNTIF(C:C,M19)+COUNTIF(E:E,M19)+COUNTIF(G:G,M19)+COUNTIF(I:I,M19) -> 1 | O19: =IF(N19>=10,(COUNTIF(K:K,M19)/N19),"Insuficiente") -> Insuficiente
M20: Trakiri | N20: =COUNTIF(C:C,M20)+COUNTIF(E:E,M20)+COUNTIF(G:G,M20)+COUNTIF(I:I,M20) -> 1 | O20: =IF(N20>=10,(COUNTIF(K:K,M20)/N20),"Insuficiente") -> Insuficiente
M21: Who Time | N21: =COUNTIF(C:C,M21)+COUNTIF(E:E,M21)+COUNTIF(G:G,M21)+COUNTIF(I:I,M21) -> 2 | O21: =IF(N21>=10,(COUNTIF(K:K,M21)/N21),"Insuficiente") -> Insuficiente
M22: Who Villains | N22: =COUNTIF(C:C,M22)+COUNTIF(E:E,M22)+COUNTIF(G:G,M22)+COUNTIF(I:I,M22) -> 3 | O22: =IF(N22>=10,(COUNTIF(K:K,M22)/N22),"Insuficiente") -> Insuficiente
M23: Winota | N23: =COUNTIF(C:C,M23)+COUNTIF(E:E,M23)+COUNTIF(G:G,M23)+COUNTIF(I:I,M23) -> 2 | O23: =IF(N23>=10,(COUNTIF(K:K,M23)/N23),"Insuficiente") -> Insuficiente
M24: Yuriko | N24: =COUNTIF(C:C,M24)+COUNTIF(E:E,M24)+COUNTIF(G:G,M24)+COUNTIF(I:I,M24) -> 1 | O24: =IF(N24>=10,(COUNTIF(K:K,M24)/N24),"Insuficiente") -> Insuficiente
... M26: Zimone | N26: =COUNTIF(C:C,M26)+COUNTIF(E:E,M26)+COUNTIF(G:G,M26)+COUNTIF(I:I,M26) -> 8 | O26: =IF(N26>=10,(COUNTIF(K:K,M26)/N26),"Insuficiente") -> Insuficiente

Sheet RESUMO
A1: Thrakiri | E1: Gitrog | I1: Elfos | M1: Jhoira | Q1: Fractius | U1: Muzzio
A3: Total | B3: {=_xlfn._xlws.SORT(C3:C101,1,-1,0)} -> Uthros, Titanic Godcore | C3: =IF(Thrakiri!D3="Não",Thrakiri!C3, " ") | E3: Total | F3: {=_xlfn._xlws.SORT(G3:G101,1,-1,0)} -> Ulamog, the Infinite Gyre | G3: =IF(Gitrog!D3="Não",Gitrog!C3, " ") | I3: Total | J3: {=_xlfn._xlws.SORT(K3:K101,1,-1,0)} -> Zagoth Triome | K3: =IF(Elfos!D3="Não",Elfos!C3, " ") | M3: Total | N3: {=_xlfn._xlws.SORT(O3:O101,1,-1,0)} -> Valfenda | O3: =IF(Jhoira!D3="Não",Jhoira!C4, " ") | Q3: Total | R3: {=_xlfn._xlws.SORT(S3:S101,1,-1,0)} -> Trioma de Zagoth | S3: =IF(Fractius!D3="Não",Fractius!C3, " ") | U3: Total | V3: {=_xlfn._xlws.SORT(W3:W101,1,-1,0)} -> The Mycosynth Gardens | W3: =IF(Muzzio!D3="Não",Muzzio!C3, " ")
A4: =Thrakiri!G3 -> 6 | B4: The Mycosynth Gardens | C4: =IF(Thrakiri!D3="Não",Thrakiri!C4, " ") | E4: =Gitrog!G3 -> 12 | F4: Titania, Voice of Gaea | G4: =IF(Gitrog!D3="Não",Gitrog!C4, " ") | I4: =Elfos!G3 -> 6 | J4: Three Tree City | K4: =IF(Elfos!D3="Não",Elfos!C4, " ") | M4: =Jhoira!G4 -> 6 | N4: Ulamog, o Profanador | O4: =IF(Jhoira!D5="Não",Jhoira!C5, " ") | Q4: =Fractius!G3 -> 9 | R4: Trioma de Raugrin | S4: =IF(Fractius!D3="Não",Fractius!C4, " ") | U4: =Muzzio!G3 -> 14 | V4: Sonic Screwdriver | W4: =IF(Muzzio!D3="Não",Muzzio!C4, " ")
B5: The Eternity Elevator | C5: =IF(Thrakiri!D5="Não",Thrakiri!C5, " ") | F5: Takenuma, Charco Abandonado | G5: =IF(Gitrog!D5="Não",Gitrog!C5, " ") | J5: Nissa, Resurgent Animist | K5: =IF(Elfos!D5="Não",Elfos!C5, " ") | N5: Planetary Annihilation | O5: =IF(Jhoira!D6="Não",Jhoira!C6, " ") | R5: Thrumming Hivepool | S5: =IF(Fractius!D5="Não",Fractius!C5, " ") -> Trioma de Zagoth | V5: Rings of Brighthearth | W5: =IF(Muzzio!D5="Não",Muzzio!C5, " ")
B6: Shaku da Honra Desgastada | C6: =IF(Thrakiri!D6="Não",Thrakiri!C6, " ") | F6: Phyrexian Tower | G6: =IF(Gitrog!D6="Não",Gitrog!C6, " ") | J6: Evendo, Waking Haven | K6: =IF(Elfos!D6="Não",Elfos!C6, " ") -> Alchemist's Refuge | N6: Mistrise Village | O6: =IF(Jhoira!D7="Não",Jhoira!C7, " ") | R6: Sliver Gravemother | S6: =IF(Fractius!D6="Não",Fractius!C6, " ") -> Trioma de Raugrin | V6: Portal to Phyrexia | W6: =IF(Muzzio!D6="Não",Muzzio!C6, " ")
B7: Obelisco de Obsidiana | C7: =IF(Thrakiri!D7="Não",Thrakiri!C7, " ") | F7: Petrified Field | G7: =IF(Gitrog!D7="Não",Gitrog!C7, " ") | J7: Dionus, Elvish Archdruid | K7: =IF(Elfos!D7="Não",Elfos!C7, " ") | N7: Emrakul, um Novo Mundo | O7: =IF(Jhoira!D8="Não",Jhoira!C8, " ") | R7: Rakdos Signet | S7: =IF(Fractius!D7="Não",Fractius!C7, " ") | V7: Pingente de Ampulheta de Gerrard | W7: =IF(Muzzio!D7="Não",Muzzio!C7, " ")
B8: Matoya, Archon Elder | C8: =IF(Thrakiri!D8="Não",Thrakiri!C8, " ") | F8: Ondulações de Morte-Vida | G8: =IF(Gitrog!D8="Não",Gitrog!C8, " ") | J8: Alchemist's Refuge | K8: =IF(Elfos!D8="Não",Elfos!C8, " ") | N8: Cyber Conversion | O8: =IF(Jhoira!D9="Não",Jhoira!C9, " ") -> Valfenda | R8: Raffine's Tower | S8: =IF(Fractius!D8="Não",Fractius!C8, " ") -> Raffine's Tower | V8: Mirrex | W8: =IF(Muzzio!D8="Não",Muzzio!C8, " ")
C9: =IF(Thrakiri!D9="Não",Thrakiri!C9, " ") | F9: Hedge Shredder | G9: =IF(Gitrog!D9="Não",Gitrog!C9, " ") | K9: =IF(Elfos!D9="Não",Elfos!C9, " ") | O9: =IF(Jhoira!D10="Não",Jhoira!C10, " ") -> Mistrise Village | R9: Jetmir's Garden | S9: =IF(Fractius!D9="Não",Fractius!C9, " ") | V9: Gogo, Master of Mimicry | W9: =IF(Muzzio!D9="Não",Muzzio!C9, " ")
C10: =IF(Thrakiri!D10="Não",Thrakiri!C10, " ") | F10: Entomb | G10: =IF(Gitrog!D10="Não",Gitrog!C10, " ") | K10: =IF(Elfos!D10="Não",Elfos!C10, " ") | O10: =IF(Jhoira!D11="Não",Jhoira!C11, " ") | R10: Caverna das Almas | S10: =IF(Fractius!D10="Não",Fractius!C10, " ") | V10: Extinguisher Battleship | W10: =IF(Muzzio!D10="Não",Muzzio!C10, " ")
C11: =IF(Thrakiri!D11="Não",Thrakiri!C11, " ") | F11: Delighted Halfling | G11: =IF(Gitrog!D11="Não",Gitrog!C11, " ") | K11: =IF(Elfos!D11="Não",Elfos!C11, " ") | O11: =IF(Jhoira!D12="Não",Jhoira!C12, " ") | S11: =IF(Fractius!D11="Não",Fractius!C11, " ") -> Jetmir's Garden | V11: Dauntless Scrapbot | W11: =IF(Muzzio!D11="Não",Muzzio!C11, " ")
C12: =IF(Thrakiri!D12="Não",Thrakiri!C12, " ") | F12: Crisol dos Mundos | G12: =IF(Gitrog!D12="Não",Gitrog!C12, " ") | K12: =IF(Elfos!D12="Não",Elfos!C12, " ") | O12: =IF(Jhoira!D13="Não",Jhoira!C13, " ") | S12: =IF(Fractius!D12="Não",Fractius!C12, " ") | V12: Chimil, o Sol Interior | W12: =IF(Muzzio!D12="Não",Muzzio!C12, " ")
C13: =IF(Thrakiri!D13="Não",Thrakiri!C13, " ") | F13: Broodheart Engine | G13: =IF(Gitrog!D13="Não",Gitrog!C13, " ") -> Phyrexian Tower | K13: =IF(Elfos!D13="Não",Elfos!C13, " ") -> Zagoth Triome | O13: =IF(Jhoira!D14="Não",Jhoira!C14, " ") | S13: =IF(Fractius!D13="Não",Fractius!C13, " ") -> Caverna das Almas | V13: Caixa Enigmática Desconcertante | W13: =IF(Muzzio!D13="Não",Muzzio!C13, " ") -> Academy Ruins
C14: =IF(Thrakiri!D14="Não",Thrakiri!C14, " ") | F14: Ancient Tomb | G14: =IF(Gitrog!D14="Não",Gitrog!C14, " ") | K14: =IF(Elfos!D14="Não",Elfos!C14, " ") | O14: =IF(Jhoira!D15="Não",Jhoira!C15, " ") | S14: =IF(Fractius!D14="Não",Fractius!C14, " ") | V14: Academy Ruins | W14: =IF(Muzzio!D14="Não",Muzzio!C14, " ")
C15: =IF(Thrakiri!D15="Não",Thrakiri!C15, " ") | G15: =IF(Gitrog!D15="Não",Gitrog!C15, " ") | K15: =IF(Elfos!D15="Não",Elfos!C15, " ") | O15: =IF(Jhoira!D16="Não",Jhoira!C16, " ") | S15: =IF(Fractius!D15="Não",Fractius!C15, " ") | V15: A Joia do Enigma | W15: =IF(Muzzio!D15="Não",Muzzio!C15, " ") -> Mirrex
C16: =IF(Thrakiri!D16="Não",Thrakiri!C16, " ") | G16: =IF(Gitrog!D16="Não",Gitrog!C16, " ") | K16: =IF(Elfos!D16="Não",Elfos!C16, " ") | O16: =IF(Jhoira!D17="Não",Jhoira!C17, " ") | S16: =IF(Fractius!D16="Não",Fractius!C16, " ") | W16: =IF(Muzzio!D16="Não",Muzzio!C16, " ") -> The Mycosynth Gardens
C17: =IF(Thrakiri!D20="Não",Thrakiri!C20, " ") | G17: =IF(Gitrog!D17="Não",Gitrog!C17, " ") -> Petrified Field | K17: =IF(Elfos!D17="Não",Elfos!C17, " ") | O17: =IF(Jhoira!D18="Não",Jhoira!C18, " ") | S17: =IF(Fractius!D17="Não",Fractius!C17, " ") | W17: =IF(Muzzio!D17="Não",Muzzio!C17, " ")
C18: =IF(Thrakiri!D21="Não",Thrakiri!C21, " ") | G18: =IF(Gitrog!D18="Não",Gitrog!C18, " ") -> Ancient Tomb | K18: =IF(Elfos!D18="Não",Elfos!C18, " ") | O18: =IF(Jhoira!D19="Não",Jhoira!C19, " ") | S18: =IF(Fractius!D18="Não",Fractius!C18, " ") | W18: =IF(Muzzio!D18="Não",Muzzio!C18, " ")
C19: =IF(Thrakiri!D22="Não",Thrakiri!C22, " ") | G19: =IF(Gitrog!D19="Não",Gitrog!C19, " ") | K19: =IF(Elfos!D19="Não",Elfos!C19, " ") | O19: =IF(Jhoira!D20="Não",Jhoira!C20, " ") | S19: =IF(Fractius!D19="Não",Fractius!C19, " ") | W19: =IF(Muzzio!D19="Não",Muzzio!C19, " ")
C20: =IF(Thrakiri!D23="Não",Thrakiri!C23, " ") | G20: =IF(Gitrog!D20="Não",Gitrog!C20, " ") | K20: =IF(Elfos!D20="Não",Elfos!C20, " ") -> Three Tree City | O20: =IF(Jhoira!D21="Não",Jhoira!C21, " ") | S20: =IF(Fractius!D20="Não",Fractius!C20, " ") | W20: =IF(Muzzio!D20="Não",Muzzio!C20, " ")
C21: =IF(Thrakiri!D24="Não",Thrakiri!C24, " ") | G21: =IF(Gitrog!D21="Não",Gitrog!C21, " ") | K21: =IF(Elfos!D21="Não",Elfos!C21, " ") -> Evendo, Waking Haven | O21: =IF(Jhoira!D22="Não",Jhoira!C22, " ") | S21: =IF(Fractius!D21="Não",Fractius!C21, " ") | W21: =IF(Muzzio!D21="Não",Muzzio!C21, " ")
C22: =IF(Thrakiri!D25="Não",Thrakiri!C25, " ") | G22: =IF(Gitrog!D22="Não",Gitrog!C22, " ") | K22: =IF(Elfos!D22="Não",Elfos!C22, " ") | O22: =IF(Jhoira!D23="Não",Jhoira!C23, " ") | S22: =IF(Fractius!D22="Não",Fractius!C22, " ") | W22: =IF(Muzzio!D22="Não",Muzzio!C22, " ")
C23: =IF(Thrakiri!D26="Não",Thrakiri!C26, " ") | G23: =IF(Gitrog!D23="Não",Gitrog!C23, " ") | K23: =IF(Elfos!D23="Não",Elfos!C23, " ") | O23: =IF(Jhoira!D24="Não",Jhoira!C24, " ") | S23: =IF(Fractius!D23="Não",Fractius!C23, " ") | W23: =IF(Muzzio!D23="Não",Muzzio!C23, " ")
C24: =IF(Thrakiri!D27="Não",Thrakiri!C27, " ") | G24: =IF(Gitrog!D83="Não",Gitrog!C83, " ") | K24: =IF(Elfos!D24="Não",Elfos!C24, " ") | O24: =IF(Jhoira!D25="Não",Jhoira!C25, " ") | S24: =IF(Fractius!D24="Não",Fractius!C24, " ") | W24: =IF(Muzzio!D24="Não",Muzzio!C24, " ")
C25: =IF(Thrakiri!D28="Não",Thrakiri!C28, " ") | G25: =IF(Gitrog!D24="Não",Gitrog!C24, " ") -> Takenuma, Charco Abandonado | K25: =IF(Elfos!D25="Não",Elfos!C25, " ") | O25: =IF(Jhoira!D26="Não",Jhoira!C26, " ") | S25: =IF(Fractius!D25="Não",Fractius!C25, " ") | W25: =IF(Muzzio!D25="Não",Muzzio!C25, " ")
C26: =IF(Thrakiri!D29="Não",Thrakiri!C29, " ") | G26: =IF(Gitrog!D25="Não",Gitrog!C25, " ") | K26: =IF(Elfos!D26="Não",Elfos!C26, " ") | O26: =IF(Jhoira!D27="Não",Jhoira!C27, " ") | S26: =IF(Fractius!D26="Não",Fractius!C26, " ") | W26: =IF(Muzzio!D26="Não",Muzzio!C26, " ")
C27: =IF(Thrakiri!D30="Não",Thrakiri!C30, " ") | G27: =IF(Gitrog!D26="Não",Gitrog!C26, " ") | K27: =IF(Elfos!D27="Não",Elfos!C27, " ") | O27: =IF(Jhoira!D28="Não",Jhoira!C28, " ") | S27: =IF(Fractius!D27="Não",Fractius!C27, " ") | W27: =IF(Muzzio!D27="Não",Muzzio!C27, " ")
C28: =IF(Thrakiri!D31="Não",Thrakiri!C31, " ") | G28: =IF(Gitrog!D27="Não",Gitrog!C27, " ") | K28: =IF(Elfos!D28="Não",Elfos!C28, " ") | O28: =IF(Jhoira!D29="Não",Jhoira!C29, " ") | S28: =IF(Fractius!D28="Não",Fractius!C28, " ") | W28: =IF(Muzzio!D28="Não",Muzzio!C28, " ")
C29: =IF(Thrakiri!D32="Não",Thrakiri!C32, " ") | G29: =IF(Gitrog!D28="Não",Gitrog!C28, " ") | K29: =IF(Elfos!D29="Não",Elfos!C29, " ") | O29: =IF(Jhoira!D30="Não",Jhoira!C30, " ") | S29: =IF(Fractius!D87="Não",Fractius!C87, " ") | W29: =IF(Muzzio!D29="Não",Muzzio!C29, " ")
C30: =IF(Thrakiri!D18="Não",Thrakiri!C18, " ") | G30: =IF(Gitrog!D29="Não",Gitrog!C29, " ") | K30: =IF(Elfos!D30="Não",Elfos!C30, " ") | O30: =IF(Jhoira!D31="Não",Jhoira!C31, " ") | S30: =IF(Fractius!D29="Não",Fractius!C29, " ") | W30: =IF(Muzzio!D30="Não",Muzzio!C30, " ")
C31: =IF(Thrakiri!D33="Não",Thrakiri!C33, " ") | G31: =IF(Gitrog!D30="Não",Gitrog!C30, " ") | K31: =IF(Elfos!D31="Não",Elfos!C31, " ") | O31: =IF(Jhoira!D32="Não",Jhoira!C32, " ") | S31: =IF(Fractius!D30="Não",Fractius!C30, " ") | W31: =IF(Muzzio!D31="Não",Muzzio!C31, " ")
C32: =IF(Thrakiri!D34="Não",Thrakiri!C34, " ") | G32: =IF(Gitrog!D31="Não",Gitrog!C31, " ") | K32: =IF(Elfos!D32="Não",Elfos!C32, " ") | O32: =IF(Jhoira!D33="Não",Jhoira!C33, " ") | S32: =IF(Fractius!D31="Não",Fractius!C31, " ") | W32: =IF(Muzzio!D33="Não",Muzzio!C33, " ")
C33: =IF(Thrakiri!D35="Não",Thrakiri!C35, " ") | G33: =IF(Gitrog!D32="Não",Gitrog!C32, " ") | K33: =IF(Elfos!D33="Não",Elfos!C33, " ") | O33: =IF(Jhoira!D34="Não",Jhoira!C34, " ") | S33: =IF(Fractius!D32="Não",Fractius!C32, " ") | W33: =IF(Muzzio!D39="Não",Muzzio!C39, " ")
C34: =IF(Thrakiri!D36="Não",Thrakiri!C36, " ") | G34: =IF(Gitrog!D33="Não",Gitrog!C33, " ") | K34: =IF(Elfos!D34="Não",Elfos!C34, " ") | O34: =IF(Jhoira!D35="Não",Jhoira!C35, " ") | S34: =IF(Fractius!D33="Não",Fractius!C33, " ") | W34: =IF(Muzzio!D50="Não",Muzzio!C50, " ")
C35: =IF(Thrakiri!D37="Não",Thrakiri!C37, " ") | G35: =IF(Gitrog!D34="Não",Gitrog!C34, " ") | K35: =IF(Elfos!D35="Não",Elfos!C35, " ") | O35: =IF(Jhoira!D36="Não",Jhoira!C36, " ") | S35: =IF(Fractius!D34="Não",Fractius!C34, " ") | W35: =IF(Muzzio!D49="Não",Muzzio!C49, " ") -> Caixa Enigmática Desconcertante
C36: =IF(Thrakiri!D38="Não",Thrakiri!C38, " ") | G36: =IF(Gitrog!D35="Não",Gitrog!C35, " ") | K36: =IF(Elfos!D36="Não",Elfos!C36, " ") | O36: =IF(Jhoira!D38="Não",Jhoira!C38, " ") | S36: =IF(Fractius!D35="Não",Fractius!C35, " ") | W36: =IF(Muzzio!D45="Não",Muzzio!C45, " ")
C37: =IF(Thrakiri!D39="Não",Thrakiri!C39, " ") | G37: =IF(Gitrog!D36="Não",Gitrog!C36, " ") | K37: =IF(Elfos!D37="Não",Elfos!C37, " ") | O37: =IF(Jhoira!D39="Não",Jhoira!C39, " ") | S37: =IF(Fractius!D36="Não",Fractius!C36, " ") | W37: =IF(Muzzio!D48="Não",Muzzio!C48, " ")
C38: =IF(Thrakiri!D40="Não",Thrakiri!C40, " ") | G38: =IF(Gitrog!D37="Não",Gitrog!C37, " ") | K38: =IF(Elfos!D38="Não",Elfos!C38, " ") | O38: =IF(Jhoira!D40="Não",Jhoira!C40, " ") | S38: =IF(Fractius!D37="Não",Fractius!C37, " ") | W38: =IF(Muzzio!D46="Não",Muzzio!C46, " ")
C39: =IF(Thrakiri!D41="Não",Thrakiri!C41, " ") | G39: =IF(Gitrog!D38="Não",Gitrog!C38, " ") | K39: =IF(Elfos!D39="Não",Elfos!C39, " ") | O39: =IF(Jhoira!D41="Não",Jhoira!C41, " ") | S39: =IF(Fractius!D38="Não",Fractius!C38, " ") | W39: =IF(Muzzio!D52="Não",Muzzio!C52, " ")
C40: =IF(Thrakiri!D42="Não",Thrakiri!C42, " ") | G40: =IF(Gitrog!D39="Não",Gitrog!C39, " ") | K40: =IF(Elfos!D40="Não",Elfos!C40, " ") | O40: =IF(Jhoira!D43="Não",Jhoira!C43, " ") | S40: =IF(Fractius!D39="Não",Fractius!C39, " ") | W40: =IF(Muzzio!D38="Não",Muzzio!C38, " ")
C41: =IF(Thrakiri!D43="Não",Thrakiri!C43, " ") | G41: =IF(Gitrog!D40="Não",Gitrog!C40, " ") | K41: =IF(Elfos!D41="Não",Elfos!C41, " ") | O41: =IF(Jhoira!D42="Não",Jhoira!C42, " ") -> Ulamog, o Profanador | S41: =IF(Fractius!D40="Não",Fractius!C40, " ") | W41: =IF(Muzzio!D34="Não",Muzzio!C34, " ")
...

Sheet RESUMO2
A1: Rielle | E1: Alela | I1: Arcades | M1: Vial Ishai | Q1: Yuriko | U1: Zedruu
A3: Total | B3: {=_xlfn._xlws.SORT(C3:C101,1,-1,0)} -> Sokenzan, Crisol da Afronta | C3: =IF(Rielle!D3="Não",Rielle!C3, " ") | E3: Total | F3: {=_xlfn._xlws.SORT(G3:G101,1,-1,0)} -> Westvale Abbey | G3: =IF(Alela!D3="Não",Alela!C3, " ") | I3: Total | J3: {=_xlfn._xlws.SORT(K3:K101,1,-1,0)} -> Teyo, Geometric Tactician | K3: =IF(Arcades!D3="Não",Arcades!C3, " ") | M3: Total | N3: {=_xlfn._xlws.SORT(O3:O101,1,-1,0)} -> Watery Grave | O3: =IF(VialIshai!D3="Não",VialIshai!C3, " ") | Q3: Total | R3: {=_xlfn._xlws.SORT(S3:S101,1,-1,0)} -> Watery Grave | S3: =IF(Yuriko!D3="Não",Yuriko!C3, " ") | U3: Total | V3: {=_xlfn._xlws.SORT(W3:W101,1,-1,0)} -> Reliquary Tower | W3: =IF(Zedruu!D3="Não",Zedruu!C3, " ") -> Homeward Path
A4: =Rielle!G3 -> 7 | B4: Serenata das Estriges | C4: =IF(Rielle!D3="Não",Rielle!C4, " ") | E4: =Alela!G3 -> 5 | F4: Renewed Solidarity | G4: =IF(Alela!D3="Não",Alela!C4, " ") | I4: =Arcades!G3 -> 2 | J4: Alchemist's Refuge | K4: =IF(Arcades!D3="Não",Arcades!C4, " ") | M4: =VialIshai!G3 -> 11 | N4: Vontade Dominadora | O4: =IF(VialIshai!D3="Não",VialIshai!C4, " ") | Q4: =Yuriko!G3 -> 14 | R4: Valfenda | S4: =IF(Yuriko!D3="Não",Yuriko!C4, " ") | U4: =Zedruu!G3 -> 3 | V4: Homeward Path | W4: =IF(Zedruu!D3="Não",Zedruu!C4, " ") -> Reliquary Tower
B5: Ojer Pakpatiq, Era Profunda | C5: =IF(Rielle!D5="Não",Rielle!C5, " ") | F5: Olho de Ojer Taq | G5: =IF(Alela!D5="Não",Alela!C5, " ") | K5: =IF(Arcades!D5="Não",Arcades!C5, " ") | N5: Spectator Seating | O5: =IF(VialIshai!D5="Não",VialIshai!C5, " ") | R5: Temporal Trespass | S5: =IF(Yuriko!D5="Não",Yuriko!C5, " ") -> Shizo, Death's Storehouse | V5: Emergency Eject | W5: =IF(Zedruu!D5="Não",Zedruu!C5, " ")
B6: Collector's Vault | C6: =IF(Rielle!D6="Não",Rielle!C6, " ") | F6: Lagoa Espelhada | G6: =IF(Alela!D6="Não",Alela!C6, " ") | K6: =IF(Arcades!D6="Não",Arcades!C6, " ") | N6: Prismatic Strands | O6: =IF(VialIshai!D6="Não",VialIshai!C6, " ") | R6: Temporal Manipulation | S6: =IF(Yuriko!D6="Não",Yuriko!C6, " ") -> Sea Gate Restoration | V6: Árbitro Silencioso | W6: =IF(Zedruu!D6="Não",Zedruu!C6, " ")
B7: Careful Study | C7: =IF(Rielle!D7="Não",Rielle!C7, " ") | F7: Adagia, Windswept Bastion | G7: =IF(Alela!D7="Não",Alela!C7, " ") | K7: =IF(Arcades!D7="Não",Arcades!C7, " ") | N7: Polluted Delta | O7: =IF(VialIshai!D7="Não",VialIshai!C7, " ") | R7: Shizo, Death's Storehouse | S7: =IF(Yuriko!D7="Não",Yuriko!C7, " ") | W7: =IF(Zedruu!D7="Não",Zedruu!C7, " ")
B8: Baral, Chief of Compliance | C8: =IF(Rielle!D8="Não",Rielle!C8, " ") | G8: =IF(Alela!D8="Não",Alela!C8, " ") | K8: =IF(Arcades!D8="Não",Arcades!C8, " ") | N8: Mandate of Peace | O8: =IF(VialIshai!D8="Não",VialIshai!C8, " ") | R8: Sea Gate Restoration | S8: =IF(Yuriko!D8="Não",Yuriko!C8, " ") -> Morphic Pool | W8: =IF(Zedruu!D8="Não",Zedruu!C8, " ")
B9: Afundar em Estupor | C9: =IF(Rielle!D9="Não",Rielle!C9, " ") | G9: =IF(Alela!D9="Não",Alela!C9, " ") | K9: =IF(Arcades!D9="Não",Arcades!C9, " ") | N9: Luxury Suite | O9: =IF(VialIshai!D9="Não",VialIshai!C9, " ") | R9: Satoru, the Infiltrator | S9: =IF(Yuriko!D9="Não",Yuriko!C9, " ") | W9: =IF(Zedruu!D9="Não",Zedruu!C9, " ")
C10: =IF(Rielle!D10="Não",Rielle!C10, " ") | G10: =IF(Alela!D10="Não",Alela!C10, " ") | K10: =IF(Arcades!D10="Não",Arcades!C10, " ") | N10: Chronomantic Escape | O10: =IF(VialIshai!D10="Não",VialIshai!C10, " ") | R10: Mystic Reflection | S10: =IF(Yuriko!D10="Não",Yuriko!C10, " ") | W10: =IF(Zedruu!D10="Não",Zedruu!C10, " ")
C11: =IF(Rielle!D11="Não",Rielle!C11, " ") | G11: =IF(Alela!D11="Não",Alela!C11, " ") | K11: =IF(Arcades!D11="Não",Arcades!C11, " ") | N11: Batwing Brume | O11: =IF(VialIshai!D11="Não",VialIshai!C11, " ") | R11: Morphic Pool | S11: =IF(Yuriko!D11="Não",Yuriko!C11, " ") | W11: =IF(Zedruu!D11="Não",Zedruu!C11, " ")
C12: =IF(Rielle!D12="Não",Rielle!C12, " ") | G12: =IF(Alela!D12="Não",Alela!C12, " ") | K12: =IF(Arcades!D12="Não",Arcades!C12, " ") | N12: Arid Mesa | O12: =IF(VialIshai!D12="Não",VialIshai!C12, " ") -> Polluted Delta | R12: Louisoix's Sacrifice | S12: =IF(Yuriko!D12="Não",Yuriko!C12, " ") -> Creeping Tar Pit | W12: =IF(Zedruu!D12="Não",Zedruu!C12, " ")
C13: =IF(Rielle!D13="Não",Rielle!C13, " ") | G13: =IF(Alela!D13="Não",Alela!C13, " ") | K13: =IF(Arcades!D13="Não",Arcades!C13, " ") | N13: Amphibian Downpour | O13: =IF(VialIshai!D13="Não",VialIshai!C13, " ") | R13: Faerie Slumber Party | S13: =IF(Yuriko!D13="Não",Yuriko!C13, " ") | W13: =IF(Zedruu!D13="Não",Zedruu!C13, " ")
C14: =IF(Rielle!D14="Não",Rielle!C14, " ") | G14: =IF(Alela!D14="Não",Alela!C14, " ") | K14: =IF(Arcades!D14="Não",Arcades!C14, " ") | O14: =IF(VialIshai!D14="Não",VialIshai!C14, " ") | R14: Drowned Catacomb | S14: =IF(Yuriko!D14="Não",Yuriko!C14, " ") | W14: =IF(Zedruu!D14="Não",Zedruu!C14, " ")
C15: =IF(Rielle!D15="Não",Rielle!C15, " ") | G15: =IF(Alela!D15="Não",Alela!C15, " ") | K15: =IF(Arcades!D15="Não",Arcades!C15, " ") | O15: =IF(VialIshai!D15="Não",VialIshai!C15, " ") | R15: Dour Port-Mage | S15: =IF(Yuriko!D15="Não",Yuriko!C15, " ") | W15: =IF(Zedruu!D15="Não",Zedruu!C15, " ")
C16: =IF(Rielle!D16="Não",Rielle!C16, " ") -> Sokenzan, Crisol da Afronta | G16: =IF(Alela!D16="Não",Alela!C16, " ") | K16: =IF(Arcades!D16="Não",Arcades!C16, " ") | O16: =IF(VialIshai!D16="Não",VialIshai!C16, " ") | R16: Creeping Tar Pit | S16: =IF(Yuriko!D16="Não",Yuriko!C16, " ") | W16: =IF(Zedruu!D16="Não",Zedruu!C16, " ")
C17: =IF(Rielle!D17="Não",Rielle!C17, " ") | G17: =IF(Alela!D17="Não",Alela!C17, " ") | K17: =IF(Arcades!D17="Não",Arcades!C17, " ") | O17: =IF(VialIshai!D17="Não",VialIshai!C17, " ") | S17: =IF(Yuriko!D17="Não",Yuriko!C17, " ") | W17: =IF(Zedruu!D17="Não",Zedruu!C17, " ")
C18: =IF(Rielle!D18="Não",Rielle!C18, " ") -> Afundar em Estupor | G18: =IF(Alela!D18="Não",Alela!C18, " ") -> Westvale Abbey | K18: =IF(Arcades!D18="Não",Arcades!C18, " ") | O18: =IF(VialIshai!D18="Não",VialIshai!C18, " ") | S18: =IF(Yuriko!D18="Não",Yuriko!C18, " ") -> Watery Grave | W18: =IF(Zedruu!D18="Não",Zedruu!C18, " ")
C19: =IF(Rielle!D19="Não",Rielle!C19, " ") | G19: =IF(Alela!D19="Não",Alela!C19, " ") | K19: =IF(Arcades!D19="Não",Arcades!C19, " ") | O19: =IF(VialIshai!D19="Não",VialIshai!C19, " ") -> Arid Mesa | S19: =IF(Yuriko!D19="Não",Yuriko!C19, " ") -> Drowned Catacomb | W19: =IF(Zedruu!D19="Não",Zedruu!C19, " ")
C20: =IF(Rielle!D20="Não",Rielle!C20, " ") | G20: =IF(Alela!D20="Não",Alela!C20, " ") | K20: =IF(Arcades!D20="Não",Arcades!C20, " ") | O20: =IF(VialIshai!D20="Não",VialIshai!C20, " ") | S20: =IF(Yuriko!D20="Não",Yuriko!C20, " ") -> Valfenda | W20: =IF(Zedruu!D20="Não",Zedruu!C20, " ")
C21: =IF(Rielle!D21="Não",Rielle!C21, " ") | G21: =IF(Alela!D21="Não",Alela!C21, " ") | K21: =IF(Arcades!D21="Não",Arcades!C21, " ") | O21: =IF(VialIshai!D21="Não",VialIshai!C21, " ") | S21: =IF(Yuriko!D21="Não",Yuriko!C21, " ") | W21: =IF(Zedruu!D21="Não",Zedruu!C21, " ")
C22: =IF(Rielle!D22="Não",Rielle!C22, " ") | G22: =IF(Alela!D35="Não",Alela!C35, " ") | K22: =IF(Arcades!D22="Não",Arcades!C22, " ") -> Alchemist's Refuge | O22: =IF(VialIshai!D22="Não",VialIshai!C22, " ") -> Watery Grave | S22: =IF(Yuriko!D22="Não",Yuriko!C22, " ") | W22: =IF(Zedruu!D22="Não",Zedruu!C22, " ")
C23: =IF(Rielle!D23="Não",Rielle!C23, " ") | G23: =IF(Alela!D22="Não",Alela!C22, " ") | K23: =IF(Arcades!D23="Não",Arcades!C23, " ") | O23: =IF(VialIshai!D23="Não",VialIshai!C23, " ") | S23: =IF(Yuriko!D23="Não",Yuriko!C23, " ") | W23: =IF(Zedruu!D23="Não",Zedruu!C23, " ")
C24: =IF(Rielle!D24="Não",Rielle!C24, " ") | G24: =IF(Alela!D23="Não",Alela!C23, " ") -> Lagoa Espelhada | K24: =IF(Arcades!D24="Não",Arcades!C24, " ") | O24: =IF(VialIshai!D24="Não",VialIshai!C24, " ") | S24: =IF(Yuriko!D24="Não",Yuriko!C24, " ") | W24: =IF(Zedruu!D24="Não",Zedruu!C24, " ")
C25: =IF(Rielle!D25="Não",Rielle!C25, " ") | G25: =IF(Alela!D24="Não",Alela!C24, " ") -> Adagia, Windswept Bastion | K25: =IF(Arcades!D25="Não",Arcades!C25, " ") | O25: =IF(VialIshai!D25="Não",VialIshai!C25, " ") | S25: =IF(Yuriko!D25="Não",Yuriko!C25, " ") | W25: =IF(Zedruu!D25="Não",Zedruu!C25, " ")
C26: =IF(Rielle!D26="Não",Rielle!C26, " ") | G26: =IF(Alela!D25="Não",Alela!C25, " ") | K26: =IF(Arcades!D26="Não",Arcades!C26, " ") | O26: =IF(VialIshai!D26="Não",VialIshai!C26, " ") | S26: =IF(Yuriko!D26="Não",Yuriko!C26, " ") | W26: =IF(Zedruu!D26="Não",Zedruu!C26, " ")
C27: =IF(Rielle!D27="Não",Rielle!C27, " ") | G27: =IF(Alela!D28="Não",Alela!C28, " ") | K27: =IF(Arcades!D27="Não",Arcades!C27, " ") | O27: =IF(VialIshai!D27="Não",VialIshai!C27, " ") | S27: =IF(Yuriko!D27="Não",Yuriko!C27, " ") | W27: =IF(Zedruu!D27="Não",Zedruu!C27, " ")
C28: =IF(Rielle!D28="Não",Rielle!C28, " ") | G28: =IF(Alela!D29="Não",Alela!C29, " ") | K28: =IF(Arcades!D28="Não",Arcades!C28, " ") | O28: =IF(VialIshai!D28="Não",VialIshai!C28, " ") | S28: =IF(Yuriko!D28="Não",Yuriko!C28, " ") | W28: =IF(Zedruu!D28="Não",Zedruu!C28, " ")
C29: =IF(Rielle!D29="Não",Rielle!C29, " ") | G29: =IF(Alela!D30="Não",Alela!C30, " ") | K29: =IF(Arcades!D29="Não",Arcades!C29, " ") | O29: =IF(VialIshai!D29="Não",VialIshai!C29, " ") | S29: =IF(Yuriko!D29="Não",Yuriko!C29, " ") | W29: =IF(Zedruu!D29="Não",Zedruu!C29, " ")
C30: =IF(Rielle!D30="Não",Rielle!C30, " ") | G30: =IF(Alela!D27="Não",Alela!C27, " ") | K30: =IF(Arcades!D30="Não",Arcades!C30, " ") | O30: =IF(VialIshai!D30="Não",VialIshai!C30, " ") | S30: =IF(Yuriko!D30="Não",Yuriko!C30, " ") | W30: =IF(Zedruu!D30="Não",Zedruu!C30, " ")
C31: =IF(Rielle!D31="Não",Rielle!C31, " ") | G31: =IF(Alela!D31="Não",Alela!C31, " ") | K31: =IF(Arcades!D31="Não",Arcades!C31, " ") | O31: =IF(VialIshai!D31="Não",VialIshai!C31, " ") | S31: =IF(Yuriko!D31="Não",Yuriko!C31, " ") | W31: =IF(Zedruu!D31="Não",Zedruu!C31, " ")
C32: =IF(Rielle!D32="Não",Rielle!C32, " ") | G32: =IF(Alela!D32="Não",Alela!C32, " ") | K32: =IF(Arcades!D32="Não",Arcades!C32, " ") | O32: =IF(VialIshai!D34="Não",VialIshai!C34, " ") | S32: =IF(Yuriko!D32="Não",Yuriko!C32, " ") | W32: =IF(Zedruu!D32="Não",Zedruu!C32, " ")
C33: =IF(Rielle!D33="Não",Rielle!C33, " ") | G33: =IF(Alela!D34="Não",Alela!C34, " ") | K33: =IF(Arcades!D33="Não",Arcades!C33, " ") | O33: =IF(VialIshai!D35="Não",VialIshai!C35, " ") | S33: =IF(Yuriko!D33="Não",Yuriko!C33, " ") | W33: =IF(Zedruu!D33="Não",Zedruu!C33, " ")
C34: =IF(Rielle!D34="Não",Rielle!C34, " ") | G34: =IF(Alela!D26="Não",Alela!C26, " ") | K34: =IF(Arcades!D34="Não",Arcades!C34, " ") | O34: =IF(VialIshai!D36="Não",VialIshai!C36, " ") | S34: =IF(Yuriko!D34="Não",Yuriko!C34, " ") | W34: =IF(Zedruu!D34="Não",Zedruu!C34, " ")
C35: =IF(Rielle!D35="Não",Rielle!C35, " ") | G35: =IF(Alela!D36="Não",Alela!C36, " ") | K35: =IF(Arcades!D35="Não",Arcades!C35, " ") | O35: =IF(VialIshai!D37="Não",VialIshai!C37, " ") | S35: =IF(Yuriko!D35="Não",Yuriko!C35, " ") | W35: =IF(Zedruu!D35="Não",Zedruu!C35, " ")
C36: =IF(Rielle!D36="Não",Rielle!C36, " ") | G36: =IF(Alela!D37="Não",Alela!C37, " ") | K36: =IF(Arcades!D36="Não",Arcades!C36, " ") | O36: =IF(VialIshai!D38="Não",VialIshai!C38, " ") | S36: =IF(Yuriko!D36="Não",Yuriko!C36, " ") | W36: =IF(Zedruu!D36="Não",Zedruu!C36, " ")
C37: =IF(Rielle!D89="Não",Rielle!C89, " ") -> Baral, Chief of Compliance | G37: =IF(Alela!D38="Não",Alela!C38, " ") | K37: =IF(Arcades!D88="Não",Arcades!C88, " ") | O37: =IF(VialIshai!D39="Não",VialIshai!C39, " ") | S37: =IF(Yuriko!D37="Não",Yuriko!C37, " ") -> Satoru, the Infiltrator | W37: =IF(Zedruu!D37="Não",Zedruu!C37, " ")
C38: =IF(Rielle!D38="Não",Rielle!C38, " ") | G38: =IF(Alela!D39="Não",Alela!C39, " ") | K38: =IF(Arcades!D37="Não",Arcades!C37, " ") | O38: =IF(VialIshai!D40="Não",VialIshai!C40, " ") | S38: =IF(Yuriko!D38="Não",Yuriko!C38, " ") | W38: =IF(Zedruu!D38="Não",Zedruu!C38, " ")
C39: =IF(Rielle!D94="Não",Rielle!C94, " ") | G39: =IF(Alela!D40="Não",Alela!C40, " ") | K39: =IF(Arcades!D38="Não",Arcades!C38, " ") | O39: =IF(VialIshai!D41="Não",VialIshai!C41, " ") | S39: =IF(Yuriko!D39="Não",Yuriko!C39, " ") | W39: =IF(Zedruu!D39="Não",Zedruu!C39, " ")
C40: =IF(Rielle!D39="Não",Rielle!C39, " ") | G40: =IF(Alela!D41="Não",Alela!C41, " ") | K40: =IF(Arcades!D39="Não",Arcades!C39, " ") | O40: =IF(VialIshai!D42="Não",VialIshai!C42, " ") | S40: =IF(Yuriko!D40="Não",Yuriko!C40, " ") | W40: =IF(Zedruu!D40="Não",Zedruu!C40, " ")
C41: =IF(Rielle!D40="Não",Rielle!C40, " ") | G41: =IF(Alela!D42="Não",Alela!C42, " ") | K41: =IF(Arcades!D40="Não",Arcades!C40, " ") | O41: =IF(VialIshai!D43="Não",VialIshai!C43, " ") | S41: =IF(Yuriko!D42="Não",Yuriko!C42, " ") | W41: =IF(Zedruu!D41="Não",Zedruu!C41, " ")
...

Sheet RESUMO3
A1: Inalla | E1: Carlos | I1: Oona | M1: Kresh | Q1: Akiri | U1: Breya
A3: Total | B3: {=_xlfn._xlws.SORT(C3:C101,1,-1,0)} -> Saw in Half | C3: =IF(Inalla!D3="Não",Inalla!C3, "") | E3: Total | F3: {=_xlfn._xlws.SORT(G3:G101,1,-1,0)} -> Vault of the Archangel | G3: =IF(Carlos!D3="Não",Carlos!C3, " ") | I3: Total | J3: {=_xlfn._xlws.SORT(K3:K101,1,-1,0)} -> Unstoppable Plan | K3: =IF(Oona!D3="Não",Oona!C3, " ") -> Jidoor, Aristocratic Capital // Overture | M3: Total | N3: {=_xlfn._xlws.SORT(O3:O101,1,-1,0)} -> The Masamune | O3: =IF(Kresh!D3="Não",Kresh!C3, " ") | Q3: Total | R3: {=_xlfn._xlws.SORT(S3:S101,1,-1,0)} -> Stoneforge Mystic | S3: =IF(Akiri!D3="Não",Akiri!C3, " ") | U3: Total | V3: {=_xlfn._xlws.SORT(W3:W101,1,-1,0)} -> Weapons Manufacturing | W3: =IF(Breya!D3="Não",Breya!C3, " ")
A4: =Inalla!G3 -> 13 | B4: Reliquary Tower | C4: =IF(Inalla!D3="Não",Inalla!C3, "") | E4: =Carlos!G3 -> 17 | F4: Unholy Annex // Ritual Chamber | G4: =IF(Carlos!D3="Não",Carlos!C4, " ") | I4: =Oona!G3 -> 9 | J4: Três Passos à Frente | K4: =IF(Oona!D3="Não",Oona!C4, " ") -> Santuário Místico | M4: =Kresh!G3 -> 9 | N4: Saqueador Amaldiçoado | O4: =IF(Kresh!D3="Não",Kresh!C4, " ") | Q4: =Akiri!G3 -> 12 | R4: Lightning Greaves | S4: =IF(Akiri!D3="Não",Akiri!C4, " ") | U4: =Breya!G3 -> 6 | V4: The Mycosynth Gardens | W4: =IF(Breya!D3="Não",Breya!C4, " ")
B5: Negociador de Almas do Viveiro | C5: =IF(Inalla!D5="Não",Inalla!C5, "") | F5: Terramorphic Expanse | G5: =IF(Carlos!D5="Não",Carlos!C5, " ") | J5: The Eternity Elevator | K5: =IF(Oona!D5="Não",Oona!C5, " ") | N5: Red XIII, Proud Warrior | O5: =IF(Kresh!D5="Não",Kresh!C5, " ") | R5: Kellan, the Fae-Blooded // Birthright Boon | S5: =IF(Akiri!D5="Não",Akiri!C5, " ") | V5: Reflecting Pool | W5: =IF(Breya!D5="Não",Breya!C5, " ")
B6: Molten Echoes | C6: =IF(Inalla!D6="Não",Inalla!C6, "") | F6: Takenuma, Charco Abandonado | G6: =IF(Carlos!D6="Não",Carlos!C6, " ") -> Terramorphic Expanse | J6: Sonic Screwdriver | K6: =IF(Oona!D6="Não",Oona!C6, " ") | N6: Pain for All | O6: =IF(Kresh!D6="Não",Kresh!C6, " ") | R6: Jitte Perdida | S6: =IF(Akiri!D6="Não",Akiri!C6, " ") | V6: Long-Range Sensor | W6: =IF(Breya!D6="Não",Breya!C6, " ")
B7: Mistbind Clique | C7: =IF(Inalla!D7="Não",Inalla!C7, "") | F7: Sorin da Casa Markov | G7: =IF(Carlos!D7="Não",Carlos!C7, " ") | J7: Season of Weaving | K7: =IF(Oona!D7="Não",Oona!C7, " ") | N7: Nibelheim Aflame | O7: =IF(Kresh!D7="Não",Kresh!C7, " ") | R7: Firion, Wild Rose Warrior | S7: =IF(Akiri!D7="Não",Akiri!C7, " ") | V7: Daretti, Ingenious Iconoclast | W7: =IF(Breya!D7="Não",Breya!C7, " ")
B8: Merchant of Secrets | C8: =IF(Inalla!D8="Não",Inalla!C8, "") | F8: Mother of runes | G8: =IF(Carlos!D8="Não",Carlos!C8, " ") -> Bojuka Bog | J8: Scour for Scrap | K8: =IF(Oona!D8="Não",Oona!C8, " ") | N8: Jenova, Ancient Calamity | O8: =IF(Kresh!D8="Não",Kresh!C8, " ") | R8: Espada de Verdade e Justiça | S8: =IF(Akiri!D8="Não",Akiri!C8, " ") | V8: Adagia, Windswept Bastion | W8: =IF(Breya!D8="Não",Breya!C8, " ")
B9: Glasspool Mimic | C9: =IF(Inalla!D9="Não",Inalla!C9, "") | F9: Keen Duelist | G9: =IF(Carlos!D9="Não",Carlos!C9, " ") | J9: Santuário Místico | K9: =IF(Oona!D9="Não",Oona!C9, " ") | N9: High-Society Hunter | O9: =IF(Kresh!D9="Não",Kresh!C9, " ") | R9: Espada de Luz e Sombra | S9: =IF(Akiri!D9="Não",Akiri!C9, " ") | W9: =IF(Breya!D9="Não",Breya!C9, " ") -> The Mycosynth Gardens
B10: Dour Port-Mage | C10: =IF(Inalla!D10="Não",Inalla!C10, "") -> Reliquary Tower | F10: Hierofante de Elenda | G10: =IF(Carlos!D10="Não",Carlos!C10, " ") | J10: Moonlit Meditation | K10: =IF(Oona!D10="Não",Oona!C10, " ") | N10: Chandra's Ignition | O10: =IF(Kresh!D10="Não",Kresh!C10, " ") | R10: Espada de Fogo e Gelo | S10: =IF(Akiri!D10="Não",Akiri!C10, " ") | W10: =IF(Breya!D10="Não",Breya!C10, " ")
B11: Diário de Tarrian | C11: =IF(Inalla!D11="Não",Inalla!C11, "") | F11: Haliya, Guided by Light | G11: =IF(Carlos!D11="Não",Carlos!C11, " ") | J11: Jidoor, Aristocratic Capital // Overture | K11: =IF(Oona!D11="Não",Oona!C11, " ") | N11: Bugenhagen, Wise Elder | O11: =IF(Kresh!D11="Não",Kresh!C11, " ") | R11: Espada de Banquete e Fome | S11: =IF(Akiri!D11="Não",Akiri!C11, " ") | W11: =IF(Breya!D11="Não",Breya!C11, " ") -> Reflecting Pool
B12: Burnt Offering | C12: =IF(Inalla!D12="Não",Inalla!C12, "") | F12: Guia das Almas | G12: =IF(Carlos!D12="Não",Carlos!C12, " ") | J12: Invasion of Segovia | K12: =IF(Oona!D12="Não",Oona!C12, " ") | O12: =IF(Kresh!D12="Não",Kresh!C12, " ") | R12: Espada da Riqueza e do Poder | S12: =IF(Akiri!D12="Não",Akiri!C12, " ") | W12: =IF(Breya!D12="Não",Breya!C12, " ")
B13: Bojuka Bog | C13: =IF(Inalla!D13="Não",Inalla!C13, "") | F13: Giver of Runes | G13: =IF(Carlos!D13="Não",Carlos!C13, " ") -> Vault of the Archangel | K13: =IF(Oona!D13="Não",Oona!C13, " ") | O13: =IF(Kresh!D13="Não",Kresh!C13, " ") | R13: Cloud, Midgar Mercenary | S13: =IF(Akiri!D13="Não",Akiri!C13, " ") | W13: =IF(Breya!D13="Não",Breya!C13, " ")
B14: Arcane Signet | C14: =IF(Inalla!D14="Não",Inalla!C14, "") | F14: Exemplar of Light | G14: =IF(Carlos!D14="Não",Carlos!C14, " ") | K14: =IF(Oona!D14="Não",Oona!C14, " ") | O14: =IF(Kresh!D14="Não",Kresh!C14, " ") | R14: Cid, Freeflier Pilot | S14: =IF(Akiri!D14="Não",Akiri!C14, " ") | W14: =IF(Breya!D14="Não",Breya!C14, " ")
B15: Arcane Lighthouse | C15: =IF(Inalla!D15="Não",Inalla!C15, "") | F15: Evolving Wilds | G15: =IF(Carlos!D15="Não",Carlos!C15, " ") | K15: =IF(Oona!D15="Não",Oona!C15, " ") | O15: =IF(Kresh!D15="Não",Kresh!C15, " ") | S15: =IF(Akiri!D15="Não",Akiri!C15, " ") | W15: =IF(Breya!D15="Não",Breya!C15, " ")
C16: =IF(Inalla!D16="Não",Inalla!C16, "") | F16: Enduring Innocence | G16: =IF(Carlos!D16="Não",Carlos!C16, " ") | K16: =IF(Oona!D16="Não",Oona!C16, " ") | O16: =IF(Kresh!D16="Não",Kresh!C16, " ") | S16: =IF(Akiri!D16="Não",Akiri!C16, " ") | W16: =IF(Breya!D16="Não",Breya!C16, " ")
C17: =IF(Inalla!D17="Não",Inalla!C17, "") | F17: Bojuka Bog | G17: =IF(Carlos!D17="Não",Carlos!C17, " ") -> Takenuma, Charco Abandonado | K17: =IF(Oona!D17="Não",Oona!C17, " ") | O17: =IF(Kresh!D17="Não",Kresh!C17, " ") | S17: =IF(Akiri!D17="Não",Akiri!C17, " ") | W17: =IF(Breya!D17="Não",Breya!C17, " ")
C18: =IF(Inalla!D18="Não",Inalla!C18, "") | F18: Autoridade dos Cônsules | G18: =IF(Carlos!D18="Não",Carlos!C18, " ") | K18: =IF(Oona!D18="Não",Oona!C18, " ") | O18: =IF(Kresh!D18="Não",Kresh!C18, " ") | S18: =IF(Akiri!D18="Não",Akiri!C18, " ") | W18: =IF(Breya!D30="Não",Breya!C30, " ")
C19: =IF(Inalla!D19="Não",Inalla!C19, "") -> Bojuka Bog | F19: Ascensão do Avernus | G19: =IF(Carlos!D19="Não",Carlos!C19, " ") | K19: =IF(Oona!D19="Não",Oona!C19, " ") | O19: =IF(Kresh!D19="Não",Kresh!C19, " ") | S19: =IF(Akiri!D19="Não",Akiri!C19, " ") | W19: =IF(Breya!D19="Não",Breya!C19, " ")
C20: =IF(Inalla!D20="Não",Inalla!C20, "") -> Arcane Lighthouse | G20: =IF(Carlos!D20="Não",Carlos!C20, " ") | K20: =IF(Oona!D20="Não",Oona!C20, " ") | O20: =IF(Kresh!D20="Não",Kresh!C20, " ") | S20: =IF(Akiri!D20="Não",Akiri!C20, " ") | W20: =IF(Breya!D20="Não",Breya!C20, " ")
C21: =IF(Inalla!D21="Não",Inalla!C21, "") | G21: =IF(Carlos!D21="Não",Carlos!C21, " ") | K21: =IF(Oona!D21="Não",Oona!C21, " ") | O21: =IF(Kresh!D21="Não",Kresh!C21, " ") | S21: =IF(Akiri!D21="Não",Akiri!C21, " ") | W21: =IF(Breya!D22="Não",Breya!C22, " ")
C22: =IF(Inalla!D22="Não",Inalla!C22, "") | G22: =IF(Carlos!D22="Não",Carlos!C22, " ") | K22: =IF(Oona!D22="Não",Oona!C22, " ") | O22: =IF(Kresh!D22="Não",Kresh!C22, " ") | S22: =IF(Akiri!D22="Não",Akiri!C22, " ") | W22: =IF(Breya!D24="Não",Breya!C24, " ")
C23: =IF(Inalla!D23="Não",Inalla!C23, "") -> Glasspool Mimic | G23: =IF(Carlos!D23="Não",Carlos!C23, " ") | K23: =IF(Oona!D23="Não",Oona!C23, " ") | O23: =IF(Kresh!D23="Não",Kresh!C23, " ") | S23: =IF(Akiri!D23="Não",Akiri!C23, " ") | W23: =IF(Breya!D23="Não",Breya!C23, " ")
C24: =IF(Inalla!D24="Não",Inalla!C24, "") | G24: =IF(Carlos!D24="Não",Carlos!C24, " ") | K24: =IF(Oona!D24="Não",Oona!C24, " ") | O24: =IF(Kresh!D24="Não",Kresh!C24, " ") | S24: =IF(Akiri!D24="Não",Akiri!C24, " ") | W24: =IF(Breya!D31="Não",Breya!C31, " ") -> Adagia, Windswept Bastion
C25: =IF(Inalla!D25="Não",Inalla!C25, "") | G25: =IF(Carlos!D25="Não",Carlos!C25, " ") -> Evolving Wilds | K25: =IF(Oona!D25="Não",Oona!C25, " ") | O25: =IF(Kresh!D25="Não",Kresh!C25, " ") | S25: =IF(Akiri!D25="Não",Akiri!C25, " ") | W25: =IF(Breya!D32="Não",Breya!C32, " ")
C26: =IF(Inalla!D26="Não",Inalla!C26, "") | G26: =IF(Carlos!D26="Não",Carlos!C26, " ") | K26: =IF(Oona!D26="Não",Oona!C26, " ") | O26: =IF(Kresh!D26="Não",Kresh!C26, " ") | S26: =IF(Akiri!D26="Não",Akiri!C26, " ") | W26: =IF(Breya!D33="Não",Breya!C33, " ")
C27: =IF(Inalla!D27="Não",Inalla!C27, "") | G27: =IF(Carlos!D27="Não",Carlos!C27, " ") | K27: =IF(Oona!D27="Não",Oona!C27, " ") | O27: =IF(Kresh!D27="Não",Kresh!C27, " ") | S27: =IF(Akiri!D27="Não",Akiri!C27, " ") | W27: =IF(Breya!D25="Não",Breya!C25, " ")
C28: =IF(Inalla!D28="Não",Inalla!C28, "") | G28: =IF(Carlos!D28="Não",Carlos!C28, " ") | K28: =IF(Oona!D28="Não",Oona!C28, " ") | O28: =IF(Kresh!D28="Não",Kresh!C28, " ") | S28: =IF(Akiri!D28="Não",Akiri!C28, " ") | W28: =IF(Breya!D29="Não",Breya!C29, " ")
C29: =IF(Inalla!D29="Não",Inalla!C29, "") | G29: =IF(Carlos!D29="Não",Carlos!C29, " ") | K29: =IF(Oona!D29="Não",Oona!C29, " ") | O29: =IF(Kresh!D29="Não",Kresh!C29, " ") | S29: =IF(Akiri!D29="Não",Akiri!C29, " ") | W29: =IF(Breya!D34="Não",Breya!C34, " ")
C30: =IF(Inalla!D30="Não",Inalla!C30, "") | G30: =IF(Carlos!D30="Não",Carlos!C30, " ") | K30: =IF(Oona!D30="Não",Oona!C30, " ") | O30: =IF(Kresh!D30="Não",Kresh!C30, " ") | S30: =IF(Akiri!D30="Não",Akiri!C30, " ") | W30: =IF(Breya!D35="Não",Breya!C35, " ")
C31: =IF(Inalla!D31="Não",Inalla!C31, "") | G31: =IF(Carlos!D31="Não",Carlos!C31, " ") | K31: =IF(Oona!D31="Não",Oona!C31, " ") | O31: =IF(Kresh!D31="Não",Kresh!C31, " ") | S31: =IF(Akiri!D31="Não",Akiri!C31, " ") | W31: =IF(Breya!D21="Não",Breya!C21, " ")
C32: =IF(Inalla!D32="Não",Inalla!C32, "") | G32: =IF(Carlos!D32="Não",Carlos!C32, " ") | K32: =IF(Oona!D32="Não",Oona!C32, " ") | O32: =IF(Kresh!D32="Não",Kresh!C32, " ") | S32: =IF(Akiri!D32="Não",Akiri!C32, " ") | W32: =IF(Breya!D26="Não",Breya!C26, " ")
C33: =IF(Inalla!D33="Não",Inalla!C33, "") | G33: =IF(Carlos!D33="Não",Carlos!C33, " ") | K33: =IF(Oona!D33="Não",Oona!C33, " ") | O33: =IF(Kresh!D33="Não",Kresh!C33, " ") | S33: =IF(Akiri!D33="Não",Akiri!C33, " ") | W33: =IF(Breya!D28="Não",Breya!C28, " ")
C34: =IF(Inalla!D34="Não",Inalla!C34, "") | G34: =IF(Carlos!D34="Não",Carlos!C34, " ") | K34: =IF(Oona!D34="Não",Oona!C34, " ") | O34: =IF(Kresh!D34="Não",Kresh!C34, " ") | S34: =IF(Akiri!D34="Não",Akiri!C34, " ") | W34: =IF(Breya!D36="Não",Breya!C36, " ")
C35: =IF(Inalla!D35="Não",Inalla!C35, "") | G35: =IF(Carlos!D35="Não",Carlos!C35, " ") | K35: =IF(Oona!D35="Não",Oona!C35, " ") | O35: =IF(Kresh!D35="Não",Kresh!C35, " ") | S35: =IF(Akiri!D35="Não",Akiri!C35, " ") | W35: =IF(Breya!D27="Não",Breya!C27, " ")
C36: =IF(Inalla!D36="Não",Inalla!C36, "") | G36: =IF(Carlos!D36="Não",Carlos!C36, " ") | K36: =IF(Oona!D36="Não",Oona!C36, " ") | O36: =IF(Kresh!D36="Não",Kresh!C36, " ") | S36: =IF(Akiri!D36="Não",Akiri!C36, " ") | W36: =IF(Breya!D18="Não",Breya!C18, " ")
C37: =IF(Inalla!D37="Não",Inalla!C37, "") | G37: =IF(Carlos!D37="Não",Carlos!C37, " ") | K37: =IF(Oona!D49="Não",Oona!C49, " ") -> The Eternity Elevator | O37: =IF(Kresh!D37="Não",Kresh!C37, " ") | S37: =IF(Akiri!D37="Não",Akiri!C37, " ") | W37: =IF(Breya!D37="Não",Breya!C37, " ")
C38: =IF(Inalla!D46="Não",Inalla!C46, "") | G38: =IF(Carlos!D42="Não",Carlos!C42, " ") | K38: =IF(Oona!D38="Não",Oona!C38, " ") | O38: =IF(Kresh!D38="Não",Kresh!C38, " ") | S38: =IF(Akiri!D38="Não",Akiri!C38, " ") | W38: =IF(Breya!D38="Não",Breya!C38, " ")
C39: =IF(Inalla!D47="Não",Inalla!C47, "") | G39: =IF(Carlos!D43="Não",Carlos!C43, " ") | K39: =IF(Oona!D50="Não",Oona!C50, " ") | O39: =IF(Kresh!D39="Não",Kresh!C39, " ") | S39: =IF(Akiri!D39="Não",Akiri!C39, " ") | W39: =IF(Breya!D46="Não",Breya!C46, " ")
C40: =IF(Inalla!D74="Não",Inalla!C74, "") -> Mistbind Clique | G40: =IF(Carlos!D44="Não",Carlos!C44, " ") | K40: =IF(Oona!D39="Não",Oona!C39, " ") | O40: =IF(Kresh!D40="Não",Kresh!C40, " ") | S40: =IF(Akiri!D40="Não",Akiri!C40, " ") -> Cid, Freeflier Pilot | W40: =IF(Breya!D40="Não",Breya!C40, " ")
C41: =IF(Inalla!D56="Não",Inalla!C56, "") | G41: =IF(Carlos!D45="Não",Carlos!C45, " ") | K41: =IF(Oona!D40="Não",Oona!C40, " ") | O41: =IF(Kresh!D41="Não",Kresh!C41, " ") | S41: =IF(Akiri!D41="Não",Akiri!C41, " ") | W41: =IF(Breya!D41="Não",Breya!C41, " ")
...

Sheet RESUMO4
A1: Rani | E1: Sisay | I1: OWA | M1: Narset Mill | Q1: Kumena | U1: Zimone e Dina
A3: Total | B3: {=_xlfn._xlws.SORT(C3:C101,1,-1,0)} -> Xantcha, Agente Adormecida | C3: =IF(Rani!D3="Não",Rani!C3, "") -> Rogue's Passage | E3: Total | F3: {=_xlfn._xlws.SORT(G3:G101,1,-1,0)} -> Vronos, Masked Inquisitor | G3: =IF(Sisay!D3="Não",Sisay!C3, "") | I3: Total | J3: {=_xlfn._xlws.SORT(K3:K101,1,-1,0)} -> Warren Soultrader | K3: =IF(OWA!D3="Não",OWA!C3, "") | M3: Total | N3: {=_xlfn._xlws.SORT(O3:O101,1,-1,0)} -> Zellix, Sanity Flayer | O3: =IF(Narset!D3="Não",Narset!C3,"") | Q3: Total | R3: {=_xlfn._xlws.SORT(S3:S101,1,-1,0)} -> Vanquisher's Banner | S3: =IF(Kumena!D3="Não",Kumena!C3,"") -> Reliquary Tower | U3: Total | V3: {=_xlfn._xlws.SORT(W3:W101,1,-1,0)} -> Zagoth Triome | W3: =IF(Zimone!D3="Não",Zimone!C3,"")
A4: =Rani!G3 -> 20 | B4: Trenzalore Clocktower | C4: =IF(Rani!D3="Não",Rani!C3, "") -> Rogue's Passage | E4: =Sisay!G3 -> 11 | F4: Ripples of Potential | G4: =IF(Sisay!D3="Não",Sisay!C3, "") | I4: =OWA!G3 -> 7 | J4: Susur Secundi, Void Altar | K4: =IF(OWA!D3="Não",OWA!C3, "") | M4: =Narset!G3 -> 32 | N4: World at War | O4: =IF(Narset!D3="Não",Narset!C4,"") | Q4: =Kumena!G3 -> 26 | R4: Tishana, Voice of Thunder | S4: =IF(Kumena!D3="Não",Kumena!C4,"") -> Command Tower | U4: =Zimone!G3 -> 17 | V4: Three Visits | W4: =IF(Zimone!D3="Não",Zimone!C4,"")
B5: Thought Vessel | C5: =IF(Rani!D5="Não",Rani!C5, "") | F5: Oko, Thief of Crowns | G5: =IF(Sisay!D5="Não",Sisay!C5, "") | J5: Stridehangar Automaton | K5: =IF(OWA!D5="Não",OWA!C5, "") | N5: Windcrag Siege | O5: =IF(Narset!D5="Não",Narset!C5,"") | R5: Throne of the God-Pharaoh | S5: =IF(Kumena!D5="Não",Kumena!C5,"") | V5: Thousand-Year Elixir | W5: =IF(Zimone!D5="Não",Zimone!C5,"")
B6: Sulfur Falls | C6: =IF(Rani!D6="Não",Rani!C6, "") | F6: O Dínamo Peregrino | G6: =IF(Sisay!D6="Não",Sisay!C6, "") | J6: Scattered Groves | K6: =IF(OWA!D6="Não",OWA!C6, "") | N6: Training Center | O6: =IF(Narset!D6="Não",Narset!C6,"") | R6: Surgespanner | S6: =IF(Kumena!D6="Não",Kumena!C6,"") | V6: Teferi's Ageless Insight | W6: =IF(Zimone!D6="Não",Zimone!C6,"")
B7: Sol Ring | C7: =IF(Rani!D7="Não",Rani!C7, "") | F7: Nicol Bolas, God-Pharaoh | G7: =IF(Sisay!D7="Não",Sisay!C7, "") | J7: Promessa de Aclazotz | K7: =IF(OWA!D7="Não",OWA!C7, "") | N7: The Water Crystal | O7: =IF(Narset!D7="Não",Narset!C7,"") -> Sokenzan, Crucible of Defiance | R7: Summon: Leviathan | S7: =IF(Kumena!D7="Não",Kumena!C7,"") | V7: Sothera, the Supervoid | W7: =IF(Zimone!D7="Não",Zimone!C7,"")
B8: Rogue's Passage | C8: =IF(Rani!D8="Não",Rani!C8, "") -> Archway of Innovation | F8: Lolth, Rainha Aranha | G8: =IF(Sisay!D8="Não",Sisay!C8, "") | J8: Illustrious Wanderglyph | K8: =IF(OWA!D8="Não",OWA!C8, "") | N8: Subjugar a Horda | O8: =IF(Narset!D8="Não",Narset!C8,"") -> Slayers' Stronghold | R8: Stonybrook Banneret | S8: =IF(Kumena!D8="Não",Kumena!C8,"") | V8: Scalding Tarn | W8: =IF(Zimone!D8="Não",Zimone!C8,"")
B9: Rogue's Passage | C9: =IF(Rani!D9="Não",Rani!C9, "") -> Trenzalore Clocktower | F9: Kaya the Inexorable | G9: =IF(Sisay!D9="Não",Sisay!C9, "") | J9: Dollmaker's Shop // Porcelain Gallery | K9: =IF(OWA!D9="Não",OWA!C9, "") | N9: Spectator Seating | O9: =IF(Narset!D9="Não",Narset!C9,"") -> Sea of Clouds | R9: Sol Ring | S9: =IF(Kumena!D9="Não",Kumena!C9,"") | V9: Polluted Delta | W9: =IF(Zimone!D9="Não",Zimone!C9,"") -> Fabled Passage
B10: Reliquary Tower | C10: =IF(Rani!D10="Não",Rani!C10, "") -> Havengul Laboratory | F10: Karn Liberated | G10: =IF(Sisay!D10="Não",Sisay!C10, "") | K10: =IF(OWA!D10="Não",OWA!C10, "") -> Scattered Groves | N10: Spark Double | O10: =IF(Narset!D10="Não",Narset!C10,"") -> Training Center | R10: Singer of Swift Rivers | S10: =IF(Kumena!D10="Não",Kumena!C10,"") | V10: Oathsworn Vampire | W10: =IF(Zimone!D10="Não",Zimone!C10,"") -> Bala Ged Recovery
B11: Life of the Party | C11: =IF(Rani!D11="Não",Rani!C11, "") -> Bojuka Bog | F11: Freyalise, Llanowar's Fury | G11: =IF(Sisay!D11="Não",Sisay!C11, "") | K11: =IF(OWA!D11="Não",OWA!C11, "") | N11: Sol Ring | O11: =IF(Narset!D11="Não",Narset!C11,"") -> Spectator Seating | R11: Simic Charm | S11: =IF(Kumena!D11="Não",Kumena!C11,"") | V11: Misty Rainforest | W11: =IF(Zimone!D11="Não",Zimone!C11,"")
B12: Havengul Laboratory | C12: =IF(Rani!D12="Não",Rani!C12, "") -> Reliquary Tower | F12: Elspeth, Sun's Champion | G12: =IF(Sisay!D12="Não",Sisay!C12, "") | K12: =IF(OWA!D12="Não",OWA!C12, "") | N12: Sokenzan, Crucible of Defiance | O12: =IF(Narset!D12="Não",Narset!C12,"") | R12: Seahunter | S12: =IF(Kumena!D12="Não",Kumena!C12,"") | V12: Marvin, Murderous Mimic | W12: =IF(Zimone!D12="Não",Zimone!C12,"")
B13: Gallifrey Council Chamber | C13: =IF(Rani!D13="Não",Rani!C13, "") -> Access Tunnel | F13: Commodore Guff | G13: =IF(Sisay!D13="Não",Sisay!C13, "") | K13: =IF(OWA!D13="Não",OWA!C13, "") | N13: Smuggler's Share | O13: =IF(Narset!D13="Não",Narset!C13,"") -> Clifftop Retreat | R13: Reliquary Tower | S13: =IF(Kumena!D13="Não",Kumena!C13,"") | V13: Jadar, Ghoulcaller of Nephalia | W13: =IF(Zimone!D13="Não",Zimone!C13,"")
B14: Frenzied Gorespawn | C14: =IF(Rani!D14="Não",Rani!C14, "") | G14: =IF(Sisay!D14="Não",Sisay!C14, "") | K14: =IF(OWA!D14="Não",OWA!C14, "") | N14: Slayers' Stronghold | O14: =IF(Narset!D14="Não",Narset!C14,"") | R14: Metallic Mimic | S14: =IF(Kumena!D14="Não",Kumena!C14,"") | V14: Horizon Explorer | W14: =IF(Zimone!D14="Não",Zimone!C14,"") -> Zagoth Triome
B15: Fellwar Stone | C15: =IF(Rani!D15="Não",Rani!C15, "") -> Drowned Catacomb | G15: =IF(Sisay!D15="Não",Sisay!C15, "") | K15: =IF(OWA!D15="Não",OWA!C15, "") | N15: Slash the Ranks | O15: =IF(Narset!D15="Não",Narset!C15,"") | R15: Merrow Harbinger | S15: =IF(Kumena!D15="Não",Kumena!C15,"") | V15: Grave Pact | W15: =IF(Zimone!D15="Não",Zimone!C15,"")
B16: Equilíbrio de Poderes | C16: =IF(Rani!D16="Não",Rani!C16, "") -> Sulfur Falls | G16: =IF(Sisay!D16="Não",Sisay!C16, "") | K16: =IF(OWA!D16="Não",OWA!C16, "") | N16: Sea of Clouds | O16: =IF(Narset!D16="Não",Narset!C16,"") | R16: Merrow Commerce | S16: =IF(Kumena!D16="Não",Kumena!C16,"") | V16: Fabled Passage | W16: =IF(Zimone!D16="Não",Zimone!C16,"") -> Breeding Pool
B17: Dúplice Debochada | C17: =IF(Rani!D17="Não",Rani!C17, "") -> Gallifrey Council Chamber | G17: =IF(Sisay!D17="Não",Sisay!C17, "") | K17: =IF(OWA!D17="Não",OWA!C17, "") | N17: Sculpted Sunburst | O17: =IF(Narset!D17="Não",Narset!C17,"") -> Adarkar Wastes | R17: Master of the Pearl Trident | S17: =IF(Kumena!D17="Não",Kumena!C17,"") | V17: Breeding Pool | W17: =IF(Zimone!D17="Não",Zimone!C17,"")
B18: Drowned Catacomb | C18: =IF(Rani!D18="Não",Rani!C18, "") | G18: =IF(Sisay!D18="Não",Sisay!C18, "") | K18: =IF(OWA!D18="Não",OWA!C18, "") | N18: Relentless Assault | O18: =IF(Narset!D18="Não",Narset!C18,"") | R18: Lullmage Mentor | S18: =IF(Kumena!D18="Não",Kumena!C18,"") | V18: Bloodstained Mire | W18: =IF(Zimone!D18="Não",Zimone!C18,"") -> Bloodstained Mire
B19: Cyber Conversion | C19: =IF(Rani!D85="Não",Rani!C85, "") | G19: =IF(Sisay!D19="Não",Sisay!C19, "") | K19: =IF(OWA!D19="Não",OWA!C19, "") | N19: Reforge the Soul | O19: =IF(Narset!D19="Não",Narset!C19,"") | R19: Lord of Atlantis | S19: =IF(Kumena!D19="Não",Kumena!C19,"") | V19: Bala Ged Recovery | W19: =IF(Zimone!D19="Não",Zimone!C19,"") -> Scalding Tarn
B20: Counterspell | C20: =IF(Rani!D19="Não",Rani!C19, "") | G20: =IF(Sisay!D20="Não",Sisay!C20, "") | K20: =IF(OWA!D20="Não",OWA!C20, "") | N20: Psychic Corrosion | O20: =IF(Narset!D20="Não",Narset!C20,"") | R20: Kodama's Reach | S20: =IF(Kumena!D20="Não",Kumena!C20,"") | V20: Ancient Greenwarden | W20: =IF(Zimone!D20="Não",Zimone!C20,"") -> Polluted Delta
B21: Bojuka Bog | C21: =IF(Rani!D20="Não",Rani!C20, "") | G21: =IF(Sisay!D21="Não",Sisay!C21, "") | K21: =IF(OWA!D21="Não",OWA!C21, "") | N21: Monastery Siege | O21: =IF(Narset!D21="Não",Narset!C21,"") | R21: Herald of Secret Streams | S21: =IF(Kumena!D21="Não",Kumena!C21,"") | W21: =IF(Zimone!D21="Não",Zimone!C21,"")
B22: Archway of Innovation | C22: =IF(Rani!D21="Não",Rani!C21, "") | G22: =IF(Sisay!D22="Não",Sisay!C22, "") | K22: =IF(OWA!D22="Não",OWA!C22, "") | N22: Memory Erosion | O22: =IF(Narset!D22="Não",Narset!C22,"") -> Jidoor, Aristocratic Capital | R22: Harvest Season | S22: =IF(Kumena!D22="Não",Kumena!C22,"") | W22: =IF(Zimone!D22="Não",Zimone!C22,"")
B23: Access Tunnel | C23: =IF(Rani!D22="Não",Rani!C22, "") | G23: =IF(Sisay!D23="Não",Sisay!C23, "") | K23: =IF(OWA!D23="Não",OWA!C23, "") | N23: Maddening Cacophony | O23: =IF(Narset!D23="Não",Narset!C23,"") | R23: Hakbal da Alma Crescente | S23: =IF(Kumena!D23="Não",Kumena!C23,"") | W23: =IF(Zimone!D23="Não",Zimone!C23,"")
C24: =IF(Rani!D23="Não",Rani!C23, "") | G24: =IF(Sisay!D24="Não",Sisay!C24, "") | K24: =IF(OWA!D24="Não",OWA!C24, "") | N24: Lightning Greaves | O24: =IF(Narset!D24="Não",Narset!C24,"") | R24: Emperor Mihail II | S24: =IF(Kumena!D24="Não",Kumena!C24,"") | W24: =IF(Zimone!D24="Não",Zimone!C24,"")
C25: =IF(Rani!D24="Não",Rani!C24, "") | G25: =IF(Sisay!D25="Não",Sisay!C25, "") | K25: =IF(OWA!D25="Não",OWA!C25, "") | N25: Khorvath's Fury | O25: =IF(Narset!D25="Não",Narset!C25,"") | R25: Deeproot Historian | S25: =IF(Kumena!D25="Não",Kumena!C25,"") | W25: =IF(Zimone!D25="Não",Zimone!C25,"")
C26: =IF(Rani!D25="Não",Rani!C25, "") | G26: =IF(Sisay!D26="Não",Sisay!C26, "") | K26: =IF(OWA!D26="Não",OWA!C26, "") | N26: Jidoor, Aristocratic Capital | O26: =IF(Narset!D26="Não",Narset!C26,"") | R26: Coralhelm Commander | S26: =IF(Kumena!D26="Não",Kumena!C26,"") | W26: =IF(Zimone!D26="Não",Zimone!C26,"") -> Misty Rainforest
C27: =IF(Rani!D26="Não",Rani!C26, "") | G27: =IF(Sisay!D27="Não",Sisay!C27, "") | K27: =IF(OWA!D27="Não",OWA!C27, "") -> Susur Secundi, Void Altar | N27: Irenicus's Vile Duplication | O27: =IF(Narset!D27="Não",Narset!C27,"") | R27: Command Tower | S27: =IF(Kumena!D27="Não",Kumena!C27,"") | W27: =IF(Zimone!D27="Não",Zimone!C27,"")
C28: =IF(Rani!D27="Não",Rani!C27, "") | G28: =IF(Sisay!D28="Não",Sisay!C28, "") | K28: =IF(OWA!D28="Não",OWA!C28, "") | N28: Incendiary Command | O28: =IF(Narset!D28="Não",Narset!C28,"") | R28: Call to the Kindred | S28: =IF(Kumena!D28="Não",Kumena!C28,"") | W28: =IF(Zimone!D28="Não",Zimone!C28,"")
C29: =IF(Rani!D28="Não",Rani!C28, "") | G29: =IF(Sisay!D29="Não",Sisay!C29, "") | K29: =IF(OWA!D30="Não",OWA!C30, "") | N29: Ghostly Prison | O29: =IF(Narset!D29="Não",Narset!C29,"") | R29: Beast Within | S29: =IF(Kumena!D29="Não",Kumena!C29,"") | W29: =IF(Zimone!D29="Não",Zimone!C29,"")
C30: =IF(Rani!D29="Não",Rani!C29, "") | G30: =IF(Sisay!D30="Não",Sisay!C30, "") | K30: =IF(OWA!D31="Não",OWA!C31, "") | N30: Genji Glove | O30: =IF(Narset!D30="Não",Narset!C30,"") | S30: =IF(Kumena!D30="Não",Kumena!C30,"") | W30: =IF(Zimone!D30="Não",Zimone!C30,"")
C31: =IF(Rani!D30="Não",Rani!C30, "") | G31: =IF(Sisay!D31="Não",Sisay!C31, "") | K31: =IF(OWA!D32="Não",OWA!C32, "") | N31: Full Throttle | O31: =IF(Narset!D31="Não",Narset!C31,"") | S31: =IF(Kumena!D31="Não",Kumena!C31,"") | W31: =IF(Zimone!D31="Não",Zimone!C31,"")
C32: =IF(Rani!D31="Não",Rani!C31, "") | G32: =IF(Sisay!D32="Não",Sisay!C32, "") | K32: =IF(OWA!D33="Não",OWA!C33, "") | N32: Clifftop Retreat | O32: =IF(Narset!D32="Não",Narset!C32,"") | S32: =IF(Kumena!D32="Não",Kumena!C32,"") | W32: =IF(Zimone!D33="Não",Zimone!C33,"")
C33: =IF(Rani!D32="Não",Rani!C32, "") | G33: =IF(Sisay!D33="Não",Sisay!C33, "") | K33: =IF(OWA!D69="Não",OWA!C69, "") | N33: Aligned Heart | O33: =IF(Narset!D33="Não",Narset!C33,"") | S33: =IF(Kumena!D33="Não",Kumena!C33,"") | W33: =IF(Zimone!D34="Não",Zimone!C34,"")
C34: =IF(Rani!D33="Não",Rani!C33, "") | G34: =IF(Sisay!D34="Não",Sisay!C34, "") | K34: =IF(OWA!D34="Não",OWA!C34, "") | N34: Adarkar Wastes | O34: =IF(Narset!D34="Não",Narset!C34,"") | S34: =IF(Kumena!D34="Não",Kumena!C34,"") | W34: =IF(Zimone!D35="Não",Zimone!C35,"")
C35: =IF(Rani!D34="Não",Rani!C34, "") | G35: =IF(Sisay!D35="Não",Sisay!C35, "") | K35: =IF(OWA!D35="Não",OWA!C35, "") | O35: =IF(Narset!D35="Não",Narset!C35,"") | S35: =IF(Kumena!D35="Não",Kumena!C35,"") | W35: =IF(Zimone!D36="Não",Zimone!C36,"")
C36: =IF(Rani!D35="Não",Rani!C35, "") | G36: =IF(Sisay!D36="Não",Sisay!C36, "") | K36: =IF(OWA!D37="Não",OWA!C37, "") | O36: =IF(Narset!D36="Não",Narset!C36,"") | S36: =IF(Kumena!D36="Não",Kumena!C36,"") -> Sol Ring | W36: =IF(Zimone!D37="Não",Zimone!C37,"")
C37: =IF(Rani!D36="Não",Rani!C36, "") | G37: =IF(Sisay!D37="Não",Sisay!C37, "") | K37: =IF(OWA!D65="Não",OWA!C65, "") | O37: =IF(Narset!D37="Não",Narset!C37,"") | S37: =IF(Kumena!D37="Não",Kumena!C37,"") | W37: =IF(Zimone!D38="Não",Zimone!C38,"")
C38: =IF(Rani!D37="Não",Rani!C37, "") | G38: =IF(Sisay!D38="Não",Sisay!C38, "") | K38: =IF(OWA!D38="Não",OWA!C38, "") | O38: =IF(Narset!D38="Não",Narset!C38,"") -> Sol Ring | S38: =IF(Kumena!D38="Não",Kumena!C38,"") | W38: =IF(Zimone!D39="Não",Zimone!C39,"")
